Workbook

Sheet Setup
A1: Field | B1: Value
A2: reviewerId | B2: R_A
A3: reviewerName (optional)
A4: reviewerRole | B4: R_A
A5: year | B5: 2024

Sheet Checks
A1: Check | B1: Result
A2: Reviewer role | B2: =Setup!B4
A3: Candidates | B3: 113
A4: Primary ready rows | B4: =COUNTIF('C_jama.2024.0318'!$G$2:$G$15,"PRIMARY READY")+COUNTIF('C_jama.2024.0572'!$G$2:$G$20,"PRIMARY READY")+COUNTIF('C_jama.2024.11057'!$G$2:$G$6,"PRIMARY READY")+COUNTIF('C_jama.2024.12829'!$G$2:$G$8,"PRIMARY READY")+COUNTIF('C_jama.2024.19585'!$G$2:$G$8,"PRIMARY READY")+COUNTIF('C_jama.2024.2302'!$G$2:$G$7,"PRIMARY READY")+COUNTIF('C_jama.2024.23898'!$G$2:$G$14,"PRIMARY READY")+COUNTIF('C_jama.2024.25786'!$G$2:$G$16,"PRIMARY READY")+COUNTIF('C_jama.2024.4183'!$G$2:$G$15,"PRIMARY READY")+COUNTIF('C_jama.2024.6063'!$G$2:$G$14,"PRIMARY READY")
A5: Discuss / unresolved rows | B5: =COUNTIF('C_jama.2024.0318'!$D$2:$D$15,"discuss")+COUNTIF('C_jama.2024.0572'!$D$2:$D$20,"discuss")+COUNTIF('C_jama.2024.11057'!$D$2:$D$6,"discuss")+COUNTIF('C_jama.2024.12829'!$D$2:$D$8,"discuss")+COUNTIF('C_jama.2024.19585'!$D$2:$D$8,"discuss")+COUNTIF('C_jama.2024.2302'!$D$2:$D$7,"discuss")+COUNTIF('C_jama.2024.23898'!$D$2:$D$14,"discuss")+COUNTIF('C_jama.2024.25786'!$D$2:$D$16,"discuss")+COUNTIF('C_jama.2024.4183'!$D$2:$D$15,"discuss")+COUNTIF('C_jama.2024.6063'!$D$2:$D$14,"discuss")
A6: Unfinished rows | B6: =B3-B4
A7: Workflow status | B7: =IF(B4=B3,"PRIMARY READY","ACTION NEEDED")
A8: Meaning | B8: PRIMARY READY means independent entry is complete. Discuss remains unresolved and is not counted as absence of error.
A9: Next action | B9: Inspect G on the C_ sheets. Save and deliver this file after review.

Sheet Papers
A1: Paper | B1: Review worksheet | C1: Candidates
A2: jama.2024.0318 | B2: C_jama.2024.0318 | C2: 14
A3: jama.2024.0572 | B3: C_jama.2024.0572 | C3: 19
A4: jama.2024.11057 | B4: C_jama.2024.11057 | C4: 5
A5: jama.2024.12829 | B5: C_jama.2024.12829 | C5: 7
A6: jama.2024.19585 | B6: C_jama.2024.19585 | C6: 7
A7: jama.2024.2302 | B7: C_jama.2024.2302 | C7: 6
A8: jama.2024.23898 | B8: C_jama.2024.23898 | C8: 13
A9: jama.2024.25786 | B9: C_jama.2024.25786 | C9: 15
A10: jama.2024.4183 | B10: C_jama.2024.4183 | C10: 14
A11: jama.2024.6063 | B11: C_jama.2024.6063 | C11: 13

Sheet C_jama.2024.0318
A1: Candidate key | B1: Candidate title | C1: Source location | D1: Disposition | E1: Review domain (AI suggestion; editable) | F1: Complete | G1: Validation hint | H1: Statistical_or_numerical issue | I1: Substantiveness | J1: Downstream impact | K1: Report-internal or planning-material inconsistency | L1: Protocol interpretation | R1: Notes (optional)
A2: 2024::jama.2024.0318::C001 | B2: Positive HbA1c point and signed interval | C2: every affected occurrence: jama_courcoulas_2024_oi_240004_1721756962.76052.pdf — main p1 abstract, jama_courcoulas_2024_oi_240004_1721756962.76052.pdf — main p3 Results paragraph, and jama_courcoulas_2024_oi_240004_1721756962.76052.pdf — main p6 Table 2 HbA1c row and footnote b; all REPORT by published result content. | D2: retain | E2: statistical_results | F2: primary_done | G2: =IFERROR(IF(LEN(TRIM(CLEAN(SUBSTITUTE(Setup!$B$2,CHAR(160)," "))))=0,"CHECK REVIEWER ID",IF(OR(A2="",COUNTIF($A$2:$A$15,A2)<>1,LEFT(A2,LEN("2024::jama.2024.0318::"))<>"2024::jama.2024.0318::"),"CHECK KEY",IF(OR(AND(NOT(AND(D2="retain",E2="statistical_results")),H2<>"",NOT(EXACT(H2,"not_applicable"))),AND(NOT(AND(D2="retain",E2="statistical_results")),I2<>"",NOT(EXACT(I2,"not_applicable"))),AND(NOT(AND(D2="retain",E2="statistical_results")),J2<>"",NOT(EXACT(J2,"not_applicable"))),AND(NOT(AND(D2="retain",OR(E2="report_internal_inconsistency",E2="plan_material"))),K2<>"",NOT(EXACT(K2,"not_applicable"))),AND(NOT(AND(D2="retain",E2="protocol_report")),L2<>"",NOT(EXACT(L2,"not_applicable")))),"CLEAR INACTIVE VALUES",IF(OR(NOT(OR(EXACT(D2,"retain"),EXACT(D2,"exclude"),EXACT(D2,"discuss"))),NOT(OR(EXACT(E2,"statistical_results"),EXACT(E2,"report_internal_inconsistency"),EXACT(E2,"plan_material"),EXACT(E2,"protocol_report"))),AND(AND(D2="retain",E2="statistical_results"),NOT(OR(EXACT(H2,"confirmed_issue"),EXACT(H2,"probable_issue"),EXACT(H2,"not_issue"),EXACT(H2,"indeterminate")))),AND(AND(D2="retain",E2="statistical_results"),NOT(OR(EXACT(I2,"substantive"),EXACT(I2,"minor_presentation"),EXACT(I2,"indeterminate")))),AND(AND(D2="retain",E2="statistical_results"),J2<>"",NOT(OR(EXACT(J2,"direct"),EXACT(J2,"possible"),EXACT(J2,"unlikely"),EXACT(J2,"unknown")))),AND(AND(D2="retain",OR(E2="report_internal_inconsistency",E2="plan_material")),NOT(OR(EXACT(K2,"substantive_inconsistency"),EXACT(K2,"minor_presentation"),EXACT(K2,"non_inconsistency"),EXACT(K2,"indeterminate")))),AND(AND(D2="retain",E2="protocol_report"),L2<>"",NOT(OR(EXACT(L2,"substantive_difference"),EXACT(L2,"minor_presentation"),EXACT(L2,"version_timing"),EXACT(L2,"non_inconsistency"),EXACT(L2,"indeterminate"))))),"CHECK FIELDS",IF(AND(F2<>"",NOT(OR(EXACT(F2,"no"),EXACT(F2,"primary_done")))),"CHECK COMPLETE",IF(EXACT(F2,"primary_done"),"PRIMARY READY","PRIMARY DRAFT")))))),"CHECK INPUT / KEY") | H2: confirmed_issue | I2: minor_presentation | J2: unlikely | K2: =IF(AND(OR(D2="retain",D2=""),OR(E2="report_internal_inconsistency",E2="plan_material")),"","not_applicable") | L2: =IF(AND(OR(D2="retain",D2=""),E2="protocol_report"),"","not_applicable") | R2: Main p1 abstract and p3 Results give HbA1c changes as unsigned 0.2% and 1.6% with signed CIs (-0.5 to 0.2; -1.8 to -1.3); +1.6 lies outside its CI. Table 2 p6 (rendered) prints -0.2 and -1.6 with the same CIs, so the intended signed values are recoverable. Sign presentation error, not a numerical error.
A3: 2024::jama.2024.0318::C002 | B3: Year-12 HbA1c P value | C3: jama_courcoulas_2024_oi_240004_1721756962.76052.pdf — main p1 abstract, jama_courcoulas_2024_oi_240004_1721756962.76052.pdf — main p3 year-12 result, joi240004supp2_prod_1721756962.82552.pdf — supplement p15 eTable 2 HbA1c row, and joi240004supp2_prod_1721756962.82552.pdf — supplement p4 ITT model/visit contrasts; all REPORT. Contextual correction notice: jama_courcoulas_2024_oi_240004_1721756962.76052.pdf — main p9 registry-link correction. | D3: retain | E3: statistical_results | F3: primary_done | G3: =IFERROR(IF(LEN(TRIM(CLEAN(SUBSTITUTE(Setup!$B$2,CHAR(160)," "))))=0,"CHECK REVIEWER ID",IF(OR(A3="",COUNTIF($A$2:$A$15,A3)<>1,LEFT(A3,LEN("2024::jama.2024.0318::"))<>"2024::jama.2024.0318::"),"CHECK KEY",IF(OR(AND(NOT(AND(D3="retain",E3="statistical_results")),H3<>"",NOT(EXACT(H3,"not_applicable"))),AND(NOT(AND(D3="retain",E3="statistical_results")),I3<>"",NOT(EXACT(I3,"not_applicable"))),AND(NOT(AND(D3="retain",E3="statistical_results")),J3<>"",NOT(EXACT(J3,"not_applicable"))),AND(NOT(AND(D3="retain",OR(E3="report_internal_inconsistency",E3="plan_material"))),K3<>"",NOT(EXACT(K3,"not_applicable"))),AND(NOT(AND(D3="retain",E3="protocol_report")),L3<>"",NOT(EXACT(L3,"not_applicable")))),"CLEAR INACTIVE VALUES",IF(OR(NOT(OR(EXACT(D3,"retain"),EXACT(D3,"exclude"),EXACT(D3,"discuss"))),NOT(OR(EXACT(E3,"statistical_results"),EXACT(E3,"report_internal_inconsistency"),EXACT(E3,"plan_material"),EXACT(E3,"protocol_report"))),AND(AND(D3="retain",E3="statistical_results"),NOT(OR(EXACT(H3,"confirmed_issue"),EXACT(H3,"probable_issue"),EXACT(H3,"not_issue"),EXACT(H3,"indeterminate")))),AND(AND(D3="retain",E3="statistical_results"),NOT(OR(EXACT(I3,"substantive"),EXACT(I3,"minor_presentation"),EXACT(I3,"indeterminate")))),AND(AND(D3="retain",E3="statistical_results"),J3<>"",NOT(OR(EXACT(J3,"direct"),EXACT(J3,"possible"),EXACT(J3,"unlikely"),EXACT(J3,"unknown")))),AND(AND(D3="retain",OR(E3="report_internal_inconsistency",E3="plan_material")),NOT(OR(EXACT(K3,"substantive_inconsistency"),EXACT(K3,"minor_presentation"),EXACT(K3,"non_inconsistency"),EXACT(K3,"indeterminate")))),AND(AND(D3="retain",E3="protocol_report"),L3<>"",NOT(OR(EXACT(L3,"substantive_difference"),EXACT(L3,"minor_presentation"),EXACT(L3,"version_timing"),EXACT(L3,"non_inconsistency"),EXACT(L3,"indeterminate"))))),"CHECK FIELDS",IF(AND(F3<>"",NOT(OR(EXACT(F3,"no"),EXACT(F3,"primary_done")))),"CHECK COMPLETE",IF(EXACT(F3,"primary_done"),"PRIMARY READY","PRIMARY DRAFT")))))),"CHECK INPUT / KEY") | H3: confirmed_issue | I3: minor_presentation | J3: unlikely | K3: =IF(AND(OR(D3="retain",D3=""),OR(E3="report_internal_inconsistency",E3="plan_material")),"","not_applicable") | L3: =IF(AND(OR(D3="retain",D3=""),E3="protocol_report"),"","not_applicable") | R3: Year-12 HbA1c difference -1.1 (95% CI -1.7 to -0.5) has P=.002 in main p1/p3 but P<.001 in eTable 2 (supp2 p15). CI-implied P (Wald) = 0.00033; over all rounding-consistent limits with estimate at the midpoint, max P = 0.0009, so .002 is incompatible with the printed CI. Both significant; interpretation unchanged.
A4: 2024::jama.2024.0318::C003 | B4: Pooled mortality percentage | C4: jama_courcoulas_2024_oi_240004_1721756962.76052.pdf — main p1 abstract cohort and deaths, jama_courcoulas_2024_oi_240004_1721756962.76052.pdf — p3 enrolled cohort, jama_courcoulas_2024_oi_240004_1721756962.76052.pdf — p4 Table 1 headers, jama_courcoulas_2024_oi_240004_1721756962.76052.pdf — p7 death paragraph, and jama_courcoulas_2024_oi_240004_1721756962.76052.pdf — p8 Table 3 headers/Death row/footnote; all REPORT. | D4: retain | E4: statistical_results | F4: primary_done | G4: =IFERROR(IF(LEN(TRIM(CLEAN(SUBSTITUTE(Setup!$B$2,CHAR(160)," "))))=0,"CHECK REVIEWER ID",IF(OR(A4="",COUNTIF($A$2:$A$15,A4)<>1,LEFT(A4,LEN("2024::jama.2024.0318::"))<>"2024::jama.2024.0318::"),"CHECK KEY",IF(OR(AND(NOT(AND(D4="retain",E4="statistical_results")),H4<>"",NOT(EXACT(H4,"not_applicable"))),AND(NOT(AND(D4="retain",E4="statistical_results")),I4<>"",NOT(EXACT(I4,"not_applicable"))),AND(NOT(AND(D4="retain",E4="statistical_results")),J4<>"",NOT(EXACT(J4,"not_applicable"))),AND(NOT(AND(D4="retain",OR(E4="report_internal_inconsistency",E4="plan_material"))),K4<>"",NOT(EXACT(K4,"not_applicable"))),AND(NOT(AND(D4="retain",E4="protocol_report")),L4<>"",NOT(EXACT(L4,"not_applicable")))),"CLEAR INACTIVE VALUES",IF(OR(NOT(OR(EXACT(D4,"retain"),EXACT(D4,"exclude"),EXACT(D4,"discuss"))),NOT(OR(EXACT(E4,"statistical_results"),EXACT(E4,"report_internal_inconsistency"),EXACT(E4,"plan_material"),EXACT(E4,"protocol_report"))),AND(AND(D4="retain",E4="statistical_results"),NOT(OR(EXACT(H4,"confirmed_issue"),EXACT(H4,"probable_issue"),EXACT(H4,"not_issue"),EXACT(H4,"indeterminate")))),AND(AND(D4="retain",E4="statistical_results"),NOT(OR(EXACT(I4,"substantive"),EXACT(I4,"minor_presentation"),EXACT(I4,"indeterminate")))),AND(AND(D4="retain",E4="statistical_results"),J4<>"",NOT(OR(EXACT(J4,"direct"),EXACT(J4,"possible"),EXACT(J4,"unlikely"),EXACT(J4,"unknown")))),AND(AND(D4="retain",OR(E4="report_internal_inconsistency",E4="plan_material")),NOT(OR(EXACT(K4,"substantive_inconsistency"),EXACT(K4,"minor_presentation"),EXACT(K4,"non_inconsistency"),EXACT(K4,"indeterminate")))),AND(AND(D4="retain",E4="protocol_report"),L4<>"",NOT(OR(EXACT(L4,"substantive_difference"),EXACT(L4,"minor_presentation"),EXACT(L4,"version_timing"),EXACT(L4,"non_inconsistency"),EXACT(L4,"indeterminate"))))),"CHECK FIELDS",IF(AND(F4<>"",NOT(OR(EXACT(F4,"no"),EXACT(F4,"primary_done")))),"CHECK COMPLETE",IF(EXACT(F4,"primary_done"),"PRIMARY READY","PRIMARY DRAFT")))))),"CHECK INPUT / KEY") | H4: confirmed_issue | I4: substantive | J4: possible | K4: =IF(AND(OR(D4="retain",D4=""),OR(E4="report_internal_inconsistency",E4="plan_material")),"","not_applicable") | L4: =IF(AND(OR(D4="retain",D4=""),E4="protocol_report"),"","not_applicable") | R4: Abstract p1: '4 deaths (2.2%), 2 in each group' among 262 enrolled. 4/262 = 1.53%; Table 3 p8 gives 2/96 (2.1%) and 2/166 (1.2%), both correct. No denominator in the paper yields 2.2% for 4 deaths. The abstract percentage overstates pooled mortality.
A5: 2024::jama.2024.0318::C004 | B5: Primary HbA1c response scale | C5: PLAN joi240004supp1_prod_1721756962.80052.pdf — p17 primary endpoint, joi240004supp1_prod_1721756962.80052.pdf — p26 A1 response, joi240004supp1_prod_1721756962.80052.pdf — p27 hypothesis/power assumptions, joi240004supp1_prod_1721756962.80052.pdf — p29 Table A1/Figure A1; REPORT jama_courcoulas_2024_oi_240004_1721756962.76052.pdf — main p2 outcome/statistical methods, jama_courcoulas_2024_oi_240004_1721756962.76052.pdf — main p6 Table 2/footnotes, joi240004supp2_prod_1721756962.82552.pdf — supplement p4 primary model, joi240004supp2_prod_1721756962.82552.pdf — p15 eTable 2/footnote b, joi240004supp2_prod_1721756962.82552.pdf — p16 continued footnote c. | D5: retain | E5: protocol_report | F5: primary_done | G5: =IFERROR(IF(LEN(TRIM(CLEAN(SUBSTITUTE(Setup!$B$2,CHAR(160)," "))))=0,"CHECK REVIEWER ID",IF(OR(A5="",COUNTIF($A$2:$A$15,A5)<>1,LEFT(A5,LEN("2024::jama.2024.0318::"))<>"2024::jama.2024.0318::"),"CHECK KEY",IF(OR(AND(NOT(AND(D5="retain",E5="statistical_results")),H5<>"",NOT(EXACT(H5,"not_applicable"))),AND(NOT(AND(D5="retain",E5="statistical_results")),I5<>"",NOT(EXACT(I5,"not_applicable"))),AND(NOT(AND(D5="retain",E5="statistical_results")),J5<>"",NOT(EXACT(J5,"not_applicable"))),AND(NOT(AND(D5="retain",OR(E5="report_internal_inconsistency",E5="plan_material"))),K5<>"",NOT(EXACT(K5,"not_applicable"))),AND(NOT(AND(D5="retain",E5="protocol_report")),L5<>"",NOT(EXACT(L5,"not_applicable")))),"CLEAR INACTIVE VALUES",IF(OR(NOT(OR(EXACT(D5,"retain"),EXACT(D5,"exclude"),EXACT(D5,"discuss"))),NOT(OR(EXACT(E5,"statistical_results"),EXACT(E5,"report_internal_inconsistency"),EXACT(E5,"plan_material"),EXACT(E5,"protocol_report"))),AND(AND(D5="retain",E5="statistical_results"),NOT(OR(EXACT(H5,"confirmed_issue"),EXACT(H5,"probable_issue"),EXACT(H5,"not_issue"),EXACT(H5,"indeterminate")))),AND(AND(D5="retain",E5="statistical_results"),NOT(OR(EXACT(I5,"substantive"),EXACT(I5,"minor_presentation"),EXACT(I5,"indeterminate")))),AND(AND(D5="retain",E5="statistical_results"),J5<>"",NOT(OR(EXACT(J5,"direct"),EXACT(J5,"possible"),EXACT(J5,"unlikely"),EXACT(J5,"unknown")))),AND(AND(D5="retain",OR(E5="report_internal_inconsistency",E5="plan_material")),NOT(OR(EXACT(K5,"substantive_inconsistency"),EXACT(K5,"minor_presentation"),EXACT(K5,"non_inconsistency"),EXACT(K5,"indeterminate")))),AND(AND(D5="retain",E5="protocol_report"),L5<>"",NOT(OR(EXACT(L5,"substantive_difference"),EXACT(L5,"minor_presentation"),EXACT(L5,"version_timing"),EXACT(L5,"non_inconsistency"),EXACT(L5,"indeterminate"))))),"CHECK FIELDS",IF(AND(F5<>"",NOT(OR(EXACT(F5,"no"),EXACT(F5,"primary_done")))),"CHECK COMPLETE",IF(EXACT(F5,"primary_done"),"PRIMARY READY","PRIMARY DRAFT")))))),"CHECK INPUT / KEY") | H5: =IF(AND(OR(D5="retain",D5=""),E5="statistical_results"),"","not_applicable") | I5: =IF(AND(OR(D5="retain",D5=""),E5="statistical_results"),"","not_applicable") | J5: =IF(AND(OR(D5="retain",D5=""),E5="statistical_results"),"","not_applicable") | K5: =IF(AND(OR(D5="retain",D5=""),OR(E5="report_internal_inconsistency",E5="plan_material")),"","not_applicable") | L5: substantive_difference | R5: Plan (supp1 p17, p26-27, p29 Table A1, Fig A1) defines the primary outcome as relative percent change in HbA1c (power: -15% vs -7% to +2%). Report Table 2 footnote b and eTable 2 present net (absolute) change for HbA1c (-1.4 points), while main p2 still says 'percent change'. The reported primary scale differs from the planned one.
A6: 2024::jama.2024.0318::C005 | B6: Remission medication-free window | C6: PLAN joi240004supp1_prod_1721756962.80052.pdf — p18 remission item 2, joi240004supp1_prod_1721756962.80052.pdf — p29 Table A1 remission row; REPORT jama_courcoulas_2024_oi_240004_1721756962.76052.pdf — main p2 remission definition, jama_courcoulas_2024_oi_240004_1721756962.76052.pdf — p1 abstract remission rates, jama_courcoulas_2024_oi_240004_1721756962.76052.pdf — p7 Figure 3/caption. The associated reported OR is found in jama_courcoulas_2024_oi_240004_1721756962.76052.pdf — main p6 Table 2. | D6: retain | E6: protocol_report | F6: primary_done | G6: =IFERROR(IF(LEN(TRIM(CLEAN(SUBSTITUTE(Setup!$B$2,CHAR(160)," "))))=0,"CHECK REVIEWER ID",IF(OR(A6="",COUNTIF($A$2:$A$15,A6)<>1,LEFT(A6,LEN("2024::jama.2024.0318::"))<>"2024::jama.2024.0318::"),"CHECK KEY",IF(OR(AND(NOT(AND(D6="retain",E6="statistical_results")),H6<>"",NOT(EXACT(H6,"not_applicable"))),AND(NOT(AND(D6="retain",E6="statistical_results")),I6<>"",NOT(EXACT(I6,"not_applicable"))),AND(NOT(AND(D6="retain",E6="statistical_results")),J6<>"",NOT(EXACT(J6,"not_applicable"))),AND(NOT(AND(D6="retain",OR(E6="report_internal_inconsistency",E6="plan_material"))),K6<>"",NOT(EXACT(K6,"not_applicable"))),AND(NOT(AND(D6="retain",E6="protocol_report")),L6<>"",NOT(EXACT(L6,"not_applicable")))),"CLEAR INACTIVE VALUES",IF(OR(NOT(OR(EXACT(D6,"retain"),EXACT(D6,"exclude"),EXACT(D6,"discuss"))),NOT(OR(EXACT(E6,"statistical_results"),EXACT(E6,"report_internal_inconsistency"),EXACT(E6,"plan_material"),EXACT(E6,"protocol_report"))),AND(AND(D6="retain",E6="statistical_results"),NOT(OR(EXACT(H6,"confirmed_issue"),EXACT(H6,"probable_issue"),EXACT(H6,"not_issue"),EXACT(H6,"indeterminate")))),AND(AND(D6="retain",E6="statistical_results"),NOT(OR(EXACT(I6,"substantive"),EXACT(I6,"minor_presentation"),EXACT(I6,"indeterminate")))),AND(AND(D6="retain",E6="statistical_results"),J6<>"",NOT(OR(EXACT(J6,"direct"),EXACT(J6,"possible"),EXACT(J6,"unlikely"),EXACT(J6,"unknown")))),AND(AND(D6="retain",OR(E6="report_internal_inconsistency",E6="plan_material")),NOT(OR(EXACT(K6,"substantive_inconsistency"),EXACT(K6,"minor_presentation"),EXACT(K6,"non_inconsistency"),EXACT(K6,"indeterminate")))),AND(AND(D6="retain",E6="protocol_report"),L6<>"",NOT(OR(EXACT(L6,"substantive_difference"),EXACT(L6,"minor_presentation"),EXACT(L6,"version_timing"),EXACT(L6,"non_inconsistency"),EXACT(L6,"indeterminate"))))),"CHECK FIELDS",IF(AND(F6<>"",NOT(OR(EXACT(F6,"no"),EXACT(F6,"primary_done")))),"CHECK COMPLETE",IF(EXACT(F6,"primary_done"),"PRIMARY READY","PRIMARY DRAFT")))))),"CHECK INPUT / KEY") | H6: =IF(AND(OR(D6="retain",D6=""),E6="statistical_results"),"","not_applicable") | I6: =IF(AND(OR(D6="retain",D6=""),E6="statistical_results"),"","not_applicable") | J6: =IF(AND(OR(D6="retain",D6=""),E6="statistical_results"),"","not_applicable") | K6: =IF(AND(OR(D6="retain",D6=""),OR(E6="report_internal_inconsistency",E6="plan_material")),"","not_applicable") | L6: indeterminate | R6: Plan supp1 p18 and p29 Table A1 define remission as HbA1c <6.5% without diabetes medications, no duration; main p2 adds 'for at least 3 months, assessed annually'. Difference exists, but the plan defers operational definitions to a Manual of Operations (p18) that was not supplied, so whether the 3-month window is new cannot be settled.
A7: 2024::jama.2024.0318::C006 | B7: Cardiovascular outcome status | C7: PLAN joi240004supp1_prod_1721756962.80052.pdf — p18 secondary list/section 4.4, joi240004supp1_prod_1721756962.80052.pdf — p29 Table A1 Aim 2 efficacy entries, joi240004supp1_prod_1721756962.80052.pdf — p30 Table A1 continuation/safety entry; REPORT jama_courcoulas_2024_oi_240004_1721756962.76052.pdf — main p2 other secondary outcomes, jama_courcoulas_2024_oi_240004_1721756962.76052.pdf — p1 abstract cardiovascular finding, jama_courcoulas_2024_oi_240004_1721756962.76052.pdf — p8 Table 3 cardiovascular rows. | D7: retain | E7: protocol_report | F7: primary_done | G7: =IFERROR(IF(LEN(TRIM(CLEAN(SUBSTITUTE(Setup!$B$2,CHAR(160)," "))))=0,"CHECK REVIEWER ID",IF(OR(A7="",COUNTIF($A$2:$A$15,A7)<>1,LEFT(A7,LEN("2024::jama.2024.0318::"))<>"2024::jama.2024.0318::"),"CHECK KEY",IF(OR(AND(NOT(AND(D7="retain",E7="statistical_results")),H7<>"",NOT(EXACT(H7,"not_applicable"))),AND(NOT(AND(D7="retain",E7="statistical_results")),I7<>"",NOT(EXACT(I7,"not_applicable"))),AND(NOT(AND(D7="retain",E7="statistical_results")),J7<>"",NOT(EXACT(J7,"not_applicable"))),AND(NOT(AND(D7="retain",OR(E7="report_internal_inconsistency",E7="plan_material"))),K7<>"",NOT(EXACT(K7,"not_applicable"))),AND(NOT(AND(D7="retain",E7="protocol_report")),L7<>"",NOT(EXACT(L7,"not_applicable")))),"CLEAR INACTIVE VALUES",IF(OR(NOT(OR(EXACT(D7,"retain"),EXACT(D7,"exclude"),EXACT(D7,"discuss"))),NOT(OR(EXACT(E7,"statistical_results"),EXACT(E7,"report_internal_inconsistency"),EXACT(E7,"plan_material"),EXACT(E7,"protocol_report"))),AND(AND(D7="retain",E7="statistical_results"),NOT(OR(EXACT(H7,"confirmed_issue"),EXACT(H7,"probable_issue"),EXACT(H7,"not_issue"),EXACT(H7,"indeterminate")))),AND(AND(D7="retain",E7="statistical_results"),NOT(OR(EXACT(I7,"substantive"),EXACT(I7,"minor_presentation"),EXACT(I7,"indeterminate")))),AND(AND(D7="retain",E7="statistical_results"),J7<>"",NOT(OR(EXACT(J7,"direct"),EXACT(J7,"possible"),EXACT(J7,"unlikely"),EXACT(J7,"unknown")))),AND(AND(D7="retain",OR(E7="report_internal_inconsistency",E7="plan_material")),NOT(OR(EXACT(K7,"substantive_inconsistency"),EXACT(K7,"minor_presentation"),EXACT(K7,"non_inconsistency"),EXACT(K7,"indeterminate")))),AND(AND(D7="retain",E7="protocol_report"),L7<>"",NOT(OR(EXACT(L7,"substantive_difference"),EXACT(L7,"minor_presentation"),EXACT(L7,"version_timing"),EXACT(L7,"non_inconsistency"),EXACT(L7,"indeterminate"))))),"CHECK FIELDS",IF(AND(F7<>"",NOT(OR(EXACT(F7,"no"),EXACT(F7,"primary_done")))),"CHECK COMPLETE",IF(EXACT(F7,"primary_done"),"PRIMARY READY","PRIMARY DRAFT")))))),"CHECK INPUT / KEY") | H7: =IF(AND(OR(D7="retain",D7=""),E7="statistical_results"),"","not_applicable") | I7: =IF(AND(OR(D7="retain",D7=""),E7="statistical_results"),"","not_applicable") | J7: =IF(AND(OR(D7="retain",D7=""),E7="statistical_results"),"","not_applicable") | K7: =IF(AND(OR(D7="retain",D7=""),OR(E7="report_internal_inconsistency",E7="plan_material")),"","not_applicable") | L7: minor_presentation | R7: Plan Table A1 (supp1 p30) lists 'major adverse cardiovascular events' under Aim 2 Safety; main p2 lists MACE among secondary outcomes. However, plan section 4.3 (p18) already lists 'microvascular or macrovascular events' as secondary and p18 says some study outcomes are also secondary, so the status change is mainly a labeling difference.
A8: 2024::jama.2024.0318::C007 | B8: Primary baseline adjustment | C8: PLAN joi240004supp1_prod_1721756962.80052.pdf — p26 A1 and Z definition, joi240004supp1_prod_1721756962.80052.pdf — p34 further baseline sensitivities; REPORT jama_courcoulas_2024_oi_240004_1721756962.76052.pdf — main p2 fixed-effect list, jama_courcoulas_2024_oi_240004_1721756962.76052.pdf — p3 fixed-effect continuation, joi240004supp2_prod_1721756962.82552.pdf — supplement p4 primary model. | D8: retain | E8: protocol_report | F8: primary_done | G8: =IFERROR(IF(LEN(TRIM(CLEAN(SUBSTITUTE(Setup!$B$2,CHAR(160)," "))))=0,"CHECK REVIEWER ID",IF(OR(A8="",COUNTIF($A$2:$A$15,A8)<>1,LEFT(A8,LEN("2024::jama.2024.0318::"))<>"2024::jama.2024.0318::"),"CHECK KEY",IF(OR(AND(NOT(AND(D8="retain",E8="statistical_results")),H8<>"",NOT(EXACT(H8,"not_applicable"))),AND(NOT(AND(D8="retain",E8="statistical_results")),I8<>"",NOT(EXACT(I8,"not_applicable"))),AND(NOT(AND(D8="retain",E8="statistical_results")),J8<>"",NOT(EXACT(J8,"not_applicable"))),AND(NOT(AND(D8="retain",OR(E8="report_internal_inconsistency",E8="plan_material"))),K8<>"",NOT(EXACT(K8,"not_applicable"))),AND(NOT(AND(D8="retain",E8="protocol_report")),L8<>"",NOT(EXACT(L8,"not_applicable")))),"CLEAR INACTIVE VALUES",IF(OR(NOT(OR(EXACT(D8,"retain"),EXACT(D8,"exclude"),EXACT(D8,"discuss"))),NOT(OR(EXACT(E8,"statistical_results"),EXACT(E8,"report_internal_inconsistency"),EXACT(E8,"plan_material"),EXACT(E8,"protocol_report"))),AND(AND(D8="retain",E8="statistical_results"),NOT(OR(EXACT(H8,"confirmed_issue"),EXACT(H8,"probable_issue"),EXACT(H8,"not_issue"),EXACT(H8,"indeterminate")))),AND(AND(D8="retain",E8="statistical_results"),NOT(OR(EXACT(I8,"substantive"),EXACT(I8,"minor_presentation"),EXACT(I8,"indeterminate")))),AND(AND(D8="retain",E8="statistical_results"),J8<>"",NOT(OR(EXACT(J8,"direct"),EXACT(J8,"possible"),EXACT(J8,"unlikely"),EXACT(J8,"unknown")))),AND(AND(D8="retain",OR(E8="report_internal_inconsistency",E8="plan_material")),NOT(OR(EXACT(K8,"substantive_inconsistency"),EXACT(K8,"minor_presentation"),EXACT(K8,"non_inconsistency"),EXACT(K8,"indeterminate")))),AND(AND(D8="retain",E8="protocol_report"),L8<>"",NOT(OR(EXACT(L8,"substantive_difference"),EXACT(L8,"minor_presentation"),EXACT(L8,"version_timing"),EXACT(L8,"non_inconsistency"),EXACT(L8,"indeterminate"))))),"CHECK FIELDS",IF(AND(F8<>"",NOT(OR(EXACT(F8,"no"),EXACT(F8,"primary_done")))),"CHECK COMPLETE",IF(EXACT(F8,"primary_done"),"PRIMARY READY","PRIMARY DRAFT")))))),"CHECK INPUT / KEY") | H8: =IF(AND(OR(D8="retain",D8=""),E8="statistical_results"),"","not_applicable") | I8: =IF(AND(OR(D8="retain",D8=""),E8="statistical_results"),"","not_applicable") | J8: =IF(AND(OR(D8="retain",D8=""),E8="statistical_results"),"","not_applicable") | K8: =IF(AND(OR(D8="retain",D8=""),OR(E8="report_internal_inconsistency",E8="plan_material")),"","not_applicable") | L8: substantive_difference | R8: Plan model A1 (supp1 p26) has group, visit, group x visit and site (Z = site indicators) as fixed effects; baseline HbA1c appears only among further sensitivity covariates (p34). Report primary model (main p2-3; supp2 p4) adds baseline HbA1c as a fixed effect. Covariate set of the primary model changed; not disclosed as a change.
A9: 2024::jama.2024.0318::C008 | B9: Planned primary sensitivity package not reported | C9: PLAN joi240004supp1_prod_1721756962.80052.pdf — p30 MICE/Rubin/pattern-mixture/crossover sensitivity, joi240004supp1_prod_1721756962.80052.pdf — p31 treatment×censoring weight and postcrossover discard, joi240004supp1_prod_1721756962.80052.pdf — p34 expanded baseline sensitivities; REPORT jama_courcoulas_2024_oi_240004_1721756962.76052.pdf — main p3 methods/sensitivity estimate, jama_courcoulas_2024_oi_240004_1721756962.76052.pdf — p9 limitations, joi240004supp2_prod_1721756962.82552.pdf — supplement p4 model, joi240004supp2_prod_1721756962.82552.pdf — p5 IPW formula/assignment/missingness, joi240004supp2_prod_1721756962.82552.pdf — p6 continuation, joi240004supp2_prod_1721756962.82552.pdf — p9 eFigure 2. | D9: retain | E9: protocol_report | F9: primary_done | G9: =IFERROR(IF(LEN(TRIM(CLEAN(SUBSTITUTE(Setup!$B$2,CHAR(160)," "))))=0,"CHECK REVIEWER ID",IF(OR(A9="",COUNTIF($A$2:$A$15,A9)<>1,LEFT(A9,LEN("2024::jama.2024.0318::"))<>"2024::jama.2024.0318::"),"CHECK KEY",IF(OR(AND(NOT(AND(D9="retain",E9="statistical_results")),H9<>"",NOT(EXACT(H9,"not_applicable"))),AND(NOT(AND(D9="retain",E9="statistical_results")),I9<>"",NOT(EXACT(I9,"not_applicable"))),AND(NOT(AND(D9="retain",E9="statistical_results")),J9<>"",NOT(EXACT(J9,"not_applicable"))),AND(NOT(AND(D9="retain",OR(E9="report_internal_inconsistency",E9="plan_material"))),K9<>"",NOT(EXACT(K9,"not_applicable"))),AND(NOT(AND(D9="retain",E9="protocol_report")),L9<>"",NOT(EXACT(L9,"not_applicable")))),"CLEAR INACTIVE VALUES",IF(OR(NOT(OR(EXACT(D9,"retain"),EXACT(D9,"exclude"),EXACT(D9,"discuss"))),NOT(OR(EXACT(E9,"statistical_results"),EXACT(E9,"report_internal_inconsistency"),EXACT(E9,"plan_material"),EXACT(E9,"protocol_report"))),AND(AND(D9="retain",E9="statistical_results"),NOT(OR(EXACT(H9,"confirmed_issue"),EXACT(H9,"probable_issue"),EXACT(H9,"not_issue"),EXACT(H9,"indeterminate")))),AND(AND(D9="retain",E9="statistical_results"),NOT(OR(EXACT(I9,"substantive"),EXACT(I9,"minor_presentation"),EXACT(I9,"indeterminate")))),AND(AND(D9="retain",E9="statistical_results"),J9<>"",NOT(OR(EXACT(J9,"direct"),EXACT(J9,"possible"),EXACT(J9,"unlikely"),EXACT(J9,"unknown")))),AND(AND(D9="retain",OR(E9="report_internal_inconsistency",E9="plan_material")),NOT(OR(EXACT(K9,"substantive_inconsistency"),EXACT(K9,"minor_presentation"),EXACT(K9,"non_inconsistency"),EXACT(K9,"indeterminate")))),AND(AND(D9="retain",E9="protocol_report"),L9<>"",NOT(OR(EXACT(L9,"substantive_difference"),EXACT(L9,"minor_presentation"),EXACT(L9,"version_timing"),EXACT(L9,"non_inconsistency"),EXACT(L9,"indeterminate"))))),"CHECK FIELDS",IF(AND(F9<>"",NOT(OR(EXACT(F9,"no"),EXACT(F9,"primary_done")))),"CHECK COMPLETE",IF(EXACT(F9,"primary_done"),"PRIMARY READY","PRIMARY DRAFT")))))),"CHECK INPUT / KEY") | H9: =IF(AND(OR(D9="retain",D9=""),E9="statistical_results"),"","not_applicable") | I9: =IF(AND(OR(D9="retain",D9=""),E9="statistical_results"),"","not_applicable") | J9: =IF(AND(OR(D9="retain",D9=""),E9="statistical_results"),"","not_applicable") | K9: =IF(AND(OR(D9="retain",D9=""),OR(E9="report_internal_inconsistency",E9="plan_material")),"","not_applicable") | L9: substantive_difference | R9: Plan supp1 p30-31, p34 promises MICE with Rubin's rules, pattern-mixture models, a censoring weight combined with IPTW, a per-protocol analysis discarding post-crossover outcomes, and baseline-covariate sensitivity analyses. Searched main and supp2 in full: only the treatment-IPW per-protocol analysis (main p3, supp2 p5, eFigure 2) is reported; no MICE, pattern-mixture or discard analysis.
A10: 2024::jama.2024.0318::C009 | B10: Planned binary A2 and reported GEE | C10: PLAN joi240004supp1_prod_1721756962.80052.pdf — p27 A2/secondary-model text; REPORT jama_courcoulas_2024_oi_240004_1721756962.76052.pdf — main p3 binary/GEE paragraph, jama_courcoulas_2024_oi_240004_1721756962.76052.pdf — p6 Table 2 binary rows, joi240004supp2_prod_1721756962.82552.pdf — supplement p4 binary GEE, joi240004supp2_prod_1721756962.82552.pdf — p5 continuation, joi240004supp2_prod_1721756962.82552.pdf — p15 eTable 2 binary rows. | D10: retain | E10: protocol_report | F10: primary_done | G10: =IFERROR(IF(LEN(TRIM(CLEAN(SUBSTITUTE(Setup!$B$2,CHAR(160)," "))))=0,"CHECK REVIEWER ID",IF(OR(A10="",COUNTIF($A$2:$A$15,A10)<>1,LEFT(A10,LEN("2024::jama.2024.0318::"))<>"2024::jama.2024.0318::"),"CHECK KEY",IF(OR(AND(NOT(AND(D10="retain",E10="statistical_results")),H10<>"",NOT(EXACT(H10,"not_applicable"))),AND(NOT(AND(D10="retain",E10="statistical_results")),I10<>"",NOT(EXACT(I10,"not_applicable"))),AND(NOT(AND(D10="retain",E10="statistical_results")),J10<>"",NOT(EXACT(J10,"not_applicable"))),AND(NOT(AND(D10="retain",OR(E10="report_internal_inconsistency",E10="plan_material"))),K10<>"",NOT(EXACT(K10,"not_applicable"))),AND(NOT(AND(D10="retain",E10="protocol_report")),L10<>"",NOT(EXACT(L10,"not_applicable")))),"CLEAR INACTIVE VALUES",IF(OR(NOT(OR(EXACT(D10,"retain"),EXACT(D10,"exclude"),EXACT(D10,"discuss"))),NOT(OR(EXACT(E10,"statistical_results"),EXACT(E10,"report_internal_inconsistency"),EXACT(E10,"plan_material"),EXACT(E10,"protocol_report"))),AND(AND(D10="retain",E10="statistical_results"),NOT(OR(EXACT(H10,"confirmed_issue"),EXACT(H10,"probable_issue"),EXACT(H10,"not_issue"),EXACT(H10,"indeterminate")))),AND(AND(D10="retain",E10="statistical_results"),NOT(OR(EXACT(I10,"substantive"),EXACT(I10,"minor_presentation"),EXACT(I10,"indeterminate")))),AND(AND(D10="retain",E10="statistical_results"),J10<>"",NOT(OR(EXACT(J10,"direct"),EXACT(J10,"possible"),EXACT(J10,"unlikely"),EXACT(J10,"unknown")))),AND(AND(D10="retain",OR(E10="report_internal_inconsistency",E10="plan_material")),NOT(OR(EXACT(K10,"substantive_inconsistency"),EXACT(K10,"minor_presentation"),EXACT(K10,"non_inconsistency"),EXACT(K10,"indeterminate")))),AND(AND(D10="retain",E10="protocol_report"),L10<>"",NOT(OR(EXACT(L10,"substantive_difference"),EXACT(L10,"minor_presentation"),EXACT(L10,"version_timing"),EXACT(L10,"non_inconsistency"),EXACT(L10,"indeterminate"))))),"CHECK FIELDS",IF(AND(F10<>"",NOT(OR(EXACT(F10,"no"),EXACT(F10,"primary_done")))),"CHECK COMPLETE",IF(EXACT(F10,"primary_done"),"PRIMARY READY","PRIMARY DRAFT")))))),"CHECK INPUT / KEY") | H10: =IF(AND(OR(D10="retain",D10=""),E10="statistical_results"),"","not_applicable") | I10: =IF(AND(OR(D10="retain",D10=""),E10="statistical_results"),"","not_applicable") | J10: =IF(AND(OR(D10="retain",D10=""),E10="statistical_results"),"","not_applicable") | K10: =IF(AND(OR(D10="retain",D10=""),OR(E10="report_internal_inconsistency",E10="plan_material")),"","not_applicable") | L10: substantive_difference | R10: Plan supp1 p27 specifies mixed-effects logistic models (A2, patient random intercept; conditional log OR) for glycemic control and remission; report (main p3; supp2 p4) uses GEE with sandwich SEs adjusting for site and baseline HbA1c. Model family and estimand (conditional vs marginal OR) differ; baseline HbA1c covariate also added.
A11: 2024::jama.2024.0318::C010 | B11: Medical medication OR interval pattern | C11: REPORT jama_courcoulas_2024_oi_240004_1721756962.76052.pdf — main p6 Table 2 use-of-medications medical change column and all binary comparator cells/footnotes, and corroborating REPORT joi240004supp2_prod_1721756962.82552.pdf — supplement p4 GEE/sandwich method. Every lower/upper limit and displayed decimal precision was visually checked. | D11: retain | E11: statistical_results | F11: primary_done | G11: =IFERROR(IF(LEN(TRIM(CLEAN(SUBSTITUTE(Setup!$B$2,CHAR(160)," "))))=0,"CHECK REVIEWER ID",IF(OR(A11="",COUNTIF($A$2:$A$15,A11)<>1,LEFT(A11,LEN("2024::jama.2024.0318::"))<>"2024::jama.2024.0318::"),"CHECK KEY",IF(OR(AND(NOT(AND(D11="retain",E11="statistical_results")),H11<>"",NOT(EXACT(H11,"not_applicable"))),AND(NOT(AND(D11="retain",E11="statistical_results")),I11<>"",NOT(EXACT(I11,"not_applicable"))),AND(NOT(AND(D11="retain",E11="statistical_results")),J11<>"",NOT(EXACT(J11,"not_applicable"))),AND(NOT(AND(D11="retain",OR(E11="report_internal_inconsistency",E11="plan_material"))),K11<>"",NOT(EXACT(K11,"not_applicable"))),AND(NOT(AND(D11="retain",E11="protocol_report")),L11<>"",NOT(EXACT(L11,"not_applicable")))),"CLEAR INACTIVE VALUES",IF(OR(NOT(OR(EXACT(D11,"retain"),EXACT(D11,"exclude"),EXACT(D11,"discuss"))),NOT(OR(EXACT(E11,"statistical_results"),EXACT(E11,"report_internal_inconsistency"),EXACT(E11,"plan_material"),EXACT(E11,"protocol_report"))),AND(AND(D11="retain",E11="statistical_results"),NOT(OR(EXACT(H11,"confirmed_issue"),EXACT(H11,"probable_issue"),EXACT(H11,"not_issue"),EXACT(H11,"indeterminate")))),AND(AND(D11="retain",E11="statistical_results"),NOT(OR(EXACT(I11,"substantive"),EXACT(I11,"minor_presentation"),EXACT(I11,"indeterminate")))),AND(AND(D11="retain",E11="statistical_results"),J11<>"",NOT(OR(EXACT(J11,"direct"),EXACT(J11,"possible"),EXACT(J11,"unlikely"),EXACT(J11,"unknown")))),AND(AND(D11="retain",OR(E11="report_internal_inconsistency",E11="plan_material")),NOT(OR(EXACT(K11,"substantive_inconsistency"),EXACT(K11,"minor_presentation"),EXACT(K11,"non_inconsistency"),EXACT(K11,"indeterminate")))),AND(AND(D11="retain",E11="protocol_report"),L11<>"",NOT(OR(EXACT(L11,"substantive_difference"),EXACT(L11,"minor_presentation"),EXACT(L11,"version_timing"),EXACT(L11,"non_inconsistency"),EXACT(L11,"indeterminate"))))),"CHECK FIELDS",IF(AND(F11<>"",NOT(OR(EXACT(F11,"no"),EXACT(F11,"primary_done")))),"CHECK COMPLETE",IF(EXACT(F11,"primary_done"),"PRIMARY READY","PRIMARY DRAFT")))))),"CHECK INPUT / KEY") | H11: confirmed_issue | I11: minor_presentation | J11: unlikely | K11: =IF(AND(OR(D11="retain",D11=""),OR(E11="report_internal_inconsistency",E11="plan_material")),"","not_applicable") | L11: =IF(AND(OR(D11="retain",D11=""),E11="protocol_report"),"","not_applicable") | R11: Table 2 p6 (rendered) medical 'use of medications' OR 0.10 (0.01 to 3.27): geometric midpoint sqrt(0.01*3.27)=0.18; with 0.01 in [0.005,0.015] the midpoint range is 0.128-0.222, excluding 0.10. All 17 other binary OR cells reproduce (ratio 0.98-1.06; 0.03 (0.01-0.11) fits within rounding). Lower limit implied by 0.10 and 3.27 is 0.003, so the lower bound is likely misprinted.
A12: 2024::jama.2024.0318::C011 | B12: Vascular and safety test mapping | C12: PLAN joi240004supp1_prod_1721756962.80052.pdf — p34 Aim 2 vascular/safety paragraph, joi240004supp1_prod_1721756962.80052.pdf — p35 power/secondary continuation, joi240004supp1_prod_1721756962.80052.pdf — p26 separate baseline-comparison CMH paragraph; REPORT jama_courcoulas_2024_oi_240004_1721756962.76052.pdf — main p1 abstract cardiovascular statement, jama_courcoulas_2024_oi_240004_1721756962.76052.pdf — p7 event/procedure narrative, joi240004supp2_prod_1721756962.82552.pdf — supplement p6 event-test methods, joi240004supp2_prod_1721756962.82552.pdf — p17 nutritional categorical comparisons, joi240004supp2_prod_1721756962.82552.pdf — p19 eTable 5 example P cells, joi240004supp2_prod_1721756962.82552.pdf — p20 eTable 5 footnote b, joi240004supp2_prod_1721756962.82552.pdf — p21 eTable 6/footnote b. | D12: retain | E12: protocol_report | F12: primary_done | G12: =IFERROR(IF(LEN(TRIM(CLEAN(SUBSTITUTE(Setup!$B$2,CHAR(160)," "))))=0,"CHECK REVIEWER ID",IF(OR(A12="",COUNTIF($A$2:$A$15,A12)<>1,LEFT(A12,LEN("2024::jama.2024.0318::"))<>"2024::jama.2024.0318::"),"CHECK KEY",IF(OR(AND(NOT(AND(D12="retain",E12="statistical_results")),H12<>"",NOT(EXACT(H12,"not_applicable"))),AND(NOT(AND(D12="retain",E12="statistical_results")),I12<>"",NOT(EXACT(I12,"not_applicable"))),AND(NOT(AND(D12="retain",E12="statistical_results")),J12<>"",NOT(EXACT(J12,"not_applicable"))),AND(NOT(AND(D12="retain",OR(E12="report_internal_inconsistency",E12="plan_material"))),K12<>"",NOT(EXACT(K12,"not_applicable"))),AND(NOT(AND(D12="retain",E12="protocol_report")),L12<>"",NOT(EXACT(L12,"not_applicable")))),"CLEAR INACTIVE VALUES",IF(OR(NOT(OR(EXACT(D12,"retain"),EXACT(D12,"exclude"),EXACT(D12,"discuss"))),NOT(OR(EXACT(E12,"statistical_results"),EXACT(E12,"report_internal_inconsistency"),EXACT(E12,"plan_material"),EXACT(E12,"protocol_report"))),AND(AND(D12="retain",E12="statistical_results"),NOT(OR(EXACT(H12,"confirmed_issue"),EXACT(H12,"probable_issue"),EXACT(H12,"not_issue"),EXACT(H12,"indeterminate")))),AND(AND(D12="retain",E12="statistical_results"),NOT(OR(EXACT(I12,"substantive"),EXACT(I12,"minor_presentation"),EXACT(I12,"indeterminate")))),AND(AND(D12="retain",E12="statistical_results"),J12<>"",NOT(OR(EXACT(J12,"direct"),EXACT(J12,"possible"),EXACT(J12,"unlikely"),EXACT(J12,"unknown")))),AND(AND(D12="retain",OR(E12="report_internal_inconsistency",E12="plan_material")),NOT(OR(EXACT(K12,"substantive_inconsistency"),EXACT(K12,"minor_presentation"),EXACT(K12,"non_inconsistency"),EXACT(K12,"indeterminate")))),AND(AND(D12="retain",E12="protocol_report"),L12<>"",NOT(OR(EXACT(L12,"substantive_difference"),EXACT(L12,"minor_presentation"),EXACT(L12,"version_timing"),EXACT(L12,"non_inconsistency"),EXACT(L12,"indeterminate"))))),"CHECK FIELDS",IF(AND(F12<>"",NOT(OR(EXACT(F12,"no"),EXACT(F12,"primary_done")))),"CHECK COMPLETE",IF(EXACT(F12,"primary_done"),"PRIMARY READY","PRIMARY DRAFT")))))),"CHECK INPUT / KEY") | H12: =IF(AND(OR(D12="retain",D12=""),E12="statistical_results"),"","not_applicable") | I12: =IF(AND(OR(D12="retain",D12=""),E12="statistical_results"),"","not_applicable") | J12: =IF(AND(OR(D12="retain",D12=""),E12="statistical_results"),"","not_applicable") | K12: =IF(AND(OR(D12="retain",D12=""),OR(E12="report_internal_inconsistency",E12="plan_material")),"","not_applicable") | L12: substantive_difference | R12: Plan supp1 p34 specifies Cochran-Mantel-Haenszel tests for micro/macrovascular events and safety outcomes; report supp2 p6 and eTable 5/6 footnotes use chi-squared or Fisher's exact tests. Stratified versus unstratified test; the plan does not name the strata. Low-stakes method change for descriptive safety comparisons.
A13: 2024::jama.2024.0318::C012 | B13: Fixed site and power variance specification | C13: PLAN joi240004supp1_prod_1721756962.80052.pdf — p26 A1/b_i/Z definition, joi240004supp1_prod_1721756962.80052.pdf — p28 primary power variance-component paragraph, joi240004supp1_prod_1721756962.80052.pdf — p31 heterogeneity/distribution paragraph; corroborating REPORT jama_courcoulas_2024_oi_240004_1721756962.76052.pdf — main p2 primary model, jama_courcoulas_2024_oi_240004_1721756962.76052.pdf — p3 fixed-effect continuation, joi240004supp2_prod_1721756962.82552.pdf — supplement p4 fixed-site model. PLAN joi240004supp1_prod_1721756962.80052.pdf — p27 identifiability clause was also reread. | D13: retain | E13: plan_material | F13: primary_done | G13: =IFERROR(IF(LEN(TRIM(CLEAN(SUBSTITUTE(Setup!$B$2,CHAR(160)," "))))=0,"CHECK REVIEWER ID",IF(OR(A13="",COUNTIF($A$2:$A$15,A13)<>1,LEFT(A13,LEN("2024::jama.2024.0318::"))<>"2024::jama.2024.0318::"),"CHECK KEY",IF(OR(AND(NOT(AND(D13="retain",E13="statistical_results")),H13<>"",NOT(EXACT(H13,"not_applicable"))),AND(NOT(AND(D13="retain",E13="statistical_results")),I13<>"",NOT(EXACT(I13,"not_applicable"))),AND(NOT(AND(D13="retain",E13="statistical_results")),J13<>"",NOT(EXACT(J13,"not_applicable"))),AND(NOT(AND(D13="retain",OR(E13="report_internal_inconsistency",E13="plan_material"))),K13<>"",NOT(EXACT(K13,"not_applicable"))),AND(NOT(AND(D13="retain",E13="protocol_report")),L13<>"",NOT(EXACT(L13,"not_applicable")))),"CLEAR INACTIVE VALUES",IF(OR(NOT(OR(EXACT(D13,"retain"),EXACT(D13,"exclude"),EXACT(D13,"discuss"))),NOT(OR(EXACT(E13,"statistical_results"),EXACT(E13,"report_internal_inconsistency"),EXACT(E13,"plan_material"),EXACT(E13,"protocol_report"))),AND(AND(D13="retain",E13="statistical_results"),NOT(OR(EXACT(H13,"confirmed_issue"),EXACT(H13,"probable_issue"),EXACT(H13,"not_issue"),EXACT(H13,"indeterminate")))),AND(AND(D13="retain",E13="statistical_results"),NOT(OR(EXACT(I13,"substantive"),EXACT(I13,"minor_presentation"),EXACT(I13,"indeterminate")))),AND(AND(D13="retain",E13="statistical_results"),J13<>"",NOT(OR(EXACT(J13,"direct"),EXACT(J13,"possible"),EXACT(J13,"unlikely"),EXACT(J13,"unknown")))),AND(AND(D13="retain",OR(E13="report_internal_inconsistency",E13="plan_material")),NOT(OR(EXACT(K13,"substantive_inconsistency"),EXACT(K13,"minor_presentation"),EXACT(K13,"non_inconsistency"),EXACT(K13,"indeterminate")))),AND(AND(D13="retain",E13="protocol_report"),L13<>"",NOT(OR(EXACT(L13,"substantive_difference"),EXACT(L13,"minor_presentation"),EXACT(L13,"version_timing"),EXACT(L13,"non_inconsistency"),EXACT(L13,"indeterminate"))))),"CHECK FIELDS",IF(AND(F13<>"",NOT(OR(EXACT(F13,"no"),EXACT(F13,"primary_done")))),"CHECK COMPLETE",IF(EXACT(F13,"primary_done"),"PRIMARY READY","PRIMARY DRAFT")))))),"CHECK INPUT / KEY") | H13: =IF(AND(OR(D13="retain",D13=""),E13="statistical_results"),"","not_applicable") | I13: =IF(AND(OR(D13="retain",D13=""),E13="statistical_results"),"","not_applicable") | J13: =IF(AND(OR(D13="retain",D13=""),E13="statistical_results"),"","not_applicable") | K13: substantive_inconsistency | L13: =IF(AND(OR(D13="retain",D13=""),E13="protocol_report"),"","not_applicable") | R13: Within the plan (supp1): model A1 (p26) treats site as a fixed effect b_i (with Z also site indicators), but the power section (p28) uses a fitted variance component sigma_b=0.06 for site, and p31 says site-specific effects 'follow some distribution' and the CI describes heterogeneity, i.e., a random-site model. Fixed versus random site is internally inconsistent in the plan.
A14: 2024::jama.2024.0318::C013 | B14: Appendix randomization-dropout accounting | C14: PLAN joi240004supp1_prod_1721756962.80052.pdf — p55 Appendix 2 table title, # Randomized and Number underwent intervention† rows, joi240004supp1_prod_1721756962.80052.pdf — p56 table continuation and dagger definition/dropout statement, and corroborating PLAN joi240004supp1_prod_1721756962.80052.pdf — p27 randomized/initiated population paragraph. | D14: retain | E14: plan_material | F14: primary_done | G14: =IFERROR(IF(LEN(TRIM(CLEAN(SUBSTITUTE(Setup!$B$2,CHAR(160)," "))))=0,"CHECK REVIEWER ID",IF(OR(A14="",COUNTIF($A$2:$A$15,A14)<>1,LEFT(A14,LEN("2024::jama.2024.0318::"))<>"2024::jama.2024.0318::"),"CHECK KEY",IF(OR(AND(NOT(AND(D14="retain",E14="statistical_results")),H14<>"",NOT(EXACT(H14,"not_applicable"))),AND(NOT(AND(D14="retain",E14="statistical_results")),I14<>"",NOT(EXACT(I14,"not_applicable"))),AND(NOT(AND(D14="retain",E14="statistical_results")),J14<>"",NOT(EXACT(J14,"not_applicable"))),AND(NOT(AND(D14="retain",OR(E14="report_internal_inconsistency",E14="plan_material"))),K14<>"",NOT(EXACT(K14,"not_applicable"))),AND(NOT(AND(D14="retain",E14="protocol_report")),L14<>"",NOT(EXACT(L14,"not_applicable")))),"CLEAR INACTIVE VALUES",IF(OR(NOT(OR(EXACT(D14,"retain"),EXACT(D14,"exclude"),EXACT(D14,"discuss"))),NOT(OR(EXACT(E14,"statistical_results"),EXACT(E14,"report_internal_inconsistency"),EXACT(E14,"plan_material"),EXACT(E14,"protocol_report"))),AND(AND(D14="retain",E14="statistical_results"),NOT(OR(EXACT(H14,"confirmed_issue"),EXACT(H14,"probable_issue"),EXACT(H14,"not_issue"),EXACT(H14,"indeterminate")))),AND(AND(D14="retain",E14="statistical_results"),NOT(OR(EXACT(I14,"substantive"),EXACT(I14,"minor_presentation"),EXACT(I14,"indeterminate")))),AND(AND(D14="retain",E14="statistical_results"),J14<>"",NOT(OR(EXACT(J14,"direct"),EXACT(J14,"possible"),EXACT(J14,"unlikely"),EXACT(J14,"unknown")))),AND(AND(D14="retain",OR(E14="report_internal_inconsistency",E14="plan_material")),NOT(OR(EXACT(K14,"substantive_inconsistency"),EXACT(K14,"minor_presentation"),EXACT(K14,"non_inconsistency"),EXACT(K14,"indeterminate")))),AND(AND(D14="retain",E14="protocol_report"),L14<>"",NOT(OR(EXACT(L14,"substantive_difference"),EXACT(L14,"minor_presentation"),EXACT(L14,"version_timing"),EXACT(L14,"non_inconsistency"),EXACT(L14,"indeterminate"))))),"CHECK FIELDS",IF(AND(F14<>"",NOT(OR(EXACT(F14,"no"),EXACT(F14,"primary_done")))),"CHECK COMPLETE",IF(EXACT(F14,"primary_done"),"PRIMARY READY","PRIMARY DRAFT")))))),"CHECK INPUT / KEY") | H14: =IF(AND(OR(D14="retain",D14=""),E14="statistical_results"),"","not_applicable") | I14: =IF(AND(OR(D14="retain",D14=""),E14="statistical_results"),"","not_applicable") | J14: =IF(AND(OR(D14="retain",D14=""),E14="statistical_results"),"","not_applicable") | K14: minor_presentation | L14: =IF(AND(OR(D14="retain",D14=""),E14="protocol_report"),"","not_applicable") | R14: Plan Appendix 2 (supp1 p55-56): randomized 155+69+43+45+43 = 355, underwent intervention 154+61+38+40+32 = 325, so 30 did not start; the dagger footnote says 38 dropped at randomization. Died (3), lost (20) and eligible (302) reconcile with p27. The 38 conflicts with the table. Note: the report (main p3, Fig 1) states 39 withdrew before intervention and 316 eligible, closer to the footnote.
A15: 2024::jama.2024.0318::C014 | B15: Other race count and percentage | C15: REPORT joi240004supp2_prod_1721756962.82552.pdf — supplement p14 eTable 1 7-year column, race rows and footnotes a/b. | D15: retain | E15: statistical_results | F15: primary_done | G15: =IFERROR(IF(LEN(TRIM(CLEAN(SUBSTITUTE(Setup!$B$2,CHAR(160)," "))))=0,"CHECK REVIEWER ID",IF(OR(A15="",COUNTIF($A$2:$A$15,A15)<>1,LEFT(A15,LEN("2024::jama.2024.0318::"))<>"2024::jama.2024.0318::"),"CHECK KEY",IF(OR(AND(NOT(AND(D15="retain",E15="statistical_results")),H15<>"",NOT(EXACT(H15,"not_applicable"))),AND(NOT(AND(D15="retain",E15="statistical_results")),I15<>"",NOT(EXACT(I15,"not_applicable"))),AND(NOT(AND(D15="retain",E15="statistical_results")),J15<>"",NOT(EXACT(J15,"not_applicable"))),AND(NOT(AND(D15="retain",OR(E15="report_internal_inconsistency",E15="plan_material"))),K15<>"",NOT(EXACT(K15,"not_applicable"))),AND(NOT(AND(D15="retain",E15="protocol_report")),L15<>"",NOT(EXACT(L15,"not_applicable")))),"CLEAR INACTIVE VALUES",IF(OR(NOT(OR(EXACT(D15,"retain"),EXACT(D15,"exclude"),EXACT(D15,"discuss"))),NOT(OR(EXACT(E15,"statistical_results"),EXACT(E15,"report_internal_inconsistency"),EXACT(E15,"plan_material"),EXACT(E15,"protocol_report"))),AND(AND(D15="retain",E15="statistical_results"),NOT(OR(EXACT(H15,"confirmed_issue"),EXACT(H15,"probable_issue"),EXACT(H15,"not_issue"),EXACT(H15,"indeterminate")))),AND(AND(D15="retain",E15="statistical_results"),NOT(OR(EXACT(I15,"substantive"),EXACT(I15,"minor_presentation"),EXACT(I15,"indeterminate")))),AND(AND(D15="retain",E15="statistical_results"),J15<>"",NOT(OR(EXACT(J15,"direct"),EXACT(J15,"possible"),EXACT(J15,"unlikely"),EXACT(J15,"unknown")))),AND(AND(D15="retain",OR(E15="report_internal_inconsistency",E15="plan_material")),NOT(OR(EXACT(K15,"substantive_inconsistency"),EXACT(K15,"minor_presentation"),EXACT(K15,"non_inconsistency"),EXACT(K15,"indeterminate")))),AND(AND(D15="retain",E15="protocol_report"),L15<>"",NOT(OR(EXACT(L15,"substantive_difference"),EXACT(L15,"minor_presentation"),EXACT(L15,"version_timing"),EXACT(L15,"non_inconsistency"),EXACT(L15,"indeterminate"))))),"CHECK FIELDS",IF(AND(F15<>"",NOT(OR(EXACT(F15,"no"),EXACT(F15,"primary_done")))),"CHECK COMPLETE",IF(EXACT(F15,"primary_done"),"PRIMARY READY","PRIMARY DRAFT")))))),"CHECK INPUT / KEY") | H15: confirmed_issue | I15: minor_presentation | J15: unlikely | K15: =IF(AND(OR(D15="retain",D15=""),OR(E15="report_internal_inconsistency",E15="plan_material")),"","not_applicable") | L15: =IF(AND(OR(D15="retain",D15=""),E15="protocol_report"),"","not_applicable") | R15: eTable 1 (supp2 p14) 7-year column: Other race 4 (1.9) with N=262; 4/262 = 1.5%. Black 81 (30.9) and White 176 (67.2) reproduce, but 81+176+4 = 261. Main Table 1 gives White 59+118 = 177 (67.6%), so eTable 1 White (176) also disagrees with Table 1.

Sheet C_jama.2024.0572
A1: Candidate key | B1: Candidate title | C1: Source location | D1: Disposition | E1: Review domain (AI suggestion; editable) | F1: Complete | G1: Validation hint | H1: Statistical_or_numerical issue | I1: Substantiveness | J1: Downstream impact | K1: Report-internal or planning-material inconsistency | L1: Protocol interpretation | R1: Notes (optional)
A2: 2024::jama.2024.0572::C001 | B2: Follow-up MRI analysis-population count | C2: jama_sarraj_2024_oi_240006_1708623114.96234.pdf — Main p.4, Results imaging paragraph; jama_sarraj_2024_oi_240006_1708623114.96234.pdf — Main p.9, infarct-growth paragraph; jama_sarraj_2024_oi_240006_1708623114.96234.pdf — Main p.11 discussion; joi240006supp5_prod_1708623115.01733.pdf — Results p.51 eTable11; jama_sarraj_2024_oi_240006_1708623114.96234.pdf — Main p.6 baseline-MRI context | D2: retain | E2: statistical_results | F2: primary_done | G2: =IFERROR(IF(LEN(TRIM(CLEAN(SUBSTITUTE(Setup!$B$2,CHAR(160)," "))))=0,"CHECK REVIEWER ID",IF(OR(A2="",COUNTIF($A$2:$A$20,A2)<>1,LEFT(A2,LEN("2024::jama.2024.0572::"))<>"2024::jama.2024.0572::"),"CHECK KEY",IF(OR(AND(NOT(AND(D2="retain",E2="statistical_results")),H2<>"",NOT(EXACT(H2,"not_applicable"))),AND(NOT(AND(D2="retain",E2="statistical_results")),I2<>"",NOT(EXACT(I2,"not_applicable"))),AND(NOT(AND(D2="retain",E2="statistical_results")),J2<>"",NOT(EXACT(J2,"not_applicable"))),AND(NOT(AND(D2="retain",OR(E2="report_internal_inconsistency",E2="plan_material"))),K2<>"",NOT(EXACT(K2,"not_applicable"))),AND(NOT(AND(D2="retain",E2="protocol_report")),L2<>"",NOT(EXACT(L2,"not_applicable")))),"CLEAR INACTIVE VALUES",IF(OR(NOT(OR(EXACT(D2,"retain"),EXACT(D2,"exclude"),EXACT(D2,"discuss"))),NOT(OR(EXACT(E2,"statistical_results"),EXACT(E2,"report_internal_inconsistency"),EXACT(E2,"plan_material"),EXACT(E2,"protocol_report"))),AND(AND(D2="retain",E2="statistical_results"),NOT(OR(EXACT(H2,"confirmed_issue"),EXACT(H2,"probable_issue"),EXACT(H2,"not_issue"),EXACT(H2,"indeterminate")))),AND(AND(D2="retain",E2="statistical_results"),NOT(OR(EXACT(I2,"substantive"),EXACT(I2,"minor_presentation"),EXACT(I2,"indeterminate")))),AND(AND(D2="retain",E2="statistical_results"),J2<>"",NOT(OR(EXACT(J2,"direct"),EXACT(J2,"possible"),EXACT(J2,"unlikely"),EXACT(J2,"unknown")))),AND(AND(D2="retain",OR(E2="report_internal_inconsistency",E2="plan_material")),NOT(OR(EXACT(K2,"substantive_inconsistency"),EXACT(K2,"minor_presentation"),EXACT(K2,"non_inconsistency"),EXACT(K2,"indeterminate")))),AND(AND(D2="retain",E2="protocol_report"),L2<>"",NOT(OR(EXACT(L2,"substantive_difference"),EXACT(L2,"minor_presentation"),EXACT(L2,"version_timing"),EXACT(L2,"non_inconsistency"),EXACT(L2,"indeterminate"))))),"CHECK FIELDS",IF(AND(F2<>"",NOT(OR(EXACT(F2,"no"),EXACT(F2,"primary_done")))),"CHECK COMPLETE",IF(EXACT(F2,"primary_done"),"PRIMARY READY","PRIMARY DRAFT")))))),"CHECK INPUT / KEY") | H2: confirmed_issue | I2: substantive | J2: possible | K2: =IF(AND(OR(D2="retain",D2=""),OR(E2="report_internal_inconsistency",E2="plan_material")),"","not_applicable") | L2: =IF(AND(OR(D2="retain",D2=""),E2="protocol_report"),"","not_applicable") | R2: Main p4: follow-up imaging was MRI in 8/336 (2%) and CT in 328/336 (98%); main p9 and eTable 11 (supp5 p51): MR diffusion follow-up in 204 (61%) = 101+24+79; discussion p11 'two-thirds'. 8 matches baseline MR DWI (Table 1: 3+5), so p4 appears to describe baseline modality as follow-up. Reader cannot tell which follow-up modality mix applies to infarct volumes.
A3: 2024::jama.2024.0572::C002 | B3: Primary treatment-group specification | C3: joi240006supp4_prod_1708623115.00733.pdf — Analysis SAP p.3, §5.1; joi240006supp4_prod_1708623115.00733.pdf — Its p.4, §5.2.1; jama_sarraj_2024_oi_240006_1708623114.96234.pdf — Main p.4, Statistical Analysis; jama_sarraj_2024_oi_240006_1708623114.96234.pdf — Main p.6 Figure1; joi240006supp5_prod_1708623115.01733.pdf — results p.8 flow diagram; joi240006supp5_prod_1708623115.01733.pdf — Results p.38 eTable2 | D3: retain | E3: protocol_report | F3: primary_done | G3: =IFERROR(IF(LEN(TRIM(CLEAN(SUBSTITUTE(Setup!$B$2,CHAR(160)," "))))=0,"CHECK REVIEWER ID",IF(OR(A3="",COUNTIF($A$2:$A$20,A3)<>1,LEFT(A3,LEN("2024::jama.2024.0572::"))<>"2024::jama.2024.0572::"),"CHECK KEY",IF(OR(AND(NOT(AND(D3="retain",E3="statistical_results")),H3<>"",NOT(EXACT(H3,"not_applicable"))),AND(NOT(AND(D3="retain",E3="statistical_results")),I3<>"",NOT(EXACT(I3,"not_applicable"))),AND(NOT(AND(D3="retain",E3="statistical_results")),J3<>"",NOT(EXACT(J3,"not_applicable"))),AND(NOT(AND(D3="retain",OR(E3="report_internal_inconsistency",E3="plan_material"))),K3<>"",NOT(EXACT(K3,"not_applicable"))),AND(NOT(AND(D3="retain",E3="protocol_report")),L3<>"",NOT(EXACT(L3,"not_applicable")))),"CLEAR INACTIVE VALUES",IF(OR(NOT(OR(EXACT(D3,"retain"),EXACT(D3,"exclude"),EXACT(D3,"discuss"))),NOT(OR(EXACT(E3,"statistical_results"),EXACT(E3,"report_internal_inconsistency"),EXACT(E3,"plan_material"),EXACT(E3,"protocol_report"))),AND(AND(D3="retain",E3="statistical_results"),NOT(OR(EXACT(H3,"confirmed_issue"),EXACT(H3,"probable_issue"),EXACT(H3,"not_issue"),EXACT(H3,"indeterminate")))),AND(AND(D3="retain",E3="statistical_results"),NOT(OR(EXACT(I3,"substantive"),EXACT(I3,"minor_presentation"),EXACT(I3,"indeterminate")))),AND(AND(D3="retain",E3="statistical_results"),J3<>"",NOT(OR(EXACT(J3,"direct"),EXACT(J3,"possible"),EXACT(J3,"unlikely"),EXACT(J3,"unknown")))),AND(AND(D3="retain",OR(E3="report_internal_inconsistency",E3="plan_material")),NOT(OR(EXACT(K3,"substantive_inconsistency"),EXACT(K3,"minor_presentation"),EXACT(K3,"non_inconsistency"),EXACT(K3,"indeterminate")))),AND(AND(D3="retain",E3="protocol_report"),L3<>"",NOT(OR(EXACT(L3,"substantive_difference"),EXACT(L3,"minor_presentation"),EXACT(L3,"version_timing"),EXACT(L3,"non_inconsistency"),EXACT(L3,"indeterminate"))))),"CHECK FIELDS",IF(AND(F3<>"",NOT(OR(EXACT(F3,"no"),EXACT(F3,"primary_done")))),"CHECK COMPLETE",IF(EXACT(F3,"primary_done"),"PRIMARY READY","PRIMARY DRAFT")))))),"CHECK INPUT / KEY") | H3: =IF(AND(OR(D3="retain",D3=""),E3="statistical_results"),"","not_applicable") | I3: =IF(AND(OR(D3="retain",D3=""),E3="statistical_results"),"","not_applicable") | J3: =IF(AND(OR(D3="retain",D3=""),E3="statistical_results"),"","not_applicable") | K3: =IF(AND(OR(D3="retain",D3=""),OR(E3="report_internal_inconsistency",E3="plan_material")),"","not_applicable") | L3: substantive_difference | R3: Analysis SAP (supp4 p3, 5.1): 'All analyses will be performed under an as-treated approach.' Report (main p4 Statistical Analysis; Table 1 168/168 vs Table 2 170/166) analyzes treatment comparisons across imaging strata by randomized group (ITT) and within-arm associations as treated. Analysis population for the main treatment-effect comparisons differs from plan; not described as a change. Practical impact limited (2 MM-to-EVT crossovers).
A4: 2024::jama.2024.0572::C003 | B4: Composite-core analysis hierarchy and prespecification | C4: joi240006supp4_prod_1708623115.00733.pdf — Analysis SAP p.3 imaging-definition bullets; joi240006supp4_prod_1708623115.00733.pdf — SAP p.7 appendix item1; jama_sarraj_2024_oi_240006_1708623114.96234.pdf — Main p.4 methods; jama_sarraj_2024_oi_240006_1708623114.96234.pdf — Main p.6; jama_sarraj_2024_oi_240006_1708623114.96234.pdf — main p.8 Figure3; joi240006supp5_prod_1708623115.01733.pdf — results p.16 eFigure10; jama_sarraj_2024_oi_240006_1708623114.96234.pdf — Main p.1 abstract; jama_sarraj_2024_oi_240006_1708623114.96234.pdf — Main p.11 limitations | D4: retain | E4: protocol_report | F4: primary_done | G4: =IFERROR(IF(LEN(TRIM(CLEAN(SUBSTITUTE(Setup!$B$2,CHAR(160)," "))))=0,"CHECK REVIEWER ID",IF(OR(A4="",COUNTIF($A$2:$A$20,A4)<>1,LEFT(A4,LEN("2024::jama.2024.0572::"))<>"2024::jama.2024.0572::"),"CHECK KEY",IF(OR(AND(NOT(AND(D4="retain",E4="statistical_results")),H4<>"",NOT(EXACT(H4,"not_applicable"))),AND(NOT(AND(D4="retain",E4="statistical_results")),I4<>"",NOT(EXACT(I4,"not_applicable"))),AND(NOT(AND(D4="retain",E4="statistical_results")),J4<>"",NOT(EXACT(J4,"not_applicable"))),AND(NOT(AND(D4="retain",OR(E4="report_internal_inconsistency",E4="plan_material"))),K4<>"",NOT(EXACT(K4,"not_applicable"))),AND(NOT(AND(D4="retain",E4="protocol_report")),L4<>"",NOT(EXACT(L4,"not_applicable")))),"CLEAR INACTIVE VALUES",IF(OR(NOT(OR(EXACT(D4,"retain"),EXACT(D4,"exclude"),EXACT(D4,"discuss"))),NOT(OR(EXACT(E4,"statistical_results"),EXACT(E4,"report_internal_inconsistency"),EXACT(E4,"plan_material"),EXACT(E4,"protocol_report"))),AND(AND(D4="retain",E4="statistical_results"),NOT(OR(EXACT(H4,"confirmed_issue"),EXACT(H4,"probable_issue"),EXACT(H4,"not_issue"),EXACT(H4,"indeterminate")))),AND(AND(D4="retain",E4="statistical_results"),NOT(OR(EXACT(I4,"substantive"),EXACT(I4,"minor_presentation"),EXACT(I4,"indeterminate")))),AND(AND(D4="retain",E4="statistical_results"),J4<>"",NOT(OR(EXACT(J4,"direct"),EXACT(J4,"possible"),EXACT(J4,"unlikely"),EXACT(J4,"unknown")))),AND(AND(D4="retain",OR(E4="report_internal_inconsistency",E4="plan_material")),NOT(OR(EXACT(K4,"substantive_inconsistency"),EXACT(K4,"minor_presentation"),EXACT(K4,"non_inconsistency"),EXACT(K4,"indeterminate")))),AND(AND(D4="retain",E4="protocol_report"),L4<>"",NOT(OR(EXACT(L4,"substantive_difference"),EXACT(L4,"minor_presentation"),EXACT(L4,"version_timing"),EXACT(L4,"non_inconsistency"),EXACT(L4,"indeterminate"))))),"CHECK FIELDS",IF(AND(F4<>"",NOT(OR(EXACT(F4,"no"),EXACT(F4,"primary_done")))),"CHECK COMPLETE",IF(EXACT(F4,"primary_done"),"PRIMARY READY","PRIMARY DRAFT")))))),"CHECK INPUT / KEY") | H4: =IF(AND(OR(D4="retain",D4=""),E4="statistical_results"),"","not_applicable") | I4: =IF(AND(OR(D4="retain",D4=""),E4="statistical_results"),"","not_applicable") | J4: =IF(AND(OR(D4="retain",D4=""),E4="statistical_results"),"","not_applicable") | K4: =IF(AND(OR(D4="retain",D4=""),OR(E4="report_internal_inconsistency",E4="plan_material")),"","not_applicable") | L4: substantive_difference | R4: Analysis SAP (supp4 p3, imaging definitions) makes the composite core (larger of CTP/MRI and CT hypodensity) the primary volume and CTP/MRI core a sensitivity analysis; SAP appendix p7 calls composite core 'pre-specified'. Report (main p4, p6; supp5 eFig 10-16) makes CTP/MRI core primary and labels composite-core analyses 'post hoc'; limitations (p10) say the composite concept was preplanned. Primary/sensitivity roles reversed and prespecification mislabeled.
