Workbook

Sheet Start
A1: Step | B1: Instructions
A2: Release | B2: TEST ONLY — SYNTHETIC INPUTS — NEVER RESEARCH DATA
A3: Coordinator | B3: Assign two different people to the two role files. Distribute only the corresponding file to each person. Roles are labels, not person IDs. This standalone file cannot verify the identity in another file.
A4: 1. Begin | B4: Save As a working copy in Excel. Enter your own reviewer ID (or identifying name) in Setup B2 and optional full name in B3. Setup B4 identifies this file's role; B5 is the cohort year.
A5: 2. Read | B5: Use Papers links to open each C_ sheet. Candidate-key links open embedded Evidence. Filter Candidates, Evidence, Links and Relations by key for full context. Click source labels in Links to open original PDFs. Keep the source-folder structure when using relative links.
A6: 3. Assess | B6: Choose D=retain, exclude, or discuss. Confirm or change the AI-suggested domain in E. Answer applicable H-L, using Codebook definitions. R holds optional English notes. Yellow = common/required; blue = optional; gray = inactive. M-Q are empty spacers.
A7: 4. Applicability | B7: For retain: statistical_results requires H and I; J is optional. report_internal_inconsistency and plan_material require K. protocol_report has no extra required judgment; L is optional. Exclude/discuss have no active H-L judgments.
A8: 5. Defaults | B8: Untouched H-L formulas display blank for a potentially applicable field while D is blank or retain; otherwise not_applicable. Choosing an answer replaces its formula. Blank means unanswered, with no inherited answer. Optional active fields may stay blank. Active fields cannot use not_applicable.
A9: 6. Changes | B9: Before changing a completed row, manually set F=no, make changes, review again, then mark primary_done. Excel formulas cannot reset an entered flag. Domain/disposition changes do not erase literal answers. CLEAR INACTIVE VALUES: delete stale inactive answers or set them to not_applicable; answer newly active required fields.
A10: 7. Finish each row | B10: After manual evidence review, set F=primary_done. G must show PRIMARY READY. Invalid pasted values are checked as well as dropdown choices. D and a valid E are required even for exclude/discuss. Completion alone does not establish scientific accuracy.
A11: 8. Inspect and deliver | B11: Inspect G and Checks; filter Decisions status for unfinished rows. When Checks shows PRIMARY READY, save the completed workbook and deliver this file. Review, calculations and delivery use Excel alone. Keep normal Excel backup copies; never regenerate a completed review file.
A12: Uncertainty | B12: Discuss is a completed independent response when otherwise valid. It records unresolved scientific uncertainty and initiates no shared workflow. Checks displays discuss totals separately; completing data entry does not resolve uncertainty.
... A17: Validation status | B17: Construction static and formula-engine checks are documented in the accompanying VALIDATION.md. Interactive desktop Excel smoke testing and visual rendering are pending. Excel recalculates on opening.

Sheet Setup
A1: Field | B1: Value
A2: reviewerId / identifying name | B2: TEST_REVIEWER
A3: reviewerName (optional) | B3: TEST ONLY
A4: reviewerRole | B4: R_A
A5: year | B5: 2025

Sheet Checks
A1: Check | B1: Result
A2: Reviewer role | B2: =Setup!B4 -> R_A
A3: Candidates | B3: 131
A4: Primary ready rows | B4: =COUNTIF(Decisions!G2:G132,"PRIMARY READY") -> 131
A5: Unfinished rows | B5: =B3-B4 -> 0
A6: Discuss / unresolved rows | B6: =COUNTIF(Decisions!K2:K132,"discuss") -> 0
A7: Workflow status | B7: =IF(B4=B3,"PRIMARY READY","ACTION NEEDED") -> PRIMARY READY
A8: Interpretation | B8: Completion means independent entry is finished. Discuss remains unresolved; affected paper outcome counts are withheld.
A9: Next action | B9: Filter Decisions status; return to C_ inputs. When primary-ready, save and deliver this file.
A10: Ready discuss rows | B10: =COUNTIFS(Decisions!G2:G132,"PRIMARY READY",Decisions!K2:K132,"discuss") -> 0

Sheet Papers
A1: Paper | B1: Review worksheet | C1: Candidates
A2: jama.2024.24764 | B2: C_jama.2024.24764 | C2: 8
A3: jama.2024.27643 | B3: C_jama.2024.27643 | C3: 8
A4: jama.2025.11178 | B4: C_jama.2025.11178 | C4: 37
A5: jama.2025.15185 | B5: C_jama.2025.15185 | C5: 12
A6: jama.2025.15440 | B6: C_jama.2025.15440 | C6: 2
A7: jama.2025.16450 | B7: C_jama.2025.16450 | C7: 10
A8: jama.2025.19563 | B8: C_jama.2025.19563 | C8: 7
A9: jama.2025.19843 | B9: C_jama.2025.19843 | C9: 1
A10: jama.2025.20765 | B10: C_jama.2025.20765 | C10: 13
A11: jama.2025.24175 | B11: C_jama.2025.24175 | C11: 14
A12: jama.2025.4390 | B12: C_jama.2025.4390 | C12: 3
A13: jama.2025.7583 | B13: C_jama.2025.7583 | C13: 3
... A16: jama.2025.9663 | B16: C_jama.2025.9663 | C16: 3

Sheet C_jama.2024.24764
A1: Candidate key | B1: Candidate title | C1: Source location | D1: Disposition | E1: Review domain (AI suggestion; editable) | F1: Complete | G1: Validation hint | H1: Statistcal_or_numerical issue | I1: Substantiveness | J1: Downstream impact | K1: Report-internal or planning-material inconsistency | L1: Protocol interpretation | R1: Notes (optional)
A2: 2025::jama.2024.24764::C001 | B2: Smoking percentages use a different denominator from the printed smoking totals | C2: jama_atherton_2025_oi_240145_1741627844.85412.pdf — PDF p. 5, Table 1 | D2: retain | E2: statistical_results | F2: primary_done | G2: =IFERROR(IF(LEN(TRIM(CLEAN(SUBSTITUTE(Setup!$B$2,CHAR(160)," "))))=0,"CHECK REVIEWER ID",IF(OR(A2="",(COUNTIF('C_jama.2024.24764'!$A$2:$A$9,A2)+COUNTIF('C_jama.2024.27643'!$A$2:$A$9,A2)+COUNTIF('C_jama.2025.11178'!$A$2:$A$38,A2)+COUNTIF('C_jama.2025.15185'!$A$2:$A$13,A2)+COUNTIF('C_jama.2025.15440'!$A$2:$A$3,A2)+COUNTIF('C_jama.2025.16450'!$A$2:$A$11,A2)+COUNTIF('C_jama.2025.19563'!$A$2:$A$8,A2)+COUNTIF('C_jama.2025.19843'!$A$2:$A$2,A2)+COUNTIF('C_jama.2025.20765'!$A$2:$A$14,A2)+COUNTIF('C_jama.2025.24175'!$A$2:$A$15,A2)+COUNTIF('C_jama.2025.4390'!$A$2:$A$4,A2)+COUNTIF('C_jama.2025.7583'!$A$2:$A$4,A2)+COUNTIF('C_jama.2025.7710'!$A$2:$A$5,A2)+COUNTIF('C_jama.2025.9110'!$A$2:$A$7,A2)+COUNTIF('C_jama.2025.9663'!$A$2:$A$4,A2))<>1,COUNTIFS(Candidates!$G$2:$G$132,A2,Candidates!$K$2:$K$132,"jama.2024.24764")<>1),"CHECK KEY",IF(OR(AND(NOT(AND(D2="retain",E2="statistical_results")),H2<>"",H2<>"not_applicable"),AND(NOT(AND(D2="retain",E2="statistical_results")),I2<>"",I2<>"not_applicable"),AND(NOT(AND(D2="retain",E2="statistical_results")),J2<>"",J2<>"not_applicable"),AND(NOT(AND(D2="retain",OR(E2="report_internal_inconsistency",E2="plan_material"))),K2<>"",K2<>"not_applicable"),AND(NOT(AND(D2="retain",E2="protocol_report")),L2<>"",L2<>"not_applicable")),"CLEAR INACTIVE VALUES",IF(OR(NOT(OR(D2="retain",D2="exclude",D2="discuss")),NOT(OR(E2="statistical_results",E2="report_internal_inconsistency",E2="plan_material",E2="protocol_report")),AND(AND(D2="retain",E2="statistical_results"),NOT(OR(H2="confirmed_issue",H2="probable_issue",H2="not_issue",H2="indeterminate"))),AND(AND(D2="retain",E2="statistical_results"),NOT(OR(I2="substantive",I2="minor_presentation",I2="indeterminate"))),AND(AND(D2="retain",E2="statistical_results"),J2<>"",NOT(OR(J2="direct",J2="possible",J2="unlikely",J2="unknown"))),AND(AND(D2="retain",OR(E2="report_internal_inconsistency",E2="plan_material")),NOT(OR(K2="substantive_inconsistency",K2="minor_presentation",K2="non_inconsistency",K2="indeterminate"))),AND(AND(D2="retain",E2="protocol_report"),L2<>"",NOT(OR(L2="substantive_difference",L2="minor_presentation",L2="version_timing",L2="non_inconsistency",L2="indeterminate")))),"CHECK FIELDS",IF(AND(F2<>"",NOT(OR(F2="no",F2="primary_done"))),"CHECK COMPLETE",IF(F2="primary_done","PRIMARY READY","PRIMARY DRAFT")))))),"CHECK INPUT / KEY") -> PRIMARY READY | H2: confirmed_issue | I2: substantive | R2: TEST 2025::jama.2024.24764::C001
A3: 2025::jama.2024.24764::C002 | B3: Operating-surgeon level totals exceed participant denominators without a multi-response qualifier | C3: jama_atherton_2025_oi_240145_1741627844.85412.pdf — PDF p. 7, Table 2 | D3: retain | E3: statistical_results | F3: primary_done | G3: =IFERROR(IF(LEN(TRIM(CLEAN(SUBSTITUTE(Setup!$B$2,CHAR(160)," "))))=0,"CHECK REVIEWER ID",IF(OR(A3="",(COUNTIF('C_jama.2024.24764'!$A$2:$A$9,A3)+COUNTIF('C_jama.2024.27643'!$A$2:$A$9,A3)+COUNTIF('C_jama.2025.11178'!$A$2:$A$38,A3)+COUNTIF('C_jama.2025.15185'!$A$2:$A$13,A3)+COUNTIF('C_jama.2025.15440'!$A$2:$A$3,A3)+COUNTIF('C_jama.2025.16450'!$A$2:$A$11,A3)+COUNTIF('C_jama.2025.19563'!$A$2:$A$8,A3)+COUNTIF('C_jama.2025.19843'!$A$2:$A$2,A3)+COUNTIF('C_jama.2025.20765'!$A$2:$A$14,A3)+COUNTIF('C_jama.2025.24175'!$A$2:$A$15,A3)+COUNTIF('C_jama.2025.4390'!$A$2:$A$4,A3)+COUNTIF('C_jama.2025.7583'!$A$2:$A$4,A3)+COUNTIF('C_jama.2025.7710'!$A$2:$A$5,A3)+COUNTIF('C_jama.2025.9110'!$A$2:$A$7,A3)+COUNTIF('C_jama.2025.9663'!$A$2:$A$4,A3))<>1,COUNTIFS(Candidates!$G$2:$G$132,A3,Candidates!$K$2:$K$132,"jama.2024.24764")<>1),"CHECK KEY",IF(OR(AND(NOT(AND(D3="retain",E3="statistical_results")),H3<>"",H3<>"not_applicable"),AND(NOT(AND(D3="retain",E3="statistical_results")),I3<>"",I3<>"not_applicable"),AND(NOT(AND(D3="retain",E3="statistical_results")),J3<>"",J3<>"not_applicable"),AND(NOT(AND(D3="retain",OR(E3="report_internal_inconsistency",E3="plan_material"))),K3<>"",K3<>"not_applicable"),AND(NOT(AND(D3="retain",E3="protocol_report")),L3<>"",L3<>"not_applicable")),"CLEAR INACTIVE VALUES",IF(OR(NOT(OR(D3="retain",D3="exclude",D3="discuss")),NOT(OR(E3="statistical_results",E3="report_internal_inconsistency",E3="plan_material",E3="protocol_report")),AND(AND(D3="retain",E3="statistical_results"),NOT(OR(H3="confirmed_issue",H3="probable_issue",H3="not_issue",H3="indeterminate"))),AND(AND(D3="retain",E3="statistical_results"),NOT(OR(I3="substantive",I3="minor_presentation",I3="indeterminate"))),AND(AND(D3="retain",E3="statistical_results"),J3<>"",NOT(OR(J3="direct",J3="possible",J3="unlikely",J3="unknown"))),AND(AND(D3="retain",OR(E3="report_internal_inconsistency",E3="plan_material")),NOT(OR(K3="substantive_inconsistency",K3="minor_presentation",K3="non_inconsistency",K3="indeterminate"))),AND(AND(D3="retain",E3="protocol_report"),L3<>"",NOT(OR(L3="substantive_difference",L3="minor_presentation",L3="version_timing",L3="non_inconsistency",L3="indeterminate")))),"CHECK FIELDS",IF(AND(F3<>"",NOT(OR(F3="no",F3="primary_done"))),"CHECK COMPLETE",IF(F3="primary_done","PRIMARY READY","PRIMARY DRAFT")))))),"CHECK INPUT / KEY") -> PRIMARY READY | H3: confirmed_issue | I3: substantive | R3: TEST 2025::jama.2024.24764::C002
A4: 2025::jama.2024.24764::C003 | B4: Fascia-closing surgeon level totals exceed participant denominators without a multi-response qualifier | C4: jama_atherton_2025_oi_240145_1741627844.85412.pdf — PDF p. 7, Table 2 continuation | D4: retain | E4: statistical_results | F4: primary_done | G4: =IFERROR(IF(LEN(TRIM(CLEAN(SUBSTITUTE(Setup!$B$2,CHAR(160)," "))))=0,"CHECK REVIEWER ID",IF(OR(A4="",(COUNTIF('C_jama.2024.24764'!$A$2:$A$9,A4)+COUNTIF('C_jama.2024.27643'!$A$2:$A$9,A4)+COUNTIF('C_jama.2025.11178'!$A$2:$A$38,A4)+COUNTIF('C_jama.2025.15185'!$A$2:$A$13,A4)+COUNTIF('C_jama.2025.15440'!$A$2:$A$3,A4)+COUNTIF('C_jama.2025.16450'!$A$2:$A$11,A4)+COUNTIF('C_jama.2025.19563'!$A$2:$A$8,A4)+COUNTIF('C_jama.2025.19843'!$A$2:$A$2,A4)+COUNTIF('C_jama.2025.20765'!$A$2:$A$14,A4)+COUNTIF('C_jama.2025.24175'!$A$2:$A$15,A4)+COUNTIF('C_jama.2025.4390'!$A$2:$A$4,A4)+COUNTIF('C_jama.2025.7583'!$A$2:$A$4,A4)+COUNTIF('C_jama.2025.7710'!$A$2:$A$5,A4)+COUNTIF('C_jama.2025.9110'!$A$2:$A$7,A4)+COUNTIF('C_jama.2025.9663'!$A$2:$A$4,A4))<>1,COUNTIFS(Candidates!$G$2:$G$132,A4,Candidates!$K$2:$K$132,"jama.2024.24764")<>1),"CHECK KEY",IF(OR(AND(NOT(AND(D4="retain",E4="statistical_results")),H4<>"",H4<>"not_applicable"),AND(NOT(AND(D4="retain",E4="statistical_results")),I4<>"",I4<>"not_applicable"),AND(NOT(AND(D4="retain",E4="statistical_results")),J4<>"",J4<>"not_applicable"),AND(NOT(AND(D4="retain",OR(E4="report_internal_inconsistency",E4="plan_material"))),K4<>"",K4<>"not_applicable"),AND(NOT(AND(D4="retain",E4="protocol_report")),L4<>"",L4<>"not_applicable")),"CLEAR INACTIVE VALUES",IF(OR(NOT(OR(D4="retain",D4="exclude",D4="discuss")),NOT(OR(E4="statistical_results",E4="report_internal_inconsistency",E4="plan_material",E4="protocol_report")),AND(AND(D4="retain",E4="statistical_results"),NOT(OR(H4="confirmed_issue",H4="probable_issue",H4="not_issue",H4="indeterminate"))),AND(AND(D4="retain",E4="statistical_results"),NOT(OR(I4="substantive",I4="minor_presentation",I4="indeterminate"))),AND(AND(D4="retain",E4="statistical_results"),J4<>"",NOT(OR(J4="direct",J4="possible",J4="unlikely",J4="unknown"))),AND(AND(D4="retain",OR(E4="report_internal_inconsistency",E4="plan_material")),NOT(OR(K4="substantive_inconsistency",K4="minor_presentation",K4="non_inconsistency",K4="indeterminate"))),AND(AND(D4="retain",E4="protocol_report"),L4<>"",NOT(OR(L4="substantive_difference",L4="minor_presentation",L4="version_timing",L4="non_inconsistency",L4="indeterminate")))),"CHECK FIELDS",IF(AND(F4<>"",NOT(OR(F4="no",F4="primary_done"))),"CHECK COMPLETE",IF(F4="primary_done","PRIMARY READY","PRIMARY DRAFT")))))),"CHECK INPUT / KEY") -> PRIMARY READY | H4: confirmed_issue | I4: substantive | R4: TEST 2025::jama.2024.24764::C003
A5: 2025::jama.2024.24764::C004 | B5: Skin-closing surgeon level totals exceed participant denominators without a multi-response qualifier | C5: jama_atherton_2025_oi_240145_1741627844.85412.pdf — PDF p. 7, Table 2 continuation | D5: retain | E5: statistical_results | F5: primary_done | G5: =IFERROR(IF(LEN(TRIM(CLEAN(SUBSTITUTE(Setup!$B$2,CHAR(160)," "))))=0,"CHECK REVIEWER ID",IF(OR(A5="",(COUNTIF('C_jama.2024.24764'!$A$2:$A$9,A5)+COUNTIF('C_jama.2024.27643'!$A$2:$A$9,A5)+COUNTIF('C_jama.2025.11178'!$A$2:$A$38,A5)+COUNTIF('C_jama.2025.15185'!$A$2:$A$13,A5)+COUNTIF('C_jama.2025.15440'!$A$2:$A$3,A5)+COUNTIF('C_jama.2025.16450'!$A$2:$A$11,A5)+COUNTIF('C_jama.2025.19563'!$A$2:$A$8,A5)+COUNTIF('C_jama.2025.19843'!$A$2:$A$2,A5)+COUNTIF('C_jama.2025.20765'!$A$2:$A$14,A5)+COUNTIF('C_jama.2025.24175'!$A$2:$A$15,A5)+COUNTIF('C_jama.2025.4390'!$A$2:$A$4,A5)+COUNTIF('C_jama.2025.7583'!$A$2:$A$4,A5)+COUNTIF('C_jama.2025.7710'!$A$2:$A$5,A5)+COUNTIF('C_jama.2025.9110'!$A$2:$A$7,A5)+COUNTIF('C_jama.2025.9663'!$A$2:$A$4,A5))<>1,COUNTIFS(Candidates!$G$2:$G$132,A5,Candidates!$K$2:$K$132,"jama.2024.24764")<>1),"CHECK KEY",IF(OR(AND(NOT(AND(D5="retain",E5="statistical_results")),H5<>"",H5<>"not_applicable"),AND(NOT(AND(D5="retain",E5="statistical_results")),I5<>"",I5<>"not_applicable"),AND(NOT(AND(D5="retain",E5="statistical_results")),J5<>"",J5<>"not_applicable"),AND(NOT(AND(D5="retain",OR(E5="report_internal_inconsistency",E5="plan_material"))),K5<>"",K5<>"not_applicable"),AND(NOT(AND(D5="retain",E5="protocol_report")),L5<>"",L5<>"not_applicable")),"CLEAR INACTIVE VALUES",IF(OR(NOT(OR(D5="retain",D5="exclude",D5="discuss")),NOT(OR(E5="statistical_results",E5="report_internal_inconsistency",E5="plan_material",E5="protocol_report")),AND(AND(D5="retain",E5="statistical_results"),NOT(OR(H5="confirmed_issue",H5="probable_issue",H5="not_issue",H5="indeterminate"))),AND(AND(D5="retain",E5="statistical_results"),NOT(OR(I5="substantive",I5="minor_presentation",I5="indeterminate"))),AND(AND(D5="retain",E5="statistical_results"),J5<>"",NOT(OR(J5="direct",J5="possible",J5="unlikely",J5="unknown"))),AND(AND(D5="retain",OR(E5="report_internal_inconsistency",E5="plan_material")),NOT(OR(K5="substantive_inconsistency",K5="minor_presentation",K5="non_inconsistency",K5="indeterminate"))),AND(AND(D5="retain",E5="protocol_report"),L5<>"",NOT(OR(L5="substantive_difference",L5="minor_presentation",L5="version_timing",L5="non_inconsistency",L5="indeterminate")))),"CHECK FIELDS",IF(AND(F5<>"",NOT(OR(F5="no",F5="primary_done"))),"CHECK COMPLETE",IF(F5="primary_done","PRIMARY READY","PRIMARY DRAFT")))))),"CHECK INPUT / KEY") -> PRIMARY READY | H5: confirmed_issue | I5: substantive | R5: TEST 2025::jama.2024.24764::C004
A6: 2025::jama.2024.24764::C005 | B6: Control-arm mortality differs between participant flow and 30-day safety reporting | C6: jama_atherton_2025_oi_240145_1741627844.85412.pdf — PDF p. 3, Figure 1; PDF p. 6, safety narrative; PDF p. 8, Table 3 | D6: retain | E6: report_internal_inconsistency | F6: primary_done | G6: =IFERROR(IF(LEN(TRIM(CLEAN(SUBSTITUTE(Setup!$B$2,CHAR(160)," "))))=0,"CHECK REVIEWER ID",IF(OR(A6="",(COUNTIF('C_jama.2024.24764'!$A$2:$A$9,A6)+COUNTIF('C_jama.2024.27643'!$A$2:$A$9,A6)+COUNTIF('C_jama.2025.11178'!$A$2:$A$38,A6)+COUNTIF('C_jama.2025.15185'!$A$2:$A$13,A6)+COUNTIF('C_jama.2025.15440'!$A$2:$A$3,A6)+COUNTIF('C_jama.2025.16450'!$A$2:$A$11,A6)+COUNTIF('C_jama.2025.19563'!$A$2:$A$8,A6)+COUNTIF('C_jama.2025.19843'!$A$2:$A$2,A6)+COUNTIF('C_jama.2025.20765'!$A$2:$A$14,A6)+COUNTIF('C_jama.2025.24175'!$A$2:$A$15,A6)+COUNTIF('C_jama.2025.4390'!$A$2:$A$4,A6)+COUNTIF('C_jama.2025.7583'!$A$2:$A$4,A6)+COUNTIF('C_jama.2025.7710'!$A$2:$A$5,A6)+COUNTIF('C_jama.2025.9110'!$A$2:$A$7,A6)+COUNTIF('C_jama.2025.9663'!$A$2:$A$4,A6))<>1,COUNTIFS(Candidates!$G$2:$G$132,A6,Candidates!$K$2:$K$132,"jama.2024.24764")<>1),"CHECK KEY",IF(OR(AND(NOT(AND(D6="retain",E6="statistical_results")),H6<>"",H6<>"not_applicable"),AND(NOT(AND(D6="retain",E6="statistical_results")),I6<>"",I6<>"not_applicable"),AND(NOT(AND(D6="retain",E6="statistical_results")),J6<>"",J6<>"not_applicable"),AND(NOT(AND(D6="retain",OR(E6="report_internal_inconsistency",E6="plan_material"))),K6<>"",K6<>"not_applicable"),AND(NOT(AND(D6="retain",E6="protocol_report")),L6<>"",L6<>"not_applicable")),"CLEAR INACTIVE VALUES",IF(OR(NOT(OR(D6="retain",D6="exclude",D6="discuss")),NOT(OR(E6="statistical_results",E6="report_internal_inconsistency",E6="plan_material",E6="protocol_report")),AND(AND(D6="retain",E6="statistical_results"),NOT(OR(H6="confirmed_issue",H6="probable_issue",H6="not_issue",H6="indeterminate"))),AND(AND(D6="retain",E6="statistical_results"),NOT(OR(I6="substantive",I6="minor_presentation",I6="indeterminate"))),AND(AND(D6="retain",E6="statistical_results"),J6<>"",NOT(OR(J6="direct",J6="possible",J6="unlikely",J6="unknown"))),AND(AND(D6="retain",OR(E6="report_internal_inconsistency",E6="plan_material")),NOT(OR(K6="substantive_inconsistency",K6="minor_presentation",K6="non_inconsistency",K6="indeterminate"))),AND(AND(D6="retain",E6="protocol_report"),L6<>"",NOT(OR(L6="substantive_difference",L6="minor_presentation",L6="version_timing",L6="non_inconsistency",L6="indeterminate")))),"CHECK FIELDS",IF(AND(F6<>"",NOT(OR(F6="no",F6="primary_done"))),"CHECK COMPLETE",IF(F6="primary_done","PRIMARY READY","PRIMARY DRAFT")))))),"CHECK INPUT / KEY") -> PRIMARY READY | K6: substantive_inconsistency | R6: TEST 2025::jama.2024.24764::C005
A7: 2025::jama.2024.24764::C006 | B7: Longitudinal quality-of-life covariance specification differs between SAP and final article | C7: joi240145supp1_prod_1741627844.87412.pdf — PDF p. 26, SAP; jama_atherton_2025_oi_240145_1741627844.85412.pdf — PDF p. 4, Statistical Analysis | D7: retain | E7: protocol_report | F7: primary_done | G7: =IFERROR(IF(LEN(TRIM(CLEAN(SUBSTITUTE(Setup!$B$2,CHAR(160)," "))))=0,"CHECK REVIEWER ID",IF(OR(A7="",(COUNTIF('C_jama.2024.24764'!$A$2:$A$9,A7)+COUNTIF('C_jama.2024.27643'!$A$2:$A$9,A7)+COUNTIF('C_jama.2025.11178'!$A$2:$A$38,A7)+COUNTIF('C_jama.2025.15185'!$A$2:$A$13,A7)+COUNTIF('C_jama.2025.15440'!$A$2:$A$3,A7)+COUNTIF('C_jama.2025.16450'!$A$2:$A$11,A7)+COUNTIF('C_jama.2025.19563'!$A$2:$A$8,A7)+COUNTIF('C_jama.2025.19843'!$A$2:$A$2,A7)+COUNTIF('C_jama.2025.20765'!$A$2:$A$14,A7)+COUNTIF('C_jama.2025.24175'!$A$2:$A$15,A7)+COUNTIF('C_jama.2025.4390'!$A$2:$A$4,A7)+COUNTIF('C_jama.2025.7583'!$A$2:$A$4,A7)+COUNTIF('C_jama.2025.7710'!$A$2:$A$5,A7)+COUNTIF('C_jama.2025.9110'!$A$2:$A$7,A7)+COUNTIF('C_jama.2025.9663'!$A$2:$A$4,A7))<>1,COUNTIFS(Candidates!$G$2:$G$132,A7,Candidates!$K$2:$K$132,"jama.2024.24764")<>1),"CHECK KEY",IF(OR(AND(NOT(AND(D7="retain",E7="statistical_results")),H7<>"",H7<>"not_applicable"),AND(NOT(AND(D7="retain",E7="statistical_results")),I7<>"",I7<>"not_applicable"),AND(NOT(AND(D7="retain",E7="statistical_results")),J7<>"",J7<>"not_applicable"),AND(NOT(AND(D7="retain",OR(E7="report_internal_inconsistency",E7="plan_material"))),K7<>"",K7<>"not_applicable"),AND(NOT(AND(D7="retain",E7="protocol_report")),L7<>"",L7<>"not_applicable")),"CLEAR INACTIVE VALUES",IF(OR(NOT(OR(D7="retain",D7="exclude",D7="discuss")),NOT(OR(E7="statistical_results",E7="report_internal_inconsistency",E7="plan_material",E7="protocol_report")),AND(AND(D7="retain",E7="statistical_results"),NOT(OR(H7="confirmed_issue",H7="probable_issue",H7="not_issue",H7="indeterminate"))),AND(AND(D7="retain",E7="statistical_results"),NOT(OR(I7="substantive",I7="minor_presentation",I7="indeterminate"))),AND(AND(D7="retain",E7="statistical_results"),J7<>"",NOT(OR(J7="direct",J7="possible",J7="unlikely",J7="unknown"))),AND(AND(D7="retain",OR(E7="report_internal_inconsistency",E7="plan_material")),NOT(OR(K7="substantive_inconsistency",K7="minor_presentation",K7="non_inconsistency",K7="indeterminate"))),AND(AND(D7="retain",E7="protocol_report"),L7<>"",NOT(OR(L7="substantive_difference",L7="minor_presentation",L7="version_timing",L7="non_inconsistency",L7="indeterminate")))),"CHECK FIELDS",IF(AND(F7<>"",NOT(OR(F7="no",F7="primary_done"))),"CHECK COMPLETE",IF(F7="primary_done","PRIMARY READY","PRIMARY DRAFT")))))),"CHECK INPUT / KEY") -> PRIMARY READY | R7: TEST 2025::jama.2024.24764::C006
A8: 2025::jama.2024.24764::C007 | B8: Length-of-stay effect measure and model differ between SAP/protocol and final article | C8: joi240145supp1_prod_1741627844.87412.pdf — PDF p. 25, SAP; joi240145supp4_prod_1741627844.90412.pdf — PDF p. 39, protocol; jama_atherton_2025_oi_240145_1741627844.85412.pdf — PDF p. 4; PDF p. 8, Table 3 | D8: retain | E8: protocol_report | F8: primary_done | G8: =IFERROR(IF(LEN(TRIM(CLEAN(SUBSTITUTE(Setup!$B$2,CHAR(160)," "))))=0,"CHECK REVIEWER ID",IF(OR(A8="",(COUNTIF('C_jama.2024.24764'!$A$2:$A$9,A8)+COUNTIF('C_jama.2024.27643'!$A$2:$A$9,A8)+COUNTIF('C_jama.2025.11178'!$A$2:$A$38,A8)+COUNTIF('C_jama.2025.15185'!$A$2:$A$13,A8)+COUNTIF('C_jama.2025.15440'!$A$2:$A$3,A8)+COUNTIF('C_jama.2025.16450'!$A$2:$A$11,A8)+COUNTIF('C_jama.2025.19563'!$A$2:$A$8,A8)+COUNTIF('C_jama.2025.19843'!$A$2:$A$2,A8)+COUNTIF('C_jama.2025.20765'!$A$2:$A$14,A8)+COUNTIF('C_jama.2025.24175'!$A$2:$A$15,A8)+COUNTIF('C_jama.2025.4390'!$A$2:$A$4,A8)+COUNTIF('C_jama.2025.7583'!$A$2:$A$4,A8)+COUNTIF('C_jama.2025.7710'!$A$2:$A$5,A8)+COUNTIF('C_jama.2025.9110'!$A$2:$A$7,A8)+COUNTIF('C_jama.2025.9663'!$A$2:$A$4,A8))<>1,COUNTIFS(Candidates!$G$2:$G$132,A8,Candidates!$K$2:$K$132,"jama.2024.24764")<>1),"CHECK KEY",IF(OR(AND(NOT(AND(D8="retain",E8="statistical_results")),H8<>"",H8<>"not_applicable"),AND(NOT(AND(D8="retain",E8="statistical_results")),I8<>"",I8<>"not_applicable"),AND(NOT(AND(D8="retain",E8="statistical_results")),J8<>"",J8<>"not_applicable"),AND(NOT(AND(D8="retain",OR(E8="report_internal_inconsistency",E8="plan_material"))),K8<>"",K8<>"not_applicable"),AND(NOT(AND(D8="retain",E8="protocol_report")),L8<>"",L8<>"not_applicable")),"CLEAR INACTIVE VALUES",IF(OR(NOT(OR(D8="retain",D8="exclude",D8="discuss")),NOT(OR(E8="statistical_results",E8="report_internal_inconsistency",E8="plan_material",E8="protocol_report")),AND(AND(D8="retain",E8="statistical_results"),NOT(OR(H8="confirmed_issue",H8="probable_issue",H8="not_issue",H8="indeterminate"))),AND(AND(D8="retain",E8="statistical_results"),NOT(OR(I8="substantive",I8="minor_presentation",I8="indeterminate"))),AND(AND(D8="retain",E8="statistical_results"),J8<>"",NOT(OR(J8="direct",J8="possible",J8="unlikely",J8="unknown"))),AND(AND(D8="retain",OR(E8="report_internal_inconsistency",E8="plan_material")),NOT(OR(K8="substantive_inconsistency",K8="minor_presentation",K8="non_inconsistency",K8="indeterminate"))),AND(AND(D8="retain",E8="protocol_report"),L8<>"",NOT(OR(L8="substantive_difference",L8="minor_presentation",L8="version_timing",L8="non_inconsistency",L8="indeterminate")))),"CHECK FIELDS",IF(AND(F8<>"",NOT(OR(F8="no",F8="primary_done"))),"CHECK COMPLETE",IF(F8="primary_done","PRIMARY READY","PRIMARY DRAFT")))))),"CHECK INPUT / KEY") -> PRIMARY READY | R8: TEST 2025::jama.2024.24764::C007
A9: 2025::jama.2024.24764::C008 | B9: Australia-inclusive length-of-stay result differs from the stated UK-only analysis population | C9: joi240145supp1_prod_1741627844.87412.pdf — PDF p. 18, SAP endpoint; PDF p. 25, SAP population; joi240145supp4_prod_1741627844.90412.pdf — PDF p. 24, protocol; jama_atherton_2025_oi_240145_1741627844.85412.pdf — PDF p. 1, abstract; PDF p. 8, Table 3 | D9: retain | E9: protocol_report | F9: primary_done | G9: =IFERROR(IF(LEN(TRIM(CLEAN(SUBSTITUTE(Setup!$B$2,CHAR(160)," "))))=0,"CHECK REVIEWER ID",IF(OR(A9="",(COUNTIF('C_jama.2024.24764'!$A$2:$A$9,A9)+COUNTIF('C_jama.2024.27643'!$A$2:$A$9,A9)+COUNTIF('C_jama.2025.11178'!$A$2:$A$38,A9)+COUNTIF('C_jama.2025.15185'!$A$2:$A$13,A9)+COUNTIF('C_jama.2025.15440'!$A$2:$A$3,A9)+COUNTIF('C_jama.2025.16450'!$A$2:$A$11,A9)+COUNTIF('C_jama.2025.19563'!$A$2:$A$8,A9)+COUNTIF('C_jama.2025.19843'!$A$2:$A$2,A9)+COUNTIF('C_jama.2025.20765'!$A$2:$A$14,A9)+COUNTIF('C_jama.2025.24175'!$A$2:$A$15,A9)+COUNTIF('C_jama.2025.4390'!$A$2:$A$4,A9)+COUNTIF('C_jama.2025.7583'!$A$2:$A$4,A9)+COUNTIF('C_jama.2025.7710'!$A$2:$A$5,A9)+COUNTIF('C_jama.2025.9110'!$A$2:$A$7,A9)+COUNTIF('C_jama.2025.9663'!$A$2:$A$4,A9))<>1,COUNTIFS(Candidates!$G$2:$G$132,A9,Candidates!$K$2:$K$132,"jama.2024.24764")<>1),"CHECK KEY",IF(OR(AND(NOT(AND(D9="retain",E9="statistical_results")),H9<>"",H9<>"not_applicable"),AND(NOT(AND(D9="retain",E9="statistical_results")),I9<>"",I9<>"not_applicable"),AND(NOT(AND(D9="retain",E9="statistical_results")),J9<>"",J9<>"not_applicable"),AND(NOT(AND(D9="retain",OR(E9="report_internal_inconsistency",E9="plan_material"))),K9<>"",K9<>"not_applicable"),AND(NOT(AND(D9="retain",E9="protocol_report")),L9<>"",L9<>"not_applicable")),"CLEAR INACTIVE VALUES",IF(OR(NOT(OR(D9="retain",D9="exclude",D9="discuss")),NOT(OR(E9="statistical_results",E9="report_internal_inconsistency",E9="plan_material",E9="protocol_report")),AND(AND(D9="retain",E9="statistical_results"),NOT(OR(H9="confirmed_issue",H9="probable_issue",H9="not_issue",H9="indeterminate"))),AND(AND(D9="retain",E9="statistical_results"),NOT(OR(I9="substantive",I9="minor_presentation",I9="indeterminate"))),AND(AND(D9="retain",E9="statistical_results"),J9<>"",NOT(OR(J9="direct",J9="possible",J9="unlikely",J9="unknown"))),AND(AND(D9="retain",OR(E9="report_internal_inconsistency",E9="plan_material")),NOT(OR(K9="substantive_inconsistency",K9="minor_presentation",K9="non_inconsistency",K9="indeterminate"))),AND(AND(D9="retain",E9="protocol_report"),L9<>"",NOT(OR(L9="substantive_difference",L9="minor_presentation",L9="version_timing",L9="non_inconsistency",L9="indeterminate")))),"CHECK FIELDS",IF(AND(F9<>"",NOT(OR(F9="no",F9="primary_done"))),"CHECK COMPLETE",IF(F9="primary_done","PRIMARY READY","PRIMARY DRAFT")))))),"CHECK INPUT / KEY") -> PRIMARY READY | R9: TEST 2025::jama.2024.24764::C008

Sheet C_jama.2024.27643
A1: Candidate key | B1: Candidate title | C1: Source location | D1: Disposition | E1: Review domain (AI suggestion; editable) | F1: Complete | G1: Validation hint | H1: Statistcal_or_numerical issue | I1: Substantiveness | J1: Downstream impact | K1: Report-internal or planning-material inconsistency | L1: Protocol interpretation | R1: Notes (optional)
A2: 2025::jama.2024.27643::C001 | B2: Shared-placebo race missingness does not reconcile with the printed denominator | C2: jama_berry_2025_oi_240158_1742927563.7361.pdf — Table 1 and footnote b, PDF p. 6 | D2: retain | E2: statistical_results | F2: primary_done | G2: =IFERROR(IF(LEN(TRIM(CLEAN(SUBSTITUTE(Setup!$B$2,CHAR(160)," "))))=0,"CHECK REVIEWER ID",IF(OR(A2="",(COUNTIF('C_jama.2024.24764'!$A$2:$A$9,A2)+COUNTIF('C_jama.2024.27643'!$A$2:$A$9,A2)+COUNTIF('C_jama.2025.11178'!$A$2:$A$38,A2)+COUNTIF('C_jama.2025.15185'!$A$2:$A$13,A2)+COUNTIF('C_jama.2025.15440'!$A$2:$A$3,A2)+COUNTIF('C_jama.2025.16450'!$A$2:$A$11,A2)+COUNTIF('C_jama.2025.19563'!$A$2:$A$8,A2)+COUNTIF('C_jama.2025.19843'!$A$2:$A$2,A2)+COUNTIF('C_jama.2025.20765'!$A$2:$A$14,A2)+COUNTIF('C_jama.2025.24175'!$A$2:$A$15,A2)+COUNTIF('C_jama.2025.4390'!$A$2:$A$4,A2)+COUNTIF('C_jama.2025.7583'!$A$2:$A$4,A2)+COUNTIF('C_jama.2025.7710'!$A$2:$A$5,A2)+COUNTIF('C_jama.2025.9110'!$A$2:$A$7,A2)+COUNTIF('C_jama.2025.9663'!$A$2:$A$4,A2))<>1,COUNTIFS(Candidates!$G$2:$G$132,A2,Candidates!$K$2:$K$132,"jama.2024.27643")<>1),"CHECK KEY",IF(OR(AND(NOT(AND(D2="retain",E2="statistical_results")),H2<>"",H2<>"not_applicable"),AND(NOT(AND(D2="retain",E2="statistical_results")),I2<>"",I2<>"not_applicable"),AND(NOT(AND(D2="retain",E2="statistical_results")),J2<>"",J2<>"not_applicable"),AND(NOT(AND(D2="retain",OR(E2="report_internal_inconsistency",E2="plan_material"))),K2<>"",K2<>"not_applicable"),AND(NOT(AND(D2="retain",E2="protocol_report")),L2<>"",L2<>"not_applicable")),"CLEAR INACTIVE VALUES",IF(OR(NOT(OR(D2="retain",D2="exclude",D2="discuss")),NOT(OR(E2="statistical_results",E2="report_internal_inconsistency",E2="plan_material",E2="protocol_report")),AND(AND(D2="retain",E2="statistical_results"),NOT(OR(H2="confirmed_issue",H2="probable_issue",H2="not_issue",H2="indeterminate"))),AND(AND(D2="retain",E2="statistical_results"),NOT(OR(I2="substantive",I2="minor_presentation",I2="indeterminate"))),AND(AND(D2="retain",E2="statistical_results"),J2<>"",NOT(OR(J2="direct",J2="possible",J2="unlikely",J2="unknown"))),AND(AND(D2="retain",OR(E2="report_internal_inconsistency",E2="plan_material")),NOT(OR(K2="substantive_inconsistency",K2="minor_presentation",K2="non_inconsistency",K2="indeterminate"))),AND(AND(D2="retain",E2="protocol_report"),L2<>"",NOT(OR(L2="substantive_difference",L2="minor_presentation",L2="version_timing",L2="non_inconsistency",L2="indeterminate")))),"CHECK FIELDS",IF(AND(F2<>"",NOT(OR(F2="no",F2="primary_done"))),"CHECK COMPLETE",IF(F2="primary_done","PRIMARY READY","PRIMARY DRAFT")))))),"CHECK INPUT / KEY") -> PRIMARY READY | H2: confirmed_issue | I2: substantive | R2: TEST 2025::jama.2024.27643::C001
A3: 2025::jama.2024.27643::C002 | B3: SVC values have incompatible monthly-rate and 24-week-change labels | C3: jama_berry_2025_oi_240158_1742927563.7361.pdf — Secondary Efficacy Outcomes, PDF p. 4; joi240158supp3_prod_1742927563.7911.pdf — eTable 3A, PDF p. 16 | D3: retain | E3: report_internal_inconsistency | F3: primary_done | G3: =IFERROR(IF(LEN(TRIM(CLEAN(SUBSTITUTE(Setup!$B$2,CHAR(160)," "))))=0,"CHECK REVIEWER ID",IF(OR(A3="",(COUNTIF('C_jama.2024.24764'!$A$2:$A$9,A3)+COUNTIF('C_jama.2024.27643'!$A$2:$A$9,A3)+COUNTIF('C_jama.2025.11178'!$A$2:$A$38,A3)+COUNTIF('C_jama.2025.15185'!$A$2:$A$13,A3)+COUNTIF('C_jama.2025.15440'!$A$2:$A$3,A3)+COUNTIF('C_jama.2025.16450'!$A$2:$A$11,A3)+COUNTIF('C_jama.2025.19563'!$A$2:$A$8,A3)+COUNTIF('C_jama.2025.19843'!$A$2:$A$2,A3)+COUNTIF('C_jama.2025.20765'!$A$2:$A$14,A3)+COUNTIF('C_jama.2025.24175'!$A$2:$A$15,A3)+COUNTIF('C_jama.2025.4390'!$A$2:$A$4,A3)+COUNTIF('C_jama.2025.7583'!$A$2:$A$4,A3)+COUNTIF('C_jama.2025.7710'!$A$2:$A$5,A3)+COUNTIF('C_jama.2025.9110'!$A$2:$A$7,A3)+COUNTIF('C_jama.2025.9663'!$A$2:$A$4,A3))<>1,COUNTIFS(Candidates!$G$2:$G$132,A3,Candidates!$K$2:$K$132,"jama.2024.27643")<>1),"CHECK KEY",IF(OR(AND(NOT(AND(D3="retain",E3="statistical_results")),H3<>"",H3<>"not_applicable"),AND(NOT(AND(D3="retain",E3="statistical_results")),I3<>"",I3<>"not_applicable"),AND(NOT(AND(D3="retain",E3="statistical_results")),J3<>"",J3<>"not_applicable"),AND(NOT(AND(D3="retain",OR(E3="report_internal_inconsistency",E3="plan_material"))),K3<>"",K3<>"not_applicable"),AND(NOT(AND(D3="retain",E3="protocol_report")),L3<>"",L3<>"not_applicable")),"CLEAR INACTIVE VALUES",IF(OR(NOT(OR(D3="retain",D3="exclude",D3="discuss")),NOT(OR(E3="statistical_results",E3="report_internal_inconsistency",E3="plan_material",E3="protocol_report")),AND(AND(D3="retain",E3="statistical_results"),NOT(OR(H3="confirmed_issue",H3="probable_issue",H3="not_issue",H3="indeterminate"))),AND(AND(D3="retain",E3="statistical_results"),NOT(OR(I3="substantive",I3="minor_presentation",I3="indeterminate"))),AND(AND(D3="retain",E3="statistical_results"),J3<>"",NOT(OR(J3="direct",J3="possible",J3="unlikely",J3="unknown"))),AND(AND(D3="retain",OR(E3="report_internal_inconsistency",E3="plan_material")),NOT(OR(K3="substantive_inconsistency",K3="minor_presentation",K3="non_inconsistency",K3="indeterminate"))),AND(AND(D3="retain",E3="protocol_report"),L3<>"",NOT(OR(L3="substantive_difference",L3="minor_presentation",L3="version_timing",L3="non_inconsistency",L3="indeterminate")))),"CHECK FIELDS",IF(AND(F3<>"",NOT(OR(F3="no",F3="primary_done"))),"CHECK COMPLETE",IF(F3="primary_done","PRIMARY READY","PRIMARY DRAFT")))))),"CHECK INPUT / KEY") -> PRIMARY READY | K3: substantive_inconsistency | R3: TEST 2025::jama.2024.27643::C002
A4: 2025::jama.2024.27643::C003 | B4: Shared-placebo ALSFRS-R credible-interval endpoints differ for the cited primary model | C4: jama_berry_2025_oi_240158_1742927563.7361.pdf — Primary Efficacy Outcome, PDF p. 4; joi240158supp3_prod_1742927563.7911.pdf — eTable 2, PDF p. 15 | D4: retain | E4: report_internal_inconsistency | F4: primary_done | G4: =IFERROR(IF(LEN(TRIM(CLEAN(SUBSTITUTE(Setup!$B$2,CHAR(160)," "))))=0,"CHECK REVIEWER ID",IF(OR(A4="",(COUNTIF('C_jama.2024.24764'!$A$2:$A$9,A4)+COUNTIF('C_jama.2024.27643'!$A$2:$A$9,A4)+COUNTIF('C_jama.2025.11178'!$A$2:$A$38,A4)+COUNTIF('C_jama.2025.15185'!$A$2:$A$13,A4)+COUNTIF('C_jama.2025.15440'!$A$2:$A$3,A4)+COUNTIF('C_jama.2025.16450'!$A$2:$A$11,A4)+COUNTIF('C_jama.2025.19563'!$A$2:$A$8,A4)+COUNTIF('C_jama.2025.19843'!$A$2:$A$2,A4)+COUNTIF('C_jama.2025.20765'!$A$2:$A$14,A4)+COUNTIF('C_jama.2025.24175'!$A$2:$A$15,A4)+COUNTIF('C_jama.2025.4390'!$A$2:$A$4,A4)+COUNTIF('C_jama.2025.7583'!$A$2:$A$4,A4)+COUNTIF('C_jama.2025.7710'!$A$2:$A$5,A4)+COUNTIF('C_jama.2025.9110'!$A$2:$A$7,A4)+COUNTIF('C_jama.2025.9663'!$A$2:$A$4,A4))<>1,COUNTIFS(Candidates!$G$2:$G$132,A4,Candidates!$K$2:$K$132,"jama.2024.27643")<>1),"CHECK KEY",IF(OR(AND(NOT(AND(D4="retain",E4="statistical_results")),H4<>"",H4<>"not_applicable"),AND(NOT(AND(D4="retain",E4="statistical_results")),I4<>"",I4<>"not_applicable"),AND(NOT(AND(D4="retain",E4="statistical_results")),J4<>"",J4<>"not_applicable"),AND(NOT(AND(D4="retain",OR(E4="report_internal_inconsistency",E4="plan_material"))),K4<>"",K4<>"not_applicable"),AND(NOT(AND(D4="retain",E4="protocol_report")),L4<>"",L4<>"not_applicable")),"CLEAR INACTIVE VALUES",IF(OR(NOT(OR(D4="retain",D4="exclude",D4="discuss")),NOT(OR(E4="statistical_results",E4="report_internal_inconsistency",E4="plan_material",E4="protocol_report")),AND(AND(D4="retain",E4="statistical_results"),NOT(OR(H4="confirmed_issue",H4="probable_issue",H4="not_issue",H4="indeterminate"))),AND(AND(D4="retain",E4="statistical_results"),NOT(OR(I4="substantive",I4="minor_presentation",I4="indeterminate"))),AND(AND(D4="retain",E4="statistical_results"),J4<>"",NOT(OR(J4="direct",J4="possible",J4="unlikely",J4="unknown"))),AND(AND(D4="retain",OR(E4="report_internal_inconsistency",E4="plan_material")),NOT(OR(K4="substantive_inconsistency",K4="minor_presentation",K4="non_inconsistency",K4="indeterminate"))),AND(AND(D4="retain",E4="protocol_report"),L4<>"",NOT(OR(L4="substantive_difference",L4="minor_presentation",L4="version_timing",L4="non_inconsistency",L4="indeterminate")))),"CHECK FIELDS",IF(AND(F4<>"",NOT(OR(F4="no",F4="primary_done"))),"CHECK COMPLETE",IF(F4="primary_done","PRIMARY READY","PRIMARY DRAFT")))))),"CHECK INPUT / KEY") -> PRIMARY READY | K4: substantive_inconsistency | R4: TEST 2025::jama.2024.27643::C003
A5: 2025::jama.2024.27643::C004 | B5: Pooled-active ALSFRS-R credible-interval endpoints differ for the cited primary model | C5: jama_berry_2025_oi_240158_1742927563.7361.pdf — Primary Efficacy Outcome, PDF p. 4; joi240158supp3_prod_1742927563.7911.pdf — eTable 2, PDF p. 15 | D5: retain | E5: report_internal_inconsistency | F5: primary_done | G5: =IFERROR(IF(LEN(TRIM(CLEAN(SUBSTITUTE(Setup!$B$2,CHAR(160)," "))))=0,"CHECK REVIEWER ID",IF(OR(A5="",(COUNTIF('C_jama.2024.24764'!$A$2:$A$9,A5)+COUNTIF('C_jama.2024.27643'!$A$2:$A$9,A5)+COUNTIF('C_jama.2025.11178'!$A$2:$A$38,A5)+COUNTIF('C_jama.2025.15185'!$A$2:$A$13,A5)+COUNTIF('C_jama.2025.15440'!$A$2:$A$3,A5)+COUNTIF('C_jama.2025.16450'!$A$2:$A$11,A5)+COUNTIF('C_jama.2025.19563'!$A$2:$A$8,A5)+COUNTIF('C_jama.2025.19843'!$A$2:$A$2,A5)+COUNTIF('C_jama.2025.20765'!$A$2:$A$14,A5)+COUNTIF('C_jama.2025.24175'!$A$2:$A$15,A5)+COUNTIF('C_jama.2025.4390'!$A$2:$A$4,A5)+COUNTIF('C_jama.2025.7583'!$A$2:$A$4,A5)+COUNTIF('C_jama.2025.7710'!$A$2:$A$5,A5)+COUNTIF('C_jama.2025.9110'!$A$2:$A$7,A5)+COUNTIF('C_jama.2025.9663'!$A$2:$A$4,A5))<>1,COUNTIFS(Candidates!$G$2:$G$132,A5,Candidates!$K$2:$K$132,"jama.2024.27643")<>1),"CHECK KEY",IF(OR(AND(NOT(AND(D5="retain",E5="statistical_results")),H5<>"",H5<>"not_applicable"),AND(NOT(AND(D5="retain",E5="statistical_results")),I5<>"",I5<>"not_applicable"),AND(NOT(AND(D5="retain",E5="statistical_results")),J5<>"",J5<>"not_applicable"),AND(NOT(AND(D5="retain",OR(E5="report_internal_inconsistency",E5="plan_material"))),K5<>"",K5<>"not_applicable"),AND(NOT(AND(D5="retain",E5="protocol_report")),L5<>"",L5<>"not_applicable")),"CLEAR INACTIVE VALUES",IF(OR(NOT(OR(D5="retain",D5="exclude",D5="discuss")),NOT(OR(E5="statistical_results",E5="report_internal_inconsistency",E5="plan_material",E5="protocol_report")),AND(AND(D5="retain",E5="statistical_results"),NOT(OR(H5="confirmed_issue",H5="probable_issue",H5="not_issue",H5="indeterminate"))),AND(AND(D5="retain",E5="statistical_results"),NOT(OR(I5="substantive",I5="minor_presentation",I5="indeterminate"))),AND(AND(D5="retain",E5="statistical_results"),J5<>"",NOT(OR(J5="direct",J5="possible",J5="unlikely",J5="unknown"))),AND(AND(D5="retain",OR(E5="report_internal_inconsistency",E5="plan_material")),NOT(OR(K5="substantive_inconsistency",K5="minor_presentation",K5="non_inconsistency",K5="indeterminate"))),AND(AND(D5="retain",E5="protocol_report"),L5<>"",NOT(OR(L5="substantive_difference",L5="minor_presentation",L5="version_timing",L5="non_inconsistency",L5="indeterminate")))),"CHECK FIELDS",IF(AND(F5<>"",NOT(OR(F5="no",F5="primary_done"))),"CHECK COMPLETE",IF(F5="primary_done","PRIMARY READY","PRIMARY DRAFT")))))),"CHECK INPUT / KEY") -> PRIMARY READY | K5: substantive_inconsistency | R5: TEST 2025::jama.2024.27643::C004
A6: 2025::jama.2024.27643::C005 | B6: Bayesian mortality event rates differ between article text and cited eTable 2 | C6: jama_berry_2025_oi_240158_1742927563.7361.pdf — Primary Efficacy Outcome, PDF p. 4; joi240158supp3_prod_1742927563.7911.pdf — eTable 2, PDF p. 15 | D6: retain | E6: report_internal_inconsistency | F6: primary_done | G6: =IFERROR(IF(LEN(TRIM(CLEAN(SUBSTITUTE(Setup!$B$2,CHAR(160)," "))))=0,"CHECK REVIEWER ID",IF(OR(A6="",(COUNTIF('C_jama.2024.24764'!$A$2:$A$9,A6)+COUNTIF('C_jama.2024.27643'!$A$2:$A$9,A6)+COUNTIF('C_jama.2025.11178'!$A$2:$A$38,A6)+COUNTIF('C_jama.2025.15185'!$A$2:$A$13,A6)+COUNTIF('C_jama.2025.15440'!$A$2:$A$3,A6)+COUNTIF('C_jama.2025.16450'!$A$2:$A$11,A6)+COUNTIF('C_jama.2025.19563'!$A$2:$A$8,A6)+COUNTIF('C_jama.2025.19843'!$A$2:$A$2,A6)+COUNTIF('C_jama.2025.20765'!$A$2:$A$14,A6)+COUNTIF('C_jama.2025.24175'!$A$2:$A$15,A6)+COUNTIF('C_jama.2025.4390'!$A$2:$A$4,A6)+COUNTIF('C_jama.2025.7583'!$A$2:$A$4,A6)+COUNTIF('C_jama.2025.7710'!$A$2:$A$5,A6)+COUNTIF('C_jama.2025.9110'!$A$2:$A$7,A6)+COUNTIF('C_jama.2025.9663'!$A$2:$A$4,A6))<>1,COUNTIFS(Candidates!$G$2:$G$132,A6,Candidates!$K$2:$K$132,"jama.2024.27643")<>1),"CHECK KEY",IF(OR(AND(NOT(AND(D6="retain",E6="statistical_results")),H6<>"",H6<>"not_applicable"),AND(NOT(AND(D6="retain",E6="statistical_results")),I6<>"",I6<>"not_applicable"),AND(NOT(AND(D6="retain",E6="statistical_results")),J6<>"",J6<>"not_applicable"),AND(NOT(AND(D6="retain",OR(E6="report_internal_inconsistency",E6="plan_material"))),K6<>"",K6<>"not_applicable"),AND(NOT(AND(D6="retain",E6="protocol_report")),L6<>"",L6<>"not_applicable")),"CLEAR INACTIVE VALUES",IF(OR(NOT(OR(D6="retain",D6="exclude",D6="discuss")),NOT(OR(E6="statistical_results",E6="report_internal_inconsistency",E6="plan_material",E6="protocol_report")),AND(AND(D6="retain",E6="statistical_results"),NOT(OR(H6="confirmed_issue",H6="probable_issue",H6="not_issue",H6="indeterminate"))),AND(AND(D6="retain",E6="statistical_results"),NOT(OR(I6="substantive",I6="minor_presentation",I6="indeterminate"))),AND(AND(D6="retain",E6="statistical_results"),J6<>"",NOT(OR(J6="direct",J6="possible",J6="unlikely",J6="unknown"))),AND(AND(D6="retain",OR(E6="report_internal_inconsistency",E6="plan_material")),NOT(OR(K6="substantive_inconsistency",K6="minor_presentation",K6="non_inconsistency",K6="indeterminate"))),AND(AND(D6="retain",E6="protocol_report"),L6<>"",NOT(OR(L6="substantive_difference",L6="minor_presentation",L6="version_timing",L6="non_inconsistency",L6="indeterminate")))),"CHECK FIELDS",IF(AND(F6<>"",NOT(OR(F6="no",F6="primary_done"))),"CHECK COMPLETE",IF(F6="primary_done","PRIMARY READY","PRIMARY DRAFT")))))),"CHECK INPUT / KEY") -> PRIMARY READY | K6: substantive_inconsistency | R6: TEST 2025::jama.2024.27643::C005
A7: 2025::jama.2024.27643::C006 | B7: Plasma NfL confidence intervals differ across Figure 3, narrative, and eTable 3B | C7: jama_berry_2025_oi_240158_1742927563.7361.pdf — Figure 3 and Biomarker Analyses, PDF p. 8; joi240158supp3_prod_1742927563.7911.pdf — eTable 3B, PDF p. 17 | D7: retain | E7: report_internal_inconsistency | F7: primary_done | G7: =IFERROR(IF(LEN(TRIM(CLEAN(SUBSTITUTE(Setup!$B$2,CHAR(160)," "))))=0,"CHECK REVIEWER ID",IF(OR(A7="",(COUNTIF('C_jama.2024.24764'!$A$2:$A$9,A7)+COUNTIF('C_jama.2024.27643'!$A$2:$A$9,A7)+COUNTIF('C_jama.2025.11178'!$A$2:$A$38,A7)+COUNTIF('C_jama.2025.15185'!$A$2:$A$13,A7)+COUNTIF('C_jama.2025.15440'!$A$2:$A$3,A7)+COUNTIF('C_jama.2025.16450'!$A$2:$A$11,A7)+COUNTIF('C_jama.2025.19563'!$A$2:$A$8,A7)+COUNTIF('C_jama.2025.19843'!$A$2:$A$2,A7)+COUNTIF('C_jama.2025.20765'!$A$2:$A$14,A7)+COUNTIF('C_jama.2025.24175'!$A$2:$A$15,A7)+COUNTIF('C_jama.2025.4390'!$A$2:$A$4,A7)+COUNTIF('C_jama.2025.7583'!$A$2:$A$4,A7)+COUNTIF('C_jama.2025.7710'!$A$2:$A$5,A7)+COUNTIF('C_jama.2025.9110'!$A$2:$A$7,A7)+COUNTIF('C_jama.2025.9663'!$A$2:$A$4,A7))<>1,COUNTIFS(Candidates!$G$2:$G$132,A7,Candidates!$K$2:$K$132,"jama.2024.27643")<>1),"CHECK KEY",IF(OR(AND(NOT(AND(D7="retain",E7="statistical_results")),H7<>"",H7<>"not_applicable"),AND(NOT(AND(D7="retain",E7="statistical_results")),I7<>"",I7<>"not_applicable"),AND(NOT(AND(D7="retain",E7="statistical_results")),J7<>"",J7<>"not_applicable"),AND(NOT(AND(D7="retain",OR(E7="report_internal_inconsistency",E7="plan_material"))),K7<>"",K7<>"not_applicable"),AND(NOT(AND(D7="retain",E7="protocol_report")),L7<>"",L7<>"not_applicable")),"CLEAR INACTIVE VALUES",IF(OR(NOT(OR(D7="retain",D7="exclude",D7="discuss")),NOT(OR(E7="statistical_results",E7="report_internal_inconsistency",E7="plan_material",E7="protocol_report")),AND(AND(D7="retain",E7="statistical_results"),NOT(OR(H7="confirmed_issue",H7="probable_issue",H7="not_issue",H7="indeterminate"))),AND(AND(D7="retain",E7="statistical_results"),NOT(OR(I7="substantive",I7="minor_presentation",I7="indeterminate"))),AND(AND(D7="retain",E7="statistical_results"),J7<>"",NOT(OR(J7="direct",J7="possible",J7="unlikely",J7="unknown"))),AND(AND(D7="retain",OR(E7="report_internal_inconsistency",E7="plan_material")),NOT(OR(K7="substantive_inconsistency",K7="minor_presentation",K7="non_inconsistency",K7="indeterminate"))),AND(AND(D7="retain",E7="protocol_report"),L7<>"",NOT(OR(L7="substantive_difference",L7="minor_presentation",L7="version_timing",L7="non_inconsistency",L7="indeterminate")))),"CHECK FIELDS",IF(AND(F7<>"",NOT(OR(F7="no",F7="primary_done"))),"CHECK COMPLETE",IF(F7="primary_done","PRIMARY READY","PRIMARY DRAFT")))))),"CHECK INPUT / KEY") -> PRIMARY READY | K7: substantive_inconsistency | R7: TEST 2025::jama.2024.27643::C006
A8: 2025::jama.2024.27643::C007 | B8: Serum NfL regimen-only values and contrast differ across displays | C8: jama_berry_2025_oi_240158_1742927563.7361.pdf — Figure 3 and Biomarker Analyses, PDF p. 8; joi240158supp3_prod_1742927563.7911.pdf — eTable 3B, PDF p. 17 | D8: retain | E8: report_internal_inconsistency | F8: primary_done | G8: =IFERROR(IF(LEN(TRIM(CLEAN(SUBSTITUTE(Setup!$B$2,CHAR(160)," "))))=0,"CHECK REVIEWER ID",IF(OR(A8="",(COUNTIF('C_jama.2024.24764'!$A$2:$A$9,A8)+COUNTIF('C_jama.2024.27643'!$A$2:$A$9,A8)+COUNTIF('C_jama.2025.11178'!$A$2:$A$38,A8)+COUNTIF('C_jama.2025.15185'!$A$2:$A$13,A8)+COUNTIF('C_jama.2025.15440'!$A$2:$A$3,A8)+COUNTIF('C_jama.2025.16450'!$A$2:$A$11,A8)+COUNTIF('C_jama.2025.19563'!$A$2:$A$8,A8)+COUNTIF('C_jama.2025.19843'!$A$2:$A$2,A8)+COUNTIF('C_jama.2025.20765'!$A$2:$A$14,A8)+COUNTIF('C_jama.2025.24175'!$A$2:$A$15,A8)+COUNTIF('C_jama.2025.4390'!$A$2:$A$4,A8)+COUNTIF('C_jama.2025.7583'!$A$2:$A$4,A8)+COUNTIF('C_jama.2025.7710'!$A$2:$A$5,A8)+COUNTIF('C_jama.2025.9110'!$A$2:$A$7,A8)+COUNTIF('C_jama.2025.9663'!$A$2:$A$4,A8))<>1,COUNTIFS(Candidates!$G$2:$G$132,A8,Candidates!$K$2:$K$132,"jama.2024.27643")<>1),"CHECK KEY",IF(OR(AND(NOT(AND(D8="retain",E8="statistical_results")),H8<>"",H8<>"not_applicable"),AND(NOT(AND(D8="retain",E8="statistical_results")),I8<>"",I8<>"not_applicable"),AND(NOT(AND(D8="retain",E8="statistical_results")),J8<>"",J8<>"not_applicable"),AND(NOT(AND(D8="retain",OR(E8="report_internal_inconsistency",E8="plan_material"))),K8<>"",K8<>"not_applicable"),AND(NOT(AND(D8="retain",E8="protocol_report")),L8<>"",L8<>"not_applicable")),"CLEAR INACTIVE VALUES",IF(OR(NOT(OR(D8="retain",D8="exclude",D8="discuss")),NOT(OR(E8="statistical_results",E8="report_internal_inconsistency",E8="plan_material",E8="protocol_report")),AND(AND(D8="retain",E8="statistical_results"),NOT(OR(H8="confirmed_issue",H8="probable_issue",H8="not_issue",H8="indeterminate"))),AND(AND(D8="retain",E8="statistical_results"),NOT(OR(I8="substantive",I8="minor_presentation",I8="indeterminate"))),AND(AND(D8="retain",E8="statistical_results"),J8<>"",NOT(OR(J8="direct",J8="possible",J8="unlikely",J8="unknown"))),AND(AND(D8="retain",OR(E8="report_internal_inconsistency",E8="plan_material")),NOT(OR(K8="substantive_inconsistency",K8="minor_presentation",K8="non_inconsistency",K8="indeterminate"))),AND(AND(D8="retain",E8="protocol_report"),L8<>"",NOT(OR(L8="substantive_difference",L8="minor_presentation",L8="version_timing",L8="non_inconsistency",L8="indeterminate")))),"CHECK FIELDS",IF(AND(F8<>"",NOT(OR(F8="no",F8="primary_done"))),"CHECK COMPLETE",IF(F8="primary_done","PRIMARY READY","PRIMARY DRAFT")))))),"CHECK INPUT / KEY") -> PRIMARY READY | K8: substantive_inconsistency | R8: TEST 2025::jama.2024.27643::C007
A9: 2025::jama.2024.27643::C008 | B9: Discussion total of 13 events conflicts with the 14 events displayed in Table 2 | C9: jama_berry_2025_oi_240158_1742927563.7361.pdf — Table 2, PDF p. 7; jama_berry_2025_oi_240158_1742927563.7361.pdf — Discussion, PDF p. 9 | D9: retain | E9: statistical_results | F9: primary_done | G9: =IFERROR(IF(LEN(TRIM(CLEAN(SUBSTITUTE(Setup!$B$2,CHAR(160)," "))))=0,"CHECK REVIEWER ID",IF(OR(A9="",(COUNTIF('C_jama.2024.24764'!$A$2:$A$9,A9)+COUNTIF('C_jama.2024.27643'!$A$2:$A$9,A9)+COUNTIF('C_jama.2025.11178'!$A$2:$A$38,A9)+COUNTIF('C_jama.2025.15185'!$A$2:$A$13,A9)+COUNTIF('C_jama.2025.15440'!$A$2:$A$3,A9)+COUNTIF('C_jama.2025.16450'!$A$2:$A$11,A9)+COUNTIF('C_jama.2025.19563'!$A$2:$A$8,A9)+COUNTIF('C_jama.2025.19843'!$A$2:$A$2,A9)+COUNTIF('C_jama.2025.20765'!$A$2:$A$14,A9)+COUNTIF('C_jama.2025.24175'!$A$2:$A$15,A9)+COUNTIF('C_jama.2025.4390'!$A$2:$A$4,A9)+COUNTIF('C_jama.2025.7583'!$A$2:$A$4,A9)+COUNTIF('C_jama.2025.7710'!$A$2:$A$5,A9)+COUNTIF('C_jama.2025.9110'!$A$2:$A$7,A9)+COUNTIF('C_jama.2025.9663'!$A$2:$A$4,A9))<>1,COUNTIFS(Candidates!$G$2:$G$132,A9,Candidates!$K$2:$K$132,"jama.2024.27643")<>1),"CHECK KEY",IF(OR(AND(NOT(AND(D9="retain",E9="statistical_results")),H9<>"",H9<>"not_applicable"),AND(NOT(AND(D9="retain",E9="statistical_results")),I9<>"",I9<>"not_applicable"),AND(NOT(AND(D9="retain",E9="statistical_results")),J9<>"",J9<>"not_applicable"),AND(NOT(AND(D9="retain",OR(E9="report_internal_inconsistency",E9="plan_material"))),K9<>"",K9<>"not_applicable"),AND(NOT(AND(D9="retain",E9="protocol_report")),L9<>"",L9<>"not_applicable")),"CLEAR INACTIVE VALUES",IF(OR(NOT(OR(D9="retain",D9="exclude",D9="discuss")),NOT(OR(E9="statistical_results",E9="report_internal_inconsistency",E9="plan_material",E9="protocol_report")),AND(AND(D9="retain",E9="statistical_results"),NOT(OR(H9="confirmed_issue",H9="probable_issue",H9="not_issue",H9="indeterminate"))),AND(AND(D9="retain",E9="statistical_results"),NOT(OR(I9="substantive",I9="minor_presentation",I9="indeterminate"))),AND(AND(D9="retain",E9="statistical_results"),J9<>"",NOT(OR(J9="direct",J9="possible",J9="unlikely",J9="unknown"))),AND(AND(D9="retain",OR(E9="report_internal_inconsistency",E9="plan_material")),NOT(OR(K9="substantive_inconsistency",K9="minor_presentation",K9="non_inconsistency",K9="indeterminate"))),AND(AND(D9="retain",E9="protocol_report"),L9<>"",NOT(OR(L9="substantive_difference",L9="minor_presentation",L9="version_timing",L9="non_inconsistency",L9="indeterminate")))),"CHECK FIELDS",IF(AND(F9<>"",NOT(OR(F9="no",F9="primary_done"))),"CHECK COMPLETE",IF(F9="primary_done","PRIMARY READY","PRIMARY DRAFT")))))),"CHECK INPUT / KEY") -> PRIMARY READY | H9: confirmed_issue | I9: substantive | R9: TEST 2025::jama.2024.27643::C008

Sheet C_jama.2025.11178
A1: Candidate key | B1: Candidate title | C1: Source location | D1: Disposition | E1: Review domain (AI suggestion; editable) | F1: Complete | G1: Validation hint | H1: Statistcal_or_numerical issue | I1: Substantiveness | J1: Downstream impact | K1: Report-internal or planning-material inconsistency | L1: Protocol interpretation | R1: Notes (optional)
A2: 2025::jama.2025.11178::C001 | B2: Conditional Figure 1 further-ineligibility component subtotal gap | C2: main article — PDF p. 5, Figure 1, “4481 Ineligible.” | D2: retain | E2: statistical_results | F2: primary_done | G2: =IFERROR(IF(LEN(TRIM(CLEAN(SUBSTITUTE(Setup!$B$2,CHAR(160)," "))))=0,"CHECK REVIEWER ID",IF(OR(A2="",(COUNTIF('C_jama.2024.24764'!$A$2:$A$9,A2)+COUNTIF('C_jama.2024.27643'!$A$2:$A$9,A2)+COUNTIF('C_jama.2025.11178'!$A$2:$A$38,A2)+COUNTIF('C_jama.2025.15185'!$A$2:$A$13,A2)+COUNTIF('C_jama.2025.15440'!$A$2:$A$3,A2)+COUNTIF('C_jama.2025.16450'!$A$2:$A$11,A2)+COUNTIF('C_jama.2025.19563'!$A$2:$A$8,A2)+COUNTIF('C_jama.2025.19843'!$A$2:$A$2,A2)+COUNTIF('C_jama.2025.20765'!$A$2:$A$14,A2)+COUNTIF('C_jama.2025.24175'!$A$2:$A$15,A2)+COUNTIF('C_jama.2025.4390'!$A$2:$A$4,A2)+COUNTIF('C_jama.2025.7583'!$A$2:$A$4,A2)+COUNTIF('C_jama.2025.7710'!$A$2:$A$5,A2)+COUNTIF('C_jama.2025.9110'!$A$2:$A$7,A2)+COUNTIF('C_jama.2025.9663'!$A$2:$A$4,A2))<>1,COUNTIFS(Candidates!$G$2:$G$132,A2,Candidates!$K$2:$K$132,"jama.2025.11178")<>1),"CHECK KEY",IF(OR(AND(NOT(AND(D2="retain",E2="statistical_results")),H2<>"",H2<>"not_applicable"),AND(NOT(AND(D2="retain",E2="statistical_results")),I2<>"",I2<>"not_applicable"),AND(NOT(AND(D2="retain",E2="statistical_results")),J2<>"",J2<>"not_applicable"),AND(NOT(AND(D2="retain",OR(E2="report_internal_inconsistency",E2="plan_material"))),K2<>"",K2<>"not_applicable"),AND(NOT(AND(D2="retain",E2="protocol_report")),L2<>"",L2<>"not_applicable")),"CLEAR INACTIVE VALUES",IF(OR(NOT(OR(D2="retain",D2="exclude",D2="discuss")),NOT(OR(E2="statistical_results",E2="report_internal_inconsistency",E2="plan_material",E2="protocol_report")),AND(AND(D2="retain",E2="statistical_results"),NOT(OR(H2="confirmed_issue",H2="probable_issue",H2="not_issue",H2="indeterminate"))),AND(AND(D2="retain",E2="statistical_results"),NOT(OR(I2="substantive",I2="minor_presentation",I2="indeterminate"))),AND(AND(D2="retain",E2="statistical_results"),J2<>"",NOT(OR(J2="direct",J2="possible",J2="unlikely",J2="unknown"))),AND(AND(D2="retain",OR(E2="report_internal_inconsistency",E2="plan_material")),NOT(OR(K2="substantive_inconsistency",K2="minor_presentation",K2="non_inconsistency",K2="indeterminate"))),AND(AND(D2="retain",E2="protocol_report"),L2<>"",NOT(OR(L2="substantive_difference",L2="minor_presentation",L2="version_timing",L2="non_inconsistency",L2="indeterminate")))),"CHECK FIELDS",IF(AND(F2<>"",NOT(OR(F2="no",F2="primary_done"))),"CHECK COMPLETE",IF(F2="primary_done","PRIMARY READY","PRIMARY DRAFT")))))),"CHECK INPUT / KEY") -> PRIMARY READY | H2: confirmed_issue | I2: substantive | R2: TEST 2025::jama.2025.11178::C001
A3: 2025::jama.2025.11178::C002 | B3: Overall eTable 1 follow-up-pattern partition | C3: results supplement — PDF p. 7, eTable 1, Overall column. | D3: retain | E3: statistical_results | F3: primary_done | G3: =IFERROR(IF(LEN(TRIM(CLEAN(SUBSTITUTE(Setup!$B$2,CHAR(160)," "))))=0,"CHECK REVIEWER ID",IF(OR(A3="",(COUNTIF('C_jama.2024.24764'!$A$2:$A$9,A3)+COUNTIF('C_jama.2024.27643'!$A$2:$A$9,A3)+COUNTIF('C_jama.2025.11178'!$A$2:$A$38,A3)+COUNTIF('C_jama.2025.15185'!$A$2:$A$13,A3)+COUNTIF('C_jama.2025.15440'!$A$2:$A$3,A3)+COUNTIF('C_jama.2025.16450'!$A$2:$A$11,A3)+COUNTIF('C_jama.2025.19563'!$A$2:$A$8,A3)+COUNTIF('C_jama.2025.19843'!$A$2:$A$2,A3)+COUNTIF('C_jama.2025.20765'!$A$2:$A$14,A3)+COUNTIF('C_jama.2025.24175'!$A$2:$A$15,A3)+COUNTIF('C_jama.2025.4390'!$A$2:$A$4,A3)+COUNTIF('C_jama.2025.7583'!$A$2:$A$4,A3)+COUNTIF('C_jama.2025.7710'!$A$2:$A$5,A3)+COUNTIF('C_jama.2025.9110'!$A$2:$A$7,A3)+COUNTIF('C_jama.2025.9663'!$A$2:$A$4,A3))<>1,COUNTIFS(Candidates!$G$2:$G$132,A3,Candidates!$K$2:$K$132,"jama.2025.11178")<>1),"CHECK KEY",IF(OR(AND(NOT(AND(D3="retain",E3="statistical_results")),H3<>"",H3<>"not_applicable"),AND(NOT(AND(D3="retain",E3="statistical_results")),I3<>"",I3<>"not_applicable"),AND(NOT(AND(D3="retain",E3="statistical_results")),J3<>"",J3<>"not_applicable"),AND(NOT(AND(D3="retain",OR(E3="report_internal_inconsistency",E3="plan_material"))),K3<>"",K3<>"not_applicable"),AND(NOT(AND(D3="retain",E3="protocol_report")),L3<>"",L3<>"not_applicable")),"CLEAR INACTIVE VALUES",IF(OR(NOT(OR(D3="retain",D3="exclude",D3="discuss")),NOT(OR(E3="statistical_results",E3="report_internal_inconsistency",E3="plan_material",E3="protocol_report")),AND(AND(D3="retain",E3="statistical_results"),NOT(OR(H3="confirmed_issue",H3="probable_issue",H3="not_issue",H3="indeterminate"))),AND(AND(D3="retain",E3="statistical_results"),NOT(OR(I3="substantive",I3="minor_presentation",I3="indeterminate"))),AND(AND(D3="retain",E3="statistical_results"),J3<>"",NOT(OR(J3="direct",J3="possible",J3="unlikely",J3="unknown"))),AND(AND(D3="retain",OR(E3="report_internal_inconsistency",E3="plan_material")),NOT(OR(K3="substantive_inconsistency",K3="minor_presentation",K3="non_inconsistency",K3="indeterminate"))),AND(AND(D3="retain",E3="protocol_report"),L3<>"",NOT(OR(L3="substantive_difference",L3="minor_presentation",L3="version_timing",L3="non_inconsistency",L3="indeterminate")))),"CHECK FIELDS",IF(AND(F3<>"",NOT(OR(F3="no",F3="primary_done"))),"CHECK COMPLETE",IF(F3="primary_done","PRIMARY READY","PRIMARY DRAFT")))))),"CHECK INPUT / KEY") -> PRIMARY READY | H3: confirmed_issue | I3: substantive | R3: TEST 2025::jama.2025.11178::C002
A4: 2025::jama.2025.11178::C003 | B4: painTRAINER eTable 1 follow-up-pattern partition | C4: results supplement — PDF p. 7, eTable 1, painTRAINER column. | D4: retain | E4: statistical_results | F4: primary_done | G4: =IFERROR(IF(LEN(TRIM(CLEAN(SUBSTITUTE(Setup!$B$2,CHAR(160)," "))))=0,"CHECK REVIEWER ID",IF(OR(A4="",(COUNTIF('C_jama.2024.24764'!$A$2:$A$9,A4)+COUNTIF('C_jama.2024.27643'!$A$2:$A$9,A4)+COUNTIF('C_jama.2025.11178'!$A$2:$A$38,A4)+COUNTIF('C_jama.2025.15185'!$A$2:$A$13,A4)+COUNTIF('C_jama.2025.15440'!$A$2:$A$3,A4)+COUNTIF('C_jama.2025.16450'!$A$2:$A$11,A4)+COUNTIF('C_jama.2025.19563'!$A$2:$A$8,A4)+COUNTIF('C_jama.2025.19843'!$A$2:$A$2,A4)+COUNTIF('C_jama.2025.20765'!$A$2:$A$14,A4)+COUNTIF('C_jama.2025.24175'!$A$2:$A$15,A4)+COUNTIF('C_jama.2025.4390'!$A$2:$A$4,A4)+COUNTIF('C_jama.2025.7583'!$A$2:$A$4,A4)+COUNTIF('C_jama.2025.7710'!$A$2:$A$5,A4)+COUNTIF('C_jama.2025.9110'!$A$2:$A$7,A4)+COUNTIF('C_jama.2025.9663'!$A$2:$A$4,A4))<>1,COUNTIFS(Candidates!$G$2:$G$132,A4,Candidates!$K$2:$K$132,"jama.2025.11178")<>1),"CHECK KEY",IF(OR(AND(NOT(AND(D4="retain",E4="statistical_results")),H4<>"",H4<>"not_applicable"),AND(NOT(AND(D4="retain",E4="statistical_results")),I4<>"",I4<>"not_applicable"),AND(NOT(AND(D4="retain",E4="statistical_results")),J4<>"",J4<>"not_applicable"),AND(NOT(AND(D4="retain",OR(E4="report_internal_inconsistency",E4="plan_material"))),K4<>"",K4<>"not_applicable"),AND(NOT(AND(D4="retain",E4="protocol_report")),L4<>"",L4<>"not_applicable")),"CLEAR INACTIVE VALUES",IF(OR(NOT(OR(D4="retain",D4="exclude",D4="discuss")),NOT(OR(E4="statistical_results",E4="report_internal_inconsistency",E4="plan_material",E4="protocol_report")),AND(AND(D4="retain",E4="statistical_results"),NOT(OR(H4="confirmed_issue",H4="probable_issue",H4="not_issue",H4="indeterminate"))),AND(AND(D4="retain",E4="statistical_results"),NOT(OR(I4="substantive",I4="minor_presentation",I4="indeterminate"))),AND(AND(D4="retain",E4="statistical_results"),J4<>"",NOT(OR(J4="direct",J4="possible",J4="unlikely",J4="unknown"))),AND(AND(D4="retain",OR(E4="report_internal_inconsistency",E4="plan_material")),NOT(OR(K4="substantive_inconsistency",K4="minor_presentation",K4="non_inconsistency",K4="indeterminate"))),AND(AND(D4="retain",E4="protocol_report"),L4<>"",NOT(OR(L4="substantive_difference",L4="minor_presentation",L4="version_timing",L4="non_inconsistency",L4="indeterminate")))),"CHECK FIELDS",IF(AND(F4<>"",NOT(OR(F4="no",F4="primary_done"))),"CHECK COMPLETE",IF(F4="primary_done","PRIMARY READY","PRIMARY DRAFT")))))),"CHECK INPUT / KEY") -> PRIMARY READY | H4: confirmed_issue | I4: substantive | R4: TEST 2025::jama.2025.11178::C003
