Workbook

Sheet Setup
A1: Field | B1: Value
A2: reviewerId | B2: R_Bulun
A3: reviewerName (optional)
A4: reviewerRole | B4: R_Bulun
A5: year | B5: 2019

Sheet Checks
A1: Check | B1: Result
A2: Reviewer role | B2: =Setup!B4
A3: Candidates | B3: 87
A4: Primary ready rows | B4: =COUNTIF('C_jama.2019.0556'!$G$2:$G$12,"PRIMARY READY")+COUNTIF('C_jama.2019.10517'!$G$2:$G$6,"PRIMARY READY")+COUNTIF('C_jama.2019.12618'!$G$2:$G$11,"PRIMARY READY")+COUNTIF('C_jama.2019.14231'!$G$2:$G$9,"PRIMARY READY")+COUNTIF('C_jama.2019.14630'!$G$2:$G$10,"PRIMARY READY")+COUNTIF('C_jama.2019.14901'!$G$2:$G$6,"PRIMARY READY")+COUNTIF('C_jama.2019.17380'!$G$2:$G$19,"PRIMARY READY")+COUNTIF('C_jama.2019.2210'!$G$2:$G$8,"PRIMARY READY")+COUNTIF('C_jama.2019.4755'!$G$2:$G$2,"PRIMARY READY")+COUNTIF('C_jama.2019.7505'!$G$2:$G$14,"PRIMARY READY")
A5: Discuss / unresolved rows | B5: =COUNTIF('C_jama.2019.0556'!$D$2:$D$12,"discuss")+COUNTIF('C_jama.2019.10517'!$D$2:$D$6,"discuss")+COUNTIF('C_jama.2019.12618'!$D$2:$D$11,"discuss")+COUNTIF('C_jama.2019.14231'!$D$2:$D$9,"discuss")+COUNTIF('C_jama.2019.14630'!$D$2:$D$10,"discuss")+COUNTIF('C_jama.2019.14901'!$D$2:$D$6,"discuss")+COUNTIF('C_jama.2019.17380'!$D$2:$D$19,"discuss")+COUNTIF('C_jama.2019.2210'!$D$2:$D$8,"discuss")+COUNTIF('C_jama.2019.4755'!$D$2:$D$2,"discuss")+COUNTIF('C_jama.2019.7505'!$D$2:$D$14,"discuss")
A6: Unfinished rows | B6: =B3-B4
A7: Workflow status | B7: =IF(B4=B3,"PRIMARY READY","ACTION NEEDED")
A8: Meaning | B8: PRIMARY READY means independent entry is complete. Discuss remains unresolved and is not counted as absence of error.
A9: Next action | B9: Inspect G on the C_ sheets. Save and deliver this file after review.

Sheet Papers
A1: Paper | B1: Review worksheet | C1: Candidates
A2: jama.2019.0556 | B2: C_jama.2019.0556 | C2: 11
A3: jama.2019.10517 | B3: C_jama.2019.10517 | C3: 5
A4: jama.2019.12618 | B4: C_jama.2019.12618 | C4: 10
A5: jama.2019.14231 | B5: C_jama.2019.14231 | C5: 8
A6: jama.2019.14630 | B6: C_jama.2019.14630 | C6: 9
A7: jama.2019.14901 | B7: C_jama.2019.14901 | C7: 5
A8: jama.2019.17380 | B8: C_jama.2019.17380 | C8: 18
A9: jama.2019.2210 | B9: C_jama.2019.2210 | C9: 7
A10: jama.2019.4755 | B10: C_jama.2019.4755 | C10: 1
A11: jama.2019.7505 | B11: C_jama.2019.7505 | C11: 13

Sheet C_jama.2019.0556
A1: Candidate key | B1: Candidate title | C1: Source location | D1: Disposition | E1: Review domain (AI suggestion; editable) | F1: Complete | G1: Validation hint | H1: Statistical_or_numerical issue | I1: Substantiveness | J1: Downstream impact | K1: Report-internal or planning-material inconsistency | L1: Protocol interpretation | R1: Notes (optional)
A2: 2019::jama.2019.0556::C001 | B2: Planned and reported daily EPA+DHA dose does not reconcile | C2: jama_bot_2019_oi_190007.pdf — Main p. 1, abstract Interventions; jama_bot_2019_oi_190007.pdf — Main p. 2, Multinutrient Supplements; joi190007supp3_prod.pdf — Results supplement p. 4, eAppendix 2; joi190007supp1_prod.pdf — Protocol p. 8, Summary intervention; joi190007supp1_prod.pdf — Protocol p. 18, intervention box; joi190007supp1_prod.pdf — Protocol p. 20, composition box; joi190007supp1_prod.pdf — Protocol p. 23, Omega-3 PUFA fish oils. | D2: retain | E2: protocol_report | F2: primary_done | G2: =IFERROR(IF(LEN(TRIM(CLEAN(SUBSTITUTE(Setup!$B$2,CHAR(160)," "))))=0,"CHECK REVIEWER ID",IF(OR(A2="",COUNTIF($A$2:$A$12,A2)<>1,LEFT(A2,LEN("2019::jama.2019.0556::"))<>"2019::jama.2019.0556::"),"CHECK KEY",IF(OR(AND(NOT(AND(D2="retain",E2="statistical_results")),H2<>"",NOT(EXACT(H2,"not_applicable"))),AND(NOT(AND(D2="retain",E2="statistical_results")),I2<>"",NOT(EXACT(I2,"not_applicable"))),AND(NOT(AND(D2="retain",E2="statistical_results")),J2<>"",NOT(EXACT(J2,"not_applicable"))),AND(NOT(AND(D2="retain",OR(E2="report_internal_inconsistency",E2="plan_material"))),K2<>"",NOT(EXACT(K2,"not_applicable"))),AND(NOT(AND(D2="retain",E2="protocol_report")),L2<>"",NOT(EXACT(L2,"not_applicable")))),"CLEAR INACTIVE VALUES",IF(OR(NOT(OR(EXACT(D2,"retain"),EXACT(D2,"exclude"),EXACT(D2,"discuss"))),NOT(OR(EXACT(E2,"statistical_results"),EXACT(E2,"report_internal_inconsistency"),EXACT(E2,"plan_material"),EXACT(E2,"protocol_report"))),AND(AND(D2="retain",E2="statistical_results"),NOT(OR(EXACT(H2,"confirmed_issue"),EXACT(H2,"probable_issue"),EXACT(H2,"not_issue"),EXACT(H2,"indeterminate")))),AND(AND(D2="retain",E2="statistical_results"),NOT(OR(EXACT(I2,"substantive"),EXACT(I2,"minor_presentation"),EXACT(I2,"indeterminate")))),AND(AND(D2="retain",E2="statistical_results"),J2<>"",NOT(OR(EXACT(J2,"direct"),EXACT(J2,"possible"),EXACT(J2,"unlikely"),EXACT(J2,"unknown")))),AND(AND(D2="retain",OR(E2="report_internal_inconsistency",E2="plan_material")),NOT(OR(EXACT(K2,"substantive_inconsistency"),EXACT(K2,"minor_presentation"),EXACT(K2,"non_inconsistency"),EXACT(K2,"indeterminate")))),AND(AND(D2="retain",E2="protocol_report"),L2<>"",NOT(OR(EXACT(L2,"substantive_difference"),EXACT(L2,"minor_presentation"),EXACT(L2,"version_timing"),EXACT(L2,"non_inconsistency"),EXACT(L2,"indeterminate"))))),"CHECK FIELDS",IF(AND(F2<>"",NOT(OR(EXACT(F2,"no"),EXACT(F2,"primary_done")))),"CHECK COMPLETE",IF(EXACT(F2,"primary_done"),"PRIMARY READY","PRIMARY DRAFT")))))),"CHECK INPUT / KEY") | H2: =IF(AND(OR(D2="retain",D2=""),E2="statistical_results"),"","not_applicable") | I2: =IF(AND(OR(D2="retain",D2=""),E2="statistical_results"),"","not_applicable") | J2: =IF(AND(OR(D2="retain",D2=""),E2="statistical_results"),"","not_applicable") | K2: =IF(AND(OR(D2="retain",D2=""),OR(E2="report_internal_inconsistency",E2="plan_material")),"","not_applicable") | L2: substantive_difference | R2: Protocol pp. 8, 18 specify 1000 mg omega-3 per capsule and p. 23 an intended EPA+DHA dose of 1.0 g/day; article pp. 1-2 and eAppendix 2 (supp3 p. 4) report 1412 mg EPA+DHA/day. 1412/1000 = 141%, outside the protocol's 90%-125% manufacturing allowance (p. 20). Not explained in the supplied documents.
A3: 2019::jama.2019.0556::C002 | B3: Planned primary analysis suite is replaced or not reported as specified | C3: joi190007supp1_prod.pdf — Protocol p. 43, §§10.1–10.2; joi190007supp2_prod.pdf — SAP p. 2, Outcomes; joi190007supp2_prod.pdf — SAP p. 3, Fourth analysis; joi190007supp2_prod.pdf — SAP p. 4, Secondary analysis; jama_bot_2019_oi_190007.pdf — Main p. 1, abstract main measures; jama_bot_2019_oi_190007.pdf — Main p. 4, Statistical Methods; jama_bot_2019_oi_190007.pdf — Main p. 6, Table 2 and continuation; jama_bot_2019_oi_190007.pdf — Main p. 8, Table 3 and footnotes. | D3: retain | E3: protocol_report | F3: primary_done | G3: =IFERROR(IF(LEN(TRIM(CLEAN(SUBSTITUTE(Setup!$B$2,CHAR(160)," "))))=0,"CHECK REVIEWER ID",IF(OR(A3="",COUNTIF($A$2:$A$12,A3)<>1,LEFT(A3,LEN("2019::jama.2019.0556::"))<>"2019::jama.2019.0556::"),"CHECK KEY",IF(OR(AND(NOT(AND(D3="retain",E3="statistical_results")),H3<>"",NOT(EXACT(H3,"not_applicable"))),AND(NOT(AND(D3="retain",E3="statistical_results")),I3<>"",NOT(EXACT(I3,"not_applicable"))),AND(NOT(AND(D3="retain",E3="statistical_results")),J3<>"",NOT(EXACT(J3,"not_applicable"))),AND(NOT(AND(D3="retain",OR(E3="report_internal_inconsistency",E3="plan_material"))),K3<>"",NOT(EXACT(K3,"not_applicable"))),AND(NOT(AND(D3="retain",E3="protocol_report")),L3<>"",NOT(EXACT(L3,"not_applicable")))),"CLEAR INACTIVE VALUES",IF(OR(NOT(OR(EXACT(D3,"retain"),EXACT(D3,"exclude"),EXACT(D3,"discuss"))),NOT(OR(EXACT(E3,"statistical_results"),EXACT(E3,"report_internal_inconsistency"),EXACT(E3,"plan_material"),EXACT(E3,"protocol_report"))),AND(AND(D3="retain",E3="statistical_results"),NOT(OR(EXACT(H3,"confirmed_issue"),EXACT(H3,"probable_issue"),EXACT(H3,"not_issue"),EXACT(H3,"indeterminate")))),AND(AND(D3="retain",E3="statistical_results"),NOT(OR(EXACT(I3,"substantive"),EXACT(I3,"minor_presentation"),EXACT(I3,"indeterminate")))),AND(AND(D3="retain",E3="statistical_results"),J3<>"",NOT(OR(EXACT(J3,"direct"),EXACT(J3,"possible"),EXACT(J3,"unlikely"),EXACT(J3,"unknown")))),AND(AND(D3="retain",OR(E3="report_internal_inconsistency",E3="plan_material")),NOT(OR(EXACT(K3,"substantive_inconsistency"),EXACT(K3,"minor_presentation"),EXACT(K3,"non_inconsistency"),EXACT(K3,"indeterminate")))),AND(AND(D3="retain",E3="protocol_report"),L3<>"",NOT(OR(EXACT(L3,"substantive_difference"),EXACT(L3,"minor_presentation"),EXACT(L3,"version_timing"),EXACT(L3,"non_inconsistency"),EXACT(L3,"indeterminate"))))),"CHECK FIELDS",IF(AND(F3<>"",NOT(OR(EXACT(F3,"no"),EXACT(F3,"primary_done")))),"CHECK COMPLETE",IF(EXACT(F3,"primary_done"),"PRIMARY READY","PRIMARY DRAFT")))))),"CHECK INPUT / KEY") | H3: =IF(AND(OR(D3="retain",D3=""),E3="statistical_results"),"","not_applicable") | I3: =IF(AND(OR(D3="retain",D3=""),E3="statistical_results"),"","not_applicable") | J3: =IF(AND(OR(D3="retain",D3=""),E3="statistical_results"),"","not_applicable") | K3: =IF(AND(OR(D3="retain",D3=""),OR(E3="report_internal_inconsistency",E3="plan_material")),"","not_applicable") | L3: version_timing | R3: Protocol v7 §10.1 (p. 43) plans Kaplan-Meier/log-rank and Cox PH as the primary time-to-event analysis plus mixed models for MDD onset and IDS; the SAP (pp. 3-4) and the article (pp. 4, 6) use logistic regression for cumulative MDD with Cox only secondary/post hoc. KM/log-rank and mixed-model MDD results are not reported. Report matches the undated SAP, so plan sequence is unclear.
A4: 2019::jama.2019.0556::C003 | B4: Online-screening BMI cutoff differs between report locations | C4: jama_bot_2019_oi_190007.pdf — Main p. 3, Figure 1 online exclusions; joi190007supp3_prod.pdf — Results supplement p. 3, inclusion criteria assessed with the online screening tool; jama_bot_2019_oi_190007.pdf — Main p. 2, eligibility; jama_bot_2019_oi_190007.pdf — main p. 1, abstract population; joi190007supp1_prod.pdf — Protocol p. 16, inclusion criteria. | D4: retain | E4: statistical_results | F4: primary_done | G4: =IFERROR(IF(LEN(TRIM(CLEAN(SUBSTITUTE(Setup!$B$2,CHAR(160)," "))))=0,"CHECK REVIEWER ID",IF(OR(A4="",COUNTIF($A$2:$A$12,A4)<>1,LEFT(A4,LEN("2019::jama.2019.0556::"))<>"2019::jama.2019.0556::"),"CHECK KEY",IF(OR(AND(NOT(AND(D4="retain",E4="statistical_results")),H4<>"",NOT(EXACT(H4,"not_applicable"))),AND(NOT(AND(D4="retain",E4="statistical_results")),I4<>"",NOT(EXACT(I4,"not_applicable"))),AND(NOT(AND(D4="retain",E4="statistical_results")),J4<>"",NOT(EXACT(J4,"not_applicable"))),AND(NOT(AND(D4="retain",OR(E4="report_internal_inconsistency",E4="plan_material"))),K4<>"",NOT(EXACT(K4,"not_applicable"))),AND(NOT(AND(D4="retain",E4="protocol_report")),L4<>"",NOT(EXACT(L4,"not_applicable")))),"CLEAR INACTIVE VALUES",IF(OR(NOT(OR(EXACT(D4,"retain"),EXACT(D4,"exclude"),EXACT(D4,"discuss"))),NOT(OR(EXACT(E4,"statistical_results"),EXACT(E4,"report_internal_inconsistency"),EXACT(E4,"plan_material"),EXACT(E4,"protocol_report"))),AND(AND(D4="retain",E4="statistical_results"),NOT(OR(EXACT(H4,"confirmed_issue"),EXACT(H4,"probable_issue"),EXACT(H4,"not_issue"),EXACT(H4,"indeterminate")))),AND(AND(D4="retain",E4="statistical_results"),NOT(OR(EXACT(I4,"substantive"),EXACT(I4,"minor_presentation"),EXACT(I4,"indeterminate")))),AND(AND(D4="retain",E4="statistical_results"),J4<>"",NOT(OR(EXACT(J4,"direct"),EXACT(J4,"possible"),EXACT(J4,"unlikely"),EXACT(J4,"unknown")))),AND(AND(D4="retain",OR(E4="report_internal_inconsistency",E4="plan_material")),NOT(OR(EXACT(K4,"substantive_inconsistency"),EXACT(K4,"minor_presentation"),EXACT(K4,"non_inconsistency"),EXACT(K4,"indeterminate")))),AND(AND(D4="retain",E4="protocol_report"),L4<>"",NOT(OR(EXACT(L4,"substantive_difference"),EXACT(L4,"minor_presentation"),EXACT(L4,"version_timing"),EXACT(L4,"non_inconsistency"),EXACT(L4,"indeterminate"))))),"CHECK FIELDS",IF(AND(F4<>"",NOT(OR(EXACT(F4,"no"),EXACT(F4,"primary_done")))),"CHECK COMPLETE",IF(EXACT(F4,"primary_done"),"PRIMARY READY","PRIMARY DRAFT")))))),"CHECK INPUT / KEY") | H4: confirmed_issue | I4: minor_presentation | J4: unlikely | K4: =IF(AND(OR(D4="retain",D4=""),OR(E4="report_internal_inconsistency",E4="plan_material")),"","not_applicable") | L4: =IF(AND(OR(D4="retain",D4=""),E4="protocol_report"),"","not_applicable") | R4: Figure 1 (main p. 3, rendered) labels 1451 online exclusions 'BMI <15 or >40', while eAppendix 1 (supp3 p. 3) states the online tool used BMI 25-40, as do the abstract and Methods. The lower cutoff of 15 contradicts 25; the later 18 telephone exclusions for BMI <25 leave open which cutoff was applied online.
A5: 2019::jama.2019.0556::C004 | B5: Sample-size total does not reconcile with four stated cell sizes | C5: jama_bot_2019_oi_190007.pdf — Main p. 4, Sample Size upper right column. | D5: retain | E5: statistical_results | F5: primary_done | G5: =IFERROR(IF(LEN(TRIM(CLEAN(SUBSTITUTE(Setup!$B$2,CHAR(160)," "))))=0,"CHECK REVIEWER ID",IF(OR(A5="",COUNTIF($A$2:$A$12,A5)<>1,LEFT(A5,LEN("2019::jama.2019.0556::"))<>"2019::jama.2019.0556::"),"CHECK KEY",IF(OR(AND(NOT(AND(D5="retain",E5="statistical_results")),H5<>"",NOT(EXACT(H5,"not_applicable"))),AND(NOT(AND(D5="retain",E5="statistical_results")),I5<>"",NOT(EXACT(I5,"not_applicable"))),AND(NOT(AND(D5="retain",E5="statistical_results")),J5<>"",NOT(EXACT(J5,"not_applicable"))),AND(NOT(AND(D5="retain",OR(E5="report_internal_inconsistency",E5="plan_material"))),K5<>"",NOT(EXACT(K5,"not_applicable"))),AND(NOT(AND(D5="retain",E5="protocol_report")),L5<>"",NOT(EXACT(L5,"not_applicable")))),"CLEAR INACTIVE VALUES",IF(OR(NOT(OR(EXACT(D5,"retain"),EXACT(D5,"exclude"),EXACT(D5,"discuss"))),NOT(OR(EXACT(E5,"statistical_results"),EXACT(E5,"report_internal_inconsistency"),EXACT(E5,"plan_material"),EXACT(E5,"protocol_report"))),AND(AND(D5="retain",E5="statistical_results"),NOT(OR(EXACT(H5,"confirmed_issue"),EXACT(H5,"probable_issue"),EXACT(H5,"not_issue"),EXACT(H5,"indeterminate")))),AND(AND(D5="retain",E5="statistical_results"),NOT(OR(EXACT(I5,"substantive"),EXACT(I5,"minor_presentation"),EXACT(I5,"indeterminate")))),AND(AND(D5="retain",E5="statistical_results"),J5<>"",NOT(OR(EXACT(J5,"direct"),EXACT(J5,"possible"),EXACT(J5,"unlikely"),EXACT(J5,"unknown")))),AND(AND(D5="retain",OR(E5="report_internal_inconsistency",E5="plan_material")),NOT(OR(EXACT(K5,"substantive_inconsistency"),EXACT(K5,"minor_presentation"),EXACT(K5,"non_inconsistency"),EXACT(K5,"indeterminate")))),AND(AND(D5="retain",E5="protocol_report"),L5<>"",NOT(OR(EXACT(L5,"substantive_difference"),EXACT(L5,"minor_presentation"),EXACT(L5,"version_timing"),EXACT(L5,"non_inconsistency"),EXACT(L5,"indeterminate"))))),"CHECK FIELDS",IF(AND(F5<>"",NOT(OR(EXACT(F5,"no"),EXACT(F5,"primary_done")))),"CHECK COMPLETE",IF(EXACT(F5,"primary_done"),"PRIMARY READY","PRIMARY DRAFT")))))),"CHECK INPUT / KEY") | H5: confirmed_issue | I5: minor_presentation | J5: unlikely | K5: =IF(AND(OR(D5="retain",D5=""),OR(E5="report_internal_inconsistency",E5="plan_material")),"","not_applicable") | L5: =IF(AND(OR(D5="retain",D5=""),E5="protocol_report"),"","not_applicable") | R5: Main p. 4: '392 participants (196 in each of the 4 possible intervention combinations)'; 4 x 196 = 784, not 392. power.prop.test(p1=.20, p2=.30, power=.90) gives n = 391.9 per group, so 392 is the size of each main-effect arm (2 cells x 196), not the total. 196/0.78 = 251.3, consistent with 250 per cell.
A6: 2019::jama.2019.0556::C005 | B6: Primary power assumptions differ between the protocol and report | C6: joi190007supp1_prod.pdf — Protocol p. 16, §4.4; joi190007supp1_prod.pdf — Protocol p. 17, calculation continuation; jama_bot_2019_oi_190007.pdf — Main p. 4, Sample Size. | D6: retain | E6: protocol_report | F6: primary_done | G6: =IFERROR(IF(LEN(TRIM(CLEAN(SUBSTITUTE(Setup!$B$2,CHAR(160)," "))))=0,"CHECK REVIEWER ID",IF(OR(A6="",COUNTIF($A$2:$A$12,A6)<>1,LEFT(A6,LEN("2019::jama.2019.0556::"))<>"2019::jama.2019.0556::"),"CHECK KEY",IF(OR(AND(NOT(AND(D6="retain",E6="statistical_results")),H6<>"",NOT(EXACT(H6,"not_applicable"))),AND(NOT(AND(D6="retain",E6="statistical_results")),I6<>"",NOT(EXACT(I6,"not_applicable"))),AND(NOT(AND(D6="retain",E6="statistical_results")),J6<>"",NOT(EXACT(J6,"not_applicable"))),AND(NOT(AND(D6="retain",OR(E6="report_internal_inconsistency",E6="plan_material"))),K6<>"",NOT(EXACT(K6,"not_applicable"))),AND(NOT(AND(D6="retain",E6="protocol_report")),L6<>"",NOT(EXACT(L6,"not_applicable")))),"CLEAR INACTIVE VALUES",IF(OR(NOT(OR(EXACT(D6,"retain"),EXACT(D6,"exclude"),EXACT(D6,"discuss"))),NOT(OR(EXACT(E6,"statistical_results"),EXACT(E6,"report_internal_inconsistency"),EXACT(E6,"plan_material"),EXACT(E6,"protocol_report"))),AND(AND(D6="retain",E6="statistical_results"),NOT(OR(EXACT(H6,"confirmed_issue"),EXACT(H6,"probable_issue"),EXACT(H6,"not_issue"),EXACT(H6,"indeterminate")))),AND(AND(D6="retain",E6="statistical_results"),NOT(OR(EXACT(I6,"substantive"),EXACT(I6,"minor_presentation"),EXACT(I6,"indeterminate")))),AND(AND(D6="retain",E6="statistical_results"),J6<>"",NOT(OR(EXACT(J6,"direct"),EXACT(J6,"possible"),EXACT(J6,"unlikely"),EXACT(J6,"unknown")))),AND(AND(D6="retain",OR(E6="report_internal_inconsistency",E6="plan_material")),NOT(OR(EXACT(K6,"substantive_inconsistency"),EXACT(K6,"minor_presentation"),EXACT(K6,"non_inconsistency"),EXACT(K6,"indeterminate")))),AND(AND(D6="retain",E6="protocol_report"),L6<>"",NOT(OR(EXACT(L6,"substantive_difference"),EXACT(L6,"minor_presentation"),EXACT(L6,"version_timing"),EXACT(L6,"non_inconsistency"),EXACT(L6,"indeterminate"))))),"CHECK FIELDS",IF(AND(F6<>"",NOT(OR(EXACT(F6,"no"),EXACT(F6,"primary_done")))),"CHECK COMPLETE",IF(EXACT(F6,"primary_done"),"PRIMARY READY","PRIMARY DRAFT")))))),"CHECK INPUT / KEY") | H6: =IF(AND(OR(D6="retain",D6=""),E6="statistical_results"),"","not_applicable") | I6: =IF(AND(OR(D6="retain",D6=""),E6="statistical_results"),"","not_applicable") | J6: =IF(AND(OR(D6="retain",D6=""),E6="statistical_results"),"","not_applicable") | K6: =IF(AND(OR(D6="retain",D6=""),OR(E6="report_internal_inconsistency",E6="plan_material")),"","not_applicable") | L6: substantive_difference | R6: Protocol §4.4 (pp. 16-17): control 30% vs intervention 15%, additive interaction, 180 per group, 20% dropout, 250 per arm. Article p. 4: 30% vs 20% (33% reduction), main effects, 196 per cell, 22% attrition, 250 per cell. Event-rate assumption and target contrast differ; final 250 per arm agrees.
A7: 2019::jama.2019.0556::C006 | B7: Prespecified outcome hierarchy differs across plan and report materials | C7: joi190007supp1_prod.pdf — Protocol p. 8, main study parameters; joi190007supp1_prod.pdf — p. 9, continuation; joi190007supp1_prod.pdf — Protocol p. 28, §§8.1.1–8.1.2; joi190007supp1_prod.pdf — Protocol p. 43, §10.1; joi190007supp2_prod.pdf — SAP p. 2, Outcomes; jama_bot_2019_oi_190007.pdf — Main p. 4, Outcomes; jama_bot_2019_oi_190007.pdf — Main p. 8, Table 3 heading. | D7: retain | E7: protocol_report | F7: primary_done | G7: =IFERROR(IF(LEN(TRIM(CLEAN(SUBSTITUTE(Setup!$B$2,CHAR(160)," "))))=0,"CHECK REVIEWER ID",IF(OR(A7="",COUNTIF($A$2:$A$12,A7)<>1,LEFT(A7,LEN("2019::jama.2019.0556::"))<>"2019::jama.2019.0556::"),"CHECK KEY",IF(OR(AND(NOT(AND(D7="retain",E7="statistical_results")),H7<>"",NOT(EXACT(H7,"not_applicable"))),AND(NOT(AND(D7="retain",E7="statistical_results")),I7<>"",NOT(EXACT(I7,"not_applicable"))),AND(NOT(AND(D7="retain",E7="statistical_results")),J7<>"",NOT(EXACT(J7,"not_applicable"))),AND(NOT(AND(D7="retain",OR(E7="report_internal_inconsistency",E7="plan_material"))),K7<>"",NOT(EXACT(K7,"not_applicable"))),AND(NOT(AND(D7="retain",E7="protocol_report")),L7<>"",NOT(EXACT(L7,"not_applicable")))),"CLEAR INACTIVE VALUES",IF(OR(NOT(OR(EXACT(D7,"retain"),EXACT(D7,"exclude"),EXACT(D7,"discuss"))),NOT(OR(EXACT(E7,"statistical_results"),EXACT(E7,"report_internal_inconsistency"),EXACT(E7,"plan_material"),EXACT(E7,"protocol_report"))),AND(AND(D7="retain",E7="statistical_results"),NOT(OR(EXACT(H7,"confirmed_issue"),EXACT(H7,"probable_issue"),EXACT(H7,"not_issue"),EXACT(H7,"indeterminate")))),AND(AND(D7="retain",E7="statistical_results"),NOT(OR(EXACT(I7,"substantive"),EXACT(I7,"minor_presentation"),EXACT(I7,"indeterminate")))),AND(AND(D7="retain",E7="statistical_results"),J7<>"",NOT(OR(EXACT(J7,"direct"),EXACT(J7,"possible"),EXACT(J7,"unlikely"),EXACT(J7,"unknown")))),AND(AND(D7="retain",OR(E7="report_internal_inconsistency",E7="plan_material")),NOT(OR(EXACT(K7,"substantive_inconsistency"),EXACT(K7,"minor_presentation"),EXACT(K7,"non_inconsistency"),EXACT(K7,"indeterminate")))),AND(AND(D7="retain",E7="protocol_report"),L7<>"",NOT(OR(EXACT(L7,"substantive_difference"),EXACT(L7,"minor_presentation"),EXACT(L7,"version_timing"),EXACT(L7,"non_inconsistency"),EXACT(L7,"indeterminate"))))),"CHECK FIELDS",IF(AND(F7<>"",NOT(OR(EXACT(F7,"no"),EXACT(F7,"primary_done")))),"CHECK COMPLETE",IF(EXACT(F7,"primary_done"),"PRIMARY READY","PRIMARY DRAFT")))))),"CHECK INPUT / KEY") | H7: =IF(AND(OR(D7="retain",D7=""),E7="statistical_results"),"","not_applicable") | I7: =IF(AND(OR(D7="retain",D7=""),E7="statistical_results"),"","not_applicable") | J7: =IF(AND(OR(D7="retain",D7=""),E7="statistical_results"),"","not_applicable") | K7: =IF(AND(OR(D7="retain",D7=""),OR(E7="report_internal_inconsistency",E7="plan_material")),"","not_applicable") | L7: version_timing | R7: Protocol v7 lists IDS with MDD incidence under main study parameters/endpoints (pp. 8-9, 28 §8.1.1; p. 43 §10.1); SAP p. 2 and article p. 4 make IDS secondary. GAD-7 and EQ-5D are protocol secondary, SAP 'Other', article secondary. Report follows the SAP for IDS; SAP is undated.
A8: 2019::jama.2019.0556::C007 | B8: Planned Cox and site/history analyses receive post hoc report designations | C8: joi190007supp1_prod.pdf — Protocol p. 43, §10.1; joi190007supp1_prod.pdf — Protocol p. 44, interaction paragraph; joi190007supp2_prod.pdf — SAP p. 4, Secondary analysis and Effect modification; joi190007supp2_prod.pdf — SAP p. 5, Effect modification continuation; jama_bot_2019_oi_190007.pdf — Main p. 4, Outcomes/Statistical Methods; jama_bot_2019_oi_190007.pdf — Main p. 6, Table 2; jama_bot_2019_oi_190007.pdf — Main p. 7, MDD results continuation; jama_bot_2019_oi_190007.pdf — Main p. 8, Effect Modification and Sensitivity Analyses; joi190007supp3_prod.pdf — Results supplement p. 18, eAppendix 10; joi190007supp3_prod.pdf — Results supplement p. 19, GAD Table B; joi190007supp3_prod.pdf — Results supplement p. 20, utility Tables C1/C2. | D8: retain | E8: protocol_report | F8: primary_done | G8: =IFERROR(IF(LEN(TRIM(CLEAN(SUBSTITUTE(Setup!$B$2,CHAR(160)," "))))=0,"CHECK REVIEWER ID",IF(OR(A8="",COUNTIF($A$2:$A$12,A8)<>1,LEFT(A8,LEN("2019::jama.2019.0556::"))<>"2019::jama.2019.0556::"),"CHECK KEY",IF(OR(AND(NOT(AND(D8="retain",E8="statistical_results")),H8<>"",NOT(EXACT(H8,"not_applicable"))),AND(NOT(AND(D8="retain",E8="statistical_results")),I8<>"",NOT(EXACT(I8,"not_applicable"))),AND(NOT(AND(D8="retain",E8="statistical_results")),J8<>"",NOT(EXACT(J8,"not_applicable"))),AND(NOT(AND(D8="retain",OR(E8="report_internal_inconsistency",E8="plan_material"))),K8<>"",NOT(EXACT(K8,"not_applicable"))),AND(NOT(AND(D8="retain",E8="protocol_report")),L8<>"",NOT(EXACT(L8,"not_applicable")))),"CLEAR INACTIVE VALUES",IF(OR(NOT(OR(EXACT(D8,"retain"),EXACT(D8,"exclude"),EXACT(D8,"discuss"))),NOT(OR(EXACT(E8,"statistical_results"),EXACT(E8,"report_internal_inconsistency"),EXACT(E8,"plan_material"),EXACT(E8,"protocol_report"))),AND(AND(D8="retain",E8="statistical_results"),NOT(OR(EXACT(H8,"confirmed_issue"),EXACT(H8,"probable_issue"),EXACT(H8,"not_issue"),EXACT(H8,"indeterminate")))),AND(AND(D8="retain",E8="statistical_results"),NOT(OR(EXACT(I8,"substantive"),EXACT(I8,"minor_presentation"),EXACT(I8,"indeterminate")))),AND(AND(D8="retain",E8="statistical_results"),J8<>"",NOT(OR(EXACT(J8,"direct"),EXACT(J8,"possible"),EXACT(J8,"unlikely"),EXACT(J8,"unknown")))),AND(AND(D8="retain",OR(E8="report_internal_inconsistency",E8="plan_material")),NOT(OR(EXACT(K8,"substantive_inconsistency"),EXACT(K8,"minor_presentation"),EXACT(K8,"non_inconsistency"),EXACT(K8,"indeterminate")))),AND(AND(D8="retain",E8="protocol_report"),L8<>"",NOT(OR(EXACT(L8,"substantive_difference"),EXACT(L8,"minor_presentation"),EXACT(L8,"version_timing"),EXACT(L8,"non_inconsistency"),EXACT(L8,"indeterminate"))))),"CHECK FIELDS",IF(AND(F8<>"",NOT(OR(EXACT(F8,"no"),EXACT(F8,"primary_done")))),"CHECK COMPLETE",IF(EXACT(F8,"primary_done"),"PRIMARY READY","PRIMARY DRAFT")))))),"CHECK INPUT / KEY") | H8: =IF(AND(OR(D8="retain",D8=""),E8="statistical_results"),"","not_applicable") | I8: =IF(AND(OR(D8="retain",D8=""),E8="statistical_results"),"","not_applicable") | J8: =IF(AND(OR(D8="retain",D8=""),E8="statistical_results"),"","not_applicable") | K8: =IF(AND(OR(D8="retain",D8=""),OR(E8="report_internal_inconsistency",E8="plan_material")),"","not_applicable") | L8: minor_presentation | R8: Cox time-to-MDD is planned in protocol §10.1 (as primary) and SAP p. 4 (secondary), and effect modification by site and MDD history in SAP pp. 4-5, yet article p. 4 and Table 2 call Cox 'post hoc' and p. 8 calls the site/history/baseline moderation analyses 'post hoc'. Analyses were done; only their prespecification status is mislabeled.
A9: 2019::jama.2019.0556::C008 | B9: Planned additive primary-outcome interaction result is not reported | C9: joi190007supp2_prod.pdf — SAP p. 4, Interaction of intervention strategies for our primary outcome; jama_bot_2019_oi_190007.pdf — Main p. 4, Statistical Methods; jama_bot_2019_oi_190007.pdf — Main p. 6, Table 2; jama_bot_2019_oi_190007.pdf — Main p. 7, narrative; joi190007supp3_prod.pdf — p. 18 moderation; joi190007supp3_prod.pdf — p. 19 GAD moderation; joi190007supp3_prod.pdf — p. 20 utility moderation; joi190007supp3_prod.pdf — p. 21 no-MI sensitivity; joi190007supp3_prod.pdf — p. 22 CACE. | D9: retain | E9: protocol_report | F9: primary_done | G9: =IFERROR(IF(LEN(TRIM(CLEAN(SUBSTITUTE(Setup!$B$2,CHAR(160)," "))))=0,"CHECK REVIEWER ID",IF(OR(A9="",COUNTIF($A$2:$A$12,A9)<>1,LEFT(A9,LEN("2019::jama.2019.0556::"))<>"2019::jama.2019.0556::"),"CHECK KEY",IF(OR(AND(NOT(AND(D9="retain",E9="statistical_results")),H9<>"",NOT(EXACT(H9,"not_applicable"))),AND(NOT(AND(D9="retain",E9="statistical_results")),I9<>"",NOT(EXACT(I9,"not_applicable"))),AND(NOT(AND(D9="retain",E9="statistical_results")),J9<>"",NOT(EXACT(J9,"not_applicable"))),AND(NOT(AND(D9="retain",OR(E9="report_internal_inconsistency",E9="plan_material"))),K9<>"",NOT(EXACT(K9,"not_applicable"))),AND(NOT(AND(D9="retain",E9="protocol_report")),L9<>"",NOT(EXACT(L9,"not_applicable")))),"CLEAR INACTIVE VALUES",IF(OR(NOT(OR(EXACT(D9,"retain"),EXACT(D9,"exclude"),EXACT(D9,"discuss"))),NOT(OR(EXACT(E9,"statistical_results"),EXACT(E9,"report_internal_inconsistency"),EXACT(E9,"plan_material"),EXACT(E9,"protocol_report"))),AND(AND(D9="retain",E9="statistical_results"),NOT(OR(EXACT(H9,"confirmed_issue"),EXACT(H9,"probable_issue"),EXACT(H9,"not_issue"),EXACT(H9,"indeterminate")))),AND(AND(D9="retain",E9="statistical_results"),NOT(OR(EXACT(I9,"substantive"),EXACT(I9,"minor_presentation"),EXACT(I9,"indeterminate")))),AND(AND(D9="retain",E9="statistical_results"),J9<>"",NOT(OR(EXACT(J9,"direct"),EXACT(J9,"possible"),EXACT(J9,"unlikely"),EXACT(J9,"unknown")))),AND(AND(D9="retain",OR(E9="report_internal_inconsistency",E9="plan_material")),NOT(OR(EXACT(K9,"substantive_inconsistency"),EXACT(K9,"minor_presentation"),EXACT(K9,"non_inconsistency"),EXACT(K9,"indeterminate")))),AND(AND(D9="retain",E9="protocol_report"),L9<>"",NOT(OR(EXACT(L9,"substantive_difference"),EXACT(L9,"minor_presentation"),EXACT(L9,"version_timing"),EXACT(L9,"non_inconsistency"),EXACT(L9,"indeterminate"))))),"CHECK FIELDS",IF(AND(F9<>"",NOT(OR(EXACT(F9,"no"),EXACT(F9,"primary_done")))),"CHECK COMPLETE",IF(EXACT(F9,"primary_done"),"PRIMARY READY","PRIMARY DRAFT")))))),"CHECK INPUT / KEY") | H9: =IF(AND(OR(D9="retain",D9=""),E9="statistical_results"),"","not_applicable") | I9: =IF(AND(OR(D9="retain",D9=""),E9="statistical_results"),"","not_applicable") | J9: =IF(AND(OR(D9="retain",D9=""),E9="statistical_results"),"","not_applicable") | K9: =IF(AND(OR(D9="retain",D9=""),OR(E9="report_internal_inconsistency",E9="plan_material")),"","not_applicable") | L9: substantive_difference | R9: SAP p. 4 plans a RERI (additive interaction) sensitivity analysis for the primary outcome with likelihood-based CIs. No RERI or additive-interaction result appears in the article or eSupplement (text search for RERI/additive/relative excess: no hits in report PDFs). Only multiplicative OR/HR interactions are reported.
A10: 2019::jama.2019.0556::C009 | B10: Planned primary-outcome missingness sensitivity is not reported | C10: joi190007supp2_prod.pdf — SAP p. 5, Missing data and drop-out; jama_bot_2019_oi_190007.pdf — Main p. 4, Statistical Methods; jama_bot_2019_oi_190007.pdf — Main p. 6, Table 2 and missingness narrative; jama_bot_2019_oi_190007.pdf — Main p. 8, sensitivity/CACE narrative; joi190007supp3_prod.pdf — Results supplement p. 21, eAppendix 11; joi190007supp3_prod.pdf — Results supplement p. 22, eAppendix 12. | D10: retain | E10: protocol_report | F10: primary_done | G10: =IFERROR(IF(LEN(TRIM(CLEAN(SUBSTITUTE(Setup!$B$2,CHAR(160)," "))))=0,"CHECK REVIEWER ID",IF(OR(A10="",COUNTIF($A$2:$A$12,A10)<>1,LEFT(A10,LEN("2019::jama.2019.0556::"))<>"2019::jama.2019.0556::"),"CHECK KEY",IF(OR(AND(NOT(AND(D10="retain",E10="statistical_results")),H10<>"",NOT(EXACT(H10,"not_applicable"))),AND(NOT(AND(D10="retain",E10="statistical_results")),I10<>"",NOT(EXACT(I10,"not_applicable"))),AND(NOT(AND(D10="retain",E10="statistical_results")),J10<>"",NOT(EXACT(J10,"not_applicable"))),AND(NOT(AND(D10="retain",OR(E10="report_internal_inconsistency",E10="plan_material"))),K10<>"",NOT(EXACT(K10,"not_applicable"))),AND(NOT(AND(D10="retain",E10="protocol_report")),L10<>"",NOT(EXACT(L10,"not_applicable")))),"CLEAR INACTIVE VALUES",IF(OR(NOT(OR(EXACT(D10,"retain"),EXACT(D10,"exclude"),EXACT(D10,"discuss"))),NOT(OR(EXACT(E10,"statistical_results"),EXACT(E10,"report_internal_inconsistency"),EXACT(E10,"plan_material"),EXACT(E10,"protocol_report"))),AND(AND(D10="retain",E10="statistical_results"),NOT(OR(EXACT(H10,"confirmed_issue"),EXACT(H10,"probable_issue"),EXACT(H10,"not_issue"),EXACT(H10,"indeterminate")))),AND(AND(D10="retain",E10="statistical_results"),NOT(OR(EXACT(I10,"substantive"),EXACT(I10,"minor_presentation"),EXACT(I10,"indeterminate")))),AND(AND(D10="retain",E10="statistical_results"),J10<>"",NOT(OR(EXACT(J10,"direct"),EXACT(J10,"possible"),EXACT(J10,"unlikely"),EXACT(J10,"unknown")))),AND(AND(D10="retain",OR(E10="report_internal_inconsistency",E10="plan_material")),NOT(OR(EXACT(K10,"substantive_inconsistency"),EXACT(K10,"minor_presentation"),EXACT(K10,"non_inconsistency"),EXACT(K10,"indeterminate")))),AND(AND(D10="retain",E10="protocol_report"),L10<>"",NOT(OR(EXACT(L10,"substantive_difference"),EXACT(L10,"minor_presentation"),EXACT(L10,"version_timing"),EXACT(L10,"non_inconsistency"),EXACT(L10,"indeterminate"))))),"CHECK FIELDS",IF(AND(F10<>"",NOT(OR(EXACT(F10,"no"),EXACT(F10,"primary_done")))),"CHECK COMPLETE",IF(EXACT(F10,"primary_done"),"PRIMARY READY","PRIMARY DRAFT")))))),"CHECK INPUT / KEY") | H10: =IF(AND(OR(D10="retain",D10=""),E10="statistical_results"),"","not_applicable") | I10: =IF(AND(OR(D10="retain",D10=""),E10="statistical_results"),"","not_applicable") | J10: =IF(AND(OR(D10="retain",D10=""),E10="statistical_results"),"","not_applicable") | K10: =IF(AND(OR(D10="retain",D10=""),OR(E10="report_internal_inconsistency",E10="plan_material")),"","not_applicable") | L10: substantive_difference | R10: SAP p. 5 commits to reported sensitivity analyses for the MAR assumption of the primary-outcome multiple imputation. The report's only no-imputation sensitivity (eAppendix 11, supp3 p. 21) covers secondary continuous outcomes; CACE (p. 22) uses MI and is not a missingness sensitivity. No primary-MDD missing-data sensitivity found.
A11: 2019::jama.2019.0556::C010 | B11: CACE explanation does not identify the mapping to the printed MDD estimates | C11: jama_bot_2019_oi_190007.pdf — Main p. 6, Table 2; jama_bot_2019_oi_190007.pdf — Main p. 8, CACE narrative; joi190007supp3_prod.pdf — Results supplement p. 14, eAppendix 7 opening; joi190007supp3_prod.pdf — Results supplement p. 15, eAppendix 7 continuation; joi190007supp3_prod.pdf — Results supplement p. 16, adherence table; joi190007supp3_prod.pdf — Results supplement p. 22, eAppendix 12. | D11: retain | E11: statistical_results | F11: primary_done | G11: =IFERROR(IF(LEN(TRIM(CLEAN(SUBSTITUTE(Setup!$B$2,CHAR(160)," "))))=0,"CHECK REVIEWER ID",IF(OR(A11="",COUNTIF($A$2:$A$12,A11)<>1,LEFT(A11,LEN("2019::jama.2019.0556::"))<>"2019::jama.2019.0556::"),"CHECK KEY",IF(OR(AND(NOT(AND(D11="retain",E11="statistical_results")),H11<>"",NOT(EXACT(H11,"not_applicable"))),AND(NOT(AND(D11="retain",E11="statistical_results")),I11<>"",NOT(EXACT(I11,"not_applicable"))),AND(NOT(AND(D11="retain",E11="statistical_results")),J11<>"",NOT(EXACT(J11,"not_applicable"))),AND(NOT(AND(D11="retain",OR(E11="report_internal_inconsistency",E11="plan_material"))),K11<>"",NOT(EXACT(K11,"not_applicable"))),AND(NOT(AND(D11="retain",E11="protocol_report")),L11<>"",NOT(EXACT(L11,"not_applicable")))),"CLEAR INACTIVE VALUES",IF(OR(NOT(OR(EXACT(D11,"retain"),EXACT(D11,"exclude"),EXACT(D11,"discuss"))),NOT(OR(EXACT(E11,"statistical_results"),EXACT(E11,"report_internal_inconsistency"),EXACT(E11,"plan_material"),EXACT(E11,"protocol_report"))),AND(AND(D11="retain",E11="statistical_results"),NOT(OR(EXACT(H11,"confirmed_issue"),EXACT(H11,"probable_issue"),EXACT(H11,"not_issue"),EXACT(H11,"indeterminate")))),AND(AND(D11="retain",E11="statistical_results"),NOT(OR(EXACT(I11,"substantive"),EXACT(I11,"minor_presentation"),EXACT(I11,"indeterminate")))),AND(AND(D11="retain",E11="statistical_results"),J11<>"",NOT(OR(EXACT(J11,"direct"),EXACT(J11,"possible"),EXACT(J11,"unlikely"),EXACT(J11,"unknown")))),AND(AND(D11="retain",OR(E11="report_internal_inconsistency",E11="plan_material")),NOT(OR(EXACT(K11,"substantive_inconsistency"),EXACT(K11,"minor_presentation"),EXACT(K11,"non_inconsistency"),EXACT(K11,"indeterminate")))),AND(AND(D11="retain",E11="protocol_report"),L11<>"",NOT(OR(EXACT(L11,"substantive_difference"),EXACT(L11,"minor_presentation"),EXACT(L11,"version_timing"),EXACT(L11,"non_inconsistency"),EXACT(L11,"indeterminate"))))),"CHECK FIELDS",IF(AND(F11<>"",NOT(OR(EXACT(F11,"no"),EXACT(F11,"primary_done")))),"CHECK COMPLETE",IF(EXACT(F11,"primary_done"),"PRIMARY READY","PRIMARY DRAFT")))))),"CHECK INPUT / KEY") | H11: probable_issue | I11: substantive | J11: possible | K11: =IF(AND(OR(D11="retain",D11=""),OR(E11="report_internal_inconsistency",E11="plan_material")),"","not_applicable") | L11: =IF(AND(OR(D11="retain",D11=""),E11="protocol_report"),"","not_applicable") | R11: eAppendix 7 (supp3 p. 15) defines CACE as ITT effect / complier proportion. ITT ORs (Table 2): supplements 1.06, therapy 0.93; CACE ORs (p. 22): 0.84 and 0.78. Any such ratio keeps the ITT direction, yet supplement CACE reverses it (crude ITT RD +0.6 pp). Therapy: exp(log 0.93/0.713) = 0.90, not 0.78. Values cannot be reproduced from the stated method.
A12: 2019::jama.2019.0556::C011 | B12: Three site coefficient and interval tuples do not reproduce the same-table relationship | C12: joi190007supp3_prod.pdf — results supplement p. 19, Table B. | D12: retain | E12: statistical_results | F12: primary_done | G12: =IFERROR(IF(LEN(TRIM(CLEAN(SUBSTITUTE(Setup!$B$2,CHAR(160)," "))))=0,"CHECK REVIEWER ID",IF(OR(A12="",COUNTIF($A$2:$A$12,A12)<>1,LEFT(A12,LEN("2019::jama.2019.0556::"))<>"2019::jama.2019.0556::"),"CHECK KEY",IF(OR(AND(NOT(AND(D12="retain",E12="statistical_results")),H12<>"",NOT(EXACT(H12,"not_applicable"))),AND(NOT(AND(D12="retain",E12="statistical_results")),I12<>"",NOT(EXACT(I12,"not_applicable"))),AND(NOT(AND(D12="retain",E12="statistical_results")),J12<>"",NOT(EXACT(J12,"not_applicable"))),AND(NOT(AND(D12="retain",OR(E12="report_internal_inconsistency",E12="plan_material"))),K12<>"",NOT(EXACT(K12,"not_applicable"))),AND(NOT(AND(D12="retain",E12="protocol_report")),L12<>"",NOT(EXACT(L12,"not_applicable")))),"CLEAR INACTIVE VALUES",IF(OR(NOT(OR(EXACT(D12,"retain"),EXACT(D12,"exclude"),EXACT(D12,"discuss"))),NOT(OR(EXACT(E12,"statistical_results"),EXACT(E12,"report_internal_inconsistency"),EXACT(E12,"plan_material"),EXACT(E12,"protocol_report"))),AND(AND(D12="retain",E12="statistical_results"),NOT(OR(EXACT(H12,"confirmed_issue"),EXACT(H12,"probable_issue"),EXACT(H12,"not_issue"),EXACT(H12,"indeterminate")))),AND(AND(D12="retain",E12="statistical_results"),NOT(OR(EXACT(I12,"substantive"),EXACT(I12,"minor_presentation"),EXACT(I12,"indeterminate")))),AND(AND(D12="retain",E12="statistical_results"),J12<>"",NOT(OR(EXACT(J12,"direct"),EXACT(J12,"possible"),EXACT(J12,"unlikely"),EXACT(J12,"unknown")))),AND(AND(D12="retain",OR(E12="report_internal_inconsistency",E12="plan_material")),NOT(OR(EXACT(K12,"substantive_inconsistency"),EXACT(K12,"minor_presentation"),EXACT(K12,"non_inconsistency"),EXACT(K12,"indeterminate")))),AND(AND(D12="retain",E12="protocol_report"),L12<>"",NOT(OR(EXACT(L12,"substantive_difference"),EXACT(L12,"minor_presentation"),EXACT(L12,"version_timing"),EXACT(L12,"non_inconsistency"),EXACT(L12,"indeterminate"))))),"CHECK FIELDS",IF(AND(F12<>"",NOT(OR(EXACT(F12,"no"),EXACT(F12,"primary_done")))),"CHECK COMPLETE",IF(EXACT(F12,"primary_done"),"PRIMARY READY","PRIMARY DRAFT")))))),"CHECK INPUT / KEY") | H12: confirmed_issue | I12: minor_presentation | J12: unlikely | K12: =IF(AND(OR(D12="retain",D12=""),OR(E12="report_internal_inconsistency",E12="plan_material")),"","not_applicable") | L12: =IF(AND(OR(D12="retain",D12=""),E12="protocol_report"),"","not_applicable") | R12: eAppendix 10 Table B (supp3 p. 19, rendered): Spain 0.107 (-0.424 to 0.520), UK 0.117 (-0.371 to 0.638), Germany 0.058 (-0.401 to 0.606) are not centered (midpoints 0.048, 0.134, 0.102) while all six other rows are. 2B-L gives 0.638, 0.605, 0.517: the upper limits appear rotated among the three site rows.

Sheet C_jama.2019.10517
A1: Candidate key | B1: Candidate title | C1: Source location | D1: Disposition | E1: Review domain (AI suggestion; editable) | F1: Complete | G1: Validation hint | H1: Statistical_or_numerical issue | I1: Substantiveness | J1: Downstream impact | K1: Report-internal or planning-material inconsistency | L1: Protocol interpretation | R1: Notes (optional)
A2: 2019::jama.2019.10517::C001 | B2: Primary relapse score component differs from the plan | C2: PLAN joi190079supp1_prod.pdf — PDF p.12, §3.9.8, lines 553–568; REPORT jama_flint_2019_oi_190079.pdf — PDF p.4, Primary Outcome: Relapse. Affected outputs and context: jama_flint_2019_oi_190079.pdf — main PDF p.1, abstract, jama_flint_2019_oi_190079.pdf — main PDF p.6, primary results and jama_flint_2019_oi_190079.pdf — main PDF p.7, Table 3 and footnotes. | D2: retain | E2: protocol_report | F2: primary_done | G2: =IFERROR(IF(LEN(TRIM(CLEAN(SUBSTITUTE(Setup!$B$2,CHAR(160)," "))))=0,"CHECK REVIEWER ID",IF(OR(A2="",COUNTIF($A$2:$A$6,A2)<>1,LEFT(A2,LEN("2019::jama.2019.10517::"))<>"2019::jama.2019.10517::"),"CHECK KEY",IF(OR(AND(NOT(AND(D2="retain",E2="statistical_results")),H2<>"",NOT(EXACT(H2,"not_applicable"))),AND(NOT(AND(D2="retain",E2="statistical_results")),I2<>"",NOT(EXACT(I2,"not_applicable"))),AND(NOT(AND(D2="retain",E2="statistical_results")),J2<>"",NOT(EXACT(J2,"not_applicable"))),AND(NOT(AND(D2="retain",OR(E2="report_internal_inconsistency",E2="plan_material"))),K2<>"",NOT(EXACT(K2,"not_applicable"))),AND(NOT(AND(D2="retain",E2="protocol_report")),L2<>"",NOT(EXACT(L2,"not_applicable")))),"CLEAR INACTIVE VALUES",IF(OR(NOT(OR(EXACT(D2,"retain"),EXACT(D2,"exclude"),EXACT(D2,"discuss"))),NOT(OR(EXACT(E2,"statistical_results"),EXACT(E2,"report_internal_inconsistency"),EXACT(E2,"plan_material"),EXACT(E2,"protocol_report"))),AND(AND(D2="retain",E2="statistical_results"),NOT(OR(EXACT(H2,"confirmed_issue"),EXACT(H2,"probable_issue"),EXACT(H2,"not_issue"),EXACT(H2,"indeterminate")))),AND(AND(D2="retain",E2="statistical_results"),NOT(OR(EXACT(I2,"substantive"),EXACT(I2,"minor_presentation"),EXACT(I2,"indeterminate")))),AND(AND(D2="retain",E2="statistical_results"),J2<>"",NOT(OR(EXACT(J2,"direct"),EXACT(J2,"possible"),EXACT(J2,"unlikely"),EXACT(J2,"unknown")))),AND(AND(D2="retain",OR(E2="report_internal_inconsistency",E2="plan_material")),NOT(OR(EXACT(K2,"substantive_inconsistency"),EXACT(K2,"minor_presentation"),EXACT(K2,"non_inconsistency"),EXACT(K2,"indeterminate")))),AND(AND(D2="retain",E2="protocol_report"),L2<>"",NOT(OR(EXACT(L2,"substantive_difference"),EXACT(L2,"minor_presentation"),EXACT(L2,"version_timing"),EXACT(L2,"non_inconsistency"),EXACT(L2,"indeterminate"))))),"CHECK FIELDS",IF(AND(F2<>"",NOT(OR(EXACT(F2,"no"),EXACT(F2,"primary_done")))),"CHECK COMPLETE",IF(EXACT(F2,"primary_done"),"PRIMARY READY","PRIMARY DRAFT")))))),"CHECK INPUT / KEY") | H2: =IF(AND(OR(D2="retain",D2=""),E2="statistical_results"),"","not_applicable") | I2: =IF(AND(OR(D2="retain",D2=""),E2="statistical_results"),"","not_applicable") | J2: =IF(AND(OR(D2="retain",D2=""),E2="statistical_results"),"","not_applicable") | K2: =IF(AND(OR(D2="retain",D2=""),OR(E2="report_internal_inconsistency",E2="plan_material")),"","not_applicable") | L2: substantive_difference | R2: Protocol §3.9.8 (p. 12): relapse criterion 2 is HAM-D >=18 AND a 5-point increase from RCT entry (preferably sustained 1 week). Article p. 4 lists HDRS >=18 alone. Primary composite definition differs as printed; the extra condition matters only for participants entering near 13-15, so the practical effect is probably small.
A3: 2019::jama.2019.10517::C002 | B3: Four prespecified key secondary counterparts are absent | C3: PLAN joi190079supp1_prod.pdf — PDF p.10, lines 473–488, joi190079supp1_prod.pdf — PLAN PDF p.14, analysis context and joi190079supp1_prod.pdf — PLAN PDF p.16, Strategies for Attrition, lines 769–772. The complete supplied REPORT absence-check union is listed page by page below; every linked page was inspected in the mechanical recheck. jama_flint_2019_oi_190079.pdf — PDF p.1: Abstract and eight headline secondary effects; jama_flint_2019_oi_190079.pdf — main PDF p.2: Key Points and explicit Aims 1–2 scope; jama_flint_2019_oi_190079.pdf — main PDF p.3: Participant flow and methods; jama_flint_2019_oi_190079.pdf — main PDF p.4: Outcome collection and model definitions; jama_flint_2019_oi_190079.pdf — main PDF p.5: Premorbid-weight description and missingness/sensitivity methods; jama_flint_2019_oi_190079.pdf — main PDF p.6: Primary results and safety/multiplicity context; jama_flint_2019_oi_190079.pdf — main PDF p.7: Secondary effects and tolerability results; jama_flint_2019_oi_190079.pdf — main PDF p.8: Table 4 and discussion; jama_flint_2019_oi_190079.pdf — main PDF p.9: Table 5, limitations and conclusion; jama_flint_2019_oi_190079.pdf — main PDF p.10: End matter and references; joi190079supp2_prod.pdf — PDF p.1: Complete eFigure index; joi190079supp2_prod.pdf — results supplement PDF p.2: Weight model means; joi190079supp2_prod.pdf — results supplement PDF p.3: Waist model means; joi190079supp2_prod.pdf — results supplement PDF p.4: Total-cholesterol model means; joi190079supp2_prod.pdf — results supplement PDF p.5: LDL model means; joi190079supp2_prod.pdf — results supplement PDF p.6: HDL model means; joi190079supp2_prod.pdf — results supplement PDF p.7: Triglyceride pattern-mixture means; joi190079supp2_prod.pdf — results supplement PDF p.8: Glucose model means; joi190079supp2_prod.pdf — results supplement PDF p.9: HbA1c model means; joi190079supp2_prod.pdf — results supplement PDF p.10: Simpson-Angus model means; joi190079supp3_prod.pdf — PDF p.1: Administrative data-sharing statement. | D3: retain | E3: protocol_report | F3: primary_done | G3: =IFERROR(IF(LEN(TRIM(CLEAN(SUBSTITUTE(Setup!$B$2,CHAR(160)," "))))=0,"CHECK REVIEWER ID",IF(OR(A3="",COUNTIF($A$2:$A$6,A3)<>1,LEFT(A3,LEN("2019::jama.2019.10517::"))<>"2019::jama.2019.10517::"),"CHECK KEY",IF(OR(AND(NOT(AND(D3="retain",E3="statistical_results")),H3<>"",NOT(EXACT(H3,"not_applicable"))),AND(NOT(AND(D3="retain",E3="statistical_results")),I3<>"",NOT(EXACT(I3,"not_applicable"))),AND(NOT(AND(D3="retain",E3="statistical_results")),J3<>"",NOT(EXACT(J3,"not_applicable"))),AND(NOT(AND(D3="retain",OR(E3="report_internal_inconsistency",E3="plan_material"))),K3<>"",NOT(EXACT(K3,"not_applicable"))),AND(NOT(AND(D3="retain",E3="protocol_report")),L3<>"",NOT(EXACT(L3,"not_applicable")))),"CLEAR INACTIVE VALUES",IF(OR(NOT(OR(EXACT(D3,"retain"),EXACT(D3,"exclude"),EXACT(D3,"discuss"))),NOT(OR(EXACT(E3,"statistical_results"),EXACT(E3,"report_internal_inconsistency"),EXACT(E3,"plan_material"),EXACT(E3,"protocol_report"))),AND(AND(D3="retain",E3="statistical_results"),NOT(OR(EXACT(H3,"confirmed_issue"),EXACT(H3,"probable_issue"),EXACT(H3,"not_issue"),EXACT(H3,"indeterminate")))),AND(AND(D3="retain",E3="statistical_results"),NOT(OR(EXACT(I3,"substantive"),EXACT(I3,"minor_presentation"),EXACT(I3,"indeterminate")))),AND(AND(D3="retain",E3="statistical_results"),J3<>"",NOT(OR(EXACT(J3,"direct"),EXACT(J3,"possible"),EXACT(J3,"unlikely"),EXACT(J3,"unknown")))),AND(AND(D3="retain",OR(E3="report_internal_inconsistency",E3="plan_material")),NOT(OR(EXACT(K3,"substantive_inconsistency"),EXACT(K3,"minor_presentation"),EXACT(K3,"non_inconsistency"),EXACT(K3,"indeterminate")))),AND(AND(D3="retain",E3="protocol_report"),L3<>"",NOT(OR(EXACT(L3,"substantive_difference"),EXACT(L3,"minor_presentation"),EXACT(L3,"version_timing"),EXACT(L3,"non_inconsistency"),EXACT(L3,"indeterminate"))))),"CHECK FIELDS",IF(AND(F3<>"",NOT(OR(EXACT(F3,"no"),EXACT(F3,"primary_done")))),"CHECK COMPLETE",IF(EXACT(F3,"primary_done"),"PRIMARY READY","PRIMARY DRAFT")))))),"CHECK INPUT / KEY") | H3: =IF(AND(OR(D3="retain",D3=""),E3="statistical_results"),"","not_applicable") | I3: =IF(AND(OR(D3="retain",D3=""),E3="statistical_results"),"","not_applicable") | J3: =IF(AND(OR(D3="retain",D3=""),E3="statistical_results"),"","not_applicable") | K3: =IF(AND(OR(D3="retain",D3=""),OR(E3="report_internal_inconsistency",E3="plan_material")),"","not_applicable") | L3: substantive_difference | R3: Protocol p. 10 names HOMA insulin resistance as the primary glycemic measure, a separate BMI alternative analysis and a secondary weight analysis accounting for depression-related weight loss; p. 16 plans an Intent-to-Attend attrition model. None appears in the article or eFigures (text search: no HOMA/insulin/BMI/intent hits). Article limits scope to Aims 1-2 but these belong to Aim 2.
A4: 2019::jama.2019.10517::C003 | B4: Adverse-event baseline differs between plan and report | C4: PLAN joi190079supp1_prod.pdf — PDF p.15, Non-Metabolic Safety Data, lines 705–717; REPORT jama_flint_2019_oi_190079.pdf — PDF p.4, Other Measures of Tolerability and jama_flint_2019_oi_190079.pdf — main PDF p.7, adverse-effect/akathisia results. Phase context: jama_flint_2019_oi_190079.pdf — main PDF p.2 and jama_flint_2019_oi_190079.pdf — main PDF p.3. | D4: retain | E4: protocol_report | F4: primary_done | G4: =IFERROR(IF(LEN(TRIM(CLEAN(SUBSTITUTE(Setup!$B$2,CHAR(160)," "))))=0,"CHECK REVIEWER ID",IF(OR(A4="",COUNTIF($A$2:$A$6,A4)<>1,LEFT(A4,LEN("2019::jama.2019.10517::"))<>"2019::jama.2019.10517::"),"CHECK KEY",IF(OR(AND(NOT(AND(D4="retain",E4="statistical_results")),H4<>"",NOT(EXACT(H4,"not_applicable"))),AND(NOT(AND(D4="retain",E4="statistical_results")),I4<>"",NOT(EXACT(I4,"not_applicable"))),AND(NOT(AND(D4="retain",E4="statistical_results")),J4<>"",NOT(EXACT(J4,"not_applicable"))),AND(NOT(AND(D4="retain",OR(E4="report_internal_inconsistency",E4="plan_material"))),K4<>"",NOT(EXACT(K4,"not_applicable"))),AND(NOT(AND(D4="retain",E4="protocol_report")),L4<>"",NOT(EXACT(L4,"not_applicable")))),"CLEAR INACTIVE VALUES",IF(OR(NOT(OR(EXACT(D4,"retain"),EXACT(D4,"exclude"),EXACT(D4,"discuss"))),NOT(OR(EXACT(E4,"statistical_results"),EXACT(E4,"report_internal_inconsistency"),EXACT(E4,"plan_material"),EXACT(E4,"protocol_report"))),AND(AND(D4="retain",E4="statistical_results"),NOT(OR(EXACT(H4,"confirmed_issue"),EXACT(H4,"probable_issue"),EXACT(H4,"not_issue"),EXACT(H4,"indeterminate")))),AND(AND(D4="retain",E4="statistical_results"),NOT(OR(EXACT(I4,"substantive"),EXACT(I4,"minor_presentation"),EXACT(I4,"indeterminate")))),AND(AND(D4="retain",E4="statistical_results"),J4<>"",NOT(OR(EXACT(J4,"direct"),EXACT(J4,"possible"),EXACT(J4,"unlikely"),EXACT(J4,"unknown")))),AND(AND(D4="retain",OR(E4="report_internal_inconsistency",E4="plan_material")),NOT(OR(EXACT(K4,"substantive_inconsistency"),EXACT(K4,"minor_presentation"),EXACT(K4,"non_inconsistency"),EXACT(K4,"indeterminate")))),AND(AND(D4="retain",E4="protocol_report"),L4<>"",NOT(OR(EXACT(L4,"substantive_difference"),EXACT(L4,"minor_presentation"),EXACT(L4,"version_timing"),EXACT(L4,"non_inconsistency"),EXACT(L4,"indeterminate"))))),"CHECK FIELDS",IF(AND(F4<>"",NOT(OR(EXACT(F4,"no"),EXACT(F4,"primary_done")))),"CHECK COMPLETE",IF(EXACT(F4,"primary_done"),"PRIMARY READY","PRIMARY DRAFT")))))),"CHECK INPUT / KEY") | H4: =IF(AND(OR(D4="retain",D4=""),E4="statistical_results"),"","not_applicable") | I4: =IF(AND(OR(D4="retain",D4=""),E4="statistical_results"),"","not_applicable") | J4: =IF(AND(OR(D4="retain",D4=""),E4="statistical_results"),"","not_applicable") | K4: =IF(AND(OR(D4="retain",D4=""),OR(E4="report_internal_inconsistency",E4="plan_material")),"","not_applicable") | L4: substantive_difference | R4: Protocol p. 15 defines phase-specific adverse-event incidence among participants not meeting the criterion at acute-phase baseline (plus week-8-onward reporting); article p. 4 defines UKU adverse effects and incident akathisia relative to RCT baseline. Reference epoch for incidence differs.
A5: 2019::jama.2019.10517::C004 | B5: Safety treatment classification differs from the plan | C5: PLAN joi190079supp1_prod.pdf — PDF p.14, H2 and joi190079supp1_prod.pdf — PLAN PDF p.16, attrition/classification; REPORT jama_flint_2019_oi_190079.pdf — PDF p.3, Figure 1, jama_flint_2019_oi_190079.pdf — main PDF p.4, Statistical Analyses, jama_flint_2019_oi_190079.pdf — main PDF p.7, secondary effects and jama_flint_2019_oi_190079.pdf — main PDF p.8, Table 4. Every affected randomized-group model title is linked separately: Weight: joi190079supp2_prod.pdf — PDF p.2, eFigure 1; Waist: joi190079supp2_prod.pdf — results supplement PDF p.3, eFigure 2; Total cholesterol: joi190079supp2_prod.pdf — results supplement PDF p.4, eFigure 3; LDL cholesterol: joi190079supp2_prod.pdf — results supplement PDF p.5, eFigure 4; HDL cholesterol: joi190079supp2_prod.pdf — results supplement PDF p.6, eFigure 5; Triglycerides: joi190079supp2_prod.pdf — results supplement PDF p.7, eFigure 6; Glucose: joi190079supp2_prod.pdf — results supplement PDF p.8, eFigure 7; HbA1c: joi190079supp2_prod.pdf — results supplement PDF p.9, eFigure 8. | D5: retain | E5: protocol_report | F5: primary_done | G5: =IFERROR(IF(LEN(TRIM(CLEAN(SUBSTITUTE(Setup!$B$2,CHAR(160)," "))))=0,"CHECK REVIEWER ID",IF(OR(A5="",COUNTIF($A$2:$A$6,A5)<>1,LEFT(A5,LEN("2019::jama.2019.10517::"))<>"2019::jama.2019.10517::"),"CHECK KEY",IF(OR(AND(NOT(AND(D5="retain",E5="statistical_results")),H5<>"",NOT(EXACT(H5,"not_applicable"))),AND(NOT(AND(D5="retain",E5="statistical_results")),I5<>"",NOT(EXACT(I5,"not_applicable"))),AND(NOT(AND(D5="retain",E5="statistical_results")),J5<>"",NOT(EXACT(J5,"not_applicable"))),AND(NOT(AND(D5="retain",OR(E5="report_internal_inconsistency",E5="plan_material"))),K5<>"",NOT(EXACT(K5,"not_applicable"))),AND(NOT(AND(D5="retain",E5="protocol_report")),L5<>"",NOT(EXACT(L5,"not_applicable")))),"CLEAR INACTIVE VALUES",IF(OR(NOT(OR(EXACT(D5,"retain"),EXACT(D5,"exclude"),EXACT(D5,"discuss"))),NOT(OR(EXACT(E5,"statistical_results"),EXACT(E5,"report_internal_inconsistency"),EXACT(E5,"plan_material"),EXACT(E5,"protocol_report"))),AND(AND(D5="retain",E5="statistical_results"),NOT(OR(EXACT(H5,"confirmed_issue"),EXACT(H5,"probable_issue"),EXACT(H5,"not_issue"),EXACT(H5,"indeterminate")))),AND(AND(D5="retain",E5="statistical_results"),NOT(OR(EXACT(I5,"substantive"),EXACT(I5,"minor_presentation"),EXACT(I5,"indeterminate")))),AND(AND(D5="retain",E5="statistical_results"),J5<>"",NOT(OR(EXACT(J5,"direct"),EXACT(J5,"possible"),EXACT(J5,"unlikely"),EXACT(J5,"unknown")))),AND(AND(D5="retain",OR(E5="report_internal_inconsistency",E5="plan_material")),NOT(OR(EXACT(K5,"substantive_inconsistency"),EXACT(K5,"minor_presentation"),EXACT(K5,"non_inconsistency"),EXACT(K5,"indeterminate")))),AND(AND(D5="retain",E5="protocol_report"),L5<>"",NOT(OR(EXACT(L5,"substantive_difference"),EXACT(L5,"minor_presentation"),EXACT(L5,"version_timing"),EXACT(L5,"non_inconsistency"),EXACT(L5,"indeterminate"))))),"CHECK FIELDS",IF(AND(F5<>"",NOT(OR(EXACT(F5,"no"),EXACT(F5,"primary_done")))),"CHECK COMPLETE",IF(EXACT(F5,"primary_done"),"PRIMARY READY","PRIMARY DRAFT")))))),"CHECK INPUT / KEY") | H5: =IF(AND(OR(D5="retain",D5=""),E5="statistical_results"),"","not_applicable") | I5: =IF(AND(OR(D5="retain",D5=""),E5="statistical_results"),"","not_applicable") | J5: =IF(AND(OR(D5="retain",D5=""),E5="statistical_results"),"","not_applicable") | K5: =IF(AND(OR(D5="retain",D5=""),OR(E5="report_internal_inconsistency",E5="plan_material")),"","not_applicable") | L5: substantive_difference | R5: Protocol pp. 14, 16: safety (H2) models classify participants 'based on medications taken during protocolized treatment' (regulatory approach). Article p. 4: 'Analyses included all randomized participants'; eFigures 1-8 titles say 'Randomized Groups'. Figure 1 shows 5 + 2 participants not treated as randomized (59+5 = 64; 60+2 = 62).
A6: 2019::jama.2019.10517::C005 | B6: Planned metabolic observation exclusion is placed in sensitivity analysis | C6: PLAN joi190079supp1_prod.pdf — PDF p.14, H2, lines 673–679; REPORT jama_flint_2019_oi_190079.pdf — PDF p.1, abstract secondary effects, jama_flint_2019_oi_190079.pdf — main PDF p.5, final Statistical Analyses paragraph and jama_flint_2019_oi_190079.pdf — main PDF p.7, secondary/drug-change results. | D6: retain | E6: protocol_report | F6: primary_done | G6: =IFERROR(IF(LEN(TRIM(CLEAN(SUBSTITUTE(Setup!$B$2,CHAR(160)," "))))=0,"CHECK REVIEWER ID",IF(OR(A6="",COUNTIF($A$2:$A$6,A6)<>1,LEFT(A6,LEN("2019::jama.2019.10517::"))<>"2019::jama.2019.10517::"),"CHECK KEY",IF(OR(AND(NOT(AND(D6="retain",E6="statistical_results")),H6<>"",NOT(EXACT(H6,"not_applicable"))),AND(NOT(AND(D6="retain",E6="statistical_results")),I6<>"",NOT(EXACT(I6,"not_applicable"))),AND(NOT(AND(D6="retain",E6="statistical_results")),J6<>"",NOT(EXACT(J6,"not_applicable"))),AND(NOT(AND(D6="retain",OR(E6="report_internal_inconsistency",E6="plan_material"))),K6<>"",NOT(EXACT(K6,"not_applicable"))),AND(NOT(AND(D6="retain",E6="protocol_report")),L6<>"",NOT(EXACT(L6,"not_applicable")))),"CLEAR INACTIVE VALUES",IF(OR(NOT(OR(EXACT(D6,"retain"),EXACT(D6,"exclude"),EXACT(D6,"discuss"))),NOT(OR(EXACT(E6,"statistical_results"),EXACT(E6,"report_internal_inconsistency"),EXACT(E6,"plan_material"),EXACT(E6,"protocol_report"))),AND(AND(D6="retain",E6="statistical_results"),NOT(OR(EXACT(H6,"confirmed_issue"),EXACT(H6,"probable_issue"),EXACT(H6,"not_issue"),EXACT(H6,"indeterminate")))),AND(AND(D6="retain",E6="statistical_results"),NOT(OR(EXACT(I6,"substantive"),EXACT(I6,"minor_presentation"),EXACT(I6,"indeterminate")))),AND(AND(D6="retain",E6="statistical_results"),J6<>"",NOT(OR(EXACT(J6,"direct"),EXACT(J6,"possible"),EXACT(J6,"unlikely"),EXACT(J6,"unknown")))),AND(AND(D6="retain",OR(E6="report_internal_inconsistency",E6="plan_material")),NOT(OR(EXACT(K6,"substantive_inconsistency"),EXACT(K6,"minor_presentation"),EXACT(K6,"non_inconsistency"),EXACT(K6,"indeterminate")))),AND(AND(D6="retain",E6="protocol_report"),L6<>"",NOT(OR(EXACT(L6,"substantive_difference"),EXACT(L6,"minor_presentation"),EXACT(L6,"version_timing"),EXACT(L6,"non_inconsistency"),EXACT(L6,"indeterminate"))))),"CHECK FIELDS",IF(AND(F6<>"",NOT(OR(EXACT(F6,"no"),EXACT(F6,"primary_done")))),"CHECK COMPLETE",IF(EXACT(F6,"primary_done"),"PRIMARY READY","PRIMARY DRAFT")))))),"CHECK INPUT / KEY") | H6: =IF(AND(OR(D6="retain",D6=""),E6="statistical_results"),"","not_applicable") | I6: =IF(AND(OR(D6="retain",D6=""),E6="statistical_results"),"","not_applicable") | J6: =IF(AND(OR(D6="retain",D6=""),E6="statistical_results"),"","not_applicable") | K6: =IF(AND(OR(D6="retain",D6=""),OR(E6="report_internal_inconsistency",E6="plan_material")),"","not_applicable") | L6: substantive_difference | R6: Protocol p. 14 builds exclusion of metabolic data after a new/changed hyperlipidemia treatment into the H2 mixed model; article pp. 5, 7 present the exclusion (statins 6+6 = 12, hypoglycemics 2+1 = 3) as a post hoc sensitivity analysis, with the main models including all data. Planned primary rule became a sensitivity analysis and is labeled post hoc.

Sheet C_jama.2019.12618
A1: Candidate key | B1: Candidate title | C1: Source location | D1: Disposition | E1: Review domain (AI suggestion; editable) | F1: Complete | G1: Validation hint | H1: Statistical_or_numerical issue | I1: Substantiveness | J1: Downstream impact | K1: Report-internal or planning-material inconsistency | L1: Protocol interpretation | R1: Notes (optional)
