Workbook

Sheet Setup
A1: Field | B1: Value
A2: reviewerId | B2: R_Bulun
A3: reviewerName (optional)
A4: reviewerRole | B4: R_Bulun
A5: year | B5: 2025

Sheet Checks
A1: Check | B1: Result
A2: Reviewer role | B2: =Setup!B4
A3: Candidates | B3: 133
A4: Primary ready rows | B4: =COUNTIF('C_jama.2024.24764'!$G$2:$G$6,"PRIMARY READY")+COUNTIF('C_jama.2024.27643'!$G$2:$G$17,"PRIMARY READY")+COUNTIF('C_jama.2025.11178'!$G$2:$G$19,"PRIMARY READY")+COUNTIF('C_jama.2025.15185'!$G$2:$G$7,"PRIMARY READY")+COUNTIF('C_jama.2025.15440'!$G$2:$G$2,"PRIMARY READY")+COUNTIF('C_jama.2025.16450'!$G$2:$G$7,"PRIMARY READY")+COUNTIF('C_jama.2025.19563'!$G$2:$G$14,"PRIMARY READY")+COUNTIF('C_jama.2025.19843'!$G$2:$G$8,"PRIMARY READY")+COUNTIF('C_jama.2025.20765'!$G$2:$G$20,"PRIMARY READY")+COUNTIF('C_jama.2025.24175'!$G$2:$G$15,"PRIMARY READY")+COUNTIF('C_jama.2025.4390'!$G$2:$G$14,"PRIMARY READY")+COUNTIF('C_jama.2025.7583'!$G$2:$G$5,"PRIMARY READY")+COUNTIF('C_jama.2025.7710'!$G$2:$G$4,"PRIMARY READY")+COUNTIF('C_jama.2025.9110'!$G$2:$G$4,"PRIMARY READY")+COUNTIF('C_jama.2025.9663'!$G$2:$G$6,"PRIMARY READY")
A5: Discuss / unresolved rows | B5: =COUNTIF('C_jama.2024.24764'!$D$2:$D$6,"discuss")+COUNTIF('C_jama.2024.27643'!$D$2:$D$17,"discuss")+COUNTIF('C_jama.2025.11178'!$D$2:$D$19,"discuss")+COUNTIF('C_jama.2025.15185'!$D$2:$D$7,"discuss")+COUNTIF('C_jama.2025.15440'!$D$2:$D$2,"discuss")+COUNTIF('C_jama.2025.16450'!$D$2:$D$7,"discuss")+COUNTIF('C_jama.2025.19563'!$D$2:$D$14,"discuss")+COUNTIF('C_jama.2025.19843'!$D$2:$D$8,"discuss")+COUNTIF('C_jama.2025.20765'!$D$2:$D$20,"discuss")+COUNTIF('C_jama.2025.24175'!$D$2:$D$15,"discuss")+COUNTIF('C_jama.2025.4390'!$D$2:$D$14,"discuss")+COUNTIF('C_jama.2025.7583'!$D$2:$D$5,"discuss")+COUNTIF('C_jama.2025.7710'!$D$2:$D$4,"discuss")+COUNTIF('C_jama.2025.9110'!$D$2:$D$4,"discuss")+COUNTIF('C_jama.2025.9663'!$D$2:$D$6,"discuss")
A6: Unfinished rows | B6: =B3-B4
A7: Workflow status | B7: =IF(B4=B3,"PRIMARY READY","ACTION NEEDED")
A8: Meaning | B8: PRIMARY READY means independent entry is complete. Discuss remains unresolved and is not counted as absence of error.
A9: Next action | B9: Inspect G on the C_ sheets. Save and deliver this file after review.

Sheet Papers
A1: Paper | B1: Review worksheet | C1: Candidates
A2: jama.2024.24764 | B2: C_jama.2024.24764 | C2: 5
A3: jama.2024.27643 | B3: C_jama.2024.27643 | C3: 16
A4: jama.2025.11178 | B4: C_jama.2025.11178 | C4: 18
A5: jama.2025.15185 | B5: C_jama.2025.15185 | C5: 6
A6: jama.2025.15440 | B6: C_jama.2025.15440 | C6: 1
A7: jama.2025.16450 | B7: C_jama.2025.16450 | C7: 6
A8: jama.2025.19563 | B8: C_jama.2025.19563 | C8: 13
A9: jama.2025.19843 | B9: C_jama.2025.19843 | C9: 7
A10: jama.2025.20765 | B10: C_jama.2025.20765 | C10: 19
A11: jama.2025.24175 | B11: C_jama.2025.24175 | C11: 14
A12: jama.2025.4390 | B12: C_jama.2025.4390 | C12: 13
A13: jama.2025.7583 | B13: C_jama.2025.7583 | C13: 4
... A16: jama.2025.9663 | B16: C_jama.2025.9663 | C16: 5

Sheet C_jama.2024.24764
A1: Candidate key | B1: Candidate title | C1: Source location | D1: Disposition | E1: Review domain (AI suggestion; editable) | F1: Complete | G1: Validation hint | H1: Statistical_or_numerical issue | I1: Substantiveness | J1: Downstream impact | K1: Report-internal or planning-material inconsistency | L1: Protocol interpretation | R1: Notes (optional)
A2: 2025::jama.2024.24764::C001 | B2: Quality-of-life conclusion versus the day-7 index test | C2: REPORT jama_atherton_2025_oi_240145_1741627844.85412.pdf — main article abstract, PDF p. 1; REPORT jama_atherton_2025_oi_240145_1741627844.85412.pdf — main Secondary Outcomes, PDF p. 6; REPORT joi240145supp3_prod_1741627844.89412.pdf — results supplement eTable 3, day-7 index, later-time rows and interaction, PDF p. 4. Corroborating PLAN joi240145supp1_prod_1741627844.87412.pdf — SAP §§5.1–5.2, PDF p. 12. | D2: retain | E2: statistical_results | F2: primary_done | G2: =IFERROR(IF(LEN(TRIM(CLEAN(SUBSTITUTE(Setup!$B$2,CHAR(160)," "))))=0,"CHECK REVIEWER ID",IF(OR(A2="",COUNTIF($A$2:$A$6,A2)<>1,LEFT(A2,LEN("2025::jama.2024.24764::"))<>"2025::jama.2024.24764::"),"CHECK KEY",IF(OR(AND(NOT(AND(D2="retain",E2="statistical_results")),H2<>"",NOT(EXACT(H2,"not_applicable"))),AND(NOT(AND(D2="retain",E2="statistical_results")),I2<>"",NOT(EXACT(I2,"not_applicable"))),AND(NOT(AND(D2="retain",E2="statistical_results")),J2<>"",NOT(EXACT(J2,"not_applicable"))),AND(NOT(AND(D2="retain",OR(E2="report_internal_inconsistency",E2="plan_material"))),K2<>"",NOT(EXACT(K2,"not_applicable"))),AND(NOT(AND(D2="retain",E2="protocol_report")),L2<>"",NOT(EXACT(L2,"not_applicable")))),"CLEAR INACTIVE VALUES",IF(OR(NOT(OR(EXACT(D2,"retain"),EXACT(D2,"exclude"),EXACT(D2,"discuss"))),NOT(OR(EXACT(E2,"statistical_results"),EXACT(E2,"report_internal_inconsistency"),EXACT(E2,"plan_material"),EXACT(E2,"protocol_report"))),AND(AND(D2="retain",E2="statistical_results"),NOT(OR(EXACT(H2,"confirmed_issue"),EXACT(H2,"probable_issue"),EXACT(H2,"not_issue"),EXACT(H2,"indeterminate")))),AND(AND(D2="retain",E2="statistical_results"),NOT(OR(EXACT(I2,"substantive"),EXACT(I2,"minor_presentation"),EXACT(I2,"indeterminate")))),AND(AND(D2="retain",E2="statistical_results"),J2<>"",NOT(OR(EXACT(J2,"direct"),EXACT(J2,"possible"),EXACT(J2,"unlikely"),EXACT(J2,"unknown")))),AND(AND(D2="retain",OR(E2="report_internal_inconsistency",E2="plan_material")),NOT(OR(EXACT(K2,"substantive_inconsistency"),EXACT(K2,"minor_presentation"),EXACT(K2,"non_inconsistency"),EXACT(K2,"indeterminate")))),AND(AND(D2="retain",E2="protocol_report"),L2<>"",NOT(OR(EXACT(L2,"substantive_difference"),EXACT(L2,"minor_presentation"),EXACT(L2,"version_timing"),EXACT(L2,"non_inconsistency"),EXACT(L2,"indeterminate"))))),"CHECK FIELDS",IF(AND(F2<>"",NOT(OR(EXACT(F2,"no"),EXACT(F2,"primary_done")))),"CHECK COMPLETE",IF(EXACT(F2,"primary_done"),"PRIMARY READY","PRIMARY DRAFT")))))),"CHECK INPUT / KEY") | H2: confirmed_issue | I2: substantive | J2: possible | K2: =IF(AND(OR(D2="retain",D2=""),OR(E2="report_internal_inconsistency",E2="plan_material")),"","not_applicable") | L2: =IF(AND(OR(D2="retain",D2=""),E2="protocol_report"),"","not_applicable") | R2: Main p.1 abstract counts quality of life among secondary outcomes with no significant difference and p.6 says no QoL differences citing eTables 2-4, but Supp3 eTable 3 p.4 shows day-7 EQ-5D index MD -0.057 (-0.104 to -0.010), P=.02 (CI-implied P=.017), a SAP-planned day-specific contrast with no multiplicity correction (SAP p.26, p.12). Summary claim contradicts the cited table.
A3: 2025::jama.2024.24764::C002 | B3: Planned hospital-stay differences versus reported geometric ratios | C3: PLAN joi240145supp1_prod_1741627844.87412.pdf — SAP §9.2, PDF p. 15, joi240145supp1_prod_1741627844.87412.pdf — SAP §9.6, PDF p. 25, joi240145supp1_prod_1741627844.87412.pdf — SAP Appendix D7 shell, PDF p. 42; PLAN joi240145supp4_prod_1741627844.90412.pdf — protocol UK definition, PDF p. 24, joi240145supp4_prod_1741627844.90412.pdf — protocol §14.2.2, PDF p. 39; REPORT jama_atherton_2025_oi_240145_1741627844.85412.pdf — main abstract, PDF p. 1, jama_atherton_2025_oi_240145_1741627844.85412.pdf — Statistical Analysis, PDF p. 4, jama_atherton_2025_oi_240145_1741627844.85412.pdf — Secondary Outcomes, PDF p. 6, jama_atherton_2025_oi_240145_1741627844.85412.pdf — Table 3 UK/pooled rows and footnote c, PDF p. 8. | D3: retain | E3: protocol_report | F3: primary_done | G3: =IFERROR(IF(LEN(TRIM(CLEAN(SUBSTITUTE(Setup!$B$2,CHAR(160)," "))))=0,"CHECK REVIEWER ID",IF(OR(A3="",COUNTIF($A$2:$A$6,A3)<>1,LEFT(A3,LEN("2025::jama.2024.24764::"))<>"2025::jama.2024.24764::"),"CHECK KEY",IF(OR(AND(NOT(AND(D3="retain",E3="statistical_results")),H3<>"",NOT(EXACT(H3,"not_applicable"))),AND(NOT(AND(D3="retain",E3="statistical_results")),I3<>"",NOT(EXACT(I3,"not_applicable"))),AND(NOT(AND(D3="retain",E3="statistical_results")),J3<>"",NOT(EXACT(J3,"not_applicable"))),AND(NOT(AND(D3="retain",OR(E3="report_internal_inconsistency",E3="plan_material"))),K3<>"",NOT(EXACT(K3,"not_applicable"))),AND(NOT(AND(D3="retain",E3="protocol_report")),L3<>"",NOT(EXACT(L3,"not_applicable")))),"CLEAR INACTIVE VALUES",IF(OR(NOT(OR(EXACT(D3,"retain"),EXACT(D3,"exclude"),EXACT(D3,"discuss"))),NOT(OR(EXACT(E3,"statistical_results"),EXACT(E3,"report_internal_inconsistency"),EXACT(E3,"plan_material"),EXACT(E3,"protocol_report"))),AND(AND(D3="retain",E3="statistical_results"),NOT(OR(EXACT(H3,"confirmed_issue"),EXACT(H3,"probable_issue"),EXACT(H3,"not_issue"),EXACT(H3,"indeterminate")))),AND(AND(D3="retain",E3="statistical_results"),NOT(OR(EXACT(I3,"substantive"),EXACT(I3,"minor_presentation"),EXACT(I3,"indeterminate")))),AND(AND(D3="retain",E3="statistical_results"),J3<>"",NOT(OR(EXACT(J3,"direct"),EXACT(J3,"possible"),EXACT(J3,"unlikely"),EXACT(J3,"unknown")))),AND(AND(D3="retain",OR(E3="report_internal_inconsistency",E3="plan_material")),NOT(OR(EXACT(K3,"substantive_inconsistency"),EXACT(K3,"minor_presentation"),EXACT(K3,"non_inconsistency"),EXACT(K3,"indeterminate")))),AND(AND(D3="retain",E3="protocol_report"),L3<>"",NOT(OR(EXACT(L3,"substantive_difference"),EXACT(L3,"minor_presentation"),EXACT(L3,"version_timing"),EXACT(L3,"non_inconsistency"),EXACT(L3,"indeterminate"))))),"CHECK FIELDS",IF(AND(F3<>"",NOT(OR(EXACT(F3,"no"),EXACT(F3,"primary_done")))),"CHECK COMPLETE",IF(EXACT(F3,"primary_done"),"PRIMARY READY","PRIMARY DRAFT")))))),"CHECK INPUT / KEY") | H3: =IF(AND(OR(D3="retain",D3=""),E3="statistical_results"),"","not_applicable") | I3: =IF(AND(OR(D3="retain",D3=""),E3="statistical_results"),"","not_applicable") | J3: =IF(AND(OR(D3="retain",D3=""),E3="statistical_results"),"","not_applicable") | K3: =IF(AND(OR(D3="retain",D3=""),OR(E3="report_internal_inconsistency",E3="plan_material")),"","not_applicable") | L3: substantive_difference | R3: SAP p.25/p.42 plans UK-only adjusted mean difference for LOS (log transform only as sensitivity, SAP p.15; protocol p.39 allows median difference if skewed); report gives adjusted ratio of geometric means for UK and adds a pooled UK+Australia analysis that is the abstract result (main pp.1, 4, 8). Log transform disclosed (main p.4).
A4: 2025::jama.2024.24764::C003 | B4: Reported predicted-survival exclusion versus supplied eligibility criteria | C4: REPORT jama_atherton_2025_oi_240145_1741627844.85412.pdf — main Eligibility Criteria, PDF p. 2 and jama_atherton_2025_oi_240145_1741627844.85412.pdf — mortality interpretation, PDF p. 10; PLAN joi240145supp4_prod_1741627844.90412.pdf — protocol §§5.1–5.2, PDF p. 17, joi240145supp4_prod_1741627844.90412.pdf — Key Eligibility Criteria summary, PDF p. 8, and joi240145supp4_prod_1741627844.90412.pdf — amendment context, PDF p. 2. | D4: retain | E4: protocol_report | F4: primary_done | G4: =IFERROR(IF(LEN(TRIM(CLEAN(SUBSTITUTE(Setup!$B$2,CHAR(160)," "))))=0,"CHECK REVIEWER ID",IF(OR(A4="",COUNTIF($A$2:$A$6,A4)<>1,LEFT(A4,LEN("2025::jama.2024.24764::"))<>"2025::jama.2024.24764::"),"CHECK KEY",IF(OR(AND(NOT(AND(D4="retain",E4="statistical_results")),H4<>"",NOT(EXACT(H4,"not_applicable"))),AND(NOT(AND(D4="retain",E4="statistical_results")),I4<>"",NOT(EXACT(I4,"not_applicable"))),AND(NOT(AND(D4="retain",E4="statistical_results")),J4<>"",NOT(EXACT(J4,"not_applicable"))),AND(NOT(AND(D4="retain",OR(E4="report_internal_inconsistency",E4="plan_material"))),K4<>"",NOT(EXACT(K4,"not_applicable"))),AND(NOT(AND(D4="retain",E4="protocol_report")),L4<>"",NOT(EXACT(L4,"not_applicable")))),"CLEAR INACTIVE VALUES",IF(OR(NOT(OR(EXACT(D4,"retain"),EXACT(D4,"exclude"),EXACT(D4,"discuss"))),NOT(OR(EXACT(E4,"statistical_results"),EXACT(E4,"report_internal_inconsistency"),EXACT(E4,"plan_material"),EXACT(E4,"protocol_report"))),AND(AND(D4="retain",E4="statistical_results"),NOT(OR(EXACT(H4,"confirmed_issue"),EXACT(H4,"probable_issue"),EXACT(H4,"not_issue"),EXACT(H4,"indeterminate")))),AND(AND(D4="retain",E4="statistical_results"),NOT(OR(EXACT(I4,"substantive"),EXACT(I4,"minor_presentation"),EXACT(I4,"indeterminate")))),AND(AND(D4="retain",E4="statistical_results"),J4<>"",NOT(OR(EXACT(J4,"direct"),EXACT(J4,"possible"),EXACT(J4,"unlikely"),EXACT(J4,"unknown")))),AND(AND(D4="retain",OR(E4="report_internal_inconsistency",E4="plan_material")),NOT(OR(EXACT(K4,"substantive_inconsistency"),EXACT(K4,"minor_presentation"),EXACT(K4,"non_inconsistency"),EXACT(K4,"indeterminate")))),AND(AND(D4="retain",E4="protocol_report"),L4<>"",NOT(OR(EXACT(L4,"substantive_difference"),EXACT(L4,"minor_presentation"),EXACT(L4,"version_timing"),EXACT(L4,"non_inconsistency"),EXACT(L4,"indeterminate"))))),"CHECK FIELDS",IF(AND(F4<>"",NOT(OR(EXACT(F4,"no"),EXACT(F4,"primary_done")))),"CHECK COMPLETE",IF(EXACT(F4,"primary_done"),"PRIMARY READY","PRIMARY DRAFT")))))),"CHECK INPUT / KEY") | H4: =IF(AND(OR(D4="retain",D4=""),E4="statistical_results"),"","not_applicable") | I4: =IF(AND(OR(D4="retain",D4=""),E4="statistical_results"),"","not_applicable") | J4: =IF(AND(OR(D4="retain",D4=""),E4="statistical_results"),"","not_applicable") | K4: =IF(AND(OR(D4="retain",D4=""),OR(E4="report_internal_inconsistency",E4="plan_material")),"","not_applicable") | L4: substantive_difference | R4: Main p.2 lists 'not expected to survive beyond 30 days' as an exclusion and p.10 invokes it; protocol v4.0 §5.1-5.2 (p.17) and summary (p.8) list only two exclusions (recent abdominal surgery, expected reopening). Table 1 also shows 7 ASA V participants, at odds with the p.10 statement.
A5: 2025::jama.2024.24764::C004 | B5: Unstructured versus independent quality-of-life covariance | C5: PLAN joi240145supp1_prod_1741627844.87412.pdf — SAP §9.6 SF-12 and EQ-5D paragraphs, PDF p. 26; REPORT jama_atherton_2025_oi_240145_1741627844.85412.pdf — main Statistical Analysis, PDF p. 4; affected REPORT jama_atherton_2025_oi_240145_1741627844.85412.pdf — main Table 3 day-30 SF-12 rows, PDF p. 8, joi240145supp3_prod_1741627844.89412.pdf — results eTable 2, all PCS/MCS rows and interactions, PDF p. 3, joi240145supp3_prod_1741627844.89412.pdf — results eTable 3 index rows/interaction, PDF p. 4, and joi240145supp3_prod_1741627844.89412.pdf — results eTable 4 health rows/interaction, PDF p. 4. | D5: retain | E5: protocol_report | F5: primary_done | G5: =IFERROR(IF(LEN(TRIM(CLEAN(SUBSTITUTE(Setup!$B$2,CHAR(160)," "))))=0,"CHECK REVIEWER ID",IF(OR(A5="",COUNTIF($A$2:$A$6,A5)<>1,LEFT(A5,LEN("2025::jama.2024.24764::"))<>"2025::jama.2024.24764::"),"CHECK KEY",IF(OR(AND(NOT(AND(D5="retain",E5="statistical_results")),H5<>"",NOT(EXACT(H5,"not_applicable"))),AND(NOT(AND(D5="retain",E5="statistical_results")),I5<>"",NOT(EXACT(I5,"not_applicable"))),AND(NOT(AND(D5="retain",E5="statistical_results")),J5<>"",NOT(EXACT(J5,"not_applicable"))),AND(NOT(AND(D5="retain",OR(E5="report_internal_inconsistency",E5="plan_material"))),K5<>"",NOT(EXACT(K5,"not_applicable"))),AND(NOT(AND(D5="retain",E5="protocol_report")),L5<>"",NOT(EXACT(L5,"not_applicable")))),"CLEAR INACTIVE VALUES",IF(OR(NOT(OR(EXACT(D5,"retain"),EXACT(D5,"exclude"),EXACT(D5,"discuss"))),NOT(OR(EXACT(E5,"statistical_results"),EXACT(E5,"report_internal_inconsistency"),EXACT(E5,"plan_material"),EXACT(E5,"protocol_report"))),AND(AND(D5="retain",E5="statistical_results"),NOT(OR(EXACT(H5,"confirmed_issue"),EXACT(H5,"probable_issue"),EXACT(H5,"not_issue"),EXACT(H5,"indeterminate")))),AND(AND(D5="retain",E5="statistical_results"),NOT(OR(EXACT(I5,"substantive"),EXACT(I5,"minor_presentation"),EXACT(I5,"indeterminate")))),AND(AND(D5="retain",E5="statistical_results"),J5<>"",NOT(OR(EXACT(J5,"direct"),EXACT(J5,"possible"),EXACT(J5,"unlikely"),EXACT(J5,"unknown")))),AND(AND(D5="retain",OR(E5="report_internal_inconsistency",E5="plan_material")),NOT(OR(EXACT(K5,"substantive_inconsistency"),EXACT(K5,"minor_presentation"),EXACT(K5,"non_inconsistency"),EXACT(K5,"indeterminate")))),AND(AND(D5="retain",E5="protocol_report"),L5<>"",NOT(OR(EXACT(L5,"substantive_difference"),EXACT(L5,"minor_presentation"),EXACT(L5,"version_timing"),EXACT(L5,"non_inconsistency"),EXACT(L5,"indeterminate"))))),"CHECK FIELDS",IF(AND(F5<>"",NOT(OR(EXACT(F5,"no"),EXACT(F5,"primary_done")))),"CHECK COMPLETE",IF(EXACT(F5,"primary_done"),"PRIMARY READY","PRIMARY DRAFT")))))),"CHECK INPUT / KEY") | H5: =IF(AND(OR(D5="retain",D5=""),E5="statistical_results"),"","not_applicable") | I5: =IF(AND(OR(D5="retain",D5=""),E5="statistical_results"),"","not_applicable") | J5: =IF(AND(OR(D5="retain",D5=""),E5="statistical_results"),"","not_applicable") | K5: =IF(AND(OR(D5="retain",D5=""),OR(E5="report_internal_inconsistency",E5="plan_material")),"","not_applicable") | L5: substantive_difference | R5: SAP §9.6 p.26 specifies unstructured covariance with robust sandwich SEs for SF-12 and EQ-5D repeated-measures models; main p.4 states an independent covariance structure was assumed. Not disclosed as a change.
A6: 2025::jama.2024.24764::C005 | B6: SAP fixed-participant parameterization and adjusted contrasts | C6: PLAN joi240145supp1_prod_1741627844.87412.pdf — SAP §9.6 SF-12 fixed-parameter declaration, PDF p. 26; PLAN joi240145supp1_prod_1741627844.87412.pdf — same paragraph's assessment-time, baseline adjustment and time-specific contrast declarations, PDF p. 26; inherited PLAN joi240145supp1_prod_1741627844.87412.pdf — EQ-5D index/health methods paragraph, PDF p. 26. No REPORT location is a conflicting party. | D6: retain | E6: plan_material | F6: primary_done | G6: =IFERROR(IF(LEN(TRIM(CLEAN(SUBSTITUTE(Setup!$B$2,CHAR(160)," "))))=0,"CHECK REVIEWER ID",IF(OR(A6="",COUNTIF($A$2:$A$6,A6)<>1,LEFT(A6,LEN("2025::jama.2024.24764::"))<>"2025::jama.2024.24764::"),"CHECK KEY",IF(OR(AND(NOT(AND(D6="retain",E6="statistical_results")),H6<>"",NOT(EXACT(H6,"not_applicable"))),AND(NOT(AND(D6="retain",E6="statistical_results")),I6<>"",NOT(EXACT(I6,"not_applicable"))),AND(NOT(AND(D6="retain",E6="statistical_results")),J6<>"",NOT(EXACT(J6,"not_applicable"))),AND(NOT(AND(D6="retain",OR(E6="report_internal_inconsistency",E6="plan_material"))),K6<>"",NOT(EXACT(K6,"not_applicable"))),AND(NOT(AND(D6="retain",E6="protocol_report")),L6<>"",NOT(EXACT(L6,"not_applicable")))),"CLEAR INACTIVE VALUES",IF(OR(NOT(OR(EXACT(D6,"retain"),EXACT(D6,"exclude"),EXACT(D6,"discuss"))),NOT(OR(EXACT(E6,"statistical_results"),EXACT(E6,"report_internal_inconsistency"),EXACT(E6,"plan_material"),EXACT(E6,"protocol_report"))),AND(AND(D6="retain",E6="statistical_results"),NOT(OR(EXACT(H6,"confirmed_issue"),EXACT(H6,"probable_issue"),EXACT(H6,"not_issue"),EXACT(H6,"indeterminate")))),AND(AND(D6="retain",E6="statistical_results"),NOT(OR(EXACT(I6,"substantive"),EXACT(I6,"minor_presentation"),EXACT(I6,"indeterminate")))),AND(AND(D6="retain",E6="statistical_results"),J6<>"",NOT(OR(EXACT(J6,"direct"),EXACT(J6,"possible"),EXACT(J6,"unlikely"),EXACT(J6,"unknown")))),AND(AND(D6="retain",OR(E6="report_internal_inconsistency",E6="plan_material")),NOT(OR(EXACT(K6,"substantive_inconsistency"),EXACT(K6,"minor_presentation"),EXACT(K6,"non_inconsistency"),EXACT(K6,"indeterminate")))),AND(AND(D6="retain",E6="protocol_report"),L6<>"",NOT(OR(EXACT(L6,"substantive_difference"),EXACT(L6,"minor_presentation"),EXACT(L6,"version_timing"),EXACT(L6,"non_inconsistency"),EXACT(L6,"indeterminate"))))),"CHECK FIELDS",IF(AND(F6<>"",NOT(OR(EXACT(F6,"no"),EXACT(F6,"primary_done")))),"CHECK COMPLETE",IF(EXACT(F6,"primary_done"),"PRIMARY READY","PRIMARY DRAFT")))))),"CHECK INPUT / KEY") | H6: =IF(AND(OR(D6="retain",D6=""),E6="statistical_results"),"","not_applicable") | I6: =IF(AND(OR(D6="retain",D6=""),E6="statistical_results"),"","not_applicable") | J6: =IF(AND(OR(D6="retain",D6=""),E6="statistical_results"),"","not_applicable") | K6: minor_presentation | L6: =IF(AND(OR(D6="retain",D6=""),E6="protocol_report"),"","not_applicable") | R6: SAP §9.6 p.26 lists participant as a fixed effect together with treatment group and baseline score; read literally, these are aliased with participant indicators. The repeated-measures/unstructured-covariance wording makes the intended model clear, so I treat it as a wording slip in the plan.

Sheet C_jama.2024.27643
A1: Candidate key | B1: Candidate title | C1: Source location | D1: Disposition | E1: Review domain (AI suggestion; editable) | F1: Complete | G1: Validation hint | H1: Statistical_or_numerical issue | I1: Substantiveness | J1: Downstream impact | K1: Report-internal or planning-material inconsistency | L1: Protocol interpretation | R1: Notes (optional)
A2: 2025::jama.2024.27643::C001 | B2: Muscle-strength outcome status | C2: Physical PDF pages; PLAN/REPORT roles are stated above and within the evidence. joi240158supp1_prod_1742927563.7611.pdf — PDF p. 112; joi240158supp1_prod_1742927563.7611.pdf — PDF p. 184; joi240158supp2_prod_1742927563.7711.pdf — PDF p. 76; joi240158supp2_prod_1742927563.7711.pdf — PDF p. 77; joi240158supp2_prod_1742927563.7711.pdf — PDF p. 78; joi240158supp2_prod_1742927563.7711.pdf — PDF p. 109; joi240158supp2_prod_1742927563.7711.pdf — PDF p. 110; joi240158supp2_prod_1742927563.7711.pdf — PDF p. 111; joi240158supp2_prod_1742927563.7711.pdf — PDF p. 112; jama_berry_2025_oi_240158_1742927563.7361.pdf — PDF p. 3; joi240158supp3_prod_1742927563.7911.pdf — PDF p. 5; joi240158supp3_prod_1742927563.7911.pdf — PDF p. 6; joi240158supp2_prod_1742927563.7711.pdf — PDF p. 104 | D2: retain | E2: protocol_report | F2: primary_done | G2: =IFERROR(IF(LEN(TRIM(CLEAN(SUBSTITUTE(Setup!$B$2,CHAR(160)," "))))=0,"CHECK REVIEWER ID",IF(OR(A2="",COUNTIF($A$2:$A$17,A2)<>1,LEFT(A2,LEN("2025::jama.2024.27643::"))<>"2025::jama.2024.27643::"),"CHECK KEY",IF(OR(AND(NOT(AND(D2="retain",E2="statistical_results")),H2<>"",NOT(EXACT(H2,"not_applicable"))),AND(NOT(AND(D2="retain",E2="statistical_results")),I2<>"",NOT(EXACT(I2,"not_applicable"))),AND(NOT(AND(D2="retain",E2="statistical_results")),J2<>"",NOT(EXACT(J2,"not_applicable"))),AND(NOT(AND(D2="retain",OR(E2="report_internal_inconsistency",E2="plan_material"))),K2<>"",NOT(EXACT(K2,"not_applicable"))),AND(NOT(AND(D2="retain",E2="protocol_report")),L2<>"",NOT(EXACT(L2,"not_applicable")))),"CLEAR INACTIVE VALUES",IF(OR(NOT(OR(EXACT(D2,"retain"),EXACT(D2,"exclude"),EXACT(D2,"discuss"))),NOT(OR(EXACT(E2,"statistical_results"),EXACT(E2,"report_internal_inconsistency"),EXACT(E2,"plan_material"),EXACT(E2,"protocol_report"))),AND(AND(D2="retain",E2="statistical_results"),NOT(OR(EXACT(H2,"confirmed_issue"),EXACT(H2,"probable_issue"),EXACT(H2,"not_issue"),EXACT(H2,"indeterminate")))),AND(AND(D2="retain",E2="statistical_results"),NOT(OR(EXACT(I2,"substantive"),EXACT(I2,"minor_presentation"),EXACT(I2,"indeterminate")))),AND(AND(D2="retain",E2="statistical_results"),J2<>"",NOT(OR(EXACT(J2,"direct"),EXACT(J2,"possible"),EXACT(J2,"unlikely"),EXACT(J2,"unknown")))),AND(AND(D2="retain",OR(E2="report_internal_inconsistency",E2="plan_material")),NOT(OR(EXACT(K2,"substantive_inconsistency"),EXACT(K2,"minor_presentation"),EXACT(K2,"non_inconsistency"),EXACT(K2,"indeterminate")))),AND(AND(D2="retain",E2="protocol_report"),L2<>"",NOT(OR(EXACT(L2,"substantive_difference"),EXACT(L2,"minor_presentation"),EXACT(L2,"version_timing"),EXACT(L2,"non_inconsistency"),EXACT(L2,"indeterminate"))))),"CHECK FIELDS",IF(AND(F2<>"",NOT(OR(EXACT(F2,"no"),EXACT(F2,"primary_done")))),"CHECK COMPLETE",IF(EXACT(F2,"primary_done"),"PRIMARY READY","PRIMARY DRAFT")))))),"CHECK INPUT / KEY") | H2: =IF(AND(OR(D2="retain",D2=""),E2="statistical_results"),"","not_applicable") | I2: =IF(AND(OR(D2="retain",D2=""),E2="statistical_results"),"","not_applicable") | J2: =IF(AND(OR(D2="retain",D2=""),E2="statistical_results"),"","not_applicable") | K2: =IF(AND(OR(D2="retain",D2=""),OR(E2="report_internal_inconsistency",E2="plan_material")),"","not_applicable") | L2: substantive_difference | R2: RSA C v3.0 (Supp1 p.112) and v6.0 (p.184) list change in muscle strength (HHD and grip) as a secondary efficacy endpoint; R-SAP v1.0/v3.0 (Supp2 pp.76-78, 109-112) and the report (main p.3; Supp3 pp.5-6) treat HHD as exploratory. Outcome-status change; report follows the SAP.
A3: 2025::jama.2024.27643::C002 | B3: Plasma NfL prespecification | C3: Physical PDF pages; PLAN/REPORT roles are stated above and within the evidence. jama_berry_2025_oi_240158_1742927563.7361.pdf — PDF p. 3; joi240158supp3_prod_1742927563.7911.pdf — PDF p. 6; joi240158supp3_prod_1742927563.7911.pdf — PDF p. 11; joi240158supp2_prod_1742927563.7711.pdf — PDF p. 110; joi240158supp2_prod_1742927563.7711.pdf — PDF p. 112; joi240158supp2_prod_1742927563.7711.pdf — PDF p. 127; joi240158supp2_prod_1742927563.7711.pdf — PDF p. 114; jama_berry_2025_oi_240158_1742927563.7361.pdf — PDF p. 8; joi240158supp3_prod_1742927563.7911.pdf — PDF p. 17 | D3: retain | E3: protocol_report | F3: primary_done | G3: =IFERROR(IF(LEN(TRIM(CLEAN(SUBSTITUTE(Setup!$B$2,CHAR(160)," "))))=0,"CHECK REVIEWER ID",IF(OR(A3="",COUNTIF($A$2:$A$17,A3)<>1,LEFT(A3,LEN("2025::jama.2024.27643::"))<>"2025::jama.2024.27643::"),"CHECK KEY",IF(OR(AND(NOT(AND(D3="retain",E3="statistical_results")),H3<>"",NOT(EXACT(H3,"not_applicable"))),AND(NOT(AND(D3="retain",E3="statistical_results")),I3<>"",NOT(EXACT(I3,"not_applicable"))),AND(NOT(AND(D3="retain",E3="statistical_results")),J3<>"",NOT(EXACT(J3,"not_applicable"))),AND(NOT(AND(D3="retain",OR(E3="report_internal_inconsistency",E3="plan_material"))),K3<>"",NOT(EXACT(K3,"not_applicable"))),AND(NOT(AND(D3="retain",E3="protocol_report")),L3<>"",NOT(EXACT(L3,"not_applicable")))),"CLEAR INACTIVE VALUES",IF(OR(NOT(OR(EXACT(D3,"retain"),EXACT(D3,"exclude"),EXACT(D3,"discuss"))),NOT(OR(EXACT(E3,"statistical_results"),EXACT(E3,"report_internal_inconsistency"),EXACT(E3,"plan_material"),EXACT(E3,"protocol_report"))),AND(AND(D3="retain",E3="statistical_results"),NOT(OR(EXACT(H3,"confirmed_issue"),EXACT(H3,"probable_issue"),EXACT(H3,"not_issue"),EXACT(H3,"indeterminate")))),AND(AND(D3="retain",E3="statistical_results"),NOT(OR(EXACT(I3,"substantive"),EXACT(I3,"minor_presentation"),EXACT(I3,"indeterminate")))),AND(AND(D3="retain",E3="statistical_results"),J3<>"",NOT(OR(EXACT(J3,"direct"),EXACT(J3,"possible"),EXACT(J3,"unlikely"),EXACT(J3,"unknown")))),AND(AND(D3="retain",OR(E3="report_internal_inconsistency",E3="plan_material")),NOT(OR(EXACT(K3,"substantive_inconsistency"),EXACT(K3,"minor_presentation"),EXACT(K3,"non_inconsistency"),EXACT(K3,"indeterminate")))),AND(AND(D3="retain",E3="protocol_report"),L3<>"",NOT(OR(EXACT(L3,"substantive_difference"),EXACT(L3,"minor_presentation"),EXACT(L3,"version_timing"),EXACT(L3,"non_inconsistency"),EXACT(L3,"indeterminate"))))),"CHECK FIELDS",IF(AND(F3<>"",NOT(OR(EXACT(F3,"no"),EXACT(F3,"primary_done")))),"CHECK COMPLETE",IF(EXACT(F3,"primary_done"),"PRIMARY READY","PRIMARY DRAFT")))))),"CHECK INPUT / KEY") | H3: =IF(AND(OR(D3="retain",D3=""),E3="statistical_results"),"","not_applicable") | I3: =IF(AND(OR(D3="retain",D3=""),E3="statistical_results"),"","not_applicable") | J3: =IF(AND(OR(D3="retain",D3=""),E3="statistical_results"),"","not_applicable") | K3: =IF(AND(OR(D3="retain",D3=""),OR(E3="report_internal_inconsistency",E3="plan_material")),"","not_applicable") | L3: substantive_difference | R3: Main p.3 says plasma NfL was prespecified (regimen-only samples); Supp3 p.6 and p.11 say plasma NfL was added post hoc (PD SAP originally specified UCH-L1 only). R-SAP v3.0 (Supp2 p.110, p.112) names serum and CSF NfL only. 'Prespecified' claim without a supplied plan basis; disclosed as post hoc in the supplement.
A4: 2025::jama.2024.27643::C003 | B4: Unreported named planned primary/key-secondary analyses | C4: Physical PDF pages; PLAN/REPORT roles are stated above and within the evidence. joi240158supp2_prod_1742927563.7711.pdf — PDF p. 116; joi240158supp2_prod_1742927563.7711.pdf — PDF p. 117; jama_berry_2025_oi_240158_1742927563.7361.pdf — PDF p. 4; joi240158supp3_prod_1742927563.7911.pdf — PDF p. 15; joi240158supp3_prod_1742927563.7911.pdf — PDF p. 9; joi240158supp2_prod_1742927563.7711.pdf — PDF p. 119; jama_berry_2025_oi_240158_1742927563.7361.pdf — PDF p. 3; joi240158supp3_prod_1742927563.7911.pdf — PDF p. 10; joi240158supp3_prod_1742927563.7911.pdf — PDF p. 16; joi240158supp3_prod_1742927563.7911.pdf — PDF p. 17; joi240158supp2_prod_1742927563.7711.pdf — PDF p. 125; jama_berry_2025_oi_240158_1742927563.7361.pdf — PDF p. 8; joi240158supp2_prod_1742927563.7711.pdf — PDF p. 113; joi240158supp2_prod_1742927563.7711.pdf — PDF p. 121; jama_berry_2025_oi_240158_1742927563.7361.pdf — PDF p. 7; joi240158supp3_prod_1742927563.7911.pdf — PDF p. 12; joi240158supp2_prod_1742927563.7711.pdf — PDF p. 126; joi240158supp3_prod_1742927563.7911.pdf — PDF p. 13; joi240158supp3_prod_1742927563.7911.pdf — PDF p. 18; joi240158supp3_prod_1742927563.7911.pdf — PDF p. 19; joi240158supp3_prod_1742927563.7911.pdf — PDF p. 20; joi240158supp3_prod_1742927563.7911.pdf — PDF p. 25; joi240158supp3_prod_1742927563.7911.pdf — PDF p. 1 | D4: retain | E4: protocol_report | F4: primary_done | G4: =IFERROR(IF(LEN(TRIM(CLEAN(SUBSTITUTE(Setup!$B$2,CHAR(160)," "))))=0,"CHECK REVIEWER ID",IF(OR(A4="",COUNTIF($A$2:$A$17,A4)<>1,LEFT(A4,LEN("2025::jama.2024.27643::"))<>"2025::jama.2024.27643::"),"CHECK KEY",IF(OR(AND(NOT(AND(D4="retain",E4="statistical_results")),H4<>"",NOT(EXACT(H4,"not_applicable"))),AND(NOT(AND(D4="retain",E4="statistical_results")),I4<>"",NOT(EXACT(I4,"not_applicable"))),AND(NOT(AND(D4="retain",E4="statistical_results")),J4<>"",NOT(EXACT(J4,"not_applicable"))),AND(NOT(AND(D4="retain",OR(E4="report_internal_inconsistency",E4="plan_material"))),K4<>"",NOT(EXACT(K4,"not_applicable"))),AND(NOT(AND(D4="retain",E4="protocol_report")),L4<>"",NOT(EXACT(L4,"not_applicable")))),"CLEAR INACTIVE VALUES",IF(OR(NOT(OR(EXACT(D4,"retain"),EXACT(D4,"exclude"),EXACT(D4,"discuss"))),NOT(OR(EXACT(E4,"statistical_results"),EXACT(E4,"report_internal_inconsistency"),EXACT(E4,"plan_material"),EXACT(E4,"protocol_report"))),AND(AND(D4="retain",E4="statistical_results"),NOT(OR(EXACT(H4,"confirmed_issue"),EXACT(H4,"probable_issue"),EXACT(H4,"not_issue"),EXACT(H4,"indeterminate")))),AND(AND(D4="retain",E4="statistical_results"),NOT(OR(EXACT(I4,"substantive"),EXACT(I4,"minor_presentation"),EXACT(I4,"indeterminate")))),AND(AND(D4="retain",E4="statistical_results"),J4<>"",NOT(OR(EXACT(J4,"direct"),EXACT(J4,"possible"),EXACT(J4,"unlikely"),EXACT(J4,"unknown")))),AND(AND(D4="retain",OR(E4="report_internal_inconsistency",E4="plan_material")),NOT(OR(EXACT(K4,"substantive_inconsistency"),EXACT(K4,"minor_presentation"),EXACT(K4,"non_inconsistency"),EXACT(K4,"indeterminate")))),AND(AND(D4="retain",E4="protocol_report"),L4<>"",NOT(OR(EXACT(L4,"substantive_difference"),EXACT(L4,"minor_presentation"),EXACT(L4,"version_timing"),EXACT(L4,"non_inconsistency"),EXACT(L4,"indeterminate"))))),"CHECK FIELDS",IF(AND(F4<>"",NOT(OR(EXACT(F4,"no"),EXACT(F4,"primary_done")))),"CHECK COMPLETE",IF(EXACT(F4,"primary_done"),"PRIMARY READY","PRIMARY DRAFT")))))),"CHECK INPUT / KEY") | H4: =IF(AND(OR(D4="retain",D4=""),E4="statistical_results"),"","not_applicable") | I4: =IF(AND(OR(D4="retain",D4=""),E4="statistical_results"),"","not_applicable") | J4: =IF(AND(OR(D4="retain",D4=""),E4="statistical_results"),"","not_applicable") | K4: =IF(AND(OR(D4="retain",D4=""),OR(E4="report_internal_inconsistency",E4="plan_material")),"","not_applicable") | L4: substantive_difference | R4: R-SAP v3.0 plans ECM sensitivity and EPP supportive DRR analyses (Supp2 pp.116-117), several joint-rank variants (p.119), placebo-reference multiple imputation (p.125), death-alone survival (p.113, 121) and subgroups incl. early disease state, urate, onset site, clinic site (pp.125-126). None has an output in the main article or Supp3 (searched); Supp3 p.6 says only 'relevant' exploratory analyses are presented.
A5: 2025::jama.2024.27643::C004 | B5: Adjusted planned CAFS versus reported Wilcoxon | C5: Physical PDF pages; PLAN/REPORT roles are stated above and within the evidence. joi240158supp2_prod_1742927563.7711.pdf — PDF p. 118; joi240158supp2_prod_1742927563.7711.pdf — PDF p. 119; jama_berry_2025_oi_240158_1742927563.7361.pdf — PDF p. 3; jama_berry_2025_oi_240158_1742927563.7361.pdf — PDF p. 4; joi240158supp3_prod_1742927563.7911.pdf — PDF p. 9; joi240158supp2_prod_1742927563.7711.pdf — PDF p. 84; joi240158supp2_prod_1742927563.7711.pdf — PDF p. 97 | D5: retain | E5: protocol_report | F5: primary_done | G5: =IFERROR(IF(LEN(TRIM(CLEAN(SUBSTITUTE(Setup!$B$2,CHAR(160)," "))))=0,"CHECK REVIEWER ID",IF(OR(A5="",COUNTIF($A$2:$A$17,A5)<>1,LEFT(A5,LEN("2025::jama.2024.27643::"))<>"2025::jama.2024.27643::"),"CHECK KEY",IF(OR(AND(NOT(AND(D5="retain",E5="statistical_results")),H5<>"",NOT(EXACT(H5,"not_applicable"))),AND(NOT(AND(D5="retain",E5="statistical_results")),I5<>"",NOT(EXACT(I5,"not_applicable"))),AND(NOT(AND(D5="retain",E5="statistical_results")),J5<>"",NOT(EXACT(J5,"not_applicable"))),AND(NOT(AND(D5="retain",OR(E5="report_internal_inconsistency",E5="plan_material"))),K5<>"",NOT(EXACT(K5,"not_applicable"))),AND(NOT(AND(D5="retain",E5="protocol_report")),L5<>"",NOT(EXACT(L5,"not_applicable")))),"CLEAR INACTIVE VALUES",IF(OR(NOT(OR(EXACT(D5,"retain"),EXACT(D5,"exclude"),EXACT(D5,"discuss"))),NOT(OR(EXACT(E5,"statistical_results"),EXACT(E5,"report_internal_inconsistency"),EXACT(E5,"plan_material"),EXACT(E5,"protocol_report"))),AND(AND(D5="retain",E5="statistical_results"),NOT(OR(EXACT(H5,"confirmed_issue"),EXACT(H5,"probable_issue"),EXACT(H5,"not_issue"),EXACT(H5,"indeterminate")))),AND(AND(D5="retain",E5="statistical_results"),NOT(OR(EXACT(I5,"substantive"),EXACT(I5,"minor_presentation"),EXACT(I5,"indeterminate")))),AND(AND(D5="retain",E5="statistical_results"),J5<>"",NOT(OR(EXACT(J5,"direct"),EXACT(J5,"possible"),EXACT(J5,"unlikely"),EXACT(J5,"unknown")))),AND(AND(D5="retain",OR(E5="report_internal_inconsistency",E5="plan_material")),NOT(OR(EXACT(K5,"substantive_inconsistency"),EXACT(K5,"minor_presentation"),EXACT(K5,"non_inconsistency"),EXACT(K5,"indeterminate")))),AND(AND(D5="retain",E5="protocol_report"),L5<>"",NOT(OR(EXACT(L5,"substantive_difference"),EXACT(L5,"minor_presentation"),EXACT(L5,"version_timing"),EXACT(L5,"non_inconsistency"),EXACT(L5,"indeterminate"))))),"CHECK FIELDS",IF(AND(F5<>"",NOT(OR(EXACT(F5,"no"),EXACT(F5,"primary_done")))),"CHECK COMPLETE",IF(EXACT(F5,"primary_done"),"PRIMARY READY","PRIMARY DRAFT")))))),"CHECK INPUT / KEY") | H5: =IF(AND(OR(D5="retain",D5=""),E5="statistical_results"),"","not_applicable") | I5: =IF(AND(OR(D5="retain",D5=""),E5="statistical_results"),"","not_applicable") | J5: =IF(AND(OR(D5="retain",D5=""),E5="statistical_results"),"","not_applicable") | K5: =IF(AND(OR(D5="retain",D5=""),OR(E5="report_internal_inconsistency",E5="plan_material")),"","not_applicable") | L5: version_timing | R5: R-SAP v3.0 (22 Jul 2022; Supp2 pp.117-118, change log p.97) makes the primary CAFS analysis a covariate-adjusted rank regression; the report uses a Wilcoxon rank-sum test (main p.3; P=.51, p.4), which matches R-SAP v1.0 (17 Mar 2022; Supp2 p.84). Which version governed the final analysis is not stated.
A6: 2025::jama.2024.27643::C005 | B6: Planned survival logrank result | C6: Physical PDF pages; PLAN/REPORT roles are stated above and within the evidence. joi240158supp2_prod_1742927563.7711.pdf — PDF p. 117; joi240158supp2_prod_1742927563.7711.pdf — PDF p. 121; joi240158supp2_prod_1742927563.7711.pdf — PDF p. 85; joi240158supp2_prod_1742927563.7711.pdf — PDF p. 86; jama_berry_2025_oi_240158_1742927563.7361.pdf — PDF p. 3; jama_berry_2025_oi_240158_1742927563.7361.pdf — PDF p. 4; jama_berry_2025_oi_240158_1742927563.7361.pdf — PDF p. 7; joi240158supp3_prod_1742927563.7911.pdf — PDF p. 10; joi240158supp2_prod_1742927563.7711.pdf — PDF p. 118 | D6: retain | E6: protocol_report | F6: primary_done | G6: =IFERROR(IF(LEN(TRIM(CLEAN(SUBSTITUTE(Setup!$B$2,CHAR(160)," "))))=0,"CHECK REVIEWER ID",IF(OR(A6="",COUNTIF($A$2:$A$17,A6)<>1,LEFT(A6,LEN("2025::jama.2024.27643::"))<>"2025::jama.2024.27643::"),"CHECK KEY",IF(OR(AND(NOT(AND(D6="retain",E6="statistical_results")),H6<>"",NOT(EXACT(H6,"not_applicable"))),AND(NOT(AND(D6="retain",E6="statistical_results")),I6<>"",NOT(EXACT(I6,"not_applicable"))),AND(NOT(AND(D6="retain",E6="statistical_results")),J6<>"",NOT(EXACT(J6,"not_applicable"))),AND(NOT(AND(D6="retain",OR(E6="report_internal_inconsistency",E6="plan_material"))),K6<>"",NOT(EXACT(K6,"not_applicable"))),AND(NOT(AND(D6="retain",E6="protocol_report")),L6<>"",NOT(EXACT(L6,"not_applicable")))),"CLEAR INACTIVE VALUES",IF(OR(NOT(OR(EXACT(D6,"retain"),EXACT(D6,"exclude"),EXACT(D6,"discuss"))),NOT(OR(EXACT(E6,"statistical_results"),EXACT(E6,"report_internal_inconsistency"),EXACT(E6,"plan_material"),EXACT(E6,"protocol_report"))),AND(AND(D6="retain",E6="statistical_results"),NOT(OR(EXACT(H6,"confirmed_issue"),EXACT(H6,"probable_issue"),EXACT(H6,"not_issue"),EXACT(H6,"indeterminate")))),AND(AND(D6="retain",E6="statistical_results"),NOT(OR(EXACT(I6,"substantive"),EXACT(I6,"minor_presentation"),EXACT(I6,"indeterminate")))),AND(AND(D6="retain",E6="statistical_results"),J6<>"",NOT(OR(EXACT(J6,"direct"),EXACT(J6,"possible"),EXACT(J6,"unlikely"),EXACT(J6,"unknown")))),AND(AND(D6="retain",OR(E6="report_internal_inconsistency",E6="plan_material")),NOT(OR(EXACT(K6,"substantive_inconsistency"),EXACT(K6,"minor_presentation"),EXACT(K6,"non_inconsistency"),EXACT(K6,"indeterminate")))),AND(AND(D6="retain",E6="protocol_report"),L6<>"",NOT(OR(EXACT(L6,"substantive_difference"),EXACT(L6,"minor_presentation"),EXACT(L6,"version_timing"),EXACT(L6,"non_inconsistency"),EXACT(L6,"indeterminate"))))),"CHECK FIELDS",IF(AND(F6<>"",NOT(OR(EXACT(F6,"no"),EXACT(F6,"primary_done")))),"CHECK COMPLETE",IF(EXACT(F6,"primary_done"),"PRIMARY READY","PRIMARY DRAFT")))))),"CHECK INPUT / KEY") | H6: =IF(AND(OR(D6="retain",D6=""),E6="statistical_results"),"","not_applicable") | I6: =IF(AND(OR(D6="retain",D6=""),E6="statistical_results"),"","not_applicable") | J6: =IF(AND(OR(D6="retain",D6=""),E6="statistical_results"),"","not_applicable") | K6: =IF(AND(OR(D6="retain",D6=""),OR(E6="report_internal_inconsistency",E6="plan_material")),"","not_applicable") | L6: substantive_difference | R6: Both R-SAP versions (Supp2 p.86, p.121) make the Kaplan-Meier/log-rank test the primary survival analysis (unadjusted Cox HR only if log-rank significant); the report gives covariate-adjusted Cox HRs and P values (main p.3, p.7 Table 2) and no log-rank result.
A7: 2025::jama.2024.27643::C006 | B7: Survival covariate-set descriptions | C7: Physical PDF pages; PLAN/REPORT roles are stated above and within the evidence. jama_berry_2025_oi_240158_1742927563.7361.pdf — PDF p. 3; joi240158supp3_prod_1742927563.7911.pdf — PDF p. 10; jama_berry_2025_oi_240158_1742927563.7361.pdf — PDF p. 7; joi240158supp3_prod_1742927563.7911.pdf — PDF p. 12; joi240158supp2_prod_1742927563.7711.pdf — PDF p. 121 | D7: retain | E7: statistical_results | F7: primary_done | G7: =IFERROR(IF(LEN(TRIM(CLEAN(SUBSTITUTE(Setup!$B$2,CHAR(160)," "))))=0,"CHECK REVIEWER ID",IF(OR(A7="",COUNTIF($A$2:$A$17,A7)<>1,LEFT(A7,LEN("2025::jama.2024.27643::"))<>"2025::jama.2024.27643::"),"CHECK KEY",IF(OR(AND(NOT(AND(D7="retain",E7="statistical_results")),H7<>"",NOT(EXACT(H7,"not_applicable"))),AND(NOT(AND(D7="retain",E7="statistical_results")),I7<>"",NOT(EXACT(I7,"not_applicable"))),AND(NOT(AND(D7="retain",E7="statistical_results")),J7<>"",NOT(EXACT(J7,"not_applicable"))),AND(NOT(AND(D7="retain",OR(E7="report_internal_inconsistency",E7="plan_material"))),K7<>"",NOT(EXACT(K7,"not_applicable"))),AND(NOT(AND(D7="retain",E7="protocol_report")),L7<>"",NOT(EXACT(L7,"not_applicable")))),"CLEAR INACTIVE VALUES",IF(OR(NOT(OR(EXACT(D7,"retain"),EXACT(D7,"exclude"),EXACT(D7,"discuss"))),NOT(OR(EXACT(E7,"statistical_results"),EXACT(E7,"report_internal_inconsistency"),EXACT(E7,"plan_material"),EXACT(E7,"protocol_report"))),AND(AND(D7="retain",E7="statistical_results"),NOT(OR(EXACT(H7,"confirmed_issue"),EXACT(H7,"probable_issue"),EXACT(H7,"not_issue"),EXACT(H7,"indeterminate")))),AND(AND(D7="retain",E7="statistical_results"),NOT(OR(EXACT(I7,"substantive"),EXACT(I7,"minor_presentation"),EXACT(I7,"indeterminate")))),AND(AND(D7="retain",E7="statistical_results"),J7<>"",NOT(OR(EXACT(J7,"direct"),EXACT(J7,"possible"),EXACT(J7,"unlikely"),EXACT(J7,"unknown")))),AND(AND(D7="retain",OR(E7="report_internal_inconsistency",E7="plan_material")),NOT(OR(EXACT(K7,"substantive_inconsistency"),EXACT(K7,"minor_presentation"),EXACT(K7,"non_inconsistency"),EXACT(K7,"indeterminate")))),AND(AND(D7="retain",E7="protocol_report"),L7<>"",NOT(OR(EXACT(L7,"substantive_difference"),EXACT(L7,"minor_presentation"),EXACT(L7,"version_timing"),EXACT(L7,"non_inconsistency"),EXACT(L7,"indeterminate"))))),"CHECK FIELDS",IF(AND(F7<>"",NOT(OR(EXACT(F7,"no"),EXACT(F7,"primary_done")))),"CHECK COMPLETE",IF(EXACT(F7,"primary_done"),"PRIMARY READY","PRIMARY DRAFT")))))),"CHECK INPUT / KEY") | H7: confirmed_issue | I7: minor_presentation | J7: unlikely | K7: =IF(AND(OR(D7="retain",D7=""),OR(E7="report_internal_inconsistency",E7="plan_material")),"","not_applicable") | L7: =IF(AND(OR(D7="retain",D7=""),E7="protocol_report"),"","not_applicable") | R7: Main p.3 and Supp3 p.10 list Cox covariates as prebaseline slope, months since onset, riluzole, edaravone and age; Table 2 footnote b (main p.7) lists the same plus sex. Same models, two covariate sets; which was fitted is not determinable.
A8: 2025::jama.2024.27643::C007 | B8: Mortality component estimates | C8: Physical PDF pages; PLAN/REPORT roles are stated above and within the evidence. jama_berry_2025_oi_240158_1742927563.7361.pdf — PDF p. 4; joi240158supp3_prod_1742927563.7911.pdf — PDF p. 15 | D8: retain | E8: statistical_results | F8: primary_done | G8: =IFERROR(IF(LEN(TRIM(CLEAN(SUBSTITUTE(Setup!$B$2,CHAR(160)," "))))=0,"CHECK REVIEWER ID",IF(OR(A8="",COUNTIF($A$2:$A$17,A8)<>1,LEFT(A8,LEN("2025::jama.2024.27643::"))<>"2025::jama.2024.27643::"),"CHECK KEY",IF(OR(AND(NOT(AND(D8="retain",E8="statistical_results")),H8<>"",NOT(EXACT(H8,"not_applicable"))),AND(NOT(AND(D8="retain",E8="statistical_results")),I8<>"",NOT(EXACT(I8,"not_applicable"))),AND(NOT(AND(D8="retain",E8="statistical_results")),J8<>"",NOT(EXACT(J8,"not_applicable"))),AND(NOT(AND(D8="retain",OR(E8="report_internal_inconsistency",E8="plan_material"))),K8<>"",NOT(EXACT(K8,"not_applicable"))),AND(NOT(AND(D8="retain",E8="protocol_report")),L8<>"",NOT(EXACT(L8,"not_applicable")))),"CLEAR INACTIVE VALUES",IF(OR(NOT(OR(EXACT(D8,"retain"),EXACT(D8,"exclude"),EXACT(D8,"discuss"))),NOT(OR(EXACT(E8,"statistical_results"),EXACT(E8,"report_internal_inconsistency"),EXACT(E8,"plan_material"),EXACT(E8,"protocol_report"))),AND(AND(D8="retain",E8="statistical_results"),NOT(OR(EXACT(H8,"confirmed_issue"),EXACT(H8,"probable_issue"),EXACT(H8,"not_issue"),EXACT(H8,"indeterminate")))),AND(AND(D8="retain",E8="statistical_results"),NOT(OR(EXACT(I8,"substantive"),EXACT(I8,"minor_presentation"),EXACT(I8,"indeterminate")))),AND(AND(D8="retain",E8="statistical_results"),J8<>"",NOT(OR(EXACT(J8,"direct"),EXACT(J8,"possible"),EXACT(J8,"unlikely"),EXACT(J8,"unknown")))),AND(AND(D8="retain",OR(E8="report_internal_inconsistency",E8="plan_material")),NOT(OR(EXACT(K8,"substantive_inconsistency"),EXACT(K8,"minor_presentation"),EXACT(K8,"non_inconsistency"),EXACT(K8,"indeterminate")))),AND(AND(D8="retain",E8="protocol_report"),L8<>"",NOT(OR(EXACT(L8,"substantive_difference"),EXACT(L8,"minor_presentation"),EXACT(L8,"version_timing"),EXACT(L8,"non_inconsistency"),EXACT(L8,"indeterminate"))))),"CHECK FIELDS",IF(AND(F8<>"",NOT(OR(EXACT(F8,"no"),EXACT(F8,"primary_done")))),"CHECK COMPLETE",IF(EXACT(F8,"primary_done"),"PRIMARY READY","PRIMARY DRAFT")))))),"CHECK INPUT / KEY") | H8: confirmed_issue | I8: substantive | J8: direct | K8: =IF(AND(OR(D8="retain",D8=""),OR(E8="report_internal_inconsistency",E8="plan_material")),"","not_applicable") | L8: =IF(AND(OR(D8="retain",D8=""),E8="protocol_report"),"","not_applicable") | R8: Main p.4 gives model mortality rates 0.007 (shared placebo) and 0.006 (CNM-Au8) events/month citing eTable 2; eTable 2 (Supp3 p.15) gives 0.010 and 0.009 (median and mean). Slope CrIs also differ (main -1.176 to -0.892 and -1.153 to -0.858 vs eTable -1.181 to -0.894 and -1.143 to -0.847).
A9: 2025::jama.2024.27643::C008 | B9: SVC change versus monthly rate | C9: Physical PDF pages; PLAN/REPORT roles are stated above and within the evidence. jama_berry_2025_oi_240158_1742927563.7361.pdf — PDF p. 4; joi240158supp3_prod_1742927563.7911.pdf — PDF p. 16; jama_berry_2025_oi_240158_1742927563.7361.pdf — PDF p. 3; joi240158supp3_prod_1742927563.7911.pdf — PDF p. 10; joi240158supp2_prod_1742927563.7711.pdf — PDF p. 119; joi240158supp2_prod_1742927563.7711.pdf — PDF p. 120; joi240158supp2_prod_1742927563.7711.pdf — PDF p. 121; joi240158supp2_prod_1742927563.7711.pdf — PDF p. 122; joi240158supp2_prod_1742927563.7711.pdf — PDF p. 123 | D9: retain | E9: report_internal_inconsistency | F9: primary_done | G9: =IFERROR(IF(LEN(TRIM(CLEAN(SUBSTITUTE(Setup!$B$2,CHAR(160)," "))))=0,"CHECK REVIEWER ID",IF(OR(A9="",COUNTIF($A$2:$A$17,A9)<>1,LEFT(A9,LEN("2025::jama.2024.27643::"))<>"2025::jama.2024.27643::"),"CHECK KEY",IF(OR(AND(NOT(AND(D9="retain",E9="statistical_results")),H9<>"",NOT(EXACT(H9,"not_applicable"))),AND(NOT(AND(D9="retain",E9="statistical_results")),I9<>"",NOT(EXACT(I9,"not_applicable"))),AND(NOT(AND(D9="retain",E9="statistical_results")),J9<>"",NOT(EXACT(J9,"not_applicable"))),AND(NOT(AND(D9="retain",OR(E9="report_internal_inconsistency",E9="plan_material"))),K9<>"",NOT(EXACT(K9,"not_applicable"))),AND(NOT(AND(D9="retain",E9="protocol_report")),L9<>"",NOT(EXACT(L9,"not_applicable")))),"CLEAR INACTIVE VALUES",IF(OR(NOT(OR(EXACT(D9,"retain"),EXACT(D9,"exclude"),EXACT(D9,"discuss"))),NOT(OR(EXACT(E9,"statistical_results"),EXACT(E9,"report_internal_inconsistency"),EXACT(E9,"plan_material"),EXACT(E9,"protocol_report"))),AND(AND(D9="retain",E9="statistical_results"),NOT(OR(EXACT(H9,"confirmed_issue"),EXACT(H9,"probable_issue"),EXACT(H9,"not_issue"),EXACT(H9,"indeterminate")))),AND(AND(D9="retain",E9="statistical_results"),NOT(OR(EXACT(I9,"substantive"),EXACT(I9,"minor_presentation"),EXACT(I9,"indeterminate")))),AND(AND(D9="retain",E9="statistical_results"),J9<>"",NOT(OR(EXACT(J9,"direct"),EXACT(J9,"possible"),EXACT(J9,"unlikely"),EXACT(J9,"unknown")))),AND(AND(D9="retain",OR(E9="report_internal_inconsistency",E9="plan_material")),NOT(OR(EXACT(K9,"substantive_inconsistency"),EXACT(K9,"minor_presentation"),EXACT(K9,"non_inconsistency"),EXACT(K9,"indeterminate")))),AND(AND(D9="retain",E9="protocol_report"),L9<>"",NOT(OR(EXACT(L9,"substantive_difference"),EXACT(L9,"minor_presentation"),EXACT(L9,"version_timing"),EXACT(L9,"non_inconsistency"),EXACT(L9,"indeterminate"))))),"CHECK FIELDS",IF(AND(F9<>"",NOT(OR(EXACT(F9,"no"),EXACT(F9,"primary_done")))),"CHECK COMPLETE",IF(EXACT(F9,"primary_done"),"PRIMARY READY","PRIMARY DRAFT")))))),"CHECK INPUT / KEY") | H9: =IF(AND(OR(D9="retain",D9=""),E9="statistical_results"),"","not_applicable") | I9: =IF(AND(OR(D9="retain",D9=""),E9="statistical_results"),"","not_applicable") | J9: =IF(AND(OR(D9="retain",D9=""),E9="statistical_results"),"","not_applicable") | K9: substantive_inconsistency | L9: =IF(AND(OR(D9="retain",D9=""),E9="protocol_report"),"","not_applicable") | R9: Main p.4 labels -9.32 vs -8.53 (difference -0.78 [-4.25 to 2.68]) as 'PPN per month', but eTable 3A (Supp3 p.16) labels them 24-week change estimates; the NfL-adjusted 'sensitivity' then gives -1.73 vs -1.55 PPN/month, a different (slope) quantity, yet is said not to change inference.
A10: 2025::jama.2024.27643::C009 | B10: Survival regimen-placebo exclusions and denominator | C10: Physical PDF pages; PLAN/REPORT roles are stated above and within the evidence. jama_berry_2025_oi_240158_1742927563.7361.pdf — PDF p. 4; jama_berry_2025_oi_240158_1742927563.7361.pdf — PDF p. 7 | D10: retain | E10: statistical_results | F10: primary_done | G10: =IFERROR(IF(LEN(TRIM(CLEAN(SUBSTITUTE(Setup!$B$2,CHAR(160)," "))))=0,"CHECK REVIEWER ID",IF(OR(A10="",COUNTIF($A$2:$A$17,A10)<>1,LEFT(A10,LEN("2025::jama.2024.27643::"))<>"2025::jama.2024.27643::"),"CHECK KEY",IF(OR(AND(NOT(AND(D10="retain",E10="statistical_results")),H10<>"",NOT(EXACT(H10,"not_applicable"))),AND(NOT(AND(D10="retain",E10="statistical_results")),I10<>"",NOT(EXACT(I10,"not_applicable"))),AND(NOT(AND(D10="retain",E10="statistical_results")),J10<>"",NOT(EXACT(J10,"not_applicable"))),AND(NOT(AND(D10="retain",OR(E10="report_internal_inconsistency",E10="plan_material"))),K10<>"",NOT(EXACT(K10,"not_applicable"))),AND(NOT(AND(D10="retain",E10="protocol_report")),L10<>"",NOT(EXACT(L10,"not_applicable")))),"CLEAR INACTIVE VALUES",IF(OR(NOT(OR(EXACT(D10,"retain"),EXACT(D10,"exclude"),EXACT(D10,"discuss"))),NOT(OR(EXACT(E10,"statistical_results"),EXACT(E10,"report_internal_inconsistency"),EXACT(E10,"plan_material"),EXACT(E10,"protocol_report"))),AND(AND(D10="retain",E10="statistical_results"),NOT(OR(EXACT(H10,"confirmed_issue"),EXACT(H10,"probable_issue"),EXACT(H10,"not_issue"),EXACT(H10,"indeterminate")))),AND(AND(D10="retain",E10="statistical_results"),NOT(OR(EXACT(I10,"substantive"),EXACT(I10,"minor_presentation"),EXACT(I10,"indeterminate")))),AND(AND(D10="retain",E10="statistical_results"),J10<>"",NOT(OR(EXACT(J10,"direct"),EXACT(J10,"possible"),EXACT(J10,"unlikely"),EXACT(J10,"unknown")))),AND(AND(D10="retain",OR(E10="report_internal_inconsistency",E10="plan_material")),NOT(OR(EXACT(K10,"substantive_inconsistency"),EXACT(K10,"minor_presentation"),EXACT(K10,"non_inconsistency"),EXACT(K10,"indeterminate")))),AND(AND(D10="retain",E10="protocol_report"),L10<>"",NOT(OR(EXACT(L10,"substantive_difference"),EXACT(L10,"minor_presentation"),EXACT(L10,"version_timing"),EXACT(L10,"non_inconsistency"),EXACT(L10,"indeterminate"))))),"CHECK FIELDS",IF(AND(F10<>"",NOT(OR(EXACT(F10,"no"),EXACT(F10,"primary_done")))),"CHECK COMPLETE",IF(EXACT(F10,"primary_done"),"PRIMARY READY","PRIMARY DRAFT")))))),"CHECK INPUT / KEY") | H10: confirmed_issue | I10: minor_presentation | J10: unlikely | K10: =IF(AND(OR(D10="retain",D10=""),OR(E10="report_internal_inconsistency",E10="plan_material")),"","not_applicable") | L10: =IF(AND(OR(D10="retain",D10=""),E10="protocol_report"),"","not_applicable") | R10: Main p.4 says '4 of the 41 participants in the regimen placebo group and 2 in the shared placebo group were excluded' for no follow-up time, but Table 2 (p.7) uses 4/41 as regimen-placebo events and only 2 shared-placebo exclusions (164-2=162). The sentence misattributes the 4 events as exclusions.
A11: 2025::jama.2024.27643::C010 | B11: Prespecified subgroup partitions | C11: Physical PDF pages; PLAN/REPORT roles are stated above and within the evidence. joi240158supp2_prod_1742927563.7711.pdf — PDF p. 89; joi240158supp2_prod_1742927563.7711.pdf — PDF p. 126; joi240158supp3_prod_1742927563.7911.pdf — PDF p. 13; joi240158supp3_prod_1742927563.7911.pdf — PDF p. 20; joi240158supp2_prod_1742927563.7711.pdf — PDF p. 88; joi240158supp3_prod_1742927563.7911.pdf — PDF p. 19; jama_berry_2025_oi_240158_1742927563.7361.pdf — PDF p. 8 | D11: retain | E11: protocol_report | F11: primary_done | G11: =IFERROR(IF(LEN(TRIM(CLEAN(SUBSTITUTE(Setup!$B$2,CHAR(160)," "))))=0,"CHECK REVIEWER ID",IF(OR(A11="",COUNTIF($A$2:$A$17,A11)<>1,LEFT(A11,LEN("2025::jama.2024.27643::"))<>"2025::jama.2024.27643::"),"CHECK KEY",IF(OR(AND(NOT(AND(D11="retain",E11="statistical_results")),H11<>"",NOT(EXACT(H11,"not_applicable"))),AND(NOT(AND(D11="retain",E11="statistical_results")),I11<>"",NOT(EXACT(I11,"not_applicable"))),AND(NOT(AND(D11="retain",E11="statistical_results")),J11<>"",NOT(EXACT(J11,"not_applicable"))),AND(NOT(AND(D11="retain",OR(E11="report_internal_inconsistency",E11="plan_material"))),K11<>"",NOT(EXACT(K11,"not_applicable"))),AND(NOT(AND(D11="retain",E11="protocol_report")),L11<>"",NOT(EXACT(L11,"not_applicable")))),"CLEAR INACTIVE VALUES",IF(OR(NOT(OR(EXACT(D11,"retain"),EXACT(D11,"exclude"),EXACT(D11,"discuss"))),NOT(OR(EXACT(E11,"statistical_results"),EXACT(E11,"report_internal_inconsistency"),EXACT(E11,"plan_material"),EXACT(E11,"protocol_report"))),AND(AND(D11="retain",E11="statistical_results"),NOT(OR(EXACT(H11,"confirmed_issue"),EXACT(H11,"probable_issue"),EXACT(H11,"not_issue"),EXACT(H11,"indeterminate")))),AND(AND(D11="retain",E11="statistical_results"),NOT(OR(EXACT(I11,"substantive"),EXACT(I11,"minor_presentation"),EXACT(I11,"indeterminate")))),AND(AND(D11="retain",E11="statistical_results"),J11<>"",NOT(OR(EXACT(J11,"direct"),EXACT(J11,"possible"),EXACT(J11,"unlikely"),EXACT(J11,"unknown")))),AND(AND(D11="retain",OR(E11="report_internal_inconsistency",E11="plan_material")),NOT(OR(EXACT(K11,"substantive_inconsistency"),EXACT(K11,"minor_presentation"),EXACT(K11,"non_inconsistency"),EXACT(K11,"indeterminate")))),AND(AND(D11="retain",E11="protocol_report"),L11<>"",NOT(OR(EXACT(L11,"substantive_difference"),EXACT(L11,"minor_presentation"),EXACT(L11,"version_timing"),EXACT(L11,"non_inconsistency"),EXACT(L11,"indeterminate"))))),"CHECK FIELDS",IF(AND(F11<>"",NOT(OR(EXACT(F11,"no"),EXACT(F11,"primary_done")))),"CHECK COMPLETE",IF(EXACT(F11,"primary_done"),"PRIMARY READY","PRIMARY DRAFT")))))),"CHECK INPUT / KEY") | H11: =IF(AND(OR(D11="retain",D11=""),E11="statistical_results"),"","not_applicable") | I11: =IF(AND(OR(D11="retain",D11=""),E11="statistical_results"),"","not_applicable") | J11: =IF(AND(OR(D11="retain",D11=""),E11="statistical_results"),"","not_applicable") | K11: =IF(AND(OR(D11="retain",D11=""),OR(E11="report_internal_inconsistency",E11="plan_material")),"","not_applicable") | L11: substantive_difference | R11: R-SAP v1.0/v3.0 subgroups (Supp2 pp.88-89, 125-126): delta-FRS in 3 fixed strata (<0.47, 0.47-<1.11, >=1.11), weight in 5 strata, El Escorial definite+<18 mo vs not both. Report (Supp3 p.13; eTable 4 pp.18-20) calls a dFRS median split prespecified, shows weight <56 kg, and splits 'Definite and <18 mo' vs 'Not definite and <18 mo'.
A12: 2025::jama.2024.27643::C011 | B12: Six-point functional-decline composite inside PLAN | C12: Physical PDF pages; PLAN/REPORT roles are stated above and within the evidence. joi240158supp1_prod_1742927563.7611.pdf — PDF p. 112; joi240158supp1_prod_1742927563.7611.pdf — PDF p. 184; joi240158supp2_prod_1742927563.7711.pdf — PDF p. 78; joi240158supp2_prod_1742927563.7711.pdf — PDF p. 111; joi240158supp2_prod_1742927563.7711.pdf — PDF p. 113; jama_berry_2025_oi_240158_1742927563.7361.pdf — PDF p. 3; joi240158supp2_prod_1742927563.7711.pdf — PDF p. 104 | D12: retain | E12: plan_material | F12: primary_done | G12: =IFERROR(IF(LEN(TRIM(CLEAN(SUBSTITUTE(Setup!$B$2,CHAR(160)," "))))=0,"CHECK REVIEWER ID",IF(OR(A12="",COUNTIF($A$2:$A$17,A12)<>1,LEFT(A12,LEN("2025::jama.2024.27643::"))<>"2025::jama.2024.27643::"),"CHECK KEY",IF(OR(AND(NOT(AND(D12="retain",E12="statistical_results")),H12<>"",NOT(EXACT(H12,"not_applicable"))),AND(NOT(AND(D12="retain",E12="statistical_results")),I12<>"",NOT(EXACT(I12,"not_applicable"))),AND(NOT(AND(D12="retain",E12="statistical_results")),J12<>"",NOT(EXACT(J12,"not_applicable"))),AND(NOT(AND(D12="retain",OR(E12="report_internal_inconsistency",E12="plan_material"))),K12<>"",NOT(EXACT(K12,"not_applicable"))),AND(NOT(AND(D12="retain",E12="protocol_report")),L12<>"",NOT(EXACT(L12,"not_applicable")))),"CLEAR INACTIVE VALUES",IF(OR(NOT(OR(EXACT(D12,"retain"),EXACT(D12,"exclude"),EXACT(D12,"discuss"))),NOT(OR(EXACT(E12,"statistical_results"),EXACT(E12,"report_internal_inconsistency"),EXACT(E12,"plan_material"),EXACT(E12,"protocol_report"))),AND(AND(D12="retain",E12="statistical_results"),NOT(OR(EXACT(H12,"confirmed_issue"),EXACT(H12,"probable_issue"),EXACT(H12,"not_issue"),EXACT(H12,"indeterminate")))),AND(AND(D12="retain",E12="statistical_results"),NOT(OR(EXACT(I12,"substantive"),EXACT(I12,"minor_presentation"),EXACT(I12,"indeterminate")))),AND(AND(D12="retain",E12="statistical_results"),J12<>"",NOT(OR(EXACT(J12,"direct"),EXACT(J12,"possible"),EXACT(J12,"unlikely"),EXACT(J12,"unknown")))),AND(AND(D12="retain",OR(E12="report_internal_inconsistency",E12="plan_material")),NOT(OR(EXACT(K12,"substantive_inconsistency"),EXACT(K12,"minor_presentation"),EXACT(K12,"non_inconsistency"),EXACT(K12,"indeterminate")))),AND(AND(D12="retain",E12="protocol_report"),L12<>"",NOT(OR(EXACT(L12,"substantive_difference"),EXACT(L12,"minor_presentation"),EXACT(L12,"version_timing"),EXACT(L12,"non_inconsistency"),EXACT(L12,"indeterminate"))))),"CHECK FIELDS",IF(AND(F12<>"",NOT(OR(EXACT(F12,"no"),EXACT(F12,"primary_done")))),"CHECK COMPLETE",IF(EXACT(F12,"primary_done"),"PRIMARY READY","PRIMARY DRAFT")))))),"CHECK INPUT / KEY") | H12: =IF(AND(OR(D12="retain",D12=""),E12="statistical_results"),"","not_applicable") | I12: =IF(AND(OR(D12="retain",D12=""),E12="statistical_results"),"","not_applicable") | J12: =IF(AND(OR(D12="retain",D12=""),E12="statistical_results"),"","not_applicable") | K12: substantive_inconsistency | L12: =IF(AND(OR(D12="retain",D12=""),E12="protocol_report"),"","not_applicable") | R12: RSA C v3.0/v6.0 (Supp1 pp.112, 184) defines the exploratory end point as the difference in the proportion with a >=6-point ALSFRS-R decline at week 24; both R-SAPs (Supp2 p.78, p.111) define time to first >=6-point decline or death/death equivalent (composite, censored). Different end point type within the plan; the report follows the SAP (main p.3).
