Workbook

Sheet Setup
A1: Field | B1: Value
A2: Reviewer ID / name | B2: BulunTe
A3: Full name (optional)
A4: Reviewer role | B4: R_B
A5: Year | B5: 2024

Sheet Checks
A1: Check | B1: Result
A2: Candidates | B2: 91
A3: Primary ready | B3: =COUNTIF('C_jama.2024.0318'!$G$2:$G$7,"PRIMARY READY")+COUNTIF('C_jama.2024.0572'!$G$2:$G$3,"PRIMARY READY")+COUNTIF('C_jama.2024.11057'!$G$2:$G$4,"PRIMARY READY")+COUNTIF('C_jama.2024.12829'!$G$2:$G$18,"PRIMARY READY")+COUNTIF('C_jama.2024.19585'!$G$2:$G$4,"PRIMARY READY")+COUNTIF('C_jama.2024.2302'!$G$2:$G$6,"PRIMARY READY")+COUNTIF('C_jama.2024.23898'!$G$2:$G$8,"PRIMARY READY")+COUNTIF('C_jama.2024.25786'!$G$2:$G$9,"PRIMARY READY")+COUNTIF('C_jama.2024.4183'!$G$2:$G$25,"PRIMARY READY")+COUNTIF('C_jama.2024.6063'!$G$2:$G$17,"PRIMARY READY")
A4: Unfinished | B4: =B2-B3
A5: Discuss / unresolved | B5: =COUNTIF('C_jama.2024.0318'!$D$2:$D$7,"discuss")+COUNTIF('C_jama.2024.0572'!$D$2:$D$3,"discuss")+COUNTIF('C_jama.2024.11057'!$D$2:$D$4,"discuss")+COUNTIF('C_jama.2024.12829'!$D$2:$D$18,"discuss")+COUNTIF('C_jama.2024.19585'!$D$2:$D$4,"discuss")+COUNTIF('C_jama.2024.2302'!$D$2:$D$6,"discuss")+COUNTIF('C_jama.2024.23898'!$D$2:$D$8,"discuss")+COUNTIF('C_jama.2024.25786'!$D$2:$D$9,"discuss")+COUNTIF('C_jama.2024.4183'!$D$2:$D$25,"discuss")+COUNTIF('C_jama.2024.6063'!$D$2:$D$17,"discuss")
A6: Workflow status | B6: =IF(B3=B2,"PRIMARY READY","ACTION NEEDED")
A7: Ready with discuss | B7: =COUNTIFS('C_jama.2024.0318'!$G$2:$G$7,"PRIMARY READY",'C_jama.2024.0318'!$D$2:$D$7,"discuss")+COUNTIFS('C_jama.2024.0572'!$G$2:$G$3,"PRIMARY READY",'C_jama.2024.0572'!$D$2:$D$3,"discuss")+COUNTIFS('C_jama.2024.11057'!$G$2:$G$4,"PRIMARY READY",'C_jama.2024.11057'!$D$2:$D$4,"discuss")+COUNTIFS('C_jama.2024.12829'!$G$2:$G$18,"PRIMARY READY",'C_jama.2024.12829'!$D$2:$D$18,"discuss")+COUNTIFS('C_jama.2024.19585'!$G$2:$G$4,"PRIMARY READY",'C_jama.2024.19585'!$D$2:$D$4,"discuss")+COUNTIFS('C_jama.2024.2302'!$G$2:$G$6,"PRIMARY READY",'C_jama.2024.2302'!$D$2:$D$6,"discuss")+COUNTIFS('C_jama.2024.23898'!$G$2:$G$8,"PRIMARY READY",'C_jama.2024.23898'!$D$2:$D$8,"discuss")+COUNTIFS('C_jama.2024.25786'!$G$2:$G$9,"PRIMARY READY",'C_jama.2024.25786'!$D$2:$D$9,"discuss")+COUNTIFS('C_jama.2024.4183'!$G$2:$G$25,"PRIMARY READY",'C_jama.2024.4183'!$D$2:$D$25,"discuss")+COUNTIFS('C_jama.2024.6063'!$G$2:$G$17,"PRIMARY READY",'C_jama.2024.6063'!$D$2:$D$17,"discuss")
A8: Meaning | B8: PRIMARY READY means independent data entry is complete; discuss remains unresolved.
A9: Next action | B9: Inspect G on the C_ sheets. Save the completed file and deliver it; preserve normal Excel backups.

Sheet Papers
A1: Paper | B1: Review worksheet | C1: Candidates
A2: jama.2024.0318 | B2: C_jama.2024.0318 | C2: 6
A3: jama.2024.0572 | B3: C_jama.2024.0572 | C3: 2
A4: jama.2024.11057 | B4: C_jama.2024.11057 | C4: 3
A5: jama.2024.12829 | B5: C_jama.2024.12829 | C5: 17
A6: jama.2024.19585 | B6: C_jama.2024.19585 | C6: 3
A7: jama.2024.2302 | B7: C_jama.2024.2302 | C7: 5
A8: jama.2024.23898 | B8: C_jama.2024.23898 | C8: 7
A9: jama.2024.25786 | B9: C_jama.2024.25786 | C9: 8
A10: jama.2024.4183 | B10: C_jama.2024.4183 | C10: 24
A11: jama.2024.6063 | B11: C_jama.2024.6063 | C11: 16

Sheet C_jama.2024.0318
A1: Candidate key | B1: Candidate title | C1: Source location | D1: Disposition | E1: Review domain | F1: Complete | G1: Validation hint | H1: Statistcal_or_numerical issue | I1: Substantiveness | J1: Downstream impact | K1: Report-internal or planning-material inconsistency | L1: Protocol interpretation | R1: Notes (optional)
A2: 2024::jama.2024.0318::C001 | B2: Figure 1 allocation branches exceed the displayed available cohort by 10 participants | C2: jama_courcoulas_2024_oi_240004_1721756962.76052.pdf — PDF p. 3, Figure 1 and adjoining Results text. | D2: retain | E2: statistical_results | F2: primary_done | G2: =IFERROR(IF(LEN(TRIM(CLEAN(SUBSTITUTE(Setup!$B$2,CHAR(160)," "))))=0,"ENTER REVIEWER ID",IF(OR(A2="",COUNTIF($A$2:$A$7,A2)<>1,LEFT(A2,LEN("2024::jama.2024.0318::"))<>"2024::jama.2024.0318::"),"CHECK KEY",IF(OR(AND(NOT(AND(D2="retain",E2="statistical_results")),H2<>"",H2<>"not_applicable"),AND(NOT(AND(D2="retain",E2="statistical_results")),I2<>"",I2<>"not_applicable"),AND(NOT(AND(D2="retain",E2="statistical_results")),J2<>"",J2<>"not_applicable"),AND(NOT(AND(D2="retain",OR(E2="report_internal_inconsistency",E2="plan_material"))),K2<>"",K2<>"not_applicable"),AND(NOT(AND(D2="retain",E2="protocol_report")),L2<>"",L2<>"not_applicable")),"CLEAR INACTIVE VALUES",IF(OR(NOT(OR(D2="retain",D2="exclude",D2="discuss")),NOT(OR(E2="statistical_results",E2="report_internal_inconsistency",E2="plan_material",E2="protocol_report")),AND(AND(D2="retain",E2="statistical_results"),NOT(OR(H2="confirmed_issue",H2="probable_issue",H2="not_issue",H2="indeterminate"))),AND(AND(D2="retain",E2="statistical_results"),NOT(OR(I2="substantive",I2="minor_presentation",I2="indeterminate"))),AND(AND(D2="retain",E2="statistical_results"),J2<>"",NOT(OR(J2="direct",J2="possible",J2="unlikely",J2="unknown"))),AND(AND(D2="retain",OR(E2="report_internal_inconsistency",E2="plan_material")),NOT(OR(K2="substantive_inconsistency",K2="minor_presentation",K2="non_inconsistency",K2="indeterminate"))),AND(AND(D2="retain",E2="protocol_report"),L2<>"",NOT(OR(L2="substantive_difference",L2="minor_presentation",L2="version_timing",L2="non_inconsistency",L2="indeterminate")))),"CHECK FIELDS",IF(AND(F2<>"",NOT(OR(F2="no",F2="primary_done"))),"CHECK COMPLETE",IF(F2<>"primary_done","PRIMARY DRAFT","PRIMARY READY")))))),"CHECK KEY / INPUT") | H2: confirmed_issue | I2: substantive | J2: possible | K2: =IF(AND(OR(D2="retain",D2=""),OR(E2="report_internal_inconsistency",E2="plan_material")),"","not_applicable") | L2: =IF(AND(OR(D2="retain",D2=""),E2="protocol_report"),"","not_applicable") | R2: Figure 1: 305 'available and randomized' branches into 193 surgery + 122 medical = 315 (10 more than the parent). 106+49+38=193 internally. Arm-specific counts among the 305 cannot be recovered, so arm-specific enrollment (166/?, 96/?) into the long-term cohort is not determinable. Analysis Ns (166, 96) are unaffected.
A3: 2024::jama.2024.0318::C002 | B3: Supplement eTable 2 mixes year-12 headings with year-7 quantitative footnote definitions | C3: joi240004supp2_prod_1721756962.82552.pdf — PDF p. 15, eTable 2 title, columns, rows, and footnotes a-b; joi240004supp2_prod_1721756962.82552.pdf — PDF p. 16, footnotes c-e; jama_courcoulas_2024_oi_240004_1721756962.76052.pdf — PDF p. 3, Results pointer to eTable 2. | D3: retain | E3: report_internal_inconsistency | F3: primary_done | G3: =IFERROR(IF(LEN(TRIM(CLEAN(SUBSTITUTE(Setup!$B$2,CHAR(160)," "))))=0,"ENTER REVIEWER ID",IF(OR(A3="",COUNTIF($A$2:$A$7,A3)<>1,LEFT(A3,LEN("2024::jama.2024.0318::"))<>"2024::jama.2024.0318::"),"CHECK KEY",IF(OR(AND(NOT(AND(D3="retain",E3="statistical_results")),H3<>"",H3<>"not_applicable"),AND(NOT(AND(D3="retain",E3="statistical_results")),I3<>"",I3<>"not_applicable"),AND(NOT(AND(D3="retain",E3="statistical_results")),J3<>"",J3<>"not_applicable"),AND(NOT(AND(D3="retain",OR(E3="report_internal_inconsistency",E3="plan_material"))),K3<>"",K3<>"not_applicable"),AND(NOT(AND(D3="retain",E3="protocol_report")),L3<>"",L3<>"not_applicable")),"CLEAR INACTIVE VALUES",IF(OR(NOT(OR(D3="retain",D3="exclude",D3="discuss")),NOT(OR(E3="statistical_results",E3="report_internal_inconsistency",E3="plan_material",E3="protocol_report")),AND(AND(D3="retain",E3="statistical_results"),NOT(OR(H3="confirmed_issue",H3="probable_issue",H3="not_issue",H3="indeterminate"))),AND(AND(D3="retain",E3="statistical_results"),NOT(OR(I3="substantive",I3="minor_presentation",I3="indeterminate"))),AND(AND(D3="retain",E3="statistical_results"),J3<>"",NOT(OR(J3="direct",J3="possible",J3="unlikely",J3="unknown"))),AND(AND(D3="retain",OR(E3="report_internal_inconsistency",E3="plan_material")),NOT(OR(K3="substantive_inconsistency",K3="minor_presentation",K3="non_inconsistency",K3="indeterminate"))),AND(AND(D3="retain",E3="protocol_report"),L3<>"",NOT(OR(L3="substantive_difference",L3="minor_presentation",L3="version_timing",L3="non_inconsistency",L3="indeterminate")))),"CHECK FIELDS",IF(AND(F3<>"",NOT(OR(F3="no",F3="primary_done"))),"CHECK COMPLETE",IF(F3<>"primary_done","PRIMARY DRAFT","PRIMARY READY")))))),"CHECK KEY / INPUT") | H3: =IF(AND(OR(D3="retain",D3=""),E3="statistical_results"),"","not_applicable") | I3: =IF(AND(OR(D3="retain",D3=""),E3="statistical_results"),"","not_applicable") | J3: =IF(AND(OR(D3="retain",D3=""),E3="statistical_results"),"","not_applicable") | K3: minor_presentation | L3: =IF(AND(OR(D3="retain",D3=""),E3="protocol_report"),"","not_applicable") | R3: eTable 2 title and columns say year 12 and values differ from main Table 2 (e.g., medical HbA1c 7.9 vs 8.0), but footnotes a-c still define 'year-7 data', '7-year over baseline' ratios and 'odds ratio at year 7'. Looks like carried-over footnotes from Table 2; the year-12 meaning is clear from the title, columns and footnote e.
A4: 2024::jama.2024.0318::C003 | B4: Matched 12-year HbA1c result has incompatible printed P values | C4: jama_courcoulas_2024_oi_240004_1721756962.76052.pdf — PDF p. 1, Abstract Results; jama_courcoulas_2024_oi_240004_1721756962.76052.pdf — PDF p. 3, Results; joi240004supp2_prod_1721756962.82552.pdf — PDF p. 15, eTable 2 HbA1c row. | D4: retain | E4: statistical_results | F4: primary_done | G4: =IFERROR(IF(LEN(TRIM(CLEAN(SUBSTITUTE(Setup!$B$2,CHAR(160)," "))))=0,"ENTER REVIEWER ID",IF(OR(A4="",COUNTIF($A$2:$A$7,A4)<>1,LEFT(A4,LEN("2024::jama.2024.0318::"))<>"2024::jama.2024.0318::"),"CHECK KEY",IF(OR(AND(NOT(AND(D4="retain",E4="statistical_results")),H4<>"",H4<>"not_applicable"),AND(NOT(AND(D4="retain",E4="statistical_results")),I4<>"",I4<>"not_applicable"),AND(NOT(AND(D4="retain",E4="statistical_results")),J4<>"",J4<>"not_applicable"),AND(NOT(AND(D4="retain",OR(E4="report_internal_inconsistency",E4="plan_material"))),K4<>"",K4<>"not_applicable"),AND(NOT(AND(D4="retain",E4="protocol_report")),L4<>"",L4<>"not_applicable")),"CLEAR INACTIVE VALUES",IF(OR(NOT(OR(D4="retain",D4="exclude",D4="discuss")),NOT(OR(E4="statistical_results",E4="report_internal_inconsistency",E4="plan_material",E4="protocol_report")),AND(AND(D4="retain",E4="statistical_results"),NOT(OR(H4="confirmed_issue",H4="probable_issue",H4="not_issue",H4="indeterminate"))),AND(AND(D4="retain",E4="statistical_results"),NOT(OR(I4="substantive",I4="minor_presentation",I4="indeterminate"))),AND(AND(D4="retain",E4="statistical_results"),J4<>"",NOT(OR(J4="direct",J4="possible",J4="unlikely",J4="unknown"))),AND(AND(D4="retain",OR(E4="report_internal_inconsistency",E4="plan_material")),NOT(OR(K4="substantive_inconsistency",K4="minor_presentation",K4="non_inconsistency",K4="indeterminate"))),AND(AND(D4="retain",E4="protocol_report"),L4<>"",NOT(OR(L4="substantive_difference",L4="minor_presentation",L4="version_timing",L4="non_inconsistency",L4="indeterminate")))),"CHECK FIELDS",IF(AND(F4<>"",NOT(OR(F4="no",F4="primary_done"))),"CHECK COMPLETE",IF(F4<>"primary_done","PRIMARY DRAFT","PRIMARY READY")))))),"CHECK KEY / INPUT") | H4: confirmed_issue | I4: minor_presentation | J4: unlikely | K4: =IF(AND(OR(D4="retain",D4=""),OR(E4="report_internal_inconsistency",E4="plan_material")),"","not_applicable") | L4: =IF(AND(OR(D4="retain",D4=""),E4="protocol_report"),"","not_applicable") | R4: Same 12-year HbA1c difference -1.1% (95% CI -1.7 to -0.5) has P=.002 in abstract/Results but P<.001 in eTable 2. Back-calculation from the CI (Wald, SE=1.2/3.92=0.306, z=3.59) gives P about .0003; even the widest CI consistent with rounding gives P <= .0009. The main-text .002 is the value that does not fit. Estimate and CI unchanged.
A5: 2024::jama.2024.0318::C004 | B5: The same year-7 glycemic outcome is labeled as both HbA1c less than or equal to 6.5% and HbA1c below 6.5% | C5: jama_courcoulas_2024_oi_240004_1721756962.76052.pdf — PDF p. 4, Results narrative; jama_courcoulas_2024_oi_240004_1721756962.76052.pdf — PDF p. 6, Table 2; joi240004supp2_prod_1721756962.82552.pdf — PDF p. 4, binary-analysis context. | D5: retain | E5: report_internal_inconsistency | F5: primary_done | G5: =IFERROR(IF(LEN(TRIM(CLEAN(SUBSTITUTE(Setup!$B$2,CHAR(160)," "))))=0,"ENTER REVIEWER ID",IF(OR(A5="",COUNTIF($A$2:$A$7,A5)<>1,LEFT(A5,LEN("2024::jama.2024.0318::"))<>"2024::jama.2024.0318::"),"CHECK KEY",IF(OR(AND(NOT(AND(D5="retain",E5="statistical_results")),H5<>"",H5<>"not_applicable"),AND(NOT(AND(D5="retain",E5="statistical_results")),I5<>"",I5<>"not_applicable"),AND(NOT(AND(D5="retain",E5="statistical_results")),J5<>"",J5<>"not_applicable"),AND(NOT(AND(D5="retain",OR(E5="report_internal_inconsistency",E5="plan_material"))),K5<>"",K5<>"not_applicable"),AND(NOT(AND(D5="retain",E5="protocol_report")),L5<>"",L5<>"not_applicable")),"CLEAR INACTIVE VALUES",IF(OR(NOT(OR(D5="retain",D5="exclude",D5="discuss")),NOT(OR(E5="statistical_results",E5="report_internal_inconsistency",E5="plan_material",E5="protocol_report")),AND(AND(D5="retain",E5="statistical_results"),NOT(OR(H5="confirmed_issue",H5="probable_issue",H5="not_issue",H5="indeterminate"))),AND(AND(D5="retain",E5="statistical_results"),NOT(OR(I5="substantive",I5="minor_presentation",I5="indeterminate"))),AND(AND(D5="retain",E5="statistical_results"),J5<>"",NOT(OR(J5="direct",J5="possible",J5="unlikely",J5="unknown"))),AND(AND(D5="retain",OR(E5="report_internal_inconsistency",E5="plan_material")),NOT(OR(K5="substantive_inconsistency",K5="minor_presentation",K5="non_inconsistency",K5="indeterminate"))),AND(AND(D5="retain",E5="protocol_report"),L5<>"",NOT(OR(L5="substantive_difference",L5="minor_presentation",L5="version_timing",L5="non_inconsistency",L5="indeterminate")))),"CHECK FIELDS",IF(AND(F5<>"",NOT(OR(F5="no",F5="primary_done"))),"CHECK COMPLETE",IF(F5<>"primary_done","PRIMARY DRAFT","PRIMARY READY")))))),"CHECK KEY / INPUT") | H5: =IF(AND(OR(D5="retain",D5=""),E5="statistical_results"),"","not_applicable") | I5: =IF(AND(OR(D5="retain",D5=""),E5="statistical_results"),"","not_applicable") | J5: =IF(AND(OR(D5="retain",D5=""),E5="statistical_results"),"","not_applicable") | K5: minor_presentation | L5: =IF(AND(OR(D5="retain",D5=""),E5="protocol_report"),"","not_applicable") | R5: Results text: 'threshold of HbA1c less than or equal to 6.5% (P=.002; Table 2)'; Table 2 row is 'HbA1c <6.5%' with P=.002. Remission is also defined with <6.5% elsewhere. Same outcome, imprecise operator in prose; meaning clear.
A6: 2024::jama.2024.0318::C005 | B6: Abstract percentage for four deaths does not reconcile with displayed group counts and denominators | C6: jama_courcoulas_2024_oi_240004_1721756962.76052.pdf — PDF p. 1, Abstract Results; jama_courcoulas_2024_oi_240004_1721756962.76052.pdf — PDF p. 3, enrolled groups; jama_courcoulas_2024_oi_240004_1721756962.76052.pdf — PDF p. 7, death narrative; jama_courcoulas_2024_oi_240004_1721756962.76052.pdf — PDF p. 8, Table 3. | D6: retain | E6: statistical_results | F6: primary_done | G6: =IFERROR(IF(LEN(TRIM(CLEAN(SUBSTITUTE(Setup!$B$2,CHAR(160)," "))))=0,"ENTER REVIEWER ID",IF(OR(A6="",COUNTIF($A$2:$A$7,A6)<>1,LEFT(A6,LEN("2024::jama.2024.0318::"))<>"2024::jama.2024.0318::"),"CHECK KEY",IF(OR(AND(NOT(AND(D6="retain",E6="statistical_results")),H6<>"",H6<>"not_applicable"),AND(NOT(AND(D6="retain",E6="statistical_results")),I6<>"",I6<>"not_applicable"),AND(NOT(AND(D6="retain",E6="statistical_results")),J6<>"",J6<>"not_applicable"),AND(NOT(AND(D6="retain",OR(E6="report_internal_inconsistency",E6="plan_material"))),K6<>"",K6<>"not_applicable"),AND(NOT(AND(D6="retain",E6="protocol_report")),L6<>"",L6<>"not_applicable")),"CLEAR INACTIVE VALUES",IF(OR(NOT(OR(D6="retain",D6="exclude",D6="discuss")),NOT(OR(E6="statistical_results",E6="report_internal_inconsistency",E6="plan_material",E6="protocol_report")),AND(AND(D6="retain",E6="statistical_results"),NOT(OR(H6="confirmed_issue",H6="probable_issue",H6="not_issue",H6="indeterminate"))),AND(AND(D6="retain",E6="statistical_results"),NOT(OR(I6="substantive",I6="minor_presentation",I6="indeterminate"))),AND(AND(D6="retain",E6="statistical_results"),J6<>"",NOT(OR(J6="direct",J6="possible",J6="unlikely",J6="unknown"))),AND(AND(D6="retain",OR(E6="report_internal_inconsistency",E6="plan_material")),NOT(OR(K6="substantive_inconsistency",K6="minor_presentation",K6="non_inconsistency",K6="indeterminate"))),AND(AND(D6="retain",E6="protocol_report"),L6<>"",NOT(OR(L6="substantive_difference",L6="minor_presentation",L6="version_timing",L6="non_inconsistency",L6="indeterminate")))),"CHECK FIELDS",IF(AND(F6<>"",NOT(OR(F6="no",F6="primary_done"))),"CHECK COMPLETE",IF(F6<>"primary_done","PRIMARY DRAFT","PRIMARY READY")))))),"CHECK KEY / INPUT") | H6: confirmed_issue | I6: minor_presentation | J6: possible | K6: =IF(AND(OR(D6="retain",D6=""),OR(E6="report_internal_inconsistency",E6="plan_material")),"","not_applicable") | L6: =IF(AND(OR(D6="retain",D6=""),E6="protocol_report"),"","not_applicable") | R6: Abstract: '4 deaths (2.2%), 2 in each group'. With the enrolled cohort (96 + 166 = 262), 4/262 = 1.5%; Table 3 gives 2/96 (2.1%) and 2/166 (1.2%). No denominator yields 2.2% for 4 deaths in the paper (would need about 182). Counts are clear; the percentage is wrong.
A7: 2024::jama.2024.0318::C006 | B7: The same exploratory BMI subgroup boundary is labeled as both 35 or greater and greater than 35 | C7: jama_courcoulas_2024_oi_240004_1721756962.76052.pdf — PDF p. 7, Results narrative; joi240004supp2_prod_1721756962.82552.pdf — PDF p. 13, eFigure 6 title, legends, and explanatory text. | D7: retain | E7: report_internal_inconsistency | F7: primary_done | G7: =IFERROR(IF(LEN(TRIM(CLEAN(SUBSTITUTE(Setup!$B$2,CHAR(160)," "))))=0,"ENTER REVIEWER ID",IF(OR(A7="",COUNTIF($A$2:$A$7,A7)<>1,LEFT(A7,LEN("2024::jama.2024.0318::"))<>"2024::jama.2024.0318::"),"CHECK KEY",IF(OR(AND(NOT(AND(D7="retain",E7="statistical_results")),H7<>"",H7<>"not_applicable"),AND(NOT(AND(D7="retain",E7="statistical_results")),I7<>"",I7<>"not_applicable"),AND(NOT(AND(D7="retain",E7="statistical_results")),J7<>"",J7<>"not_applicable"),AND(NOT(AND(D7="retain",OR(E7="report_internal_inconsistency",E7="plan_material"))),K7<>"",K7<>"not_applicable"),AND(NOT(AND(D7="retain",E7="protocol_report")),L7<>"",L7<>"not_applicable")),"CLEAR INACTIVE VALUES",IF(OR(NOT(OR(D7="retain",D7="exclude",D7="discuss")),NOT(OR(E7="statistical_results",E7="report_internal_inconsistency",E7="plan_material",E7="protocol_report")),AND(AND(D7="retain",E7="statistical_results"),NOT(OR(H7="confirmed_issue",H7="probable_issue",H7="not_issue",H7="indeterminate"))),AND(AND(D7="retain",E7="statistical_results"),NOT(OR(I7="substantive",I7="minor_presentation",I7="indeterminate"))),AND(AND(D7="retain",E7="statistical_results"),J7<>"",NOT(OR(J7="direct",J7="possible",J7="unlikely",J7="unknown"))),AND(AND(D7="retain",OR(E7="report_internal_inconsistency",E7="plan_material")),NOT(OR(K7="substantive_inconsistency",K7="minor_presentation",K7="non_inconsistency",K7="indeterminate"))),AND(AND(D7="retain",E7="protocol_report"),L7<>"",NOT(OR(L7="substantive_difference",L7="minor_presentation",L7="version_timing",L7="non_inconsistency",L7="indeterminate")))),"CHECK FIELDS",IF(AND(F7<>"",NOT(OR(F7="no",F7="primary_done"))),"CHECK COMPLETE",IF(F7<>"primary_done","PRIMARY DRAFT","PRIMARY READY")))))),"CHECK KEY / INPUT") | H7: =IF(AND(OR(D7="retain",D7=""),E7="statistical_results"),"","not_applicable") | I7: =IF(AND(OR(D7="retain",D7=""),E7="statistical_results"),"","not_applicable") | J7: =IF(AND(OR(D7="retain",D7=""),E7="statistical_results"),"","not_applicable") | K7: minor_presentation | L7: =IF(AND(OR(D7="retain",D7=""),E7="protocol_report"),"","not_applicable") | R7: Main Results: BMI 27 to <35 vs 35 or greater. eFigure 6 title, text and legends: BMI <35 and >35 (leaves BMI exactly 35 unassigned). The figure label is an imprecise operator for the same exploratory subgroup; the main text definition is the complement of <35. Meaning clear.

Sheet C_jama.2024.0572
A1: Candidate key | B1: Candidate title | C1: Source location | D1: Disposition | E1: Review domain | F1: Complete | G1: Validation hint | H1: Statistcal_or_numerical issue | I1: Substantiveness | J1: Downstream impact | K1: Report-internal or planning-material inconsistency | L1: Protocol interpretation | R1: Notes (optional)
A2: 2024::jama.2024.0572::C001 | B2: ITT Figure 2 mRS distributions conflict with ITT eTable 2 threshold counts | C2: Main article Figure 2 — PDF p. 7; Supplement 5 eTable 2 — PDF p. 38; main Results population statement — PDF p. 4; and Supplement 5 eFigure 3 — PDF p. 8. | D2: retain | E2: statistical_results | F2: primary_done | G2: =IFERROR(IF(LEN(TRIM(CLEAN(SUBSTITUTE(Setup!$B$2,CHAR(160)," "))))=0,"ENTER REVIEWER ID",IF(OR(A2="",COUNTIF($A$2:$A$3,A2)<>1,LEFT(A2,LEN("2024::jama.2024.0572::"))<>"2024::jama.2024.0572::"),"CHECK KEY",IF(OR(AND(NOT(AND(D2="retain",E2="statistical_results")),H2<>"",H2<>"not_applicable"),AND(NOT(AND(D2="retain",E2="statistical_results")),I2<>"",I2<>"not_applicable"),AND(NOT(AND(D2="retain",E2="statistical_results")),J2<>"",J2<>"not_applicable"),AND(NOT(AND(D2="retain",OR(E2="report_internal_inconsistency",E2="plan_material"))),K2<>"",K2<>"not_applicable"),AND(NOT(AND(D2="retain",E2="protocol_report")),L2<>"",L2<>"not_applicable")),"CLEAR INACTIVE VALUES",IF(OR(NOT(OR(D2="retain",D2="exclude",D2="discuss")),NOT(OR(E2="statistical_results",E2="report_internal_inconsistency",E2="plan_material",E2="protocol_report")),AND(AND(D2="retain",E2="statistical_results"),NOT(OR(H2="confirmed_issue",H2="probable_issue",H2="not_issue",H2="indeterminate"))),AND(AND(D2="retain",E2="statistical_results"),NOT(OR(I2="substantive",I2="minor_presentation",I2="indeterminate"))),AND(AND(D2="retain",E2="statistical_results"),J2<>"",NOT(OR(J2="direct",J2="possible",J2="unlikely",J2="unknown"))),AND(AND(D2="retain",OR(E2="report_internal_inconsistency",E2="plan_material")),NOT(OR(K2="substantive_inconsistency",K2="minor_presentation",K2="non_inconsistency",K2="indeterminate"))),AND(AND(D2="retain",E2="protocol_report"),L2<>"",NOT(OR(L2="substantive_difference",L2="minor_presentation",L2="version_timing",L2="non_inconsistency",L2="indeterminate")))),"CHECK FIELDS",IF(AND(F2<>"",NOT(OR(F2="no",F2="primary_done"))),"CHECK COMPLETE",IF(F2<>"primary_done","PRIMARY DRAFT","PRIMARY READY")))))),"CHECK KEY / INPUT") | H2: confirmed_issue | I2: substantive | J2: direct | K2: =IF(AND(OR(D2="retain",D2=""),OR(E2="report_internal_inconsistency",E2="plan_material")),"","not_applicable") | L2: =IF(AND(OR(D2="retain",D2=""),E2="protocol_report"),"","not_applicable") | R2: Figure 2 (ITT, n=117+51 EVT, 119+49 MM) percentages each admit exactly one count vector summing to n. Implied mRS 0-2 = 39 EVT / 14 MM and 0-3 = 75 / 39, vs eTable 2 (ITT, 168/168) 34/12 and 65/31. mRS 5-6 (76/102) and deaths (62/70) agree, so the conflict sits in mRS 2-4. Exceeds any rounding.
A3: 2024::jama.2024.0572::C002 | B3: aRR is labeled as an absolute risk reduction but displayed and interpreted as a ratio | C3: Main narrative — PDF p. 6; Main Table 2 — PDF p. 7; Main Table 3 — PDF p. 9; trial SAP — PDF p. 17; secondary-analysis SAP — PDF p. 4; and Supplement 5 eTable 7 — PDF p. 43. | D3: retain | E3: report_internal_inconsistency | F3: primary_done | G3: =IFERROR(IF(LEN(TRIM(CLEAN(SUBSTITUTE(Setup!$B$2,CHAR(160)," "))))=0,"ENTER REVIEWER ID",IF(OR(A3="",COUNTIF($A$2:$A$3,A3)<>1,LEFT(A3,LEN("2024::jama.2024.0572::"))<>"2024::jama.2024.0572::"),"CHECK KEY",IF(OR(AND(NOT(AND(D3="retain",E3="statistical_results")),H3<>"",H3<>"not_applicable"),AND(NOT(AND(D3="retain",E3="statistical_results")),I3<>"",I3<>"not_applicable"),AND(NOT(AND(D3="retain",E3="statistical_results")),J3<>"",J3<>"not_applicable"),AND(NOT(AND(D3="retain",OR(E3="report_internal_inconsistency",E3="plan_material"))),K3<>"",K3<>"not_applicable"),AND(NOT(AND(D3="retain",E3="protocol_report")),L3<>"",L3<>"not_applicable")),"CLEAR INACTIVE VALUES",IF(OR(NOT(OR(D3="retain",D3="exclude",D3="discuss")),NOT(OR(E3="statistical_results",E3="report_internal_inconsistency",E3="plan_material",E3="protocol_report")),AND(AND(D3="retain",E3="statistical_results"),NOT(OR(H3="confirmed_issue",H3="probable_issue",H3="not_issue",H3="indeterminate"))),AND(AND(D3="retain",E3="statistical_results"),NOT(OR(I3="substantive",I3="minor_presentation",I3="indeterminate"))),AND(AND(D3="retain",E3="statistical_results"),J3<>"",NOT(OR(J3="direct",J3="possible",J3="unlikely",J3="unknown"))),AND(AND(D3="retain",OR(E3="report_internal_inconsistency",E3="plan_material")),NOT(OR(K3="substantive_inconsistency",K3="minor_presentation",K3="non_inconsistency",K3="indeterminate"))),AND(AND(D3="retain",E3="protocol_report"),L3<>"",NOT(OR(L3="substantive_difference",L3="minor_presentation",L3="version_timing",L3="non_inconsistency",L3="indeterminate")))),"CHECK FIELDS",IF(AND(F3<>"",NOT(OR(F3="no",F3="primary_done"))),"CHECK COMPLETE",IF(F3<>"primary_done","PRIMARY DRAFT","PRIMARY READY")))))),"CHECK KEY / INPUT") | H3: =IF(AND(OR(D3="retain",D3=""),E3="statistical_results"),"","not_applicable") | I3: =IF(AND(OR(D3="retain",D3=""),E3="statistical_results"),"","not_applicable") | J3: =IF(AND(OR(D3="retain",D3=""),E3="statistical_results"),"","not_applicable") | K3: minor_presentation | L3: =IF(AND(OR(D3="retain",D3=""),E3="protocol_report"),"","not_applicable") | R3: aRR is expanded as 'absolute risk reduction' in the Results text and Table 2/3 abbreviation lists, but values (e.g., 0.89, 1.33 with CI 0.52-3.44) are ratio-scale, footnotes say 'aRR greater than 1 indicates higher rate ratio', aRD is reported separately, and methods/SAP use modified Poisson (risk ratios). Wrong expansion; intended ratio meaning recoverable.

Sheet C_jama.2024.11057
A1: Candidate key | B1: Candidate title | C1: Source location | D1: Disposition | E1: Review domain | F1: Complete | G1: Validation hint | H1: Statistcal_or_numerical issue | I1: Substantiveness | J1: Downstream impact | K1: Report-internal or planning-material inconsistency | L1: Protocol interpretation | R1: Notes (optional)
A2: 2024::jama.2024.11057::C001 | B2: Quit-date pre-message duration conflicts between the main article and both support documents | C2: jama_graham_2024_oi_240078_1739900423.19074.pdf — PDF p. 3; joi240078supp1_prod_1739900423.22574.pdf — PDF p. 2; joi240078supp2_prod_1739900423.24574.pdf — PDF p. 2. | D2: retain | E2: report_internal_inconsistency | F2: primary_done | G2: =IFERROR(IF(LEN(TRIM(CLEAN(SUBSTITUTE(Setup!$B$2,CHAR(160)," "))))=0,"ENTER REVIEWER ID",IF(OR(A2="",COUNTIF($A$2:$A$4,A2)<>1,LEFT(A2,LEN("2024::jama.2024.11057::"))<>"2024::jama.2024.11057::"),"CHECK KEY",IF(OR(AND(NOT(AND(D2="retain",E2="statistical_results")),H2<>"",H2<>"not_applicable"),AND(NOT(AND(D2="retain",E2="statistical_results")),I2<>"",I2<>"not_applicable"),AND(NOT(AND(D2="retain",E2="statistical_results")),J2<>"",J2<>"not_applicable"),AND(NOT(AND(D2="retain",OR(E2="report_internal_inconsistency",E2="plan_material"))),K2<>"",K2<>"not_applicable"),AND(NOT(AND(D2="retain",E2="protocol_report")),L2<>"",L2<>"not_applicable")),"CLEAR INACTIVE VALUES",IF(OR(NOT(OR(D2="retain",D2="exclude",D2="discuss")),NOT(OR(E2="statistical_results",E2="report_internal_inconsistency",E2="plan_material",E2="protocol_report")),AND(AND(D2="retain",E2="statistical_results"),NOT(OR(H2="confirmed_issue",H2="probable_issue",H2="not_issue",H2="indeterminate"))),AND(AND(D2="retain",E2="statistical_results"),NOT(OR(I2="substantive",I2="minor_presentation",I2="indeterminate"))),AND(AND(D2="retain",E2="statistical_results"),J2<>"",NOT(OR(J2="direct",J2="possible",J2="unlikely",J2="unknown"))),AND(AND(D2="retain",OR(E2="report_internal_inconsistency",E2="plan_material")),NOT(OR(K2="substantive_inconsistency",K2="minor_presentation",K2="non_inconsistency",K2="indeterminate"))),AND(AND(D2="retain",E2="protocol_report"),L2<>"",NOT(OR(L2="substantive_difference",L2="minor_presentation",L2="version_timing",L2="non_inconsistency",L2="indeterminate")))),"CHECK FIELDS",IF(AND(F2<>"",NOT(OR(F2="no",F2="primary_done"))),"CHECK COMPLETE",IF(F2<>"primary_done","PRIMARY DRAFT","PRIMARY READY")))))),"CHECK KEY / INPUT") | H2: =IF(AND(OR(D2="retain",D2=""),E2="statistical_results"),"","not_applicable") | I2: =IF(AND(OR(D2="retain",D2=""),E2="statistical_results"),"","not_applicable") | J2: =IF(AND(OR(D2="retain",D2=""),E2="statistical_results"),"","not_applicable") | K2: substantive_inconsistency | L2: =IF(AND(OR(D2="retain",D2=""),E2="protocol_report"),"","not_applicable") | R2: Main Methods: quit-date users receive messages '6 weeks before and 8 weeks after' the quit date. Results supplement eAppendix A (same report) and the protocol both say 1 week before and 8 weeks after. The conflict is inside the current report materials, not only plan vs report. The pre-quit period is a core feature of intervention dose.
A3: 2024::jama.2024.11057::C002 | B3: eTable 4 labels motivation and confidence as median (IQR) but prints single parenthetical dispersion values | C3: joi240078supp2_prod_1739900423.24574.pdf — PDF p. 12, eTable 4; joi240078supp2_prod_1739900423.24574.pdf — PDF p. 13, scale footnote; jama_graham_2024_oi_240078_1739900423.19074.pdf — PDF p. 4, Table 1 comparator. | D3: retain | E3: report_internal_inconsistency | F3: primary_done | G3: =IFERROR(IF(LEN(TRIM(CLEAN(SUBSTITUTE(Setup!$B$2,CHAR(160)," "))))=0,"ENTER REVIEWER ID",IF(OR(A3="",COUNTIF($A$2:$A$4,A3)<>1,LEFT(A3,LEN("2024::jama.2024.11057::"))<>"2024::jama.2024.11057::"),"CHECK KEY",IF(OR(AND(NOT(AND(D3="retain",E3="statistical_results")),H3<>"",H3<>"not_applicable"),AND(NOT(AND(D3="retain",E3="statistical_results")),I3<>"",I3<>"not_applicable"),AND(NOT(AND(D3="retain",E3="statistical_results")),J3<>"",J3<>"not_applicable"),AND(NOT(AND(D3="retain",OR(E3="report_internal_inconsistency",E3="plan_material"))),K3<>"",K3<>"not_applicable"),AND(NOT(AND(D3="retain",E3="protocol_report")),L3<>"",L3<>"not_applicable")),"CLEAR INACTIVE VALUES",IF(OR(NOT(OR(D3="retain",D3="exclude",D3="discuss")),NOT(OR(E3="statistical_results",E3="report_internal_inconsistency",E3="plan_material",E3="protocol_report")),AND(AND(D3="retain",E3="statistical_results"),NOT(OR(H3="confirmed_issue",H3="probable_issue",H3="not_issue",H3="indeterminate"))),AND(AND(D3="retain",E3="statistical_results"),NOT(OR(I3="substantive",I3="minor_presentation",I3="indeterminate"))),AND(AND(D3="retain",E3="statistical_results"),J3<>"",NOT(OR(J3="direct",J3="possible",J3="unlikely",J3="unknown"))),AND(AND(D3="retain",OR(E3="report_internal_inconsistency",E3="plan_material")),NOT(OR(K3="substantive_inconsistency",K3="minor_presentation",K3="non_inconsistency",K3="indeterminate"))),AND(AND(D3="retain",E3="protocol_report"),L3<>"",NOT(OR(L3="substantive_difference",L3="minor_presentation",L3="version_timing",L3="non_inconsistency",L3="indeterminate")))),"CHECK FIELDS",IF(AND(F3<>"",NOT(OR(F3="no",F3="primary_done"))),"CHECK COMPLETE",IF(F3<>"primary_done","PRIMARY DRAFT","PRIMARY READY")))))),"CHECK KEY / INPUT") | H3: =IF(AND(OR(D3="retain",D3=""),E3="statistical_results"),"","not_applicable") | I3: =IF(AND(OR(D3="retain",D3=""),E3="statistical_results"),"","not_applicable") | J3: =IF(AND(OR(D3="retain",D3=""),E3="statistical_results"),"","not_applicable") | K3: minor_presentation | L3: =IF(AND(OR(D3="retain",D3=""),E3="protocol_report"),"","not_applicable") | R3: eTable 4 labels motivation and confidence 'median (IQR)' but prints 4.1 (0.8), 3.2 (1.1), 3.5 (1.1); single-item 1-5 integer scores cannot have median 4.1, so these are almost certainly mean (SD). Concern is labeled median (IQR) with endpoint pairs, the reverse of main Table 1 (motivation/confidence median IQR; concern mean SD). Label swap; values usable.
A4: 2024::jama.2024.11057::C003 | B4: eAppendix C prints IPWR once for a result otherwise defined and labelled as IPRW | C4: joi240078supp2_prod_1739900423.24574.pdf — PDF p. 5, eAppendix C; joi240078supp2_prod_1739900423.24574.pdf — PDF p. 14, eTable 5; jama_graham_2024_oi_240078_1739900423.19074.pdf — PDF p. 4, Statistical Methods. | D4: retain | E4: report_internal_inconsistency | F4: primary_done | G4: =IFERROR(IF(LEN(TRIM(CLEAN(SUBSTITUTE(Setup!$B$2,CHAR(160)," "))))=0,"ENTER REVIEWER ID",IF(OR(A4="",COUNTIF($A$2:$A$4,A4)<>1,LEFT(A4,LEN("2024::jama.2024.11057::"))<>"2024::jama.2024.11057::"),"CHECK KEY",IF(OR(AND(NOT(AND(D4="retain",E4="statistical_results")),H4<>"",H4<>"not_applicable"),AND(NOT(AND(D4="retain",E4="statistical_results")),I4<>"",I4<>"not_applicable"),AND(NOT(AND(D4="retain",E4="statistical_results")),J4<>"",J4<>"not_applicable"),AND(NOT(AND(D4="retain",OR(E4="report_internal_inconsistency",E4="plan_material"))),K4<>"",K4<>"not_applicable"),AND(NOT(AND(D4="retain",E4="protocol_report")),L4<>"",L4<>"not_applicable")),"CLEAR INACTIVE VALUES",IF(OR(NOT(OR(D4="retain",D4="exclude",D4="discuss")),NOT(OR(E4="statistical_results",E4="report_internal_inconsistency",E4="plan_material",E4="protocol_report")),AND(AND(D4="retain",E4="statistical_results"),NOT(OR(H4="confirmed_issue",H4="probable_issue",H4="not_issue",H4="indeterminate"))),AND(AND(D4="retain",E4="statistical_results"),NOT(OR(I4="substantive",I4="minor_presentation",I4="indeterminate"))),AND(AND(D4="retain",E4="statistical_results"),J4<>"",NOT(OR(J4="direct",J4="possible",J4="unlikely",J4="unknown"))),AND(AND(D4="retain",OR(E4="report_internal_inconsistency",E4="plan_material")),NOT(OR(K4="substantive_inconsistency",K4="minor_presentation",K4="non_inconsistency",K4="indeterminate"))),AND(AND(D4="retain",E4="protocol_report"),L4<>"",NOT(OR(L4="substantive_difference",L4="minor_presentation",L4="version_timing",L4="non_inconsistency",L4="indeterminate")))),"CHECK FIELDS",IF(AND(F4<>"",NOT(OR(F4="no",F4="primary_done"))),"CHECK COMPLETE",IF(F4<>"primary_done","PRIMARY DRAFT","PRIMARY READY")))))),"CHECK KEY / INPUT") | H4: =IF(AND(OR(D4="retain",D4=""),E4="statistical_results"),"","not_applicable") | I4: =IF(AND(OR(D4="retain",D4=""),E4="statistical_results"),"","not_applicable") | J4: =IF(AND(OR(D4="retain",D4=""),E4="statistical_results"),"","not_applicable") | K4: minor_presentation | L4: =IF(AND(OR(D4="retain",D4=""),E4="protocol_report"),"","not_applicable") | R4: eAppendix C defines and repeatedly uses IPRW (inverse probability of retention weighting) but writes 'IPWR' once for the repeated-PPA result (RR 2.21, 1.67-2.93); eTable 5 labels the same result IPRW. Typographic transposition; meaning unambiguous.

Sheet C_jama.2024.12829
A1: Candidate key | B1: Candidate title | C1: Source location | D1: Disposition | E1: Review domain | F1: Complete | G1: Validation hint | H1: Statistcal_or_numerical issue | I1: Substantiveness | J1: Downstream impact | K1: Report-internal or planning-material inconsistency | L1: Protocol interpretation | R1: Notes (optional)
A2: 2024::jama.2024.12829::C001 | B2: Balloon-angioplasty female percentage does not reconcile with count and denominator | C2: DOC-001 Table 1, PDF p. 6 | D2: retain | E2: statistical_results | F2: primary_done | G2: =IFERROR(IF(LEN(TRIM(CLEAN(SUBSTITUTE(Setup!$B$2,CHAR(160)," "))))=0,"ENTER REVIEWER ID",IF(OR(A2="",COUNTIF($A$2:$A$18,A2)<>1,LEFT(A2,LEN("2024::jama.2024.12829::"))<>"2024::jama.2024.12829::"),"CHECK KEY",IF(OR(AND(NOT(AND(D2="retain",E2="statistical_results")),H2<>"",H2<>"not_applicable"),AND(NOT(AND(D2="retain",E2="statistical_results")),I2<>"",I2<>"not_applicable"),AND(NOT(AND(D2="retain",E2="statistical_results")),J2<>"",J2<>"not_applicable"),AND(NOT(AND(D2="retain",OR(E2="report_internal_inconsistency",E2="plan_material"))),K2<>"",K2<>"not_applicable"),AND(NOT(AND(D2="retain",E2="protocol_report")),L2<>"",L2<>"not_applicable")),"CLEAR INACTIVE VALUES",IF(OR(NOT(OR(D2="retain",D2="exclude",D2="discuss")),NOT(OR(E2="statistical_results",E2="report_internal_inconsistency",E2="plan_material",E2="protocol_report")),AND(AND(D2="retain",E2="statistical_results"),NOT(OR(H2="confirmed_issue",H2="probable_issue",H2="not_issue",H2="indeterminate"))),AND(AND(D2="retain",E2="statistical_results"),NOT(OR(I2="substantive",I2="minor_presentation",I2="indeterminate"))),AND(AND(D2="retain",E2="statistical_results"),J2<>"",NOT(OR(J2="direct",J2="possible",J2="unlikely",J2="unknown"))),AND(AND(D2="retain",OR(E2="report_internal_inconsistency",E2="plan_material")),NOT(OR(K2="substantive_inconsistency",K2="minor_presentation",K2="non_inconsistency",K2="indeterminate"))),AND(AND(D2="retain",E2="protocol_report"),L2<>"",NOT(OR(L2="substantive_difference",L2="minor_presentation",L2="version_timing",L2="non_inconsistency",L2="indeterminate")))),"CHECK FIELDS",IF(AND(F2<>"",NOT(OR(F2="no",F2="primary_done"))),"CHECK COMPLETE",IF(F2<>"primary_done","PRIMARY DRAFT","PRIMARY READY")))))),"CHECK KEY / INPUT") | H2: confirmed_issue | I2: minor_presentation | J2: unlikely | K2: =IF(AND(OR(D2="retain",D2=""),OR(E2="report_internal_inconsistency",E2="plan_material")),"","not_applicable") | L2: =IF(AND(OR(D2="retain",D2=""),E2="protocol_report"),"","not_applicable") | R2: Table 1 BA female 77 (30.1); 77/249 = 30.9%. Male 172 (69.1) is correct and 172+77=249, so 30.1 looks like a digit transposition of 30.9. Count is correct and unambiguous.
A3: 2024::jama.2024.12829::C002 | B3: Balloon-angioplasty ischemic-stroke percentage is outside ordinary one-decimal rounding | C3: DOC-001 Table 1, PDF p. 6; DOC-002 Table S1, PDF p. 14 | D3: retain | E3: statistical_results | F3: primary_done | G3: =IFERROR(IF(LEN(TRIM(CLEAN(SUBSTITUTE(Setup!$B$2,CHAR(160)," "))))=0,"ENTER REVIEWER ID",IF(OR(A3="",COUNTIF($A$2:$A$18,A3)<>1,LEFT(A3,LEN("2024::jama.2024.12829::"))<>"2024::jama.2024.12829::"),"CHECK KEY",IF(OR(AND(NOT(AND(D3="retain",E3="statistical_results")),H3<>"",H3<>"not_applicable"),AND(NOT(AND(D3="retain",E3="statistical_results")),I3<>"",I3<>"not_applicable"),AND(NOT(AND(D3="retain",E3="statistical_results")),J3<>"",J3<>"not_applicable"),AND(NOT(AND(D3="retain",OR(E3="report_internal_inconsistency",E3="plan_material"))),K3<>"",K3<>"not_applicable"),AND(NOT(AND(D3="retain",E3="protocol_report")),L3<>"",L3<>"not_applicable")),"CLEAR INACTIVE VALUES",IF(OR(NOT(OR(D3="retain",D3="exclude",D3="discuss")),NOT(OR(E3="statistical_results",E3="report_internal_inconsistency",E3="plan_material",E3="protocol_report")),AND(AND(D3="retain",E3="statistical_results"),NOT(OR(H3="confirmed_issue",H3="probable_issue",H3="not_issue",H3="indeterminate"))),AND(AND(D3="retain",E3="statistical_results"),NOT(OR(I3="substantive",I3="minor_presentation",I3="indeterminate"))),AND(AND(D3="retain",E3="statistical_results"),J3<>"",NOT(OR(J3="direct",J3="possible",J3="unlikely",J3="unknown"))),AND(AND(D3="retain",OR(E3="report_internal_inconsistency",E3="plan_material")),NOT(OR(K3="substantive_inconsistency",K3="minor_presentation",K3="non_inconsistency",K3="indeterminate"))),AND(AND(D3="retain",E3="protocol_report"),L3<>"",NOT(OR(L3="substantive_difference",L3="minor_presentation",L3="version_timing",L3="non_inconsistency",L3="indeterminate")))),"CHECK FIELDS",IF(AND(F3<>"",NOT(OR(F3="no",F3="primary_done"))),"CHECK COMPLETE",IF(F3<>"primary_done","PRIMARY DRAFT","PRIMARY READY")))))),"CHECK KEY / INPUT") | H3: confirmed_issue | I3: minor_presentation | J3: unlikely | K3: =IF(AND(OR(D3="retain",D3=""),OR(E3="report_internal_inconsistency",E3="plan_material")),"","not_applicable") | L3: =IF(AND(OR(D3="retain",D3=""),E3="protocol_report"),"","not_applicable") | R3: BA ischemic stroke 215 (86.4) in Table 1 and Table S1; 215/249 = 86.345%, which rounds to 86.3 (complement 34/249 = 13.7 is right, so the pair sums to 100.1). Likely a double-rounding artifact (86.345 -> 86.35 -> 86.4); Table S1 shows the same pattern elsewhere (29/249 = 11.65 printed 11.7). Trivial 0.1-point error.
A4: 2024::jama.2024.12829::C003 | B4: Table S4 procedure rows use 241 while the column header states 249 | C4: DOC-002 Table S4, PDF p. 17 | D4: exclude | E4: statistical_results | F4: primary_done | G4: =IFERROR(IF(LEN(TRIM(CLEAN(SUBSTITUTE(Setup!$B$2,CHAR(160)," "))))=0,"ENTER REVIEWER ID",IF(OR(A4="",COUNTIF($A$2:$A$18,A4)<>1,LEFT(A4,LEN("2024::jama.2024.12829::"))<>"2024::jama.2024.12829::"),"CHECK KEY",IF(OR(AND(NOT(AND(D4="retain",E4="statistical_results")),H4<>"",H4<>"not_applicable"),AND(NOT(AND(D4="retain",E4="statistical_results")),I4<>"",I4<>"not_applicable"),AND(NOT(AND(D4="retain",E4="statistical_results")),J4<>"",J4<>"not_applicable"),AND(NOT(AND(D4="retain",OR(E4="report_internal_inconsistency",E4="plan_material"))),K4<>"",K4<>"not_applicable"),AND(NOT(AND(D4="retain",E4="protocol_report")),L4<>"",L4<>"not_applicable")),"CLEAR INACTIVE VALUES",IF(OR(NOT(OR(D4="retain",D4="exclude",D4="discuss")),NOT(OR(E4="statistical_results",E4="report_internal_inconsistency",E4="plan_material",E4="protocol_report")),AND(AND(D4="retain",E4="statistical_results"),NOT(OR(H4="confirmed_issue",H4="probable_issue",H4="not_issue",H4="indeterminate"))),AND(AND(D4="retain",E4="statistical_results"),NOT(OR(I4="substantive",I4="minor_presentation",I4="indeterminate"))),AND(AND(D4="retain",E4="statistical_results"),J4<>"",NOT(OR(J4="direct",J4="possible",J4="unlikely",J4="unknown"))),AND(AND(D4="retain",OR(E4="report_internal_inconsistency",E4="plan_material")),NOT(OR(K4="substantive_inconsistency",K4="minor_presentation",K4="non_inconsistency",K4="indeterminate"))),AND(AND(D4="retain",E4="protocol_report"),L4<>"",NOT(OR(L4="substantive_difference",L4="minor_presentation",L4="version_timing",L4="non_inconsistency",L4="indeterminate")))),"CHECK FIELDS",IF(AND(F4<>"",NOT(OR(F4="no",F4="primary_done"))),"CHECK COMPLETE",IF(F4<>"primary_done","PRIMARY DRAFT","PRIMARY READY")))))),"CHECK KEY / INPUT") | H4: =IF(AND(OR(D4="retain",D4=""),E4="statistical_results"),"","not_applicable") | I4: =IF(AND(OR(D4="retain",D4=""),E4="statistical_results"),"","not_applicable") | J4: =IF(AND(OR(D4="retain",D4=""),E4="statistical_results"),"","not_applicable") | K4: =IF(AND(OR(D4="retain",D4=""),OR(E4="report_internal_inconsistency",E4="plan_material")),"","not_applicable") | L4: =IF(AND(OR(D4="retain",D4=""),E4="protocol_report"),"","not_applicable") | R4: Not an error. Table S4's header n=249 carries footnote a, which states that 241 of 249 underwent BA (7 crossovers, 1 direct stenting). Procedure rows use 241 (182+48+11 = 241; 182/241 = 75.5%), and restenosis uses the footnoted 153. Denominators are disclosed.
A5: 2024::jama.2024.12829::C004 | B5: Table S6 BA 9 (3.9) conflicts with its displayed denominator 249 | C5: DOC-002 Table S6, PDF p. 19 | D5: retain | E5: statistical_results | F5: primary_done | G5: =IFERROR(IF(LEN(TRIM(CLEAN(SUBSTITUTE(Setup!$B$2,CHAR(160)," "))))=0,"ENTER REVIEWER ID",IF(OR(A5="",COUNTIF($A$2:$A$18,A5)<>1,LEFT(A5,LEN("2024::jama.2024.12829::"))<>"2024::jama.2024.12829::"),"CHECK KEY",IF(OR(AND(NOT(AND(D5="retain",E5="statistical_results")),H5<>"",H5<>"not_applicable"),AND(NOT(AND(D5="retain",E5="statistical_results")),I5<>"",I5<>"not_applicable"),AND(NOT(AND(D5="retain",E5="statistical_results")),J5<>"",J5<>"not_applicable"),AND(NOT(AND(D5="retain",OR(E5="report_internal_inconsistency",E5="plan_material"))),K5<>"",K5<>"not_applicable"),AND(NOT(AND(D5="retain",E5="protocol_report")),L5<>"",L5<>"not_applicable")),"CLEAR INACTIVE VALUES",IF(OR(NOT(OR(D5="retain",D5="exclude",D5="discuss")),NOT(OR(E5="statistical_results",E5="report_internal_inconsistency",E5="plan_material",E5="protocol_report")),AND(AND(D5="retain",E5="statistical_results"),NOT(OR(H5="confirmed_issue",H5="probable_issue",H5="not_issue",H5="indeterminate"))),AND(AND(D5="retain",E5="statistical_results"),NOT(OR(I5="substantive",I5="minor_presentation",I5="indeterminate"))),AND(AND(D5="retain",E5="statistical_results"),J5<>"",NOT(OR(J5="direct",J5="possible",J5="unlikely",J5="unknown"))),AND(AND(D5="retain",OR(E5="report_internal_inconsistency",E5="plan_material")),NOT(OR(K5="substantive_inconsistency",K5="minor_presentation",K5="non_inconsistency",K5="indeterminate"))),AND(AND(D5="retain",E5="protocol_report"),L5<>"",NOT(OR(L5="substantive_difference",L5="minor_presentation",L5="version_timing",L5="non_inconsistency",L5="indeterminate")))),"CHECK FIELDS",IF(AND(F5<>"",NOT(OR(F5="no",F5="primary_done"))),"CHECK COMPLETE",IF(F5<>"primary_done","PRIMARY DRAFT","PRIMARY READY")))))),"CHECK KEY / INPUT") | H5: confirmed_issue | I5: minor_presentation | J5: possible | K5: =IF(AND(OR(D5="retain",D5=""),OR(E5="report_internal_inconsistency",E5="plan_material")),"","not_applicable") | L5: =IF(AND(OR(D5="retain",D5=""),E5="protocol_report"),"","not_applicable") | R5: Table S6 (center-adjusted, header n=249) prints BA 9 (3.9); 9/249 = 3.6%. 9 (3.9) is identical to the per-protocol cell in Table S8 (9/233 = 3.9%), so the row appears copied from the PPS table. Same root error as C016 (count 9 vs 11); this item is the percentage/header facet.
A6: 2024::jama.2024.12829::C005 | B6: Table S7 group headers conflict with site totals and displayed site percentages | C6: DOC-002 Table S7, PDF p. 20; DOC-001 Figure 1, PDF p. 5; DOC-002 Table S10, PDF p. 23 | D6: retain | E6: statistical_results | F6: primary_done | G6: =IFERROR(IF(LEN(TRIM(CLEAN(SUBSTITUTE(Setup!$B$2,CHAR(160)," "))))=0,"ENTER REVIEWER ID",IF(OR(A6="",COUNTIF($A$2:$A$18,A6)<>1,LEFT(A6,LEN("2024::jama.2024.12829::"))<>"2024::jama.2024.12829::"),"CHECK KEY",IF(OR(AND(NOT(AND(D6="retain",E6="statistical_results")),H6<>"",H6<>"not_applicable"),AND(NOT(AND(D6="retain",E6="statistical_results")),I6<>"",I6<>"not_applicable"),AND(NOT(AND(D6="retain",E6="statistical_results")),J6<>"",J6<>"not_applicable"),AND(NOT(AND(D6="retain",OR(E6="report_internal_inconsistency",E6="plan_material"))),K6<>"",K6<>"not_applicable"),AND(NOT(AND(D6="retain",E6="protocol_report")),L6<>"",L6<>"not_applicable")),"CLEAR INACTIVE VALUES",IF(OR(NOT(OR(D6="retain",D6="exclude",D6="discuss")),NOT(OR(E6="statistical_results",E6="report_internal_inconsistency",E6="plan_material",E6="protocol_report")),AND(AND(D6="retain",E6="statistical_results"),NOT(OR(H6="confirmed_issue",H6="probable_issue",H6="not_issue",H6="indeterminate"))),AND(AND(D6="retain",E6="statistical_results"),NOT(OR(I6="substantive",I6="minor_presentation",I6="indeterminate"))),AND(AND(D6="retain",E6="statistical_results"),J6<>"",NOT(OR(J6="direct",J6="possible",J6="unlikely",J6="unknown"))),AND(AND(D6="retain",OR(E6="report_internal_inconsistency",E6="plan_material")),NOT(OR(K6="substantive_inconsistency",K6="minor_presentation",K6="non_inconsistency",K6="indeterminate"))),AND(AND(D6="retain",E6="protocol_report"),L6<>"",NOT(OR(L6="substantive_difference",L6="minor_presentation",L6="version_timing",L6="non_inconsistency",L6="indeterminate")))),"CHECK FIELDS",IF(AND(F6<>"",NOT(OR(F6="no",F6="primary_done"))),"CHECK COMPLETE",IF(F6<>"primary_done","PRIMARY DRAFT","PRIMARY READY")))))),"CHECK KEY / INPUT") | H6: confirmed_issue | I6: minor_presentation | J6: possible | K6: =IF(AND(OR(D6="retain",D6=""),OR(E6="report_internal_inconsistency",E6="plan_material")),"","not_applicable") | L6: =IF(AND(OR(D6="retain",D6=""),E6="protocol_report"),"","not_applicable") | R6: Table S7 headers say BA N=233 / AMM N=238 (the per-protocol sizes), but site totals are 256+245 = 501 and the cell percentages imply ITT denominators: BA 4/138 and 7/111 (= 249), AMM 19/118 and 15/134 (= 252); events 4+7 = 11 and 19+15 = 34 equal the ITT counts. Headers mislabel the analysis population.
A7: 2024::jama.2024.12829::C006 | B7: Table S8 per-protocol percentages conflict with headers 249/252 | C7: DOC-002 Table S8, PDF p. 21; DOC-001 Figure 1, PDF p. 5; DOC-002 Table S10, PDF p. 23 | D7: retain | E7: statistical_results | F7: primary_done | G7: =IFERROR(IF(LEN(TRIM(CLEAN(SUBSTITUTE(Setup!$B$2,CHAR(160)," "))))=0,"ENTER REVIEWER ID",IF(OR(A7="",COUNTIF($A$2:$A$18,A7)<>1,LEFT(A7,LEN("2024::jama.2024.12829::"))<>"2024::jama.2024.12829::"),"CHECK KEY",IF(OR(AND(NOT(AND(D7="retain",E7="statistical_results")),H7<>"",H7<>"not_applicable"),AND(NOT(AND(D7="retain",E7="statistical_results")),I7<>"",I7<>"not_applicable"),AND(NOT(AND(D7="retain",E7="statistical_results")),J7<>"",J7<>"not_applicable"),AND(NOT(AND(D7="retain",OR(E7="report_internal_inconsistency",E7="plan_material"))),K7<>"",K7<>"not_applicable"),AND(NOT(AND(D7="retain",E7="protocol_report")),L7<>"",L7<>"not_applicable")),"CLEAR INACTIVE VALUES",IF(OR(NOT(OR(D7="retain",D7="exclude",D7="discuss")),NOT(OR(E7="statistical_results",E7="report_internal_inconsistency",E7="plan_material",E7="protocol_report")),AND(AND(D7="retain",E7="statistical_results"),NOT(OR(H7="confirmed_issue",H7="probable_issue",H7="not_issue",H7="indeterminate"))),AND(AND(D7="retain",E7="statistical_results"),NOT(OR(I7="substantive",I7="minor_presentation",I7="indeterminate"))),AND(AND(D7="retain",E7="statistical_results"),J7<>"",NOT(OR(J7="direct",J7="possible",J7="unlikely",J7="unknown"))),AND(AND(D7="retain",OR(E7="report_internal_inconsistency",E7="plan_material")),NOT(OR(K7="substantive_inconsistency",K7="minor_presentation",K7="non_inconsistency",K7="indeterminate"))),AND(AND(D7="retain",E7="protocol_report"),L7<>"",NOT(OR(L7="substantive_difference",L7="minor_presentation",L7="version_timing",L7="non_inconsistency",L7="indeterminate")))),"CHECK FIELDS",IF(AND(F7<>"",NOT(OR(F7="no",F7="primary_done"))),"CHECK COMPLETE",IF(F7<>"primary_done","PRIMARY DRAFT","PRIMARY READY")))))),"CHECK KEY / INPUT") | H7: confirmed_issue | I7: minor_presentation | J7: possible | K7: =IF(AND(OR(D7="retain",D7=""),OR(E7="report_internal_inconsistency",E7="plan_material")),"","not_applicable") | L7: =IF(AND(OR(D7="retain",D7=""),E7="protocol_report"),"","not_applicable") | R7: Table S8 is titled per-protocol population but its headers print n=249/252 (ITT sizes). Every percentage reproduces from the PPS denominators 233/238 (9/233 = 3.9, 33/238 = 13.9, 6/233 = 2.6, 20/238 = 8.4), matching Figure 1 and Table S10. Header n is wrong; title identifies the population correctly.
A8: 2024::jama.2024.12829::C007 | B8: Table S9 as-treated percentages conflict with headers 249/252 | C8: DOC-002 Table S9, PDF p. 22; DOC-002 Table S10, PDF p. 23 | D8: retain | E8: statistical_results | F8: primary_done | G8: =IFERROR(IF(LEN(TRIM(CLEAN(SUBSTITUTE(Setup!$B$2,CHAR(160)," "))))=0,"ENTER REVIEWER ID",IF(OR(A8="",COUNTIF($A$2:$A$18,A8)<>1,LEFT(A8,LEN("2024::jama.2024.12829::"))<>"2024::jama.2024.12829::"),"CHECK KEY",IF(OR(AND(NOT(AND(D8="retain",E8="statistical_results")),H8<>"",H8<>"not_applicable"),AND(NOT(AND(D8="retain",E8="statistical_results")),I8<>"",I8<>"not_applicable"),AND(NOT(AND(D8="retain",E8="statistical_results")),J8<>"",J8<>"not_applicable"),AND(NOT(AND(D8="retain",OR(E8="report_internal_inconsistency",E8="plan_material"))),K8<>"",K8<>"not_applicable"),AND(NOT(AND(D8="retain",E8="protocol_report")),L8<>"",L8<>"not_applicable")),"CLEAR INACTIVE VALUES",IF(OR(NOT(OR(D8="retain",D8="exclude",D8="discuss")),NOT(OR(E8="statistical_results",E8="report_internal_inconsistency",E8="plan_material",E8="protocol_report")),AND(AND(D8="retain",E8="statistical_results"),NOT(OR(H8="confirmed_issue",H8="probable_issue",H8="not_issue",H8="indeterminate"))),AND(AND(D8="retain",E8="statistical_results"),NOT(OR(I8="substantive",I8="minor_presentation",I8="indeterminate"))),AND(AND(D8="retain",E8="statistical_results"),J8<>"",NOT(OR(J8="direct",J8="possible",J8="unlikely",J8="unknown"))),AND(AND(D8="retain",OR(E8="report_internal_inconsistency",E8="plan_material")),NOT(OR(K8="substantive_inconsistency",K8="minor_presentation",K8="non_inconsistency",K8="indeterminate"))),AND(AND(D8="retain",E8="protocol_report"),L8<>"",NOT(OR(L8="substantive_difference",L8="minor_presentation",L8="version_timing",L8="non_inconsistency",L8="indeterminate")))),"CHECK FIELDS",IF(AND(F8<>"",NOT(OR(F8="no",F8="primary_done"))),"CHECK COMPLETE",IF(F8<>"primary_done","PRIMARY DRAFT","PRIMARY READY")))))),"CHECK KEY / INPUT") | H8: confirmed_issue | I8: minor_presentation | J8: possible | K8: =IF(AND(OR(D8="retain",D8=""),OR(E8="report_internal_inconsistency",E8="plan_material")),"","not_applicable") | L8: =IF(AND(OR(D8="retain",D8=""),E8="protocol_report"),"","not_applicable") | R8: Table S9 is titled as-treated population but its headers print 249/252; primary-outcome percentages reproduce from the ATS sizes in Table S10 (11/247 = 4.5, 34/254 = 13.4). Header n is wrong; title is right. (The 8 (3.3) cell is a separate error, C014.)
A9: 2024::jama.2024.12829::C008 | B9: Baseline stenosis categories include values outside the stated 70%-99% eligibility range | C9: DOC-001 eligibility, PDF p. 2; DOC-001 Figure 1, PDF p. 5; DOC-001 Table 1, PDF p. 6 | D9: exclude | E9: statistical_results | F9: primary_done | G9: =IFERROR(IF(LEN(TRIM(CLEAN(SUBSTITUTE(Setup!$B$2,CHAR(160)," "))))=0,"ENTER REVIEWER ID",IF(OR(A9="",COUNTIF($A$2:$A$18,A9)<>1,LEFT(A9,LEN("2024::jama.2024.12829::"))<>"2024::jama.2024.12829::"),"CHECK KEY",IF(OR(AND(NOT(AND(D9="retain",E9="statistical_results")),H9<>"",H9<>"not_applicable"),AND(NOT(AND(D9="retain",E9="statistical_results")),I9<>"",I9<>"not_applicable"),AND(NOT(AND(D9="retain",E9="statistical_results")),J9<>"",J9<>"not_applicable"),AND(NOT(AND(D9="retain",OR(E9="report_internal_inconsistency",E9="plan_material"))),K9<>"",K9<>"not_applicable"),AND(NOT(AND(D9="retain",E9="protocol_report")),L9<>"",L9<>"not_applicable")),"CLEAR INACTIVE VALUES",IF(OR(NOT(OR(D9="retain",D9="exclude",D9="discuss")),NOT(OR(E9="statistical_results",E9="report_internal_inconsistency",E9="plan_material",E9="protocol_report")),AND(AND(D9="retain",E9="statistical_results"),NOT(OR(H9="confirmed_issue",H9="probable_issue",H9="not_issue",H9="indeterminate"))),AND(AND(D9="retain",E9="statistical_results"),NOT(OR(I9="substantive",I9="minor_presentation",I9="indeterminate"))),AND(AND(D9="retain",E9="statistical_results"),J9<>"",NOT(OR(J9="direct",J9="possible",J9="unlikely",J9="unknown"))),AND(AND(D9="retain",OR(E9="report_internal_inconsistency",E9="plan_material")),NOT(OR(K9="substantive_inconsistency",K9="minor_presentation",K9="non_inconsistency",K9="indeterminate"))),AND(AND(D9="retain",E9="protocol_report"),L9<>"",NOT(OR(L9="substantive_difference",L9="minor_presentation",L9="version_timing",L9="non_inconsistency",L9="indeterminate")))),"CHECK FIELDS",IF(AND(F9<>"",NOT(OR(F9="no",F9="primary_done"))),"CHECK COMPLETE",IF(F9<>"primary_done","PRIMARY DRAFT","PRIMARY READY")))))),"CHECK KEY / INPUT") | H9: =IF(AND(OR(D9="retain",D9=""),E9="statistical_results"),"","not_applicable") | I9: =IF(AND(OR(D9="retain",D9=""),E9="statistical_results"),"","not_applicable") | J9: =IF(AND(OR(D9="retain",D9=""),E9="statistical_results"),"","not_applicable") | K9: =IF(AND(OR(D9="retain",D9=""),OR(E9="report_internal_inconsistency",E9="plan_material")),"","not_applicable") | L9: =IF(AND(OR(D9="retain",D9=""),E9="protocol_report"),"","not_applicable") | R9: Not a reporting error. Figure 1 discloses that after adjudication 2 AMM patients had angiographic stenosis <70% and 1 patient per arm had target-artery occlusion; these were kept in the primary (randomized) population and removed from the per-protocol set. Table 1's 60-69% (AMM 2) and 100% (1 per arm) match exactly.
A10: 2024::jama.2024.12829::C009 | B10: Thirty-day follow-up tolerance is plus or minus 3 days in the supplement but plus or minus 7 days elsewhere | C10: DOC-002 study-design graphic, PDF p. 6; DOC-001 schedule, PDF p. 3; DOC-003 schedule, PDF p. 15 | D10: retain | E10: report_internal_inconsistency | F10: primary_done | G10: =IFERROR(IF(LEN(TRIM(CLEAN(SUBSTITUTE(Setup!$B$2,CHAR(160)," "))))=0,"ENTER REVIEWER ID",IF(OR(A10="",COUNTIF($A$2:$A$18,A10)<>1,LEFT(A10,LEN("2024::jama.2024.12829::"))<>"2024::jama.2024.12829::"),"CHECK KEY",IF(OR(AND(NOT(AND(D10="retain",E10="statistical_results")),H10<>"",H10<>"not_applicable"),AND(NOT(AND(D10="retain",E10="statistical_results")),I10<>"",I10<>"not_applicable"),AND(NOT(AND(D10="retain",E10="statistical_results")),J10<>"",J10<>"not_applicable"),AND(NOT(AND(D10="retain",OR(E10="report_internal_inconsistency",E10="plan_material"))),K10<>"",K10<>"not_applicable"),AND(NOT(AND(D10="retain",E10="protocol_report")),L10<>"",L10<>"not_applicable")),"CLEAR INACTIVE VALUES",IF(OR(NOT(OR(D10="retain",D10="exclude",D10="discuss")),NOT(OR(E10="statistical_results",E10="report_internal_inconsistency",E10="plan_material",E10="protocol_report")),AND(AND(D10="retain",E10="statistical_results"),NOT(OR(H10="confirmed_issue",H10="probable_issue",H10="not_issue",H10="indeterminate"))),AND(AND(D10="retain",E10="statistical_results"),NOT(OR(I10="substantive",I10="minor_presentation",I10="indeterminate"))),AND(AND(D10="retain",E10="statistical_results"),J10<>"",NOT(OR(J10="direct",J10="possible",J10="unlikely",J10="unknown"))),AND(AND(D10="retain",OR(E10="report_internal_inconsistency",E10="plan_material")),NOT(OR(K10="substantive_inconsistency",K10="minor_presentation",K10="non_inconsistency",K10="indeterminate"))),AND(AND(D10="retain",E10="protocol_report"),L10<>"",NOT(OR(L10="substantive_difference",L10="minor_presentation",L10="version_timing",L10="non_inconsistency",L10="indeterminate")))),"CHECK FIELDS",IF(AND(F10<>"",NOT(OR(F10="no",F10="primary_done"))),"CHECK COMPLETE",IF(F10<>"primary_done","PRIMARY DRAFT","PRIMARY READY")))))),"CHECK KEY / INPUT") | H10: =IF(AND(OR(D10="retain",D10=""),E10="statistical_results"),"","not_applicable") | I10: =IF(AND(OR(D10="retain",D10=""),E10="statistical_results"),"","not_applicable") | J10: =IF(AND(OR(D10="retain",D10=""),E10="statistical_results"),"","not_applicable") | K10: minor_presentation | L10: =IF(AND(OR(D10="retain",D10=""),E10="protocol_report"),"","not_applicable") | R10: Supplement study-design graphic shows the 30-day clinical follow-up as 30±3d; main Methods and all protocol schedules give 30±7 days. The conflict is between two report documents (main vs results supplement); the protocol agrees with the main text. Visit window only; outcome definitions (events within 30 days) are not affected.
