Workbook

Sheet Setup
A1: Field | B1: Value
A2: Reviewer ID or name (required) | B2: BulunTe
A3: Reviewer name (optional)
A4: Reviewer role | B4: R_B
A5: Year | B5: 2019
A6: Schema | B6: xlsx-adjudication-independent-primary-2.3.1
A7: Identity guidance | B7: Enter your own ID or name in B2. Do not enter the role label as your identity. B3 is optional.

Sheet Checks
A1: Check | B1: Result
A2: Reviewer role | B2: =Setup!$B$4
A3: Total candidates | B3: 62
A4: Primary ready | B4: =COUNTIF('C_jama.2019.10517'!$G$2:$G$4,"PRIMARY READY")+COUNTIF('C_jama.2019.12618'!$G$2:$G$9,"PRIMARY READY")+COUNTIF('C_jama.2019.14231'!$G$2:$G$12,"PRIMARY READY")+COUNTIF('C_jama.2019.14630'!$G$2:$G$10,"PRIMARY READY")+COUNTIF('C_jama.2019.14901'!$G$2:$G$7,"PRIMARY READY")+COUNTIF('C_jama.2019.17380'!$G$2:$G$8,"PRIMARY READY")+COUNTIF('C_jama.2019.2210'!$G$2:$G$10,"PRIMARY READY")+COUNTIF('C_jama.2019.4755'!$G$2:$G$6,"PRIMARY READY")+COUNTIF('C_jama.2019.7505'!$G$2:$G$5,"PRIMARY READY")
A5: Unfinished | B5: =B3-B4
A6: Discuss / unresolved | B6: =COUNTIF('C_jama.2019.10517'!$D$2:$D$4,"discuss")+COUNTIF('C_jama.2019.12618'!$D$2:$D$9,"discuss")+COUNTIF('C_jama.2019.14231'!$D$2:$D$12,"discuss")+COUNTIF('C_jama.2019.14630'!$D$2:$D$10,"discuss")+COUNTIF('C_jama.2019.14901'!$D$2:$D$7,"discuss")+COUNTIF('C_jama.2019.17380'!$D$2:$D$8,"discuss")+COUNTIF('C_jama.2019.2210'!$D$2:$D$10,"discuss")+COUNTIF('C_jama.2019.4755'!$D$2:$D$6,"discuss")+COUNTIF('C_jama.2019.7505'!$D$2:$D$5,"discuss")
A7: Workflow status | B7: =IF(B4=B3,"PRIMARY READY","ACTION NEEDED")
A8: Ready discuss rows | B8: =COUNTIFS('C_jama.2019.10517'!$G$2:$G$4,"PRIMARY READY",'C_jama.2019.10517'!$D$2:$D$4,"discuss")+COUNTIFS('C_jama.2019.12618'!$G$2:$G$9,"PRIMARY READY",'C_jama.2019.12618'!$D$2:$D$9,"discuss")+COUNTIFS('C_jama.2019.14231'!$G$2:$G$12,"PRIMARY READY",'C_jama.2019.14231'!$D$2:$D$12,"discuss")+COUNTIFS('C_jama.2019.14630'!$G$2:$G$10,"PRIMARY READY",'C_jama.2019.14630'!$D$2:$D$10,"discuss")+COUNTIFS('C_jama.2019.14901'!$G$2:$G$7,"PRIMARY READY",'C_jama.2019.14901'!$D$2:$D$7,"discuss")+COUNTIFS('C_jama.2019.17380'!$G$2:$G$8,"PRIMARY READY",'C_jama.2019.17380'!$D$2:$D$8,"discuss")+COUNTIFS('C_jama.2019.2210'!$G$2:$G$10,"PRIMARY READY",'C_jama.2019.2210'!$D$2:$D$10,"discuss")+COUNTIFS('C_jama.2019.4755'!$G$2:$G$6,"PRIMARY READY",'C_jama.2019.4755'!$D$2:$D$6,"discuss")+COUNTIFS('C_jama.2019.7505'!$G$2:$G$5,"PRIMARY READY",'C_jama.2019.7505'!$D$2:$D$5,"discuss")
A9: Next action | B9: =IF(B7="PRIMARY READY",IF(B6>0,"Save and deliver this independent review. Discuss rows remain unresolved.","Save and deliver this independent review."),"Inspect G on each C_ sheet, correct entries and manually confirm F.")
A10: Scope | B10: Entry checks and independent completion only. Discuss is not a confirmed absence of error. Review the evidence; preserve ordinary Excel backups.

Sheet Papers
A1: Paper | B1: Review worksheet | C1: Candidates
A2: jama.2019.10517 | B2: C_jama.2019.10517 | C2: 3
A3: jama.2019.12618 | B3: C_jama.2019.12618 | C3: 8
A4: jama.2019.14231 | B4: C_jama.2019.14231 | C4: 11
A5: jama.2019.14630 | B5: C_jama.2019.14630 | C5: 9
A6: jama.2019.14901 | B6: C_jama.2019.14901 | C6: 6
A7: jama.2019.17380 | B7: C_jama.2019.17380 | C7: 7
A8: jama.2019.2210 | B8: C_jama.2019.2210 | C8: 9
A9: jama.2019.4755 | B9: C_jama.2019.4755 | C9: 5
A10: jama.2019.7505 | B10: C_jama.2019.7505 | C10: 4

Sheet C_jama.2019.10517
A1: Candidate key | B1: Candidate title | C1: Source location | D1: Disposition | E1: Review domain (AI suggestion; editable) | F1: Complete | G1: Validation hint | H1: Statistical/numerical issue | I1: Substantiveness | J1: Downstream impact | K1: Report-internal or planning-material inconsistency | L1: Protocol interpretation | R1: Notes (optional)
A2: 2019::jama.2019.10517::C001 | B2: Table 5 absolute difference does not reproduce from the displayed counts | C2: jama_flint_2019_oi_190079.pdf — PDF p. 9, Table 5, total-cholesterol and LDL rows. | D2: retain | E2: statistical_results | F2: primary_done | G2: =IFERROR(IF(OR(NOT(EXACT(Setup!$B$4,"R_B")),Setup!$B$5<>2019),"CHECK SETUP",IF(OR(LEN(TRIM(CLEAN(SUBSTITUTE(Setup!$B$2,CHAR(160)," "))))=0,Setup!$B$2<>TRIM(CLEAN(SUBSTITUTE(Setup!$B$2,CHAR(160)," ")))),"CHECK REVIEWER ID",IF(OR(A2="",COUNTIF($A$2:$A$4,A2)<>1,LEFT(A2,LEN("2019::jama.2019.10517::"))<>"2019::jama.2019.10517::"),"CHECK KEY",IF(NOT(OR(EXACT(F2,"no"),EXACT(F2,"primary_done"),EXACT(F2,""))),"CHECK COMPLETE FLAG",IF(OR(D2="",E2=""),"MISSING D / E",IF(OR(NOT(OR(EXACT(D2,"retain"),EXACT(D2,"exclude"),EXACT(D2,"discuss"))),NOT(OR(EXACT(E2,"statistical_results"),EXACT(E2,"report_internal_inconsistency"),EXACT(E2,"plan_material"),EXACT(E2,"protocol_report")))),"INVALID D / E",IF(OR(AND(NOT(AND(D2="retain",E2="statistical_results")),H2<>"",NOT(EXACT(H2,"not_applicable"))),AND(NOT(AND(D2="retain",E2="statistical_results")),I2<>"",NOT(EXACT(I2,"not_applicable"))),AND(NOT(AND(D2="retain",E2="statistical_results")),J2<>"",NOT(EXACT(J2,"not_applicable"))),AND(NOT(AND(D2="retain",OR(E2="report_internal_inconsistency",E2="plan_material"))),K2<>"",NOT(EXACT(K2,"not_applicable"))),AND(NOT(AND(D2="retain",E2="protocol_report")),L2<>"",NOT(EXACT(L2,"not_applicable")))),"CLEAR INACTIVE VALUES",IF(OR(AND(AND(D2="retain",E2="statistical_results"),OR(H2="",EXACT(H2,"not_applicable"))),AND(AND(D2="retain",E2="statistical_results"),OR(I2="",EXACT(I2,"not_applicable"))),AND(AND(D2="retain",OR(E2="report_internal_inconsistency",E2="plan_material")),OR(K2="",EXACT(K2,"not_applicable")))),"MISSING REQUIRED JUDGMENT",IF(OR(AND(AND(D2="retain",E2="statistical_results"),H2<>"",NOT(OR(EXACT(H2,"confirmed_issue"),EXACT(H2,"probable_issue"),EXACT(H2,"not_issue"),EXACT(H2,"indeterminate")))),AND(AND(D2="retain",E2="statistical_results"),I2<>"",NOT(OR(EXACT(I2,"substantive"),EXACT(I2,"minor_presentation"),EXACT(I2,"indeterminate")))),AND(AND(D2="retain",E2="statistical_results"),J2<>"",NOT(OR(EXACT(J2,"direct"),EXACT(J2,"possible"),EXACT(J2,"unlikely"),EXACT(J2,"unknown")))),AND(AND(D2="retain",OR(E2="report_internal_inconsistency",E2="plan_material")),K2<>"",NOT(OR(EXACT(K2,"substantive_inconsistency"),EXACT(K2,"minor_presentation"),EXACT(K2,"non_inconsistency"),EXACT(K2,"indeterminate")))),AND(AND(D2="retain",E2="protocol_report"),L2<>"",NOT(OR(EXACT(L2,"substantive_difference"),EXACT(L2,"minor_presentation"),EXACT(L2,"version_timing"),EXACT(L2,"non_inconsistency"),EXACT(L2,"indeterminate"))))),"INVALID ACTIVE JUDGMENT",IF(F2<>"primary_done","PRIMARY DRAFT","PRIMARY READY")))))))))),"CHECK INPUT ERROR") | H2: confirmed_issue | I2: minor_presentation | J2: unlikely | K2: =IF(AND(OR(D2="retain",D2=""),OR(E2="report_internal_inconsistency",E2="plan_material")),"","not_applicable") | L2: =IF(AND(OR(D2="retain",D2=""),E2="protocol_report"),"","not_applicable") | R2: Confirmed: 9/64 - 6/62 = 4.385 pp, which rounds to 4.4, not the printed 4.3 (both cholesterol rows). Triglyceride (3.0) and glucose (-0.2) rows reproduce. Off by 0.1 pp in a post hoc table; interpretation unchanged. The printed CI (-8 to 17.2) also does not match Wald or Newcombe intervals and its method is not stated.
A3: 2019::jama.2019.10517::C002 | B3: HbA1c interaction is labelled with a concentration unit while matched displays use percent | C3: jama_flint_2019_oi_190079.pdf — PDF p. 1, abstract Results; jama_flint_2019_oi_190079.pdf — PDF p. 7, Secondary Outcomes; jama_flint_2019_oi_190079.pdf — PDF p. 8, Table 4; and joi190079supp2_prod.pdf — PDF p. 9, eFigure 8. | D3: retain | E3: report_internal_inconsistency | F3: primary_done | G3: =IFERROR(IF(OR(NOT(EXACT(Setup!$B$4,"R_B")),Setup!$B$5<>2019),"CHECK SETUP",IF(OR(LEN(TRIM(CLEAN(SUBSTITUTE(Setup!$B$2,CHAR(160)," "))))=0,Setup!$B$2<>TRIM(CLEAN(SUBSTITUTE(Setup!$B$2,CHAR(160)," ")))),"CHECK REVIEWER ID",IF(OR(A3="",COUNTIF($A$2:$A$4,A3)<>1,LEFT(A3,LEN("2019::jama.2019.10517::"))<>"2019::jama.2019.10517::"),"CHECK KEY",IF(NOT(OR(EXACT(F3,"no"),EXACT(F3,"primary_done"),EXACT(F3,""))),"CHECK COMPLETE FLAG",IF(OR(D3="",E3=""),"MISSING D / E",IF(OR(NOT(OR(EXACT(D3,"retain"),EXACT(D3,"exclude"),EXACT(D3,"discuss"))),NOT(OR(EXACT(E3,"statistical_results"),EXACT(E3,"report_internal_inconsistency"),EXACT(E3,"plan_material"),EXACT(E3,"protocol_report")))),"INVALID D / E",IF(OR(AND(NOT(AND(D3="retain",E3="statistical_results")),H3<>"",NOT(EXACT(H3,"not_applicable"))),AND(NOT(AND(D3="retain",E3="statistical_results")),I3<>"",NOT(EXACT(I3,"not_applicable"))),AND(NOT(AND(D3="retain",E3="statistical_results")),J3<>"",NOT(EXACT(J3,"not_applicable"))),AND(NOT(AND(D3="retain",OR(E3="report_internal_inconsistency",E3="plan_material"))),K3<>"",NOT(EXACT(K3,"not_applicable"))),AND(NOT(AND(D3="retain",E3="protocol_report")),L3<>"",NOT(EXACT(L3,"not_applicable")))),"CLEAR INACTIVE VALUES",IF(OR(AND(AND(D3="retain",E3="statistical_results"),OR(H3="",EXACT(H3,"not_applicable"))),AND(AND(D3="retain",E3="statistical_results"),OR(I3="",EXACT(I3,"not_applicable"))),AND(AND(D3="retain",OR(E3="report_internal_inconsistency",E3="plan_material")),OR(K3="",EXACT(K3,"not_applicable")))),"MISSING REQUIRED JUDGMENT",IF(OR(AND(AND(D3="retain",E3="statistical_results"),H3<>"",NOT(OR(EXACT(H3,"confirmed_issue"),EXACT(H3,"probable_issue"),EXACT(H3,"not_issue"),EXACT(H3,"indeterminate")))),AND(AND(D3="retain",E3="statistical_results"),I3<>"",NOT(OR(EXACT(I3,"substantive"),EXACT(I3,"minor_presentation"),EXACT(I3,"indeterminate")))),AND(AND(D3="retain",E3="statistical_results"),J3<>"",NOT(OR(EXACT(J3,"direct"),EXACT(J3,"possible"),EXACT(J3,"unlikely"),EXACT(J3,"unknown")))),AND(AND(D3="retain",OR(E3="report_internal_inconsistency",E3="plan_material")),K3<>"",NOT(OR(EXACT(K3,"substantive_inconsistency"),EXACT(K3,"minor_presentation"),EXACT(K3,"non_inconsistency"),EXACT(K3,"indeterminate")))),AND(AND(D3="retain",E3="protocol_report"),L3<>"",NOT(OR(EXACT(L3,"substantive_difference"),EXACT(L3,"minor_presentation"),EXACT(L3,"version_timing"),EXACT(L3,"non_inconsistency"),EXACT(L3,"indeterminate"))))),"INVALID ACTIVE JUDGMENT",IF(F3<>"primary_done","PRIMARY DRAFT","PRIMARY READY")))))))))),"CHECK INPUT ERROR") | H3: =IF(AND(OR(D3="retain",D3=""),E3="statistical_results"),"","not_applicable") | I3: =IF(AND(OR(D3="retain",D3=""),E3="statistical_results"),"","not_applicable") | J3: =IF(AND(OR(D3="retain",D3=""),E3="statistical_results"),"","not_applicable") | K3: minor_presentation | L3: =IF(AND(OR(D3="retain",D3=""),E3="protocol_report"),"","not_applicable") | R3: Confirmed: abstract and Secondary Outcomes give the HbA1c daily treatment-by-time estimate as -0.0002 mg/dL (95% CI -0.0021 to 0.0016), while Table 4 labels HbA1c in % and eFigure 8 uses HbA1c (%). mg/dL is not a valid HbA1c unit; the label looks carried over from the lipid estimates. The value itself is consistent with a % scale.
A4: 2019::jama.2019.10517::C003 | B4: Protocol recruitment target conflicts between 82 and 98 participants per site | C4: joi190079supp1_prod.pdf — PDF p. 7, Figure 1 and Section 3.9.1; joi190079supp1_prod.pdf — PDF p. 17, Table 4; and joi190079supp1_prod.pdf — PDF p. 21, Section 4.2.1. | D4: retain | E4: plan_material | F4: primary_done | G4: =IFERROR(IF(OR(NOT(EXACT(Setup!$B$4,"R_B")),Setup!$B$5<>2019),"CHECK SETUP",IF(OR(LEN(TRIM(CLEAN(SUBSTITUTE(Setup!$B$2,CHAR(160)," "))))=0,Setup!$B$2<>TRIM(CLEAN(SUBSTITUTE(Setup!$B$2,CHAR(160)," ")))),"CHECK REVIEWER ID",IF(OR(A4="",COUNTIF($A$2:$A$4,A4)<>1,LEFT(A4,LEN("2019::jama.2019.10517::"))<>"2019::jama.2019.10517::"),"CHECK KEY",IF(NOT(OR(EXACT(F4,"no"),EXACT(F4,"primary_done"),EXACT(F4,""))),"CHECK COMPLETE FLAG",IF(OR(D4="",E4=""),"MISSING D / E",IF(OR(NOT(OR(EXACT(D4,"retain"),EXACT(D4,"exclude"),EXACT(D4,"discuss"))),NOT(OR(EXACT(E4,"statistical_results"),EXACT(E4,"report_internal_inconsistency"),EXACT(E4,"plan_material"),EXACT(E4,"protocol_report")))),"INVALID D / E",IF(OR(AND(NOT(AND(D4="retain",E4="statistical_results")),H4<>"",NOT(EXACT(H4,"not_applicable"))),AND(NOT(AND(D4="retain",E4="statistical_results")),I4<>"",NOT(EXACT(I4,"not_applicable"))),AND(NOT(AND(D4="retain",E4="statistical_results")),J4<>"",NOT(EXACT(J4,"not_applicable"))),AND(NOT(AND(D4="retain",OR(E4="report_internal_inconsistency",E4="plan_material"))),K4<>"",NOT(EXACT(K4,"not_applicable"))),AND(NOT(AND(D4="retain",E4="protocol_report")),L4<>"",NOT(EXACT(L4,"not_applicable")))),"CLEAR INACTIVE VALUES",IF(OR(AND(AND(D4="retain",E4="statistical_results"),OR(H4="",EXACT(H4,"not_applicable"))),AND(AND(D4="retain",E4="statistical_results"),OR(I4="",EXACT(I4,"not_applicable"))),AND(AND(D4="retain",OR(E4="report_internal_inconsistency",E4="plan_material")),OR(K4="",EXACT(K4,"not_applicable")))),"MISSING REQUIRED JUDGMENT",IF(OR(AND(AND(D4="retain",E4="statistical_results"),H4<>"",NOT(OR(EXACT(H4,"confirmed_issue"),EXACT(H4,"probable_issue"),EXACT(H4,"not_issue"),EXACT(H4,"indeterminate")))),AND(AND(D4="retain",E4="statistical_results"),I4<>"",NOT(OR(EXACT(I4,"substantive"),EXACT(I4,"minor_presentation"),EXACT(I4,"indeterminate")))),AND(AND(D4="retain",E4="statistical_results"),J4<>"",NOT(OR(EXACT(J4,"direct"),EXACT(J4,"possible"),EXACT(J4,"unlikely"),EXACT(J4,"unknown")))),AND(AND(D4="retain",OR(E4="report_internal_inconsistency",E4="plan_material")),K4<>"",NOT(OR(EXACT(K4,"substantive_inconsistency"),EXACT(K4,"minor_presentation"),EXACT(K4,"non_inconsistency"),EXACT(K4,"indeterminate")))),AND(AND(D4="retain",E4="protocol_report"),L4<>"",NOT(OR(EXACT(L4,"substantive_difference"),EXACT(L4,"minor_presentation"),EXACT(L4,"version_timing"),EXACT(L4,"non_inconsistency"),EXACT(L4,"indeterminate"))))),"INVALID ACTIVE JUDGMENT",IF(F4<>"primary_done","PRIMARY DRAFT","PRIMARY READY")))))))))),"CHECK INPUT ERROR") | H4: =IF(AND(OR(D4="retain",D4=""),E4="statistical_results"),"","not_applicable") | I4: =IF(AND(OR(D4="retain",D4=""),E4="statistical_results"),"","not_applicable") | J4: =IF(AND(OR(D4="retain",D4=""),E4="statistical_results"),"","not_applicable") | K4: minor_presentation | L4: =IF(AND(OR(D4="retain",D4=""),E4="protocol_report"),"","not_applicable") | R4: Confirmed within the protocol/data-analytic plan: section 4.2.1 says each of four sites will recruit 82 patients (=328), while Figure 1/3.9.1 (N=392), the text 'we plan to recruit 392 patients' and site Table 4 (98 per site; 98x4=392) agree on 392. The 82 is an isolated stray value; the intended target is clear and the RCT target (44/site, 176) is unaffected.

Sheet C_jama.2019.12618
A1: Candidate key | B1: Candidate title | C1: Source location | D1: Disposition | E1: Review domain (AI suggestion; editable) | F1: Complete | G1: Validation hint | H1: Statistical/numerical issue | I1: Substantiveness | J1: Downstream impact | K1: Report-internal or planning-material inconsistency | L1: Protocol interpretation | R1: Notes (optional)
A2: 2019::jama.2019.12618::C001 | B2: protocol timeline end date | C2: joi190092supp2_prod.pdf — PDF p. 11, Table 1. | D2: retain | E2: plan_material | F2: primary_done | G2: =IFERROR(IF(OR(NOT(EXACT(Setup!$B$4,"R_B")),Setup!$B$5<>2019),"CHECK SETUP",IF(OR(LEN(TRIM(CLEAN(SUBSTITUTE(Setup!$B$2,CHAR(160)," "))))=0,Setup!$B$2<>TRIM(CLEAN(SUBSTITUTE(Setup!$B$2,CHAR(160)," ")))),"CHECK REVIEWER ID",IF(OR(A2="",COUNTIF($A$2:$A$9,A2)<>1,LEFT(A2,LEN("2019::jama.2019.12618::"))<>"2019::jama.2019.12618::"),"CHECK KEY",IF(NOT(OR(EXACT(F2,"no"),EXACT(F2,"primary_done"),EXACT(F2,""))),"CHECK COMPLETE FLAG",IF(OR(D2="",E2=""),"MISSING D / E",IF(OR(NOT(OR(EXACT(D2,"retain"),EXACT(D2,"exclude"),EXACT(D2,"discuss"))),NOT(OR(EXACT(E2,"statistical_results"),EXACT(E2,"report_internal_inconsistency"),EXACT(E2,"plan_material"),EXACT(E2,"protocol_report")))),"INVALID D / E",IF(OR(AND(NOT(AND(D2="retain",E2="statistical_results")),H2<>"",NOT(EXACT(H2,"not_applicable"))),AND(NOT(AND(D2="retain",E2="statistical_results")),I2<>"",NOT(EXACT(I2,"not_applicable"))),AND(NOT(AND(D2="retain",E2="statistical_results")),J2<>"",NOT(EXACT(J2,"not_applicable"))),AND(NOT(AND(D2="retain",OR(E2="report_internal_inconsistency",E2="plan_material"))),K2<>"",NOT(EXACT(K2,"not_applicable"))),AND(NOT(AND(D2="retain",E2="protocol_report")),L2<>"",NOT(EXACT(L2,"not_applicable")))),"CLEAR INACTIVE VALUES",IF(OR(AND(AND(D2="retain",E2="statistical_results"),OR(H2="",EXACT(H2,"not_applicable"))),AND(AND(D2="retain",E2="statistical_results"),OR(I2="",EXACT(I2,"not_applicable"))),AND(AND(D2="retain",OR(E2="report_internal_inconsistency",E2="plan_material")),OR(K2="",EXACT(K2,"not_applicable")))),"MISSING REQUIRED JUDGMENT",IF(OR(AND(AND(D2="retain",E2="statistical_results"),H2<>"",NOT(OR(EXACT(H2,"confirmed_issue"),EXACT(H2,"probable_issue"),EXACT(H2,"not_issue"),EXACT(H2,"indeterminate")))),AND(AND(D2="retain",E2="statistical_results"),I2<>"",NOT(OR(EXACT(I2,"substantive"),EXACT(I2,"minor_presentation"),EXACT(I2,"indeterminate")))),AND(AND(D2="retain",E2="statistical_results"),J2<>"",NOT(OR(EXACT(J2,"direct"),EXACT(J2,"possible"),EXACT(J2,"unlikely"),EXACT(J2,"unknown")))),AND(AND(D2="retain",OR(E2="report_internal_inconsistency",E2="plan_material")),K2<>"",NOT(OR(EXACT(K2,"substantive_inconsistency"),EXACT(K2,"minor_presentation"),EXACT(K2,"non_inconsistency"),EXACT(K2,"indeterminate")))),AND(AND(D2="retain",E2="protocol_report"),L2<>"",NOT(OR(EXACT(L2,"substantive_difference"),EXACT(L2,"minor_presentation"),EXACT(L2,"version_timing"),EXACT(L2,"non_inconsistency"),EXACT(L2,"indeterminate"))))),"INVALID ACTIVE JUDGMENT",IF(F2<>"primary_done","PRIMARY DRAFT","PRIMARY READY")))))))))),"CHECK INPUT ERROR") | H2: =IF(AND(OR(D2="retain",D2=""),E2="statistical_results"),"","not_applicable") | I2: =IF(AND(OR(D2="retain",D2=""),E2="statistical_results"),"","not_applicable") | J2: =IF(AND(OR(D2="retain",D2=""),E2="statistical_results"),"","not_applicable") | K2: minor_presentation | L2: =IF(AND(OR(D2="retain",D2=""),E2="protocol_report"),"","not_applicable") | R2: Confirmed in the original MOP (Sept 2012) Table 1: enrollment through May 2015, 6-month follow-up through Dec 2015, but full 12-month follow-up 'through July 2015', earlier than both. May 2015 + 12 + 1 months is about June 2016; the April 2016 database lock is also earlier than that. Administrative projection only; no effect on trial conduct or results.
A3: 2019::jama.2019.12618::C002 | B3: eligible failure total vs switching denominators | C3: jama_rathinam_2019_oi_190092.pdf — PDF p. 7; jama_rathinam_2019_oi_190092.pdf — PDF p. 6, Table 2; jama_rathinam_2019_oi_190092.pdf — PDF p. 3, Figure 1. | D3: retain | E3: statistical_results | F3: primary_done | G3: =IFERROR(IF(OR(NOT(EXACT(Setup!$B$4,"R_B")),Setup!$B$5<>2019),"CHECK SETUP",IF(OR(LEN(TRIM(CLEAN(SUBSTITUTE(Setup!$B$2,CHAR(160)," "))))=0,Setup!$B$2<>TRIM(CLEAN(SUBSTITUTE(Setup!$B$2,CHAR(160)," ")))),"CHECK REVIEWER ID",IF(OR(A3="",COUNTIF($A$2:$A$9,A3)<>1,LEFT(A3,LEN("2019::jama.2019.12618::"))<>"2019::jama.2019.12618::"),"CHECK KEY",IF(NOT(OR(EXACT(F3,"no"),EXACT(F3,"primary_done"),EXACT(F3,""))),"CHECK COMPLETE FLAG",IF(OR(D3="",E3=""),"MISSING D / E",IF(OR(NOT(OR(EXACT(D3,"retain"),EXACT(D3,"exclude"),EXACT(D3,"discuss"))),NOT(OR(EXACT(E3,"statistical_results"),EXACT(E3,"report_internal_inconsistency"),EXACT(E3,"plan_material"),EXACT(E3,"protocol_report")))),"INVALID D / E",IF(OR(AND(NOT(AND(D3="retain",E3="statistical_results")),H3<>"",NOT(EXACT(H3,"not_applicable"))),AND(NOT(AND(D3="retain",E3="statistical_results")),I3<>"",NOT(EXACT(I3,"not_applicable"))),AND(NOT(AND(D3="retain",E3="statistical_results")),J3<>"",NOT(EXACT(J3,"not_applicable"))),AND(NOT(AND(D3="retain",OR(E3="report_internal_inconsistency",E3="plan_material"))),K3<>"",NOT(EXACT(K3,"not_applicable"))),AND(NOT(AND(D3="retain",E3="protocol_report")),L3<>"",NOT(EXACT(L3,"not_applicable")))),"CLEAR INACTIVE VALUES",IF(OR(AND(AND(D3="retain",E3="statistical_results"),OR(H3="",EXACT(H3,"not_applicable"))),AND(AND(D3="retain",E3="statistical_results"),OR(I3="",EXACT(I3,"not_applicable"))),AND(AND(D3="retain",OR(E3="report_internal_inconsistency",E3="plan_material")),OR(K3="",EXACT(K3,"not_applicable")))),"MISSING REQUIRED JUDGMENT",IF(OR(AND(AND(D3="retain",E3="statistical_results"),H3<>"",NOT(OR(EXACT(H3,"confirmed_issue"),EXACT(H3,"probable_issue"),EXACT(H3,"not_issue"),EXACT(H3,"indeterminate")))),AND(AND(D3="retain",E3="statistical_results"),I3<>"",NOT(OR(EXACT(I3,"substantive"),EXACT(I3,"minor_presentation"),EXACT(I3,"indeterminate")))),AND(AND(D3="retain",E3="statistical_results"),J3<>"",NOT(OR(EXACT(J3,"direct"),EXACT(J3,"possible"),EXACT(J3,"unlikely"),EXACT(J3,"unknown")))),AND(AND(D3="retain",OR(E3="report_internal_inconsistency",E3="plan_material")),K3<>"",NOT(OR(EXACT(K3,"substantive_inconsistency"),EXACT(K3,"minor_presentation"),EXACT(K3,"non_inconsistency"),EXACT(K3,"indeterminate")))),AND(AND(D3="retain",E3="protocol_report"),L3<>"",NOT(OR(EXACT(L3,"substantive_difference"),EXACT(L3,"minor_presentation"),EXACT(L3,"version_timing"),EXACT(L3,"non_inconsistency"),EXACT(L3,"indeterminate"))))),"INVALID ACTIVE JUDGMENT",IF(F3<>"primary_done","PRIMARY DRAFT","PRIMARY READY")))))))))),"CHECK INPUT ERROR") | H3: probable_issue | I3: minor_presentation | J3: unlikely | K3: =IF(AND(OR(D3="retain",D3=""),OR(E3="report_internal_inconsistency",E3="plan_material")),"","not_applicable") | L3: =IF(AND(OR(D3="retain",D3=""),E3="protocol_report"),"","not_applicable") | R3: The 12-month paragraph says 49 of 68 eligible failures switched, then gives 20/32 and 29/42, i.e., all 6-month failures (Table 2: 32+42=74). Excluding the 3+2 safety failures (eligibility criterion stated) gives 69, not 68. Mixed denominators and an unreconciled 68; numerators and arm percentages are correct. Descriptive, not an outcome estimate.
A4: 2019::jama.2019.12618::C003 | B4: allocation block sizes | C4: jama_rathinam_2019_oi_190092.pdf — PDF p. 2; joi190092supp2_prod.pdf — PDF p. 13; joi190092supp3_prod.pdf — PDF p. 9; joi190092supp3_prod.pdf — PDF pp. 49–50 and p. 50. | D4: exclude | E4: protocol_report | F4: primary_done | G4: =IFERROR(IF(OR(NOT(EXACT(Setup!$B$4,"R_B")),Setup!$B$5<>2019),"CHECK SETUP",IF(OR(LEN(TRIM(CLEAN(SUBSTITUTE(Setup!$B$2,CHAR(160)," "))))=0,Setup!$B$2<>TRIM(CLEAN(SUBSTITUTE(Setup!$B$2,CHAR(160)," ")))),"CHECK REVIEWER ID",IF(OR(A4="",COUNTIF($A$2:$A$9,A4)<>1,LEFT(A4,LEN("2019::jama.2019.12618::"))<>"2019::jama.2019.12618::"),"CHECK KEY",IF(NOT(OR(EXACT(F4,"no"),EXACT(F4,"primary_done"),EXACT(F4,""))),"CHECK COMPLETE FLAG",IF(OR(D4="",E4=""),"MISSING D / E",IF(OR(NOT(OR(EXACT(D4,"retain"),EXACT(D4,"exclude"),EXACT(D4,"discuss"))),NOT(OR(EXACT(E4,"statistical_results"),EXACT(E4,"report_internal_inconsistency"),EXACT(E4,"plan_material"),EXACT(E4,"protocol_report")))),"INVALID D / E",IF(OR(AND(NOT(AND(D4="retain",E4="statistical_results")),H4<>"",NOT(EXACT(H4,"not_applicable"))),AND(NOT(AND(D4="retain",E4="statistical_results")),I4<>"",NOT(EXACT(I4,"not_applicable"))),AND(NOT(AND(D4="retain",E4="statistical_results")),J4<>"",NOT(EXACT(J4,"not_applicable"))),AND(NOT(AND(D4="retain",OR(E4="report_internal_inconsistency",E4="plan_material"))),K4<>"",NOT(EXACT(K4,"not_applicable"))),AND(NOT(AND(D4="retain",E4="protocol_report")),L4<>"",NOT(EXACT(L4,"not_applicable")))),"CLEAR INACTIVE VALUES",IF(OR(AND(AND(D4="retain",E4="statistical_results"),OR(H4="",EXACT(H4,"not_applicable"))),AND(AND(D4="retain",E4="statistical_results"),OR(I4="",EXACT(I4,"not_applicable"))),AND(AND(D4="retain",OR(E4="report_internal_inconsistency",E4="plan_material")),OR(K4="",EXACT(K4,"not_applicable")))),"MISSING REQUIRED JUDGMENT",IF(OR(AND(AND(D4="retain",E4="statistical_results"),H4<>"",NOT(OR(EXACT(H4,"confirmed_issue"),EXACT(H4,"probable_issue"),EXACT(H4,"not_issue"),EXACT(H4,"indeterminate")))),AND(AND(D4="retain",E4="statistical_results"),I4<>"",NOT(OR(EXACT(I4,"substantive"),EXACT(I4,"minor_presentation"),EXACT(I4,"indeterminate")))),AND(AND(D4="retain",E4="statistical_results"),J4<>"",NOT(OR(EXACT(J4,"direct"),EXACT(J4,"possible"),EXACT(J4,"unlikely"),EXACT(J4,"unknown")))),AND(AND(D4="retain",OR(E4="report_internal_inconsistency",E4="plan_material")),K4<>"",NOT(OR(EXACT(K4,"substantive_inconsistency"),EXACT(K4,"minor_presentation"),EXACT(K4,"non_inconsistency"),EXACT(K4,"indeterminate")))),AND(AND(D4="retain",E4="protocol_report"),L4<>"",NOT(OR(EXACT(L4,"substantive_difference"),EXACT(L4,"minor_presentation"),EXACT(L4,"version_timing"),EXACT(L4,"non_inconsistency"),EXACT(L4,"indeterminate"))))),"INVALID ACTIVE JUDGMENT",IF(F4<>"primary_done","PRIMARY DRAFT","PRIMARY READY")))))))))),"CHECK INPUT ERROR") | H4: =IF(AND(OR(D4="retain",D4=""),E4="statistical_results"),"","not_applicable") | I4: =IF(AND(OR(D4="retain",D4=""),E4="statistical_results"),"","not_applicable") | J4: =IF(AND(OR(D4="retain",D4=""),E4="statistical_results"),"","not_applicable") | K4: =IF(AND(OR(D4="retain",D4=""),OR(E4="report_internal_inconsistency",E4="plan_material")),"","not_applicable") | L4: =IF(AND(OR(D4="retain",D4=""),E4="protocol_report"),"","not_applicable") | R4: Exclude. Article: permuted blocks of 4 and 6. Only the Sept 2012 MOP says 4, 6 or 8; the original SAP (29 Jan 2013) and final SAP v1.5 (Mar 2017) both specify blocks of 4 (p=2/3) and 6 (p=1/3), matching the article; the final protocol v4.5 gives no sizes. The difference is a superseded early-draft detail with no bearing on validity.
A5: 2019::jama.2019.12618::C004 | B5: six-month success injection-after-90-days criterion | C5: jama_rathinam_2019_oi_190092.pdf — PDF p. 3; jama_rathinam_2019_oi_190092.pdf — PDF p. 6; joi190092supp2_prod.pdf — PDF p. 80, §2.5.1; joi190092supp3_prod.pdf — PDF p. 70. | D5: retain | E5: protocol_report | F5: primary_done | G5: =IFERROR(IF(OR(NOT(EXACT(Setup!$B$4,"R_B")),Setup!$B$5<>2019),"CHECK SETUP",IF(OR(LEN(TRIM(CLEAN(SUBSTITUTE(Setup!$B$2,CHAR(160)," "))))=0,Setup!$B$2<>TRIM(CLEAN(SUBSTITUTE(Setup!$B$2,CHAR(160)," ")))),"CHECK REVIEWER ID",IF(OR(A5="",COUNTIF($A$2:$A$9,A5)<>1,LEFT(A5,LEN("2019::jama.2019.12618::"))<>"2019::jama.2019.12618::"),"CHECK KEY",IF(NOT(OR(EXACT(F5,"no"),EXACT(F5,"primary_done"),EXACT(F5,""))),"CHECK COMPLETE FLAG",IF(OR(D5="",E5=""),"MISSING D / E",IF(OR(NOT(OR(EXACT(D5,"retain"),EXACT(D5,"exclude"),EXACT(D5,"discuss"))),NOT(OR(EXACT(E5,"statistical_results"),EXACT(E5,"report_internal_inconsistency"),EXACT(E5,"plan_material"),EXACT(E5,"protocol_report")))),"INVALID D / E",IF(OR(AND(NOT(AND(D5="retain",E5="statistical_results")),H5<>"",NOT(EXACT(H5,"not_applicable"))),AND(NOT(AND(D5="retain",E5="statistical_results")),I5<>"",NOT(EXACT(I5,"not_applicable"))),AND(NOT(AND(D5="retain",E5="statistical_results")),J5<>"",NOT(EXACT(J5,"not_applicable"))),AND(NOT(AND(D5="retain",OR(E5="report_internal_inconsistency",E5="plan_material"))),K5<>"",NOT(EXACT(K5,"not_applicable"))),AND(NOT(AND(D5="retain",E5="protocol_report")),L5<>"",NOT(EXACT(L5,"not_applicable")))),"CLEAR INACTIVE VALUES",IF(OR(AND(AND(D5="retain",E5="statistical_results"),OR(H5="",EXACT(H5,"not_applicable"))),AND(AND(D5="retain",E5="statistical_results"),OR(I5="",EXACT(I5,"not_applicable"))),AND(AND(D5="retain",OR(E5="report_internal_inconsistency",E5="plan_material")),OR(K5="",EXACT(K5,"not_applicable")))),"MISSING REQUIRED JUDGMENT",IF(OR(AND(AND(D5="retain",E5="statistical_results"),H5<>"",NOT(OR(EXACT(H5,"confirmed_issue"),EXACT(H5,"probable_issue"),EXACT(H5,"not_issue"),EXACT(H5,"indeterminate")))),AND(AND(D5="retain",E5="statistical_results"),I5<>"",NOT(OR(EXACT(I5,"substantive"),EXACT(I5,"minor_presentation"),EXACT(I5,"indeterminate")))),AND(AND(D5="retain",E5="statistical_results"),J5<>"",NOT(OR(EXACT(J5,"direct"),EXACT(J5,"possible"),EXACT(J5,"unlikely"),EXACT(J5,"unknown")))),AND(AND(D5="retain",OR(E5="report_internal_inconsistency",E5="plan_material")),K5<>"",NOT(OR(EXACT(K5,"substantive_inconsistency"),EXACT(K5,"minor_presentation"),EXACT(K5,"non_inconsistency"),EXACT(K5,"indeterminate")))),AND(AND(D5="retain",E5="protocol_report"),L5<>"",NOT(OR(EXACT(L5,"substantive_difference"),EXACT(L5,"minor_presentation"),EXACT(L5,"version_timing"),EXACT(L5,"non_inconsistency"),EXACT(L5,"indeterminate"))))),"INVALID ACTIVE JUDGMENT",IF(F5<>"primary_done","PRIMARY DRAFT","PRIMARY READY")))))))))),"CHECK INPUT ERROR") | H5: =IF(AND(OR(D5="retain",D5=""),E5="statistical_results"),"","not_applicable") | I5: =IF(AND(OR(D5="retain",D5=""),E5="statistical_results"),"","not_applicable") | J5: =IF(AND(OR(D5="retain",D5=""),E5="statistical_results"),"","not_applicable") | K5: =IF(AND(OR(D5="retain",D5=""),OR(E5="report_internal_inconsistency",E5="plan_material")),"","not_applicable") | L5: substantive_difference | R5: Confirmed. Final MOP v4.5 2.5.1 (referenced by the SAP as the success definition) requires no periocular/intravitreal corticosteroid injection after day 90. The article's 3-part success definition omits it and calls such injections protocol deviations; 4 MTX and 4 MMF patients had them. How these 8 were classified is not stated. Primary-endpoint definition difference.
A6: 2019::jama.2019.12618::C005 | B6: missed-dose Welch P=.87 compatibility | C6: jama_rathinam_2019_oi_190092.pdf — PDF p. 4; jama_rathinam_2019_oi_190092.pdf — PDF p. 6, Table 2. | D6: retain | E6: statistical_results | F6: primary_done | G6: =IFERROR(IF(OR(NOT(EXACT(Setup!$B$4,"R_B")),Setup!$B$5<>2019),"CHECK SETUP",IF(OR(LEN(TRIM(CLEAN(SUBSTITUTE(Setup!$B$2,CHAR(160)," "))))=0,Setup!$B$2<>TRIM(CLEAN(SUBSTITUTE(Setup!$B$2,CHAR(160)," ")))),"CHECK REVIEWER ID",IF(OR(A6="",COUNTIF($A$2:$A$9,A6)<>1,LEFT(A6,LEN("2019::jama.2019.12618::"))<>"2019::jama.2019.12618::"),"CHECK KEY",IF(NOT(OR(EXACT(F6,"no"),EXACT(F6,"primary_done"),EXACT(F6,""))),"CHECK COMPLETE FLAG",IF(OR(D6="",E6=""),"MISSING D / E",IF(OR(NOT(OR(EXACT(D6,"retain"),EXACT(D6,"exclude"),EXACT(D6,"discuss"))),NOT(OR(EXACT(E6,"statistical_results"),EXACT(E6,"report_internal_inconsistency"),EXACT(E6,"plan_material"),EXACT(E6,"protocol_report")))),"INVALID D / E",IF(OR(AND(NOT(AND(D6="retain",E6="statistical_results")),H6<>"",NOT(EXACT(H6,"not_applicable"))),AND(NOT(AND(D6="retain",E6="statistical_results")),I6<>"",NOT(EXACT(I6,"not_applicable"))),AND(NOT(AND(D6="retain",E6="statistical_results")),J6<>"",NOT(EXACT(J6,"not_applicable"))),AND(NOT(AND(D6="retain",OR(E6="report_internal_inconsistency",E6="plan_material"))),K6<>"",NOT(EXACT(K6,"not_applicable"))),AND(NOT(AND(D6="retain",E6="protocol_report")),L6<>"",NOT(EXACT(L6,"not_applicable")))),"CLEAR INACTIVE VALUES",IF(OR(AND(AND(D6="retain",E6="statistical_results"),OR(H6="",EXACT(H6,"not_applicable"))),AND(AND(D6="retain",E6="statistical_results"),OR(I6="",EXACT(I6,"not_applicable"))),AND(AND(D6="retain",OR(E6="report_internal_inconsistency",E6="plan_material")),OR(K6="",EXACT(K6,"not_applicable")))),"MISSING REQUIRED JUDGMENT",IF(OR(AND(AND(D6="retain",E6="statistical_results"),H6<>"",NOT(OR(EXACT(H6,"confirmed_issue"),EXACT(H6,"probable_issue"),EXACT(H6,"not_issue"),EXACT(H6,"indeterminate")))),AND(AND(D6="retain",E6="statistical_results"),I6<>"",NOT(OR(EXACT(I6,"substantive"),EXACT(I6,"minor_presentation"),EXACT(I6,"indeterminate")))),AND(AND(D6="retain",E6="statistical_results"),J6<>"",NOT(OR(EXACT(J6,"direct"),EXACT(J6,"possible"),EXACT(J6,"unlikely"),EXACT(J6,"unknown")))),AND(AND(D6="retain",OR(E6="report_internal_inconsistency",E6="plan_material")),K6<>"",NOT(OR(EXACT(K6,"substantive_inconsistency"),EXACT(K6,"minor_presentation"),EXACT(K6,"non_inconsistency"),EXACT(K6,"indeterminate")))),AND(AND(D6="retain",E6="protocol_report"),L6<>"",NOT(OR(EXACT(L6,"substantive_difference"),EXACT(L6,"minor_presentation"),EXACT(L6,"version_timing"),EXACT(L6,"non_inconsistency"),EXACT(L6,"indeterminate"))))),"INVALID ACTIVE JUDGMENT",IF(F6<>"primary_done","PRIMARY DRAFT","PRIMARY READY")))))))))),"CHECK INPUT ERROR") | H6: confirmed_issue | I6: substantive | J6: direct | K6: =IF(AND(OR(D6="retain",D6=""),OR(E6="report_internal_inconsistency",E6="plan_material")),"","not_applicable") | L6: =IF(AND(OR(D6="retain",D6=""),E6="protocol_report"),"","not_applicable") | R6: Missed doses 4.6% (SD 1.0) vs 4.3% (SD 0.5), Welch test, P=.87 cannot all be right: Welch P is .009 with n=96/98 and .006 with 107/108. 10 of 194 patients missed >=20% (sensitivity n=184), which needs an SD of at least about 3.5, so the 'SD' values cannot be SDs. If they are SEs, P is about .86-.87. The dispersion label (or P) is wrong; extracted SDs would be off about 10-fold.
A7: 2019::jama.2019.12618::C006 | B7: main Table 3 MMF n=109 header vs supplement N=108/percentages | C7: jama_rathinam_2019_oi_190092.pdf — PDF p. 8, Table 3; joi190092supp1_prod.pdf — PDF p. 10, eTable 4; joi190092supp1_prod.pdf — PDF p. 11, eTable 5; joi190092supp1_prod.pdf — PDF p. 12, eTable 6. | D7: retain | E7: report_internal_inconsistency | F7: primary_done | G7: =IFERROR(IF(OR(NOT(EXACT(Setup!$B$4,"R_B")),Setup!$B$5<>2019),"CHECK SETUP",IF(OR(LEN(TRIM(CLEAN(SUBSTITUTE(Setup!$B$2,CHAR(160)," "))))=0,Setup!$B$2<>TRIM(CLEAN(SUBSTITUTE(Setup!$B$2,CHAR(160)," ")))),"CHECK REVIEWER ID",IF(OR(A7="",COUNTIF($A$2:$A$9,A7)<>1,LEFT(A7,LEN("2019::jama.2019.12618::"))<>"2019::jama.2019.12618::"),"CHECK KEY",IF(NOT(OR(EXACT(F7,"no"),EXACT(F7,"primary_done"),EXACT(F7,""))),"CHECK COMPLETE FLAG",IF(OR(D7="",E7=""),"MISSING D / E",IF(OR(NOT(OR(EXACT(D7,"retain"),EXACT(D7,"exclude"),EXACT(D7,"discuss"))),NOT(OR(EXACT(E7,"statistical_results"),EXACT(E7,"report_internal_inconsistency"),EXACT(E7,"plan_material"),EXACT(E7,"protocol_report")))),"INVALID D / E",IF(OR(AND(NOT(AND(D7="retain",E7="statistical_results")),H7<>"",NOT(EXACT(H7,"not_applicable"))),AND(NOT(AND(D7="retain",E7="statistical_results")),I7<>"",NOT(EXACT(I7,"not_applicable"))),AND(NOT(AND(D7="retain",E7="statistical_results")),J7<>"",NOT(EXACT(J7,"not_applicable"))),AND(NOT(AND(D7="retain",OR(E7="report_internal_inconsistency",E7="plan_material"))),K7<>"",NOT(EXACT(K7,"not_applicable"))),AND(NOT(AND(D7="retain",E7="protocol_report")),L7<>"",NOT(EXACT(L7,"not_applicable")))),"CLEAR INACTIVE VALUES",IF(OR(AND(AND(D7="retain",E7="statistical_results"),OR(H7="",EXACT(H7,"not_applicable"))),AND(AND(D7="retain",E7="statistical_results"),OR(I7="",EXACT(I7,"not_applicable"))),AND(AND(D7="retain",OR(E7="report_internal_inconsistency",E7="plan_material")),OR(K7="",EXACT(K7,"not_applicable")))),"MISSING REQUIRED JUDGMENT",IF(OR(AND(AND(D7="retain",E7="statistical_results"),H7<>"",NOT(OR(EXACT(H7,"confirmed_issue"),EXACT(H7,"probable_issue"),EXACT(H7,"not_issue"),EXACT(H7,"indeterminate")))),AND(AND(D7="retain",E7="statistical_results"),I7<>"",NOT(OR(EXACT(I7,"substantive"),EXACT(I7,"minor_presentation"),EXACT(I7,"indeterminate")))),AND(AND(D7="retain",E7="statistical_results"),J7<>"",NOT(OR(EXACT(J7,"direct"),EXACT(J7,"possible"),EXACT(J7,"unlikely"),EXACT(J7,"unknown")))),AND(AND(D7="retain",OR(E7="report_internal_inconsistency",E7="plan_material")),K7<>"",NOT(OR(EXACT(K7,"substantive_inconsistency"),EXACT(K7,"minor_presentation"),EXACT(K7,"non_inconsistency"),EXACT(K7,"indeterminate")))),AND(AND(D7="retain",E7="protocol_report"),L7<>"",NOT(OR(EXACT(L7,"substantive_difference"),EXACT(L7,"minor_presentation"),EXACT(L7,"version_timing"),EXACT(L7,"non_inconsistency"),EXACT(L7,"indeterminate"))))),"INVALID ACTIVE JUDGMENT",IF(F7<>"primary_done","PRIMARY DRAFT","PRIMARY READY")))))))))),"CHECK INPUT ERROR") | H7: =IF(AND(OR(D7="retain",D7=""),E7="statistical_results"),"","not_applicable") | I7: =IF(AND(OR(D7="retain",D7=""),E7="statistical_results"),"","not_applicable") | J7: =IF(AND(OR(D7="retain",D7=""),E7="statistical_results"),"","not_applicable") | K7: minor_presentation | L7: =IF(AND(OR(D7="retain",D7=""),E7="protocol_report"),"","not_applicable") | R7: Confirmed. Main Table 3 heads the MMF column n=109 (randomized), but all 30 MMF percentages reproduce with 108 (only 9 also reproduce with 109), and eTables 4-6 label MMF N=108. Footnote b says one MMF patient never received drug, so the intended treated denominator is inferable, but the header does not match the percentages.
A8: 2019::jama.2019.12618::C007 | B8: eTable 9 MMF serious diarrhea 1 (3.4) vs N=20 | C8: joi190092supp1_prod.pdf — PDF p. 15, eTable 9, MMF N=20, Serious Systemic diarrhea row. | D8: retain | E8: statistical_results | F8: primary_done | G8: =IFERROR(IF(OR(NOT(EXACT(Setup!$B$4,"R_B")),Setup!$B$5<>2019),"CHECK SETUP",IF(OR(LEN(TRIM(CLEAN(SUBSTITUTE(Setup!$B$2,CHAR(160)," "))))=0,Setup!$B$2<>TRIM(CLEAN(SUBSTITUTE(Setup!$B$2,CHAR(160)," ")))),"CHECK REVIEWER ID",IF(OR(A8="",COUNTIF($A$2:$A$9,A8)<>1,LEFT(A8,LEN("2019::jama.2019.12618::"))<>"2019::jama.2019.12618::"),"CHECK KEY",IF(NOT(OR(EXACT(F8,"no"),EXACT(F8,"primary_done"),EXACT(F8,""))),"CHECK COMPLETE FLAG",IF(OR(D8="",E8=""),"MISSING D / E",IF(OR(NOT(OR(EXACT(D8,"retain"),EXACT(D8,"exclude"),EXACT(D8,"discuss"))),NOT(OR(EXACT(E8,"statistical_results"),EXACT(E8,"report_internal_inconsistency"),EXACT(E8,"plan_material"),EXACT(E8,"protocol_report")))),"INVALID D / E",IF(OR(AND(NOT(AND(D8="retain",E8="statistical_results")),H8<>"",NOT(EXACT(H8,"not_applicable"))),AND(NOT(AND(D8="retain",E8="statistical_results")),I8<>"",NOT(EXACT(I8,"not_applicable"))),AND(NOT(AND(D8="retain",E8="statistical_results")),J8<>"",NOT(EXACT(J8,"not_applicable"))),AND(NOT(AND(D8="retain",OR(E8="report_internal_inconsistency",E8="plan_material"))),K8<>"",NOT(EXACT(K8,"not_applicable"))),AND(NOT(AND(D8="retain",E8="protocol_report")),L8<>"",NOT(EXACT(L8,"not_applicable")))),"CLEAR INACTIVE VALUES",IF(OR(AND(AND(D8="retain",E8="statistical_results"),OR(H8="",EXACT(H8,"not_applicable"))),AND(AND(D8="retain",E8="statistical_results"),OR(I8="",EXACT(I8,"not_applicable"))),AND(AND(D8="retain",OR(E8="report_internal_inconsistency",E8="plan_material")),OR(K8="",EXACT(K8,"not_applicable")))),"MISSING REQUIRED JUDGMENT",IF(OR(AND(AND(D8="retain",E8="statistical_results"),H8<>"",NOT(OR(EXACT(H8,"confirmed_issue"),EXACT(H8,"probable_issue"),EXACT(H8,"not_issue"),EXACT(H8,"indeterminate")))),AND(AND(D8="retain",E8="statistical_results"),I8<>"",NOT(OR(EXACT(I8,"substantive"),EXACT(I8,"minor_presentation"),EXACT(I8,"indeterminate")))),AND(AND(D8="retain",E8="statistical_results"),J8<>"",NOT(OR(EXACT(J8,"direct"),EXACT(J8,"possible"),EXACT(J8,"unlikely"),EXACT(J8,"unknown")))),AND(AND(D8="retain",OR(E8="report_internal_inconsistency",E8="plan_material")),K8<>"",NOT(OR(EXACT(K8,"substantive_inconsistency"),EXACT(K8,"minor_presentation"),EXACT(K8,"non_inconsistency"),EXACT(K8,"indeterminate")))),AND(AND(D8="retain",E8="protocol_report"),L8<>"",NOT(OR(EXACT(L8,"substantive_difference"),EXACT(L8,"minor_presentation"),EXACT(L8,"version_timing"),EXACT(L8,"non_inconsistency"),EXACT(L8,"indeterminate"))))),"INVALID ACTIVE JUDGMENT",IF(F8<>"primary_done","PRIMARY DRAFT","PRIMARY READY")))))))))),"CHECK INPUT ERROR") | H8: confirmed_issue | I8: minor_presentation | J8: unlikely | K8: =IF(AND(OR(D8="retain",D8=""),OR(E8="report_internal_inconsistency",E8="plan_material")),"","not_applicable") | L8: =IF(AND(OR(D8="retain",D8=""),E8="protocol_report"),"","not_applicable") | R8: Confirmed. eTable 9 (switchers) MMF N=20, serious systemic diarrhea 1 (3.4); 1/20 = 5.0%. 3.4% is 1/29, the MTX column denominator, and other MMF count-1 cells in the same table show 5.0. Single-cell percentage error; the count is clear.
A9: 2019::jama.2019.12618::C008 | B9: eTable 8 serious-ocular hypertension label vs eTable 1 surgery-required definition | C9: joi190092supp1_prod.pdf — PDF p. 5, eTable 1; joi190092supp1_prod.pdf — PDF p. 14, eTable 8; joi190092supp1_prod.pdf — PDF p. 15, eTable 9. | D9: retain | E9: report_internal_inconsistency | F9: primary_done | G9: =IFERROR(IF(OR(NOT(EXACT(Setup!$B$4,"R_B")),Setup!$B$5<>2019),"CHECK SETUP",IF(OR(LEN(TRIM(CLEAN(SUBSTITUTE(Setup!$B$2,CHAR(160)," "))))=0,Setup!$B$2<>TRIM(CLEAN(SUBSTITUTE(Setup!$B$2,CHAR(160)," ")))),"CHECK REVIEWER ID",IF(OR(A9="",COUNTIF($A$2:$A$9,A9)<>1,LEFT(A9,LEN("2019::jama.2019.12618::"))<>"2019::jama.2019.12618::"),"CHECK KEY",IF(NOT(OR(EXACT(F9,"no"),EXACT(F9,"primary_done"),EXACT(F9,""))),"CHECK COMPLETE FLAG",IF(OR(D9="",E9=""),"MISSING D / E",IF(OR(NOT(OR(EXACT(D9,"retain"),EXACT(D9,"exclude"),EXACT(D9,"discuss"))),NOT(OR(EXACT(E9,"statistical_results"),EXACT(E9,"report_internal_inconsistency"),EXACT(E9,"plan_material"),EXACT(E9,"protocol_report")))),"INVALID D / E",IF(OR(AND(NOT(AND(D9="retain",E9="statistical_results")),H9<>"",NOT(EXACT(H9,"not_applicable"))),AND(NOT(AND(D9="retain",E9="statistical_results")),I9<>"",NOT(EXACT(I9,"not_applicable"))),AND(NOT(AND(D9="retain",E9="statistical_results")),J9<>"",NOT(EXACT(J9,"not_applicable"))),AND(NOT(AND(D9="retain",OR(E9="report_internal_inconsistency",E9="plan_material"))),K9<>"",NOT(EXACT(K9,"not_applicable"))),AND(NOT(AND(D9="retain",E9="protocol_report")),L9<>"",NOT(EXACT(L9,"not_applicable")))),"CLEAR INACTIVE VALUES",IF(OR(AND(AND(D9="retain",E9="statistical_results"),OR(H9="",EXACT(H9,"not_applicable"))),AND(AND(D9="retain",E9="statistical_results"),OR(I9="",EXACT(I9,"not_applicable"))),AND(AND(D9="retain",OR(E9="report_internal_inconsistency",E9="plan_material")),OR(K9="",EXACT(K9,"not_applicable")))),"MISSING REQUIRED JUDGMENT",IF(OR(AND(AND(D9="retain",E9="statistical_results"),H9<>"",NOT(OR(EXACT(H9,"confirmed_issue"),EXACT(H9,"probable_issue"),EXACT(H9,"not_issue"),EXACT(H9,"indeterminate")))),AND(AND(D9="retain",E9="statistical_results"),I9<>"",NOT(OR(EXACT(I9,"substantive"),EXACT(I9,"minor_presentation"),EXACT(I9,"indeterminate")))),AND(AND(D9="retain",E9="statistical_results"),J9<>"",NOT(OR(EXACT(J9,"direct"),EXACT(J9,"possible"),EXACT(J9,"unlikely"),EXACT(J9,"unknown")))),AND(AND(D9="retain",OR(E9="report_internal_inconsistency",E9="plan_material")),K9<>"",NOT(OR(EXACT(K9,"substantive_inconsistency"),EXACT(K9,"minor_presentation"),EXACT(K9,"non_inconsistency"),EXACT(K9,"indeterminate")))),AND(AND(D9="retain",E9="protocol_report"),L9<>"",NOT(OR(EXACT(L9,"substantive_difference"),EXACT(L9,"minor_presentation"),EXACT(L9,"version_timing"),EXACT(L9,"non_inconsistency"),EXACT(L9,"indeterminate"))))),"INVALID ACTIVE JUDGMENT",IF(F9<>"primary_done","PRIMARY DRAFT","PRIMARY READY")))))))))),"CHECK INPUT ERROR") | H9: =IF(AND(OR(D9="retain",D9=""),E9="statistical_results"),"","not_applicable") | I9: =IF(AND(OR(D9="retain",D9=""),E9="statistical_results"),"","not_applicable") | J9: =IF(AND(OR(D9="retain",D9=""),E9="statistical_results"),"","not_applicable") | K9: minor_presentation | L9: =IF(AND(OR(D9="retain",D9=""),E9="protocol_report"),"","not_applicable") | R9: Confirmed. eTable 1 defines ocular hypertension >=24 mm Hg as nonserious and 'surgery required' as serious. eTable 8 lists 'Ocular hypertension >24mm Hg' under both Non-Serious and Serious Ocular (serious row MTX 1, MMF 0); eTable 9 labels the serious row 'surgery required'. Likely a copied label; one event, and the section header shows it was classed serious.

Sheet C_jama.2019.14231
A1: Candidate key | B1: Candidate title | C1: Source location | D1: Disposition | E1: Review domain (AI suggestion; editable) | F1: Complete | G1: Validation hint | H1: Statistical/numerical issue | I1: Substantiveness | J1: Downstream impact | K1: Report-internal or planning-material inconsistency | L1: Protocol interpretation | R1: Notes (optional)
A2: 2019::jama.2019.14231::C001 | B2: Protocol matching direction conflicts with the final matched cohort | C2: Main article — PDF p. 1, PDF p. 3, PDF p. 4; protocol — PDF p. 3. | D2: retain | E2: protocol_report | F2: primary_done | G2: =IFERROR(IF(OR(NOT(EXACT(Setup!$B$4,"R_B")),Setup!$B$5<>2019),"CHECK SETUP",IF(OR(LEN(TRIM(CLEAN(SUBSTITUTE(Setup!$B$2,CHAR(160)," "))))=0,Setup!$B$2<>TRIM(CLEAN(SUBSTITUTE(Setup!$B$2,CHAR(160)," ")))),"CHECK REVIEWER ID",IF(OR(A2="",COUNTIF($A$2:$A$12,A2)<>1,LEFT(A2,LEN("2019::jama.2019.14231::"))<>"2019::jama.2019.14231::"),"CHECK KEY",IF(NOT(OR(EXACT(F2,"no"),EXACT(F2,"primary_done"),EXACT(F2,""))),"CHECK COMPLETE FLAG",IF(OR(D2="",E2=""),"MISSING D / E",IF(OR(NOT(OR(EXACT(D2,"retain"),EXACT(D2,"exclude"),EXACT(D2,"discuss"))),NOT(OR(EXACT(E2,"statistical_results"),EXACT(E2,"report_internal_inconsistency"),EXACT(E2,"plan_material"),EXACT(E2,"protocol_report")))),"INVALID D / E",IF(OR(AND(NOT(AND(D2="retain",E2="statistical_results")),H2<>"",NOT(EXACT(H2,"not_applicable"))),AND(NOT(AND(D2="retain",E2="statistical_results")),I2<>"",NOT(EXACT(I2,"not_applicable"))),AND(NOT(AND(D2="retain",E2="statistical_results")),J2<>"",NOT(EXACT(J2,"not_applicable"))),AND(NOT(AND(D2="retain",OR(E2="report_internal_inconsistency",E2="plan_material"))),K2<>"",NOT(EXACT(K2,"not_applicable"))),AND(NOT(AND(D2="retain",E2="protocol_report")),L2<>"",NOT(EXACT(L2,"not_applicable")))),"CLEAR INACTIVE VALUES",IF(OR(AND(AND(D2="retain",E2="statistical_results"),OR(H2="",EXACT(H2,"not_applicable"))),AND(AND(D2="retain",E2="statistical_results"),OR(I2="",EXACT(I2,"not_applicable"))),AND(AND(D2="retain",OR(E2="report_internal_inconsistency",E2="plan_material")),OR(K2="",EXACT(K2,"not_applicable")))),"MISSING REQUIRED JUDGMENT",IF(OR(AND(AND(D2="retain",E2="statistical_results"),H2<>"",NOT(OR(EXACT(H2,"confirmed_issue"),EXACT(H2,"probable_issue"),EXACT(H2,"not_issue"),EXACT(H2,"indeterminate")))),AND(AND(D2="retain",E2="statistical_results"),I2<>"",NOT(OR(EXACT(I2,"substantive"),EXACT(I2,"minor_presentation"),EXACT(I2,"indeterminate")))),AND(AND(D2="retain",E2="statistical_results"),J2<>"",NOT(OR(EXACT(J2,"direct"),EXACT(J2,"possible"),EXACT(J2,"unlikely"),EXACT(J2,"unknown")))),AND(AND(D2="retain",OR(E2="report_internal_inconsistency",E2="plan_material")),K2<>"",NOT(OR(EXACT(K2,"substantive_inconsistency"),EXACT(K2,"minor_presentation"),EXACT(K2,"non_inconsistency"),EXACT(K2,"indeterminate")))),AND(AND(D2="retain",E2="protocol_report"),L2<>"",NOT(OR(EXACT(L2,"substantive_difference"),EXACT(L2,"minor_presentation"),EXACT(L2,"version_timing"),EXACT(L2,"non_inconsistency"),EXACT(L2,"indeterminate"))))),"INVALID ACTIVE JUDGMENT",IF(F2<>"primary_done","PRIMARY DRAFT","PRIMARY READY")))))))))),"CHECK INPUT ERROR") | H2: =IF(AND(OR(D2="retain",D2=""),E2="statistical_results"),"","not_applicable") | I2: =IF(AND(OR(D2="retain",D2=""),E2="statistical_results"),"","not_applicable") | J2: =IF(AND(OR(D2="retain",D2=""),E2="statistical_results"),"","not_applicable") | K2: =IF(AND(OR(D2="retain",D2=""),OR(E2="report_internal_inconsistency",E2="plan_material")),"","not_applicable") | L2: minor_presentation | R2: Protocol (6 Jan 2019) Matching Process says each nonsurgical patient will be matched to five surgical patients, but its own sensitivity section specifies 1:5 matching on nonsurgical index dates. The article matches each surgical patient to 5 controls (2287 x 5 = 11,435). The protocol sentence is inverted wording; planned and reported design are the same.
A3: 2019::jama.2019.14231::C002 | B3: Heart-failure ARD does not reconcile with displayed 8-year incidences | C3: Main article — PDF p. 4, PDF p. 7; Supplement 1 — PDF p. 7. | D3: retain | E3: statistical_results | F3: primary_done | G3: =IFERROR(IF(OR(NOT(EXACT(Setup!$B$4,"R_B")),Setup!$B$5<>2019),"CHECK SETUP",IF(OR(LEN(TRIM(CLEAN(SUBSTITUTE(Setup!$B$2,CHAR(160)," "))))=0,Setup!$B$2<>TRIM(CLEAN(SUBSTITUTE(Setup!$B$2,CHAR(160)," ")))),"CHECK REVIEWER ID",IF(OR(A3="",COUNTIF($A$2:$A$12,A3)<>1,LEFT(A3,LEN("2019::jama.2019.14231::"))<>"2019::jama.2019.14231::"),"CHECK KEY",IF(NOT(OR(EXACT(F3,"no"),EXACT(F3,"primary_done"),EXACT(F3,""))),"CHECK COMPLETE FLAG",IF(OR(D3="",E3=""),"MISSING D / E",IF(OR(NOT(OR(EXACT(D3,"retain"),EXACT(D3,"exclude"),EXACT(D3,"discuss"))),NOT(OR(EXACT(E3,"statistical_results"),EXACT(E3,"report_internal_inconsistency"),EXACT(E3,"plan_material"),EXACT(E3,"protocol_report")))),"INVALID D / E",IF(OR(AND(NOT(AND(D3="retain",E3="statistical_results")),H3<>"",NOT(EXACT(H3,"not_applicable"))),AND(NOT(AND(D3="retain",E3="statistical_results")),I3<>"",NOT(EXACT(I3,"not_applicable"))),AND(NOT(AND(D3="retain",E3="statistical_results")),J3<>"",NOT(EXACT(J3,"not_applicable"))),AND(NOT(AND(D3="retain",OR(E3="report_internal_inconsistency",E3="plan_material"))),K3<>"",NOT(EXACT(K3,"not_applicable"))),AND(NOT(AND(D3="retain",E3="protocol_report")),L3<>"",NOT(EXACT(L3,"not_applicable")))),"CLEAR INACTIVE VALUES",IF(OR(AND(AND(D3="retain",E3="statistical_results"),OR(H3="",EXACT(H3,"not_applicable"))),AND(AND(D3="retain",E3="statistical_results"),OR(I3="",EXACT(I3,"not_applicable"))),AND(AND(D3="retain",OR(E3="report_internal_inconsistency",E3="plan_material")),OR(K3="",EXACT(K3,"not_applicable")))),"MISSING REQUIRED JUDGMENT",IF(OR(AND(AND(D3="retain",E3="statistical_results"),H3<>"",NOT(OR(EXACT(H3,"confirmed_issue"),EXACT(H3,"probable_issue"),EXACT(H3,"not_issue"),EXACT(H3,"indeterminate")))),AND(AND(D3="retain",E3="statistical_results"),I3<>"",NOT(OR(EXACT(I3,"substantive"),EXACT(I3,"minor_presentation"),EXACT(I3,"indeterminate")))),AND(AND(D3="retain",E3="statistical_results"),J3<>"",NOT(OR(EXACT(J3,"direct"),EXACT(J3,"possible"),EXACT(J3,"unlikely"),EXACT(J3,"unknown")))),AND(AND(D3="retain",OR(E3="report_internal_inconsistency",E3="plan_material")),K3<>"",NOT(OR(EXACT(K3,"substantive_inconsistency"),EXACT(K3,"minor_presentation"),EXACT(K3,"non_inconsistency"),EXACT(K3,"indeterminate")))),AND(AND(D3="retain",E3="protocol_report"),L3<>"",NOT(OR(EXACT(L3,"substantive_difference"),EXACT(L3,"minor_presentation"),EXACT(L3,"version_timing"),EXACT(L3,"non_inconsistency"),EXACT(L3,"indeterminate"))))),"INVALID ACTIVE JUDGMENT",IF(F3<>"primary_done","PRIMARY DRAFT","PRIMARY READY")))))))))),"CHECK INPUT ERROR") | H3: confirmed_issue | I3: substantive | J3: direct | K3: =IF(AND(OR(D3="retain",D3=""),OR(E3="report_internal_inconsistency",E3="plan_material")),"","not_applicable") | L3: =IF(AND(OR(D3="retain",D3=""),E3="protocol_report"),"","not_applicable") | R3: Table 2 heart failure: 8-year KM incidence 18.9% (controls) - 6.8% (surgery) = 12.1 pp, but the ARD is printed as 12.9 (95% CI 10.4-15.1); the gap (0.8) exceeds rounding (possible 12.0-12.2). Composite and mortality rows reproduce exactly; all 5 component rows are larger by 0.3-0.9 and sit near their bootstrap-CI midpoints, which suggests a different estimand or population.
A4: 2019::jama.2019.14231::C003 | B4: Coronary-disease ARD does not reconcile with displayed 8-year incidences | C4: Main article — PDF p. 4, PDF p. 7; Supplement 1 — PDF p. 7. | D4: retain | E4: statistical_results | F4: primary_done | G4: =IFERROR(IF(OR(NOT(EXACT(Setup!$B$4,"R_B")),Setup!$B$5<>2019),"CHECK SETUP",IF(OR(LEN(TRIM(CLEAN(SUBSTITUTE(Setup!$B$2,CHAR(160)," "))))=0,Setup!$B$2<>TRIM(CLEAN(SUBSTITUTE(Setup!$B$2,CHAR(160)," ")))),"CHECK REVIEWER ID",IF(OR(A4="",COUNTIF($A$2:$A$12,A4)<>1,LEFT(A4,LEN("2019::jama.2019.14231::"))<>"2019::jama.2019.14231::"),"CHECK KEY",IF(NOT(OR(EXACT(F4,"no"),EXACT(F4,"primary_done"),EXACT(F4,""))),"CHECK COMPLETE FLAG",IF(OR(D4="",E4=""),"MISSING D / E",IF(OR(NOT(OR(EXACT(D4,"retain"),EXACT(D4,"exclude"),EXACT(D4,"discuss"))),NOT(OR(EXACT(E4,"statistical_results"),EXACT(E4,"report_internal_inconsistency"),EXACT(E4,"plan_material"),EXACT(E4,"protocol_report")))),"INVALID D / E",IF(OR(AND(NOT(AND(D4="retain",E4="statistical_results")),H4<>"",NOT(EXACT(H4,"not_applicable"))),AND(NOT(AND(D4="retain",E4="statistical_results")),I4<>"",NOT(EXACT(I4,"not_applicable"))),AND(NOT(AND(D4="retain",E4="statistical_results")),J4<>"",NOT(EXACT(J4,"not_applicable"))),AND(NOT(AND(D4="retain",OR(E4="report_internal_inconsistency",E4="plan_material"))),K4<>"",NOT(EXACT(K4,"not_applicable"))),AND(NOT(AND(D4="retain",E4="protocol_report")),L4<>"",NOT(EXACT(L4,"not_applicable")))),"CLEAR INACTIVE VALUES",IF(OR(AND(AND(D4="retain",E4="statistical_results"),OR(H4="",EXACT(H4,"not_applicable"))),AND(AND(D4="retain",E4="statistical_results"),OR(I4="",EXACT(I4,"not_applicable"))),AND(AND(D4="retain",OR(E4="report_internal_inconsistency",E4="plan_material")),OR(K4="",EXACT(K4,"not_applicable")))),"MISSING REQUIRED JUDGMENT",IF(OR(AND(AND(D4="retain",E4="statistical_results"),H4<>"",NOT(OR(EXACT(H4,"confirmed_issue"),EXACT(H4,"probable_issue"),EXACT(H4,"not_issue"),EXACT(H4,"indeterminate")))),AND(AND(D4="retain",E4="statistical_results"),I4<>"",NOT(OR(EXACT(I4,"substantive"),EXACT(I4,"minor_presentation"),EXACT(I4,"indeterminate")))),AND(AND(D4="retain",E4="statistical_results"),J4<>"",NOT(OR(EXACT(J4,"direct"),EXACT(J4,"possible"),EXACT(J4,"unlikely"),EXACT(J4,"unknown")))),AND(AND(D4="retain",OR(E4="report_internal_inconsistency",E4="plan_material")),K4<>"",NOT(OR(EXACT(K4,"substantive_inconsistency"),EXACT(K4,"minor_presentation"),EXACT(K4,"non_inconsistency"),EXACT(K4,"indeterminate")))),AND(AND(D4="retain",E4="protocol_report"),L4<>"",NOT(OR(EXACT(L4,"substantive_difference"),EXACT(L4,"minor_presentation"),EXACT(L4,"version_timing"),EXACT(L4,"non_inconsistency"),EXACT(L4,"indeterminate"))))),"INVALID ACTIVE JUDGMENT",IF(F4<>"primary_done","PRIMARY DRAFT","PRIMARY READY")))))))))),"CHECK INPUT ERROR") | H4: confirmed_issue | I4: substantive | J4: direct | K4: =IF(AND(OR(D4="retain",D4=""),OR(E4="report_internal_inconsistency",E4="plan_material")),"","not_applicable") | L4: =IF(AND(OR(D4="retain",D4=""),E4="protocol_report"),"","not_applicable") | R4: Table 2 coronary artery disease: 11.6% - 7.9% = 3.7 pp vs printed ARD 4.2 (1.9-6.8); the gap of 0.5 exceeds rounding (3.6-3.8 possible). This is part of a systematic pattern across all 5 component outcomes (printed ARD exceeds the displayed incidence difference), while composite and mortality rows reproduce. The extractable ARD is ambiguous (about 14% relative).
A5: 2019::jama.2019.14231::C004 | B5: Cerebrovascular-disease ARD does not reconcile with displayed 8-year incidences | C5: Main article — PDF p. 4, PDF p. 7; Supplement 1 — PDF p. 7. | D5: retain | E5: statistical_results | F5: primary_done | G5: =IFERROR(IF(OR(NOT(EXACT(Setup!$B$4,"R_B")),Setup!$B$5<>2019),"CHECK SETUP",IF(OR(LEN(TRIM(CLEAN(SUBSTITUTE(Setup!$B$2,CHAR(160)," "))))=0,Setup!$B$2<>TRIM(CLEAN(SUBSTITUTE(Setup!$B$2,CHAR(160)," ")))),"CHECK REVIEWER ID",IF(OR(A5="",COUNTIF($A$2:$A$12,A5)<>1,LEFT(A5,LEN("2019::jama.2019.14231::"))<>"2019::jama.2019.14231::"),"CHECK KEY",IF(NOT(OR(EXACT(F5,"no"),EXACT(F5,"primary_done"),EXACT(F5,""))),"CHECK COMPLETE FLAG",IF(OR(D5="",E5=""),"MISSING D / E",IF(OR(NOT(OR(EXACT(D5,"retain"),EXACT(D5,"exclude"),EXACT(D5,"discuss"))),NOT(OR(EXACT(E5,"statistical_results"),EXACT(E5,"report_internal_inconsistency"),EXACT(E5,"plan_material"),EXACT(E5,"protocol_report")))),"INVALID D / E",IF(OR(AND(NOT(AND(D5="retain",E5="statistical_results")),H5<>"",NOT(EXACT(H5,"not_applicable"))),AND(NOT(AND(D5="retain",E5="statistical_results")),I5<>"",NOT(EXACT(I5,"not_applicable"))),AND(NOT(AND(D5="retain",E5="statistical_results")),J5<>"",NOT(EXACT(J5,"not_applicable"))),AND(NOT(AND(D5="retain",OR(E5="report_internal_inconsistency",E5="plan_material"))),K5<>"",NOT(EXACT(K5,"not_applicable"))),AND(NOT(AND(D5="retain",E5="protocol_report")),L5<>"",NOT(EXACT(L5,"not_applicable")))),"CLEAR INACTIVE VALUES",IF(OR(AND(AND(D5="retain",E5="statistical_results"),OR(H5="",EXACT(H5,"not_applicable"))),AND(AND(D5="retain",E5="statistical_results"),OR(I5="",EXACT(I5,"not_applicable"))),AND(AND(D5="retain",OR(E5="report_internal_inconsistency",E5="plan_material")),OR(K5="",EXACT(K5,"not_applicable")))),"MISSING REQUIRED JUDGMENT",IF(OR(AND(AND(D5="retain",E5="statistical_results"),H5<>"",NOT(OR(EXACT(H5,"confirmed_issue"),EXACT(H5,"probable_issue"),EXACT(H5,"not_issue"),EXACT(H5,"indeterminate")))),AND(AND(D5="retain",E5="statistical_results"),I5<>"",NOT(OR(EXACT(I5,"substantive"),EXACT(I5,"minor_presentation"),EXACT(I5,"indeterminate")))),AND(AND(D5="retain",E5="statistical_results"),J5<>"",NOT(OR(EXACT(J5,"direct"),EXACT(J5,"possible"),EXACT(J5,"unlikely"),EXACT(J5,"unknown")))),AND(AND(D5="retain",OR(E5="report_internal_inconsistency",E5="plan_material")),K5<>"",NOT(OR(EXACT(K5,"substantive_inconsistency"),EXACT(K5,"minor_presentation"),EXACT(K5,"non_inconsistency"),EXACT(K5,"indeterminate")))),AND(AND(D5="retain",E5="protocol_report"),L5<>"",NOT(OR(EXACT(L5,"substantive_difference"),EXACT(L5,"minor_presentation"),EXACT(L5,"version_timing"),EXACT(L5,"non_inconsistency"),EXACT(L5,"indeterminate"))))),"INVALID ACTIVE JUDGMENT",IF(F5<>"primary_done","PRIMARY DRAFT","PRIMARY READY")))))))))),"CHECK INPUT ERROR") | H5: confirmed_issue | I5: substantive | J5: direct | K5: =IF(AND(OR(D5="retain",D5=""),OR(E5="report_internal_inconsistency",E5="plan_material")),"","not_applicable") | L5: =IF(AND(OR(D5="retain",D5=""),E5="protocol_report"),"","not_applicable") | R5: Table 2 cerebrovascular disease: 5.6% - 4.1% = 1.5 pp vs printed ARD 1.8 (-0.03 to 3.4); the difference can only be 1.4-1.6 from the displayed values. Same systematic pattern as the other component outcomes. 1.5 vs 1.8 is a 20% relative difference in an extractable estimate whose CI touches zero.
A6: 2019::jama.2019.14231::C005 | B6: Nephropathy ARD does not reconcile with displayed 8-year incidences | C6: Main article — PDF p. 4, PDF p. 7; Supplement 1 — PDF p. 7. | D6: retain | E6: statistical_results | F6: primary_done | G6: =IFERROR(IF(OR(NOT(EXACT(Setup!$B$4,"R_B")),Setup!$B$5<>2019),"CHECK SETUP",IF(OR(LEN(TRIM(CLEAN(SUBSTITUTE(Setup!$B$2,CHAR(160)," "))))=0,Setup!$B$2<>TRIM(CLEAN(SUBSTITUTE(Setup!$B$2,CHAR(160)," ")))),"CHECK REVIEWER ID",IF(OR(A6="",COUNTIF($A$2:$A$12,A6)<>1,LEFT(A6,LEN("2019::jama.2019.14231::"))<>"2019::jama.2019.14231::"),"CHECK KEY",IF(NOT(OR(EXACT(F6,"no"),EXACT(F6,"primary_done"),EXACT(F6,""))),"CHECK COMPLETE FLAG",IF(OR(D6="",E6=""),"MISSING D / E",IF(OR(NOT(OR(EXACT(D6,"retain"),EXACT(D6,"exclude"),EXACT(D6,"discuss"))),NOT(OR(EXACT(E6,"statistical_results"),EXACT(E6,"report_internal_inconsistency"),EXACT(E6,"plan_material"),EXACT(E6,"protocol_report")))),"INVALID D / E",IF(OR(AND(NOT(AND(D6="retain",E6="statistical_results")),H6<>"",NOT(EXACT(H6,"not_applicable"))),AND(NOT(AND(D6="retain",E6="statistical_results")),I6<>"",NOT(EXACT(I6,"not_applicable"))),AND(NOT(AND(D6="retain",E6="statistical_results")),J6<>"",NOT(EXACT(J6,"not_applicable"))),AND(NOT(AND(D6="retain",OR(E6="report_internal_inconsistency",E6="plan_material"))),K6<>"",NOT(EXACT(K6,"not_applicable"))),AND(NOT(AND(D6="retain",E6="protocol_report")),L6<>"",NOT(EXACT(L6,"not_applicable")))),"CLEAR INACTIVE VALUES",IF(OR(AND(AND(D6="retain",E6="statistical_results"),OR(H6="",EXACT(H6,"not_applicable"))),AND(AND(D6="retain",E6="statistical_results"),OR(I6="",EXACT(I6,"not_applicable"))),AND(AND(D6="retain",OR(E6="report_internal_inconsistency",E6="plan_material")),OR(K6="",EXACT(K6,"not_applicable")))),"MISSING REQUIRED JUDGMENT",IF(OR(AND(AND(D6="retain",E6="statistical_results"),H6<>"",NOT(OR(EXACT(H6,"confirmed_issue"),EXACT(H6,"probable_issue"),EXACT(H6,"not_issue"),EXACT(H6,"indeterminate")))),AND(AND(D6="retain",E6="statistical_results"),I6<>"",NOT(OR(EXACT(I6,"substantive"),EXACT(I6,"minor_presentation"),EXACT(I6,"indeterminate")))),AND(AND(D6="retain",E6="statistical_results"),J6<>"",NOT(OR(EXACT(J6,"direct"),EXACT(J6,"possible"),EXACT(J6,"unlikely"),EXACT(J6,"unknown")))),AND(AND(D6="retain",OR(E6="report_internal_inconsistency",E6="plan_material")),K6<>"",NOT(OR(EXACT(K6,"substantive_inconsistency"),EXACT(K6,"minor_presentation"),EXACT(K6,"non_inconsistency"),EXACT(K6,"indeterminate")))),AND(AND(D6="retain",E6="protocol_report"),L6<>"",NOT(OR(EXACT(L6,"substantive_difference"),EXACT(L6,"minor_presentation"),EXACT(L6,"version_timing"),EXACT(L6,"non_inconsistency"),EXACT(L6,"indeterminate"))))),"INVALID ACTIVE JUDGMENT",IF(F6<>"primary_done","PRIMARY DRAFT","PRIMARY READY")))))))))),"CHECK INPUT ERROR") | H6: confirmed_issue | I6: substantive | J6: direct | K6: =IF(AND(OR(D6="retain",D6=""),OR(E6="report_internal_inconsistency",E6="plan_material")),"","not_applicable") | L6: =IF(AND(OR(D6="retain",D6=""),E6="protocol_report"),"","not_applicable") | R6: Table 2 nephropathy: 16.3% - 6.1% = 10.2 pp vs printed ARD 11.1 (8.8-13.6); the gap of 0.9 is far beyond rounding. It belongs to the systematic component-outcome pattern (printed ARDs near bootstrap-CI midpoints, not the KM incidence difference). The extractable ARD is ambiguous.
