Workbook

Sheet Setup
A1: Field | B1: Value
A2: reviewerId | B2: BulunTe
A3: reviewerName (optional)
A4: reviewerRole | B4: R_B
A5: year | B5: 2018

Sheet Checks
A1: Check | B1: Result
A2: Reviewer role | B2: =Setup!B4
A3: Candidates | B3: 119
A4: Primary ready rows | B4: =COUNTIF('C_jama.2017.21906'!$G$2:$G$7,"PRIMARY READY")+COUNTIF('C_jama.2018.0156'!$G$2:$G$9,"PRIMARY READY")+COUNTIF('C_jama.2018.0948'!$G$2:$G$8,"PRIMARY READY")+COUNTIF('C_jama.2018.14280'!$G$2:$G$24,"PRIMARY READY")+COUNTIF('C_jama.2018.14282'!$G$2:$G$29,"PRIMARY READY")+COUNTIF('C_jama.2018.17075'!$G$2:$G$9,"PRIMARY READY")+COUNTIF('C_jama.2018.18020'!$G$2:$G$15,"PRIMARY READY")+COUNTIF('C_jama.2018.6496'!$G$2:$G$5,"PRIMARY READY")+COUNTIF('C_jama.2018.8802'!$G$2:$G$9,"PRIMARY READY")+COUNTIF('C_jama.2018.9128'!$G$2:$G$14,"PRIMARY READY")
A5: Discuss / unresolved rows | B5: =COUNTIF('C_jama.2017.21906'!$D$2:$D$7,"discuss")+COUNTIF('C_jama.2018.0156'!$D$2:$D$9,"discuss")+COUNTIF('C_jama.2018.0948'!$D$2:$D$8,"discuss")+COUNTIF('C_jama.2018.14280'!$D$2:$D$24,"discuss")+COUNTIF('C_jama.2018.14282'!$D$2:$D$29,"discuss")+COUNTIF('C_jama.2018.17075'!$D$2:$D$9,"discuss")+COUNTIF('C_jama.2018.18020'!$D$2:$D$15,"discuss")+COUNTIF('C_jama.2018.6496'!$D$2:$D$5,"discuss")+COUNTIF('C_jama.2018.8802'!$D$2:$D$9,"discuss")+COUNTIF('C_jama.2018.9128'!$D$2:$D$14,"discuss")
A6: Unfinished rows | B6: =B3-B4
A7: Workflow status | B7: =IF(B4=B3,"PRIMARY READY","ACTION NEEDED")
A8: Meaning | B8: PRIMARY READY means independent entry is complete. Discuss remains unresolved and is not counted as absence of error.
A9: Next action | B9: Inspect G on the C_ sheets. Save and deliver this file after review.

Sheet Papers
A1: Paper | B1: Review worksheet | C1: Candidates
A2: jama.2017.21906 | B2: C_jama.2017.21906 | C2: 6
A3: jama.2018.0156 | B3: C_jama.2018.0156 | C3: 8
A4: jama.2018.0948 | B4: C_jama.2018.0948 | C4: 7
A5: jama.2018.14280 | B5: C_jama.2018.14280 | C5: 23
A6: jama.2018.14282 | B6: C_jama.2018.14282 | C6: 28
A7: jama.2018.17075 | B7: C_jama.2018.17075 | C7: 8
A8: jama.2018.18020 | B8: C_jama.2018.18020 | C8: 14
A9: jama.2018.6496 | B9: C_jama.2018.6496 | C9: 4
A10: jama.2018.8802 | B10: C_jama.2018.8802 | C10: 8
A11: jama.2018.9128 | B11: C_jama.2018.9128 | C11: 13

Sheet C_jama.2017.21906
A1: Candidate key | B1: Candidate title | C1: Source location | D1: Disposition | E1: Review domain (AI suggestion; editable) | F1: Complete | G1: Validation hint | H1: Statistcal_or_numerical issue | I1: Substantiveness | J1: Downstream impact | K1: Report-internal or planning-material inconsistency | L1: Protocol interpretation | R1: Notes (optional)
A2: 2018::jama.2017.21906::C001 | B2: In-hospital beta-blocker adjusted-risk-difference CI endpoint differs between Table 2 and narrative | C2: Main article — PDF p. 6, Table 2 In-hospital β-blocker row and adjacent Results narrative. | D2: retain | E2: statistical_results | F2: primary_done | G2: =IFERROR(IF(LEN(TRIM(CLEAN(SUBSTITUTE(Setup!$B$2,CHAR(160)," "))))=0,"CHECK REVIEWER ID",IF(OR(A2="",COUNTIF($A$2:$A$7,A2)<>1,LEFT(A2,LEN("2018::jama.2017.21906::"))<>"2018::jama.2017.21906::"),"CHECK KEY",IF(OR(AND(NOT(AND(D2="retain",E2="statistical_results")),H2<>"",NOT(EXACT(H2,"not_applicable"))),AND(NOT(AND(D2="retain",E2="statistical_results")),I2<>"",NOT(EXACT(I2,"not_applicable"))),AND(NOT(AND(D2="retain",E2="statistical_results")),J2<>"",NOT(EXACT(J2,"not_applicable"))),AND(NOT(AND(D2="retain",OR(E2="report_internal_inconsistency",E2="plan_material"))),K2<>"",NOT(EXACT(K2,"not_applicable"))),AND(NOT(AND(D2="retain",E2="protocol_report")),L2<>"",NOT(EXACT(L2,"not_applicable")))),"CLEAR INACTIVE VALUES",IF(OR(NOT(OR(EXACT(D2,"retain"),EXACT(D2,"exclude"),EXACT(D2,"discuss"))),NOT(OR(EXACT(E2,"statistical_results"),EXACT(E2,"report_internal_inconsistency"),EXACT(E2,"plan_material"),EXACT(E2,"protocol_report"))),AND(AND(D2="retain",E2="statistical_results"),NOT(OR(EXACT(H2,"confirmed_issue"),EXACT(H2,"probable_issue"),EXACT(H2,"not_issue"),EXACT(H2,"indeterminate")))),AND(AND(D2="retain",E2="statistical_results"),NOT(OR(EXACT(I2,"substantive"),EXACT(I2,"minor_presentation"),EXACT(I2,"indeterminate")))),AND(AND(D2="retain",E2="statistical_results"),J2<>"",NOT(OR(EXACT(J2,"direct"),EXACT(J2,"possible"),EXACT(J2,"unlikely"),EXACT(J2,"unknown")))),AND(AND(D2="retain",OR(E2="report_internal_inconsistency",E2="plan_material")),NOT(OR(EXACT(K2,"substantive_inconsistency"),EXACT(K2,"minor_presentation"),EXACT(K2,"non_inconsistency"),EXACT(K2,"indeterminate")))),AND(AND(D2="retain",E2="protocol_report"),L2<>"",NOT(OR(EXACT(L2,"substantive_difference"),EXACT(L2,"minor_presentation"),EXACT(L2,"version_timing"),EXACT(L2,"non_inconsistency"),EXACT(L2,"indeterminate"))))),"CHECK FIELDS",IF(AND(F2<>"",NOT(OR(EXACT(F2,"no"),EXACT(F2,"primary_done")))),"CHECK COMPLETE",IF(EXACT(F2,"primary_done"),"PRIMARY READY","PRIMARY DRAFT")))))),"CHECK INPUT / KEY") | H2: confirmed_issue | I2: minor_presentation | J2: direct | K2: =IF(AND(OR(D2="retain",D2=""),OR(E2="report_internal_inconsistency",E2="plan_material")),"","not_applicable") | L2: =IF(AND(OR(D2="retain",D2=""),E2="protocol_report"),"","not_applicable") | R2: Confirmed: Table 2 gives in-hospital beta-blocker adjusted RD 6.25% (4.10 to 8.40); narrative p.6 gives 4.10%-8.10%. Table CI is symmetric about 6.25 (midpoint 6.25), narrative CI is not (midpoint 6.10), so the narrative endpoint is the error. Inference unchanged (both exclude 0); a reader extracting from the text gets a wrong bound.
A3: 2018::jama.2017.21906::C002 | B3: Discharge beta-blocker adjusted point estimates differ between Table 2 and narrative | C3: Main article — PDF p. 6, Table 2 Discharge β-blocker row; Main article — PDF p. 7, Results narrative. | D3: retain | E3: statistical_results | F3: primary_done | G3: =IFERROR(IF(LEN(TRIM(CLEAN(SUBSTITUTE(Setup!$B$2,CHAR(160)," "))))=0,"CHECK REVIEWER ID",IF(OR(A3="",COUNTIF($A$2:$A$7,A3)<>1,LEFT(A3,LEN("2018::jama.2017.21906::"))<>"2018::jama.2017.21906::"),"CHECK KEY",IF(OR(AND(NOT(AND(D3="retain",E3="statistical_results")),H3<>"",NOT(EXACT(H3,"not_applicable"))),AND(NOT(AND(D3="retain",E3="statistical_results")),I3<>"",NOT(EXACT(I3,"not_applicable"))),AND(NOT(AND(D3="retain",E3="statistical_results")),J3<>"",NOT(EXACT(J3,"not_applicable"))),AND(NOT(AND(D3="retain",OR(E3="report_internal_inconsistency",E3="plan_material"))),K3<>"",NOT(EXACT(K3,"not_applicable"))),AND(NOT(AND(D3="retain",E3="protocol_report")),L3<>"",NOT(EXACT(L3,"not_applicable")))),"CLEAR INACTIVE VALUES",IF(OR(NOT(OR(EXACT(D3,"retain"),EXACT(D3,"exclude"),EXACT(D3,"discuss"))),NOT(OR(EXACT(E3,"statistical_results"),EXACT(E3,"report_internal_inconsistency"),EXACT(E3,"plan_material"),EXACT(E3,"protocol_report"))),AND(AND(D3="retain",E3="statistical_results"),NOT(OR(EXACT(H3,"confirmed_issue"),EXACT(H3,"probable_issue"),EXACT(H3,"not_issue"),EXACT(H3,"indeterminate")))),AND(AND(D3="retain",E3="statistical_results"),NOT(OR(EXACT(I3,"substantive"),EXACT(I3,"minor_presentation"),EXACT(I3,"indeterminate")))),AND(AND(D3="retain",E3="statistical_results"),J3<>"",NOT(OR(EXACT(J3,"direct"),EXACT(J3,"possible"),EXACT(J3,"unlikely"),EXACT(J3,"unknown")))),AND(AND(D3="retain",OR(E3="report_internal_inconsistency",E3="plan_material")),NOT(OR(EXACT(K3,"substantive_inconsistency"),EXACT(K3,"minor_presentation"),EXACT(K3,"non_inconsistency"),EXACT(K3,"indeterminate")))),AND(AND(D3="retain",E3="protocol_report"),L3<>"",NOT(OR(EXACT(L3,"substantive_difference"),EXACT(L3,"minor_presentation"),EXACT(L3,"version_timing"),EXACT(L3,"non_inconsistency"),EXACT(L3,"indeterminate"))))),"CHECK FIELDS",IF(AND(F3<>"",NOT(OR(EXACT(F3,"no"),EXACT(F3,"primary_done")))),"CHECK COMPLETE",IF(EXACT(F3,"primary_done"),"PRIMARY READY","PRIMARY DRAFT")))))),"CHECK INPUT / KEY") | H3: confirmed_issue | I3: minor_presentation | J3: direct | K3: =IF(AND(OR(D3="retain",D3=""),OR(E3="report_internal_inconsistency",E3="plan_material")),"","not_applicable") | L3: =IF(AND(OR(D3="retain",D3=""),E3="protocol_report"),"","not_applicable") | R3: Confirmed: Table 2 discharge beta-blocker RD 6.69% (4.43 to 8.95), OR 1.48 (1.30-1.68); narrative p.7 RD 6.63%, OR 1.47 with identical CIs. Symmetric-CI midpoint (4.43+8.95)/2 = 6.69 supports the table; narrative RD is a typo. OR geometric midpoint 1.478 is compatible with either rounding. Small, does not change interpretation. Domain changed to statistical_results.
A4: 2018::jama.2017.21906::C003 | B4: eTable 1 difference footnote names groups not displayed in the table | C4: Online supplement — PDF p. 17, eTable 1 title, headers, values, and footnote a. | D4: retain | E4: report_internal_inconsistency | F4: primary_done | G4: =IFERROR(IF(LEN(TRIM(CLEAN(SUBSTITUTE(Setup!$B$2,CHAR(160)," "))))=0,"CHECK REVIEWER ID",IF(OR(A4="",COUNTIF($A$2:$A$7,A4)<>1,LEFT(A4,LEN("2018::jama.2017.21906::"))<>"2018::jama.2017.21906::"),"CHECK KEY",IF(OR(AND(NOT(AND(D4="retain",E4="statistical_results")),H4<>"",NOT(EXACT(H4,"not_applicable"))),AND(NOT(AND(D4="retain",E4="statistical_results")),I4<>"",NOT(EXACT(I4,"not_applicable"))),AND(NOT(AND(D4="retain",E4="statistical_results")),J4<>"",NOT(EXACT(J4,"not_applicable"))),AND(NOT(AND(D4="retain",OR(E4="report_internal_inconsistency",E4="plan_material"))),K4<>"",NOT(EXACT(K4,"not_applicable"))),AND(NOT(AND(D4="retain",E4="protocol_report")),L4<>"",NOT(EXACT(L4,"not_applicable")))),"CLEAR INACTIVE VALUES",IF(OR(NOT(OR(EXACT(D4,"retain"),EXACT(D4,"exclude"),EXACT(D4,"discuss"))),NOT(OR(EXACT(E4,"statistical_results"),EXACT(E4,"report_internal_inconsistency"),EXACT(E4,"plan_material"),EXACT(E4,"protocol_report"))),AND(AND(D4="retain",E4="statistical_results"),NOT(OR(EXACT(H4,"confirmed_issue"),EXACT(H4,"probable_issue"),EXACT(H4,"not_issue"),EXACT(H4,"indeterminate")))),AND(AND(D4="retain",E4="statistical_results"),NOT(OR(EXACT(I4,"substantive"),EXACT(I4,"minor_presentation"),EXACT(I4,"indeterminate")))),AND(AND(D4="retain",E4="statistical_results"),J4<>"",NOT(OR(EXACT(J4,"direct"),EXACT(J4,"possible"),EXACT(J4,"unlikely"),EXACT(J4,"unknown")))),AND(AND(D4="retain",OR(E4="report_internal_inconsistency",E4="plan_material")),NOT(OR(EXACT(K4,"substantive_inconsistency"),EXACT(K4,"minor_presentation"),EXACT(K4,"non_inconsistency"),EXACT(K4,"indeterminate")))),AND(AND(D4="retain",E4="protocol_report"),L4<>"",NOT(OR(EXACT(L4,"substantive_difference"),EXACT(L4,"minor_presentation"),EXACT(L4,"version_timing"),EXACT(L4,"non_inconsistency"),EXACT(L4,"indeterminate"))))),"CHECK FIELDS",IF(AND(F4<>"",NOT(OR(EXACT(F4,"no"),EXACT(F4,"primary_done")))),"CHECK COMPLETE",IF(EXACT(F4,"primary_done"),"PRIMARY READY","PRIMARY DRAFT")))))),"CHECK INPUT / KEY") | H4: =IF(AND(OR(D4="retain",D4=""),E4="statistical_results"),"","not_applicable") | I4: =IF(AND(OR(D4="retain",D4=""),E4="statistical_results"),"","not_applicable") | J4: =IF(AND(OR(D4="retain",D4=""),E4="statistical_results"),"","not_applicable") | K4: minor_presentation | L4: =IF(AND(OR(D4="retain",D4=""),E4="protocol_report"),"","not_applicable") | R4: Real labeling error: eTable 1 compares complete (n=21079) vs missing follow-up (n=295), but footnote a says Difference = intervention minus control. Every row matches missing minus complete (e.g., age 60.0-60.6 = -0.6; tobacco 42.4-30.8 = 11.6; heart rate 82.9-79.9 = 3.0), so the intended contrast is recoverable. Carry-over footnote; minor.
A5: 2018::jama.2017.21906::C004 | B5: Reported prespecified age-subgroup boundaries differ from the supplied SAP | C5: SAP — PDF p. 7, section 7.5.2; main article — PDF p. 3, Statistical Analysis; main article — PDF p. 9, Figure 3 and adjacent Results narrative. | D5: retain | E5: protocol_report | F5: primary_done | G5: =IFERROR(IF(LEN(TRIM(CLEAN(SUBSTITUTE(Setup!$B$2,CHAR(160)," "))))=0,"CHECK REVIEWER ID",IF(OR(A5="",COUNTIF($A$2:$A$7,A5)<>1,LEFT(A5,LEN("2018::jama.2017.21906::"))<>"2018::jama.2017.21906::"),"CHECK KEY",IF(OR(AND(NOT(AND(D5="retain",E5="statistical_results")),H5<>"",NOT(EXACT(H5,"not_applicable"))),AND(NOT(AND(D5="retain",E5="statistical_results")),I5<>"",NOT(EXACT(I5,"not_applicable"))),AND(NOT(AND(D5="retain",E5="statistical_results")),J5<>"",NOT(EXACT(J5,"not_applicable"))),AND(NOT(AND(D5="retain",OR(E5="report_internal_inconsistency",E5="plan_material"))),K5<>"",NOT(EXACT(K5,"not_applicable"))),AND(NOT(AND(D5="retain",E5="protocol_report")),L5<>"",NOT(EXACT(L5,"not_applicable")))),"CLEAR INACTIVE VALUES",IF(OR(NOT(OR(EXACT(D5,"retain"),EXACT(D5,"exclude"),EXACT(D5,"discuss"))),NOT(OR(EXACT(E5,"statistical_results"),EXACT(E5,"report_internal_inconsistency"),EXACT(E5,"plan_material"),EXACT(E5,"protocol_report"))),AND(AND(D5="retain",E5="statistical_results"),NOT(OR(EXACT(H5,"confirmed_issue"),EXACT(H5,"probable_issue"),EXACT(H5,"not_issue"),EXACT(H5,"indeterminate")))),AND(AND(D5="retain",E5="statistical_results"),NOT(OR(EXACT(I5,"substantive"),EXACT(I5,"minor_presentation"),EXACT(I5,"indeterminate")))),AND(AND(D5="retain",E5="statistical_results"),J5<>"",NOT(OR(EXACT(J5,"direct"),EXACT(J5,"possible"),EXACT(J5,"unlikely"),EXACT(J5,"unknown")))),AND(AND(D5="retain",OR(E5="report_internal_inconsistency",E5="plan_material")),NOT(OR(EXACT(K5,"substantive_inconsistency"),EXACT(K5,"minor_presentation"),EXACT(K5,"non_inconsistency"),EXACT(K5,"indeterminate")))),AND(AND(D5="retain",E5="protocol_report"),L5<>"",NOT(OR(EXACT(L5,"substantive_difference"),EXACT(L5,"minor_presentation"),EXACT(L5,"version_timing"),EXACT(L5,"non_inconsistency"),EXACT(L5,"indeterminate"))))),"CHECK FIELDS",IF(AND(F5<>"",NOT(OR(EXACT(F5,"no"),EXACT(F5,"primary_done")))),"CHECK COMPLETE",IF(EXACT(F5,"primary_done"),"PRIMARY READY","PRIMARY DRAFT")))))),"CHECK INPUT / KEY") | H5: =IF(AND(OR(D5="retain",D5=""),E5="statistical_results"),"","not_applicable") | I5: =IF(AND(OR(D5="retain",D5=""),E5="statistical_results"),"","not_applicable") | J5: =IF(AND(OR(D5="retain",D5=""),E5="statistical_results"),"","not_applicable") | K5: =IF(AND(OR(D5="retain",D5=""),OR(E5="report_internal_inconsistency",E5="plan_material")),"","not_applicable") | L5: substantive_difference | R5: SAP (17 June 2015) section 7.5.2 lists a priori age subgroups <65 and >65 y; the article calls its Figure 3 subgroups prespecified but shows age <50, 50-69 and >=70. Different number of groups and cutpoints for a subgroup labeled prespecified. The protocol (22 Sep 2014) gives no subgroup list. Descriptive difference; no record of an amendment supplied.
A6: 2018::jama.2017.21906::C005 | B6: The named optimal in-hospital medication composite uses different component labels across final-result tables | C6: Main article — PDF p. 3, Outcomes; main article — PDF p. 7, Table 3 footnote c; online supplement — PDF p. 21, eTable 5 footnote c; online supplement — PDF p. 22, eTable 6 footnote b. | D6: retain | E6: report_internal_inconsistency | F6: primary_done | G6: =IFERROR(IF(LEN(TRIM(CLEAN(SUBSTITUTE(Setup!$B$2,CHAR(160)," "))))=0,"CHECK REVIEWER ID",IF(OR(A6="",COUNTIF($A$2:$A$7,A6)<>1,LEFT(A6,LEN("2018::jama.2017.21906::"))<>"2018::jama.2017.21906::"),"CHECK KEY",IF(OR(AND(NOT(AND(D6="retain",E6="statistical_results")),H6<>"",NOT(EXACT(H6,"not_applicable"))),AND(NOT(AND(D6="retain",E6="statistical_results")),I6<>"",NOT(EXACT(I6,"not_applicable"))),AND(NOT(AND(D6="retain",E6="statistical_results")),J6<>"",NOT(EXACT(J6,"not_applicable"))),AND(NOT(AND(D6="retain",OR(E6="report_internal_inconsistency",E6="plan_material"))),K6<>"",NOT(EXACT(K6,"not_applicable"))),AND(NOT(AND(D6="retain",E6="protocol_report")),L6<>"",NOT(EXACT(L6,"not_applicable")))),"CLEAR INACTIVE VALUES",IF(OR(NOT(OR(EXACT(D6,"retain"),EXACT(D6,"exclude"),EXACT(D6,"discuss"))),NOT(OR(EXACT(E6,"statistical_results"),EXACT(E6,"report_internal_inconsistency"),EXACT(E6,"plan_material"),EXACT(E6,"protocol_report"))),AND(AND(D6="retain",E6="statistical_results"),NOT(OR(EXACT(H6,"confirmed_issue"),EXACT(H6,"probable_issue"),EXACT(H6,"not_issue"),EXACT(H6,"indeterminate")))),AND(AND(D6="retain",E6="statistical_results"),NOT(OR(EXACT(I6,"substantive"),EXACT(I6,"minor_presentation"),EXACT(I6,"indeterminate")))),AND(AND(D6="retain",E6="statistical_results"),J6<>"",NOT(OR(EXACT(J6,"direct"),EXACT(J6,"possible"),EXACT(J6,"unlikely"),EXACT(J6,"unknown")))),AND(AND(D6="retain",OR(E6="report_internal_inconsistency",E6="plan_material")),NOT(OR(EXACT(K6,"substantive_inconsistency"),EXACT(K6,"minor_presentation"),EXACT(K6,"non_inconsistency"),EXACT(K6,"indeterminate")))),AND(AND(D6="retain",E6="protocol_report"),L6<>"",NOT(OR(EXACT(L6,"substantive_difference"),EXACT(L6,"minor_presentation"),EXACT(L6,"version_timing"),EXACT(L6,"non_inconsistency"),EXACT(L6,"indeterminate"))))),"CHECK FIELDS",IF(AND(F6<>"",NOT(OR(EXACT(F6,"no"),EXACT(F6,"primary_done")))),"CHECK COMPLETE",IF(EXACT(F6,"primary_done"),"PRIMARY READY","PRIMARY DRAFT")))))),"CHECK INPUT / KEY") | H6: =IF(AND(OR(D6="retain",D6=""),E6="statistical_results"),"","not_applicable") | I6: =IF(AND(OR(D6="retain",D6=""),E6="statistical_results"),"","not_applicable") | J6: =IF(AND(OR(D6="retain",D6=""),E6="statistical_results"),"","not_applicable") | K6: minor_presentation | L6: =IF(AND(OR(D6="retain",D6=""),E6="protocol_report"),"","not_applicable") | R6: Real label mismatch: article Outcomes, Table 3 note c and eTable 5 note c define optimal in-hospital medication with 'anticoagulant'; eTable 6 note b says 'heparin' (as does the SAP). Likely a carried-over SAP footnote; the main article definition is clear. Whether non-heparin anticoagulants were counted is not shown, but I judge this minor rather than substantive as the AI proposed.
A7: 2018::jama.2017.21906::C006 | B7: Hospital-type subgroup is reported as prespecified but is absent from the supplied SAP subgroup list | C7: Main article — PDF p. 3, Statistical Analysis; main article — PDF p. 9, Figure 3 and adjacent Results narrative; SAP — PDF p. 7, section 7.5.2. | D7: retain | E7: protocol_report | F7: primary_done | G7: =IFERROR(IF(LEN(TRIM(CLEAN(SUBSTITUTE(Setup!$B$2,CHAR(160)," "))))=0,"CHECK REVIEWER ID",IF(OR(A7="",COUNTIF($A$2:$A$7,A7)<>1,LEFT(A7,LEN("2018::jama.2017.21906::"))<>"2018::jama.2017.21906::"),"CHECK KEY",IF(OR(AND(NOT(AND(D7="retain",E7="statistical_results")),H7<>"",NOT(EXACT(H7,"not_applicable"))),AND(NOT(AND(D7="retain",E7="statistical_results")),I7<>"",NOT(EXACT(I7,"not_applicable"))),AND(NOT(AND(D7="retain",E7="statistical_results")),J7<>"",NOT(EXACT(J7,"not_applicable"))),AND(NOT(AND(D7="retain",OR(E7="report_internal_inconsistency",E7="plan_material"))),K7<>"",NOT(EXACT(K7,"not_applicable"))),AND(NOT(AND(D7="retain",E7="protocol_report")),L7<>"",NOT(EXACT(L7,"not_applicable")))),"CLEAR INACTIVE VALUES",IF(OR(NOT(OR(EXACT(D7,"retain"),EXACT(D7,"exclude"),EXACT(D7,"discuss"))),NOT(OR(EXACT(E7,"statistical_results"),EXACT(E7,"report_internal_inconsistency"),EXACT(E7,"plan_material"),EXACT(E7,"protocol_report"))),AND(AND(D7="retain",E7="statistical_results"),NOT(OR(EXACT(H7,"confirmed_issue"),EXACT(H7,"probable_issue"),EXACT(H7,"not_issue"),EXACT(H7,"indeterminate")))),AND(AND(D7="retain",E7="statistical_results"),NOT(OR(EXACT(I7,"substantive"),EXACT(I7,"minor_presentation"),EXACT(I7,"indeterminate")))),AND(AND(D7="retain",E7="statistical_results"),J7<>"",NOT(OR(EXACT(J7,"direct"),EXACT(J7,"possible"),EXACT(J7,"unlikely"),EXACT(J7,"unknown")))),AND(AND(D7="retain",OR(E7="report_internal_inconsistency",E7="plan_material")),NOT(OR(EXACT(K7,"substantive_inconsistency"),EXACT(K7,"minor_presentation"),EXACT(K7,"non_inconsistency"),EXACT(K7,"indeterminate")))),AND(AND(D7="retain",E7="protocol_report"),L7<>"",NOT(OR(EXACT(L7,"substantive_difference"),EXACT(L7,"minor_presentation"),EXACT(L7,"version_timing"),EXACT(L7,"non_inconsistency"),EXACT(L7,"indeterminate"))))),"CHECK FIELDS",IF(AND(F7<>"",NOT(OR(EXACT(F7,"no"),EXACT(F7,"primary_done")))),"CHECK COMPLETE",IF(EXACT(F7,"primary_done"),"PRIMARY READY","PRIMARY DRAFT")))))),"CHECK INPUT / KEY") | H7: =IF(AND(OR(D7="retain",D7=""),E7="statistical_results"),"","not_applicable") | I7: =IF(AND(OR(D7="retain",D7=""),E7="statistical_results"),"","not_applicable") | J7: =IF(AND(OR(D7="retain",D7=""),E7="statistical_results"),"","not_applicable") | K7: =IF(AND(OR(D7="retain",D7=""),OR(E7="report_internal_inconsistency",E7="plan_material")),"","not_applicable") | L7: substantive_difference | R7: Article calls hospital type a prespecified subgroup (Figure 3: government 9, nonprofit 12, private 42 hospitals; 9+12+42 = 63). The SAP a priori site-level subgroups are hospital size and use of QI toolkit components; hospital type is not listed and toolkit-component use is not reported. Subgroup set differs from the plan.

Sheet C_jama.2018.0156
A1: Candidate key | B1: Candidate title | C1: Source location | D1: Disposition | E1: Review domain (AI suggestion; editable) | F1: Complete | G1: Validation hint | H1: Statistcal_or_numerical issue | I1: Substantiveness | J1: Downstream impact | K1: Report-internal or planning-material inconsistency | L1: Protocol interpretation | R1: Notes (optional)
A2: 2018::jama.2018.0156::C001 | B2: Noninferiority narrative reverses the displayed bound direction | C2: jama_jabre_2018_oi_180004.pdf — PDF p. 3 (rule); jama_jabre_2018_oi_180004.pdf — PDF p. 4 (result/narrative). | D2: retain | E2: statistical_results | F2: primary_done | G2: =IFERROR(IF(LEN(TRIM(CLEAN(SUBSTITUTE(Setup!$B$2,CHAR(160)," "))))=0,"CHECK REVIEWER ID",IF(OR(A2="",COUNTIF($A$2:$A$9,A2)<>1,LEFT(A2,LEN("2018::jama.2018.0156::"))<>"2018::jama.2018.0156::"),"CHECK KEY",IF(OR(AND(NOT(AND(D2="retain",E2="statistical_results")),H2<>"",NOT(EXACT(H2,"not_applicable"))),AND(NOT(AND(D2="retain",E2="statistical_results")),I2<>"",NOT(EXACT(I2,"not_applicable"))),AND(NOT(AND(D2="retain",E2="statistical_results")),J2<>"",NOT(EXACT(J2,"not_applicable"))),AND(NOT(AND(D2="retain",OR(E2="report_internal_inconsistency",E2="plan_material"))),K2<>"",NOT(EXACT(K2,"not_applicable"))),AND(NOT(AND(D2="retain",E2="protocol_report")),L2<>"",NOT(EXACT(L2,"not_applicable")))),"CLEAR INACTIVE VALUES",IF(OR(NOT(OR(EXACT(D2,"retain"),EXACT(D2,"exclude"),EXACT(D2,"discuss"))),NOT(OR(EXACT(E2,"statistical_results"),EXACT(E2,"report_internal_inconsistency"),EXACT(E2,"plan_material"),EXACT(E2,"protocol_report"))),AND(AND(D2="retain",E2="statistical_results"),NOT(OR(EXACT(H2,"confirmed_issue"),EXACT(H2,"probable_issue"),EXACT(H2,"not_issue"),EXACT(H2,"indeterminate")))),AND(AND(D2="retain",E2="statistical_results"),NOT(OR(EXACT(I2,"substantive"),EXACT(I2,"minor_presentation"),EXACT(I2,"indeterminate")))),AND(AND(D2="retain",E2="statistical_results"),J2<>"",NOT(OR(EXACT(J2,"direct"),EXACT(J2,"possible"),EXACT(J2,"unlikely"),EXACT(J2,"unknown")))),AND(AND(D2="retain",OR(E2="report_internal_inconsistency",E2="plan_material")),NOT(OR(EXACT(K2,"substantive_inconsistency"),EXACT(K2,"minor_presentation"),EXACT(K2,"non_inconsistency"),EXACT(K2,"indeterminate")))),AND(AND(D2="retain",E2="protocol_report"),L2<>"",NOT(OR(EXACT(L2,"substantive_difference"),EXACT(L2,"minor_presentation"),EXACT(L2,"version_timing"),EXACT(L2,"non_inconsistency"),EXACT(L2,"indeterminate"))))),"CHECK FIELDS",IF(AND(F2<>"",NOT(OR(EXACT(F2,"no"),EXACT(F2,"primary_done")))),"CHECK COMPLETE",IF(EXACT(F2,"primary_done"),"PRIMARY READY","PRIMARY DRAFT")))))),"CHECK INPUT / KEY") | H2: confirmed_issue | I2: minor_presentation | J2: unlikely | K2: =IF(AND(OR(D2="retain",D2=""),OR(E2="report_internal_inconsistency",E2="plan_material")),"","not_applicable") | L2: =IF(AND(OR(D2="retain",D2=""),E2="protocol_report"),"","not_applicable") | R2: Rule (p.3): noninferiority if lower CI limit is higher than -1%. Result (p.4): lower limit -1.64% is called 'greater than the threshold', yet the next clause correctly says noninferiority was not shown. -1.64 < -1.00, so the comparative word is wrong (or means 'larger in magnitude'). Numbers and conclusion are right; wording error only.
A3: 2018::jama.2018.0156::C002 | B3: Centre-5 pause contrast mixes a count outcome with seconds | C3: jama_jabre_2018_oi_180004.pdf — PDF p. 3 (definition); jama_jabre_2018_oi_180004.pdf — PDF p. 4 (contrast). | D3: retain | E3: report_internal_inconsistency | F3: primary_done | G3: =IFERROR(IF(LEN(TRIM(CLEAN(SUBSTITUTE(Setup!$B$2,CHAR(160)," "))))=0,"CHECK REVIEWER ID",IF(OR(A3="",COUNTIF($A$2:$A$9,A3)<>1,LEFT(A3,LEN("2018::jama.2018.0156::"))<>"2018::jama.2018.0156::"),"CHECK KEY",IF(OR(AND(NOT(AND(D3="retain",E3="statistical_results")),H3<>"",NOT(EXACT(H3,"not_applicable"))),AND(NOT(AND(D3="retain",E3="statistical_results")),I3<>"",NOT(EXACT(I3,"not_applicable"))),AND(NOT(AND(D3="retain",E3="statistical_results")),J3<>"",NOT(EXACT(J3,"not_applicable"))),AND(NOT(AND(D3="retain",OR(E3="report_internal_inconsistency",E3="plan_material"))),K3<>"",NOT(EXACT(K3,"not_applicable"))),AND(NOT(AND(D3="retain",E3="protocol_report")),L3<>"",NOT(EXACT(L3,"not_applicable")))),"CLEAR INACTIVE VALUES",IF(OR(NOT(OR(EXACT(D3,"retain"),EXACT(D3,"exclude"),EXACT(D3,"discuss"))),NOT(OR(EXACT(E3,"statistical_results"),EXACT(E3,"report_internal_inconsistency"),EXACT(E3,"plan_material"),EXACT(E3,"protocol_report"))),AND(AND(D3="retain",E3="statistical_results"),NOT(OR(EXACT(H3,"confirmed_issue"),EXACT(H3,"probable_issue"),EXACT(H3,"not_issue"),EXACT(H3,"indeterminate")))),AND(AND(D3="retain",E3="statistical_results"),NOT(OR(EXACT(I3,"substantive"),EXACT(I3,"minor_presentation"),EXACT(I3,"indeterminate")))),AND(AND(D3="retain",E3="statistical_results"),J3<>"",NOT(OR(EXACT(J3,"direct"),EXACT(J3,"possible"),EXACT(J3,"unlikely"),EXACT(J3,"unknown")))),AND(AND(D3="retain",OR(E3="report_internal_inconsistency",E3="plan_material")),NOT(OR(EXACT(K3,"substantive_inconsistency"),EXACT(K3,"minor_presentation"),EXACT(K3,"non_inconsistency"),EXACT(K3,"indeterminate")))),AND(AND(D3="retain",E3="protocol_report"),L3<>"",NOT(OR(EXACT(L3,"substantive_difference"),EXACT(L3,"minor_presentation"),EXACT(L3,"version_timing"),EXACT(L3,"non_inconsistency"),EXACT(L3,"indeterminate"))))),"CHECK FIELDS",IF(AND(F3<>"",NOT(OR(EXACT(F3,"no"),EXACT(F3,"primary_done")))),"CHECK COMPLETE",IF(EXACT(F3,"primary_done"),"PRIMARY READY","PRIMARY DRAFT")))))),"CHECK INPUT / KEY") | H3: =IF(AND(OR(D3="retain",D3=""),E3="statistical_results"),"","not_applicable") | I3: =IF(AND(OR(D3="retain",D3=""),E3="statistical_results"),"","not_applicable") | J3: =IF(AND(OR(D3="retain",D3=""),E3="statistical_results"),"","not_applicable") | K3: minor_presentation | L3: =IF(AND(OR(D3="retain",D3=""),E3="protocol_report"),"","not_applicable") | R3: Post hoc center 5 analysis: outcome is the number of pauses >2 s (p.3); result p.4 gives 27 (BMV) vs 16 (ETI); 'difference, 11 seconds [95% CI, 7 to 15]'. 27-16 = 11, so the difference is in number of pauses and the unit 'seconds' is a mislabel. Summary statistic (mean per patient?) is also unstated. Exploratory single-center result; minor.
A4: 2018::jama.2018.0156::C003 | B4: PP day-28 survival point difference does not round from the printed inputs | C4: jama_jabre_2018_oi_180004.pdf — PDF p. 6 (Table 2); joi180004supp1_prod.pdf — PDF p. 123 (rounding rule). | D4: retain | E4: statistical_results | F4: primary_done | G4: =IFERROR(IF(LEN(TRIM(CLEAN(SUBSTITUTE(Setup!$B$2,CHAR(160)," "))))=0,"CHECK REVIEWER ID",IF(OR(A4="",COUNTIF($A$2:$A$9,A4)<>1,LEFT(A4,LEN("2018::jama.2018.0156::"))<>"2018::jama.2018.0156::"),"CHECK KEY",IF(OR(AND(NOT(AND(D4="retain",E4="statistical_results")),H4<>"",NOT(EXACT(H4,"not_applicable"))),AND(NOT(AND(D4="retain",E4="statistical_results")),I4<>"",NOT(EXACT(I4,"not_applicable"))),AND(NOT(AND(D4="retain",E4="statistical_results")),J4<>"",NOT(EXACT(J4,"not_applicable"))),AND(NOT(AND(D4="retain",OR(E4="report_internal_inconsistency",E4="plan_material"))),K4<>"",NOT(EXACT(K4,"not_applicable"))),AND(NOT(AND(D4="retain",E4="protocol_report")),L4<>"",NOT(EXACT(L4,"not_applicable")))),"CLEAR INACTIVE VALUES",IF(OR(NOT(OR(EXACT(D4,"retain"),EXACT(D4,"exclude"),EXACT(D4,"discuss"))),NOT(OR(EXACT(E4,"statistical_results"),EXACT(E4,"report_internal_inconsistency"),EXACT(E4,"plan_material"),EXACT(E4,"protocol_report"))),AND(AND(D4="retain",E4="statistical_results"),NOT(OR(EXACT(H4,"confirmed_issue"),EXACT(H4,"probable_issue"),EXACT(H4,"not_issue"),EXACT(H4,"indeterminate")))),AND(AND(D4="retain",E4="statistical_results"),NOT(OR(EXACT(I4,"substantive"),EXACT(I4,"minor_presentation"),EXACT(I4,"indeterminate")))),AND(AND(D4="retain",E4="statistical_results"),J4<>"",NOT(OR(EXACT(J4,"direct"),EXACT(J4,"possible"),EXACT(J4,"unlikely"),EXACT(J4,"unknown")))),AND(AND(D4="retain",OR(E4="report_internal_inconsistency",E4="plan_material")),NOT(OR(EXACT(K4,"substantive_inconsistency"),EXACT(K4,"minor_presentation"),EXACT(K4,"non_inconsistency"),EXACT(K4,"indeterminate")))),AND(AND(D4="retain",E4="protocol_report"),L4<>"",NOT(OR(EXACT(L4,"substantive_difference"),EXACT(L4,"minor_presentation"),EXACT(L4,"version_timing"),EXACT(L4,"non_inconsistency"),EXACT(L4,"indeterminate"))))),"CHECK FIELDS",IF(AND(F4<>"",NOT(OR(EXACT(F4,"no"),EXACT(F4,"primary_done")))),"CHECK COMPLETE",IF(EXACT(F4,"primary_done"),"PRIMARY READY","PRIMARY DRAFT")))))),"CHECK INPUT / KEY") | H4: confirmed_issue | I4: minor_presentation | J4: direct | K4: =IF(AND(OR(D4="retain",D4=""),OR(E4="report_internal_inconsistency",E4="plan_material")),"","not_applicable") | L4: =IF(AND(OR(D4="retain",D4=""),E4="protocol_report"),"","not_applicable") | R4: PP survival at 28 d: 54/995 (5.427%) vs 51/943 (5.408%); RD = 0.019 pp, which rounds to 0.0, not the printed 0.1. Every other RD in Tables 2-3 reproduces exactly from counts with a simple unpooled difference, so this cell is a production error (the ITT row is 0.119 -> 0.1, possibly copied). Tiny magnitude.
A5: 2018::jama.2018.0156::C004 | B5: PP day-28 survival confidence interval has an unresolved scale/precision inconsistency | C5: jama_jabre_2018_oi_180004.pdf — PDF p. 3 (rule); PDF p. 6 (Table 2); joi180004supp1_prod.pdf — PDF p. 124 (CI rule). | D5: retain | E5: statistical_results | F5: primary_done | G5: =IFERROR(IF(LEN(TRIM(CLEAN(SUBSTITUTE(Setup!$B$2,CHAR(160)," "))))=0,"CHECK REVIEWER ID",IF(OR(A5="",COUNTIF($A$2:$A$9,A5)<>1,LEFT(A5,LEN("2018::jama.2018.0156::"))<>"2018::jama.2018.0156::"),"CHECK KEY",IF(OR(AND(NOT(AND(D5="retain",E5="statistical_results")),H5<>"",NOT(EXACT(H5,"not_applicable"))),AND(NOT(AND(D5="retain",E5="statistical_results")),I5<>"",NOT(EXACT(I5,"not_applicable"))),AND(NOT(AND(D5="retain",E5="statistical_results")),J5<>"",NOT(EXACT(J5,"not_applicable"))),AND(NOT(AND(D5="retain",OR(E5="report_internal_inconsistency",E5="plan_material"))),K5<>"",NOT(EXACT(K5,"not_applicable"))),AND(NOT(AND(D5="retain",E5="protocol_report")),L5<>"",NOT(EXACT(L5,"not_applicable")))),"CLEAR INACTIVE VALUES",IF(OR(NOT(OR(EXACT(D5,"retain"),EXACT(D5,"exclude"),EXACT(D5,"discuss"))),NOT(OR(EXACT(E5,"statistical_results"),EXACT(E5,"report_internal_inconsistency"),EXACT(E5,"plan_material"),EXACT(E5,"protocol_report"))),AND(AND(D5="retain",E5="statistical_results"),NOT(OR(EXACT(H5,"confirmed_issue"),EXACT(H5,"probable_issue"),EXACT(H5,"not_issue"),EXACT(H5,"indeterminate")))),AND(AND(D5="retain",E5="statistical_results"),NOT(OR(EXACT(I5,"substantive"),EXACT(I5,"minor_presentation"),EXACT(I5,"indeterminate")))),AND(AND(D5="retain",E5="statistical_results"),J5<>"",NOT(OR(EXACT(J5,"direct"),EXACT(J5,"possible"),EXACT(J5,"unlikely"),EXACT(J5,"unknown")))),AND(AND(D5="retain",OR(E5="report_internal_inconsistency",E5="plan_material")),NOT(OR(EXACT(K5,"substantive_inconsistency"),EXACT(K5,"minor_presentation"),EXACT(K5,"non_inconsistency"),EXACT(K5,"indeterminate")))),AND(AND(D5="retain",E5="protocol_report"),L5<>"",NOT(OR(EXACT(L5,"substantive_difference"),EXACT(L5,"minor_presentation"),EXACT(L5,"version_timing"),EXACT(L5,"non_inconsistency"),EXACT(L5,"indeterminate"))))),"CHECK FIELDS",IF(AND(F5<>"",NOT(OR(EXACT(F5,"no"),EXACT(F5,"primary_done")))),"CHECK COMPLETE",IF(EXACT(F5,"primary_done"),"PRIMARY READY","PRIMARY DRAFT")))))),"CHECK INPUT / KEY") | H5: confirmed_issue | I5: substantive | J5: direct | K5: =IF(AND(OR(D5="retain",D5=""),OR(E5="report_internal_inconsistency",E5="plan_material")),"","not_applicable") | L5: =IF(AND(OR(D5="retain",D5=""),E5="protocol_report"),"","not_applicable") | R5: PP survival at 28 d CI printed -10 to 9.7 pp. From 54/995 vs 51/943 the Wald 95% CI is -2.00 to 2.04 pp (Newcombe -2.03 to 2.05), and P = .985 matches the printed P = .99, so only the CI is wrong. The same Wald method reproduces the ITT CIs and PP ROSC CI exactly. Printed interval is about 5 times too wide and misstates precision.
A6: 2018::jama.2018.0156::C005 | B6: PP ROSC ETI percentage conflicts with its count, denominator, and signed difference | C6: jama_jabre_2018_oi_180004.pdf — PDF p. 6 (Table 2 PP ROSC row). | D6: retain | E6: statistical_results | F6: primary_done | G6: =IFERROR(IF(LEN(TRIM(CLEAN(SUBSTITUTE(Setup!$B$2,CHAR(160)," "))))=0,"CHECK REVIEWER ID",IF(OR(A6="",COUNTIF($A$2:$A$9,A6)<>1,LEFT(A6,LEN("2018::jama.2018.0156::"))<>"2018::jama.2018.0156::"),"CHECK KEY",IF(OR(AND(NOT(AND(D6="retain",E6="statistical_results")),H6<>"",NOT(EXACT(H6,"not_applicable"))),AND(NOT(AND(D6="retain",E6="statistical_results")),I6<>"",NOT(EXACT(I6,"not_applicable"))),AND(NOT(AND(D6="retain",E6="statistical_results")),J6<>"",NOT(EXACT(J6,"not_applicable"))),AND(NOT(AND(D6="retain",OR(E6="report_internal_inconsistency",E6="plan_material"))),K6<>"",NOT(EXACT(K6,"not_applicable"))),AND(NOT(AND(D6="retain",E6="protocol_report")),L6<>"",NOT(EXACT(L6,"not_applicable")))),"CLEAR INACTIVE VALUES",IF(OR(NOT(OR(EXACT(D6,"retain"),EXACT(D6,"exclude"),EXACT(D6,"discuss"))),NOT(OR(EXACT(E6,"statistical_results"),EXACT(E6,"report_internal_inconsistency"),EXACT(E6,"plan_material"),EXACT(E6,"protocol_report"))),AND(AND(D6="retain",E6="statistical_results"),NOT(OR(EXACT(H6,"confirmed_issue"),EXACT(H6,"probable_issue"),EXACT(H6,"not_issue"),EXACT(H6,"indeterminate")))),AND(AND(D6="retain",E6="statistical_results"),NOT(OR(EXACT(I6,"substantive"),EXACT(I6,"minor_presentation"),EXACT(I6,"indeterminate")))),AND(AND(D6="retain",E6="statistical_results"),J6<>"",NOT(OR(EXACT(J6,"direct"),EXACT(J6,"possible"),EXACT(J6,"unlikely"),EXACT(J6,"unknown")))),AND(AND(D6="retain",OR(E6="report_internal_inconsistency",E6="plan_material")),NOT(OR(EXACT(K6,"substantive_inconsistency"),EXACT(K6,"minor_presentation"),EXACT(K6,"non_inconsistency"),EXACT(K6,"indeterminate")))),AND(AND(D6="retain",E6="protocol_report"),L6<>"",NOT(OR(EXACT(L6,"substantive_difference"),EXACT(L6,"minor_presentation"),EXACT(L6,"version_timing"),EXACT(L6,"non_inconsistency"),EXACT(L6,"indeterminate"))))),"CHECK FIELDS",IF(AND(F6<>"",NOT(OR(EXACT(F6,"no"),EXACT(F6,"primary_done")))),"CHECK COMPLETE",IF(EXACT(F6,"primary_done"),"PRIMARY READY","PRIMARY DRAFT")))))),"CHECK INPUT / KEY") | H6: confirmed_issue | I6: substantive | J6: direct | K6: =IF(AND(OR(D6="retain",D6=""),OR(E6="report_internal_inconsistency",E6="plan_material")),"","not_applicable") | L6: =IF(AND(OR(D6="retain",D6=""),E6="protocol_report"),"","not_applicable") | R6: PP ROSC: ETI 377/943 printed 30.0%, but 377/943 = 40.0%. The difference -5.6 (95% CI -9.9 to -1.3) and P = .01 reproduce from the counts (RD -5.61, Wald -9.91 to -1.31, P = .011), so 30.0 is a typo for 40.0. As printed, the percentages imply BMV higher (34.4 vs 30.0), opposite to the difference column; an extracted arm percentage would be 10 points off.
A7: 2018::jama.2018.0156::C006 | B7: Main article and eTable report different contributing-centre counts | C7: jama_jabre_2018_oi_180004.pdf — PDF p. 2; joi180004supp2_prod.pdf — PDF p. 2 (eTable 1). | D7: retain | E7: report_internal_inconsistency | F7: primary_done | G7: =IFERROR(IF(LEN(TRIM(CLEAN(SUBSTITUTE(Setup!$B$2,CHAR(160)," "))))=0,"CHECK REVIEWER ID",IF(OR(A7="",COUNTIF($A$2:$A$9,A7)<>1,LEFT(A7,LEN("2018::jama.2018.0156::"))<>"2018::jama.2018.0156::"),"CHECK KEY",IF(OR(AND(NOT(AND(D7="retain",E7="statistical_results")),H7<>"",NOT(EXACT(H7,"not_applicable"))),AND(NOT(AND(D7="retain",E7="statistical_results")),I7<>"",NOT(EXACT(I7,"not_applicable"))),AND(NOT(AND(D7="retain",E7="statistical_results")),J7<>"",NOT(EXACT(J7,"not_applicable"))),AND(NOT(AND(D7="retain",OR(E7="report_internal_inconsistency",E7="plan_material"))),K7<>"",NOT(EXACT(K7,"not_applicable"))),AND(NOT(AND(D7="retain",E7="protocol_report")),L7<>"",NOT(EXACT(L7,"not_applicable")))),"CLEAR INACTIVE VALUES",IF(OR(NOT(OR(EXACT(D7,"retain"),EXACT(D7,"exclude"),EXACT(D7,"discuss"))),NOT(OR(EXACT(E7,"statistical_results"),EXACT(E7,"report_internal_inconsistency"),EXACT(E7,"plan_material"),EXACT(E7,"protocol_report"))),AND(AND(D7="retain",E7="statistical_results"),NOT(OR(EXACT(H7,"confirmed_issue"),EXACT(H7,"probable_issue"),EXACT(H7,"not_issue"),EXACT(H7,"indeterminate")))),AND(AND(D7="retain",E7="statistical_results"),NOT(OR(EXACT(I7,"substantive"),EXACT(I7,"minor_presentation"),EXACT(I7,"indeterminate")))),AND(AND(D7="retain",E7="statistical_results"),J7<>"",NOT(OR(EXACT(J7,"direct"),EXACT(J7,"possible"),EXACT(J7,"unlikely"),EXACT(J7,"unknown")))),AND(AND(D7="retain",OR(E7="report_internal_inconsistency",E7="plan_material")),NOT(OR(EXACT(K7,"substantive_inconsistency"),EXACT(K7,"minor_presentation"),EXACT(K7,"non_inconsistency"),EXACT(K7,"indeterminate")))),AND(AND(D7="retain",E7="protocol_report"),L7<>"",NOT(OR(EXACT(L7,"substantive_difference"),EXACT(L7,"minor_presentation"),EXACT(L7,"version_timing"),EXACT(L7,"non_inconsistency"),EXACT(L7,"indeterminate"))))),"CHECK FIELDS",IF(AND(F7<>"",NOT(OR(EXACT(F7,"no"),EXACT(F7,"primary_done")))),"CHECK COMPLETE",IF(EXACT(F7,"primary_done"),"PRIMARY READY","PRIMARY DRAFT")))))),"CHECK INPUT / KEY") | H7: =IF(AND(OR(D7="retain",D7=""),E7="statistical_results"),"","not_applicable") | I7: =IF(AND(OR(D7="retain",D7=""),E7="statistical_results"),"","not_applicable") | J7: =IF(AND(OR(D7="retain",D7=""),E7="statistical_results"),"","not_applicable") | K7: minor_presentation | L7: =IF(AND(OR(D7="retain",D7=""),E7="protocol_report"),"","not_applicable") | R7: Article p.3: 20 EMS centers (15 France, 5 Belgium). eTable 1 lists 21 contributing centre IDs (N1 to N25, one with 0 BMV/3 ETI); columns sum to 1018 and 1022. Protocol amendment (supp1 p.112) withdrew centre 19 and added centres 21-26 (25 total). The '20 centers' figure appears to come from the original protocol. Real but minor descriptive discrepancy.
A8: 2018::jama.2018.0156::C007 | B8: Published primary-endpoint description omits the amended baseline-disability qualification | C8: jama_jabre_2018_oi_180004.pdf — PDF p. 1 and PDF p. 3; joi180004supp1_prod.pdf — PDF p. 110. | D8: retain | E8: protocol_report | F8: primary_done | G8: =IFERROR(IF(LEN(TRIM(CLEAN(SUBSTITUTE(Setup!$B$2,CHAR(160)," "))))=0,"CHECK REVIEWER ID",IF(OR(A8="",COUNTIF($A$2:$A$9,A8)<>1,LEFT(A8,LEN("2018::jama.2018.0156::"))<>"2018::jama.2018.0156::"),"CHECK KEY",IF(OR(AND(NOT(AND(D8="retain",E8="statistical_results")),H8<>"",NOT(EXACT(H8,"not_applicable"))),AND(NOT(AND(D8="retain",E8="statistical_results")),I8<>"",NOT(EXACT(I8,"not_applicable"))),AND(NOT(AND(D8="retain",E8="statistical_results")),J8<>"",NOT(EXACT(J8,"not_applicable"))),AND(NOT(AND(D8="retain",OR(E8="report_internal_inconsistency",E8="plan_material"))),K8<>"",NOT(EXACT(K8,"not_applicable"))),AND(NOT(AND(D8="retain",E8="protocol_report")),L8<>"",NOT(EXACT(L8,"not_applicable")))),"CLEAR INACTIVE VALUES",IF(OR(NOT(OR(EXACT(D8,"retain"),EXACT(D8,"exclude"),EXACT(D8,"discuss"))),NOT(OR(EXACT(E8,"statistical_results"),EXACT(E8,"report_internal_inconsistency"),EXACT(E8,"plan_material"),EXACT(E8,"protocol_report"))),AND(AND(D8="retain",E8="statistical_results"),NOT(OR(EXACT(H8,"confirmed_issue"),EXACT(H8,"probable_issue"),EXACT(H8,"not_issue"),EXACT(H8,"indeterminate")))),AND(AND(D8="retain",E8="statistical_results"),NOT(OR(EXACT(I8,"substantive"),EXACT(I8,"minor_presentation"),EXACT(I8,"indeterminate")))),AND(AND(D8="retain",E8="statistical_results"),J8<>"",NOT(OR(EXACT(J8,"direct"),EXACT(J8,"possible"),EXACT(J8,"unlikely"),EXACT(J8,"unknown")))),AND(AND(D8="retain",OR(E8="report_internal_inconsistency",E8="plan_material")),NOT(OR(EXACT(K8,"substantive_inconsistency"),EXACT(K8,"minor_presentation"),EXACT(K8,"non_inconsistency"),EXACT(K8,"indeterminate")))),AND(AND(D8="retain",E8="protocol_report"),L8<>"",NOT(OR(EXACT(L8,"substantive_difference"),EXACT(L8,"minor_presentation"),EXACT(L8,"version_timing"),EXACT(L8,"non_inconsistency"),EXACT(L8,"indeterminate"))))),"CHECK FIELDS",IF(AND(F8<>"",NOT(OR(EXACT(F8,"no"),EXACT(F8,"primary_done")))),"CHECK COMPLETE",IF(EXACT(F8,"primary_done"),"PRIMARY READY","PRIMARY DRAFT")))))),"CHECK INPUT / KEY") | H8: =IF(AND(OR(D8="retain",D8=""),E8="statistical_results"),"","not_applicable") | I8: =IF(AND(OR(D8="retain",D8=""),E8="statistical_results"),"","not_applicable") | J8: =IF(AND(OR(D8="retain",D8=""),E8="statistical_results"),"","not_applicable") | K8: =IF(AND(OR(D8="retain",D8=""),OR(E8="report_internal_inconsistency",E8="plan_material")),"","not_applicable") | L8: substantive_difference | R8: Protocol V2 (22 Jan 2016, and amendment V1.4) adds to the primary endpoint: survivors with pre-arrest neurologic disability who keep the same degree of disability count as favorable. Article defines success as CPC 1-2 only, and Table 2 note b says CPC 1-2 were coded as success; reported primary counts equal CPC1+CPC2 (35+9 = 44; 37+6 = 43). SAP (Feb 2015) predates the amendment.
A9: 2018::jama.2018.0156::C008 | B9: Protocol composite technique-failure definition cannot reconcile with the article’s smaller ETI failure count if they are the same endpoint | C9: joi180004supp1_prod.pdf — PDF p. 110; jama_jabre_2018_oi_180004.pdf — PDF p. 1, PDF p. 4, and PDF p. 6. | D9: retain | E9: protocol_report | F9: primary_done | G9: =IFERROR(IF(LEN(TRIM(CLEAN(SUBSTITUTE(Setup!$B$2,CHAR(160)," "))))=0,"CHECK REVIEWER ID",IF(OR(A9="",COUNTIF($A$2:$A$9,A9)<>1,LEFT(A9,LEN("2018::jama.2018.0156::"))<>"2018::jama.2018.0156::"),"CHECK KEY",IF(OR(AND(NOT(AND(D9="retain",E9="statistical_results")),H9<>"",NOT(EXACT(H9,"not_applicable"))),AND(NOT(AND(D9="retain",E9="statistical_results")),I9<>"",NOT(EXACT(I9,"not_applicable"))),AND(NOT(AND(D9="retain",E9="statistical_results")),J9<>"",NOT(EXACT(J9,"not_applicable"))),AND(NOT(AND(D9="retain",OR(E9="report_internal_inconsistency",E9="plan_material"))),K9<>"",NOT(EXACT(K9,"not_applicable"))),AND(NOT(AND(D9="retain",E9="protocol_report")),L9<>"",NOT(EXACT(L9,"not_applicable")))),"CLEAR INACTIVE VALUES",IF(OR(NOT(OR(EXACT(D9,"retain"),EXACT(D9,"exclude"),EXACT(D9,"discuss"))),NOT(OR(EXACT(E9,"statistical_results"),EXACT(E9,"report_internal_inconsistency"),EXACT(E9,"plan_material"),EXACT(E9,"protocol_report"))),AND(AND(D9="retain",E9="statistical_results"),NOT(OR(EXACT(H9,"confirmed_issue"),EXACT(H9,"probable_issue"),EXACT(H9,"not_issue"),EXACT(H9,"indeterminate")))),AND(AND(D9="retain",E9="statistical_results"),NOT(OR(EXACT(I9,"substantive"),EXACT(I9,"minor_presentation"),EXACT(I9,"indeterminate")))),AND(AND(D9="retain",E9="statistical_results"),J9<>"",NOT(OR(EXACT(J9,"direct"),EXACT(J9,"possible"),EXACT(J9,"unlikely"),EXACT(J9,"unknown")))),AND(AND(D9="retain",OR(E9="report_internal_inconsistency",E9="plan_material")),NOT(OR(EXACT(K9,"substantive_inconsistency"),EXACT(K9,"minor_presentation"),EXACT(K9,"non_inconsistency"),EXACT(K9,"indeterminate")))),AND(AND(D9="retain",E9="protocol_report"),L9<>"",NOT(OR(EXACT(L9,"substantive_difference"),EXACT(L9,"minor_presentation"),EXACT(L9,"version_timing"),EXACT(L9,"non_inconsistency"),EXACT(L9,"indeterminate"))))),"CHECK FIELDS",IF(AND(F9<>"",NOT(OR(EXACT(F9,"no"),EXACT(F9,"primary_done")))),"CHECK COMPLETE",IF(EXACT(F9,"primary_done"),"PRIMARY READY","PRIMARY DRAFT")))))),"CHECK INPUT / KEY") | H9: =IF(AND(OR(D9="retain",D9=""),E9="statistical_results"),"","not_applicable") | I9: =IF(AND(OR(D9="retain",D9=""),E9="statistical_results"),"","not_applicable") | J9: =IF(AND(OR(D9="retain",D9=""),E9="statistical_results"),"","not_applicable") | K9: =IF(AND(OR(D9="retain",D9=""),OR(E9="report_internal_inconsistency",E9="plan_material")),"","not_applicable") | L9: substantive_difference | R9: Protocol secondary endpoint 'technique's failure' = 28-day mortality or regurgitation or procedural failure. The article lists 'rate of BMV or ETI failure' and reports only procedural failure (69/1028 vs 21/996); the composite is not reported. The AI's 27 > 21 bound is invalid: 54/1022 are ETI survivors, not deaths. Retain as a descriptive plan-report endpoint difference, not discuss.

Sheet C_jama.2018.0948
A1: Candidate key | B1: Candidate title | C1: Source location | D1: Disposition | E1: Review domain (AI suggestion; editable) | F1: Complete | G1: Validation hint | H1: Statistcal_or_numerical issue | I1: Substantiveness | J1: Downstream impact | K1: Report-internal or planning-material inconsistency | L1: Protocol interpretation | R1: Notes (optional)
A2: 2018::jama.2018.0948::C001 | B2: Inclusive versus exclusive fluid threshold in the SCD definition | C2: main article — PDF p. 4; Supplement 1 Table 5 — PDF p. 24; Supplement 3 eTable 1 — PDF p. 6. | D2: retain | E2: protocol_report | F2: primary_done | G2: =IFERROR(IF(LEN(TRIM(CLEAN(SUBSTITUTE(Setup!$B$2,CHAR(160)," "))))=0,"CHECK REVIEWER ID",IF(OR(A2="",COUNTIF($A$2:$A$8,A2)<>1,LEFT(A2,LEN("2018::jama.2018.0948::"))<>"2018::jama.2018.0948::"),"CHECK KEY",IF(OR(AND(NOT(AND(D2="retain",E2="statistical_results")),H2<>"",NOT(EXACT(H2,"not_applicable"))),AND(NOT(AND(D2="retain",E2="statistical_results")),I2<>"",NOT(EXACT(I2,"not_applicable"))),AND(NOT(AND(D2="retain",E2="statistical_results")),J2<>"",NOT(EXACT(J2,"not_applicable"))),AND(NOT(AND(D2="retain",OR(E2="report_internal_inconsistency",E2="plan_material"))),K2<>"",NOT(EXACT(K2,"not_applicable"))),AND(NOT(AND(D2="retain",E2="protocol_report")),L2<>"",NOT(EXACT(L2,"not_applicable")))),"CLEAR INACTIVE VALUES",IF(OR(NOT(OR(EXACT(D2,"retain"),EXACT(D2,"exclude"),EXACT(D2,"discuss"))),NOT(OR(EXACT(E2,"statistical_results"),EXACT(E2,"report_internal_inconsistency"),EXACT(E2,"plan_material"),EXACT(E2,"protocol_report"))),AND(AND(D2="retain",E2="statistical_results"),NOT(OR(EXACT(H2,"confirmed_issue"),EXACT(H2,"probable_issue"),EXACT(H2,"not_issue"),EXACT(H2,"indeterminate")))),AND(AND(D2="retain",E2="statistical_results"),NOT(OR(EXACT(I2,"substantive"),EXACT(I2,"minor_presentation"),EXACT(I2,"indeterminate")))),AND(AND(D2="retain",E2="statistical_results"),J2<>"",NOT(OR(EXACT(J2,"direct"),EXACT(J2,"possible"),EXACT(J2,"unlikely"),EXACT(J2,"unknown")))),AND(AND(D2="retain",OR(E2="report_internal_inconsistency",E2="plan_material")),NOT(OR(EXACT(K2,"substantive_inconsistency"),EXACT(K2,"minor_presentation"),EXACT(K2,"non_inconsistency"),EXACT(K2,"indeterminate")))),AND(AND(D2="retain",E2="protocol_report"),L2<>"",NOT(OR(EXACT(L2,"substantive_difference"),EXACT(L2,"minor_presentation"),EXACT(L2,"version_timing"),EXACT(L2,"non_inconsistency"),EXACT(L2,"indeterminate"))))),"CHECK FIELDS",IF(AND(F2<>"",NOT(OR(EXACT(F2,"no"),EXACT(F2,"primary_done")))),"CHECK COMPLETE",IF(EXACT(F2,"primary_done"),"PRIMARY READY","PRIMARY DRAFT")))))),"CHECK INPUT / KEY") | H2: =IF(AND(OR(D2="retain",D2=""),E2="statistical_results"),"","not_applicable") | I2: =IF(AND(OR(D2="retain",D2=""),E2="statistical_results"),"","not_applicable") | J2: =IF(AND(OR(D2="retain",D2=""),E2="statistical_results"),"","not_applicable") | K2: =IF(AND(OR(D2="retain",D2=""),OR(E2="report_internal_inconsistency",E2="plan_material")),"","not_applicable") | L2: indeterminate | R2: SCDE fluid component: article p.4 says boluses of '60 mL/kg or greater' in 12 h; protocol Table 5 (p.24) and Supplement 3 eTable 1 say '>60 ml/kg'. Protocol Table 5 also leaves exactly 60 outside both its <60 and >60 bands. Because 3 x 20 mL/kg = 60 is a common cumulative volume, the boundary may matter, but which rule was applied is not documented.
A3: 2018::jama.2018.0948::C002 | B3: Mortality absolute-risk-reduction percent/unit conflict | C3: Supplement 1 — PDF p. 1, p. 14, p. 29; main article — PDF p. 4. | D3: retain | E3: plan_material | F3: primary_done | G3: =IFERROR(IF(LEN(TRIM(CLEAN(SUBSTITUTE(Setup!$B$2,CHAR(160)," "))))=0,"CHECK REVIEWER ID",IF(OR(A3="",COUNTIF($A$2:$A$8,A3)<>1,LEFT(A3,LEN("2018::jama.2018.0948::"))<>"2018::jama.2018.0948::"),"CHECK KEY",IF(OR(AND(NOT(AND(D3="retain",E3="statistical_results")),H3<>"",NOT(EXACT(H3,"not_applicable"))),AND(NOT(AND(D3="retain",E3="statistical_results")),I3<>"",NOT(EXACT(I3,"not_applicable"))),AND(NOT(AND(D3="retain",E3="statistical_results")),J3<>"",NOT(EXACT(J3,"not_applicable"))),AND(NOT(AND(D3="retain",OR(E3="report_internal_inconsistency",E3="plan_material"))),K3<>"",NOT(EXACT(K3,"not_applicable"))),AND(NOT(AND(D3="retain",E3="protocol_report")),L3<>"",NOT(EXACT(L3,"not_applicable")))),"CLEAR INACTIVE VALUES",IF(OR(NOT(OR(EXACT(D3,"retain"),EXACT(D3,"exclude"),EXACT(D3,"discuss"))),NOT(OR(EXACT(E3,"statistical_results"),EXACT(E3,"report_internal_inconsistency"),EXACT(E3,"plan_material"),EXACT(E3,"protocol_report"))),AND(AND(D3="retain",E3="statistical_results"),NOT(OR(EXACT(H3,"confirmed_issue"),EXACT(H3,"probable_issue"),EXACT(H3,"not_issue"),EXACT(H3,"indeterminate")))),AND(AND(D3="retain",E3="statistical_results"),NOT(OR(EXACT(I3,"substantive"),EXACT(I3,"minor_presentation"),EXACT(I3,"indeterminate")))),AND(AND(D3="retain",E3="statistical_results"),J3<>"",NOT(OR(EXACT(J3,"direct"),EXACT(J3,"possible"),EXACT(J3,"unlikely"),EXACT(J3,"unknown")))),AND(AND(D3="retain",OR(E3="report_internal_inconsistency",E3="plan_material")),NOT(OR(EXACT(K3,"substantive_inconsistency"),EXACT(K3,"minor_presentation"),EXACT(K3,"non_inconsistency"),EXACT(K3,"indeterminate")))),AND(AND(D3="retain",E3="protocol_report"),L3<>"",NOT(OR(EXACT(L3,"substantive_difference"),EXACT(L3,"minor_presentation"),EXACT(L3,"version_timing"),EXACT(L3,"non_inconsistency"),EXACT(L3,"indeterminate"))))),"CHECK FIELDS",IF(AND(F3<>"",NOT(OR(EXACT(F3,"no"),EXACT(F3,"primary_done")))),"CHECK COMPLETE",IF(EXACT(F3,"primary_done"),"PRIMARY READY","PRIMARY DRAFT")))))),"CHECK INPUT / KEY") | H3: =IF(AND(OR(D3="retain",D3=""),E3="statistical_results"),"","not_applicable") | I3: =IF(AND(OR(D3="retain",D3=""),E3="statistical_results"),"","not_applicable") | J3: =IF(AND(OR(D3="retain",D3=""),E3="statistical_results"),"","not_applicable") | K3: minor_presentation | L3: =IF(AND(OR(D3="retain",D3=""),E3="protocol_report"),"","not_applicable") | R3: Protocol power text: summary p.1 '0.9 deaths/1000', section 2.11 p.14 'Absolute Risk Reduction 0.09%', but Power appendix p.29 says the 18% RRR 'corresponds to an absolute risk reduction of 0.9%'. 5.1/1000 x 0.178 = 0.91/1000 = 0.09%, so 0.9% is a tenfold unit typo. The article (p.4) correctly uses 0.9 per 1000. Minor.
A4: 2018::jama.2018.0948::C003 | B4: Cardiac-arrest events assigned incompatible resuscitation-scale categories | C4: Supplement 1 — PDF p. 11, Table 5 — PDF p. 24, Table 6 legend — PDF p. 27. | D4: retain | E4: plan_material | F4: primary_done | G4: =IFERROR(IF(LEN(TRIM(CLEAN(SUBSTITUTE(Setup!$B$2,CHAR(160)," "))))=0,"CHECK REVIEWER ID",IF(OR(A4="",COUNTIF($A$2:$A$8,A4)<>1,LEFT(A4,LEN("2018::jama.2018.0948::"))<>"2018::jama.2018.0948::"),"CHECK KEY",IF(OR(AND(NOT(AND(D4="retain",E4="statistical_results")),H4<>"",NOT(EXACT(H4,"not_applicable"))),AND(NOT(AND(D4="retain",E4="statistical_results")),I4<>"",NOT(EXACT(I4,"not_applicable"))),AND(NOT(AND(D4="retain",E4="statistical_results")),J4<>"",NOT(EXACT(J4,"not_applicable"))),AND(NOT(AND(D4="retain",OR(E4="report_internal_inconsistency",E4="plan_material"))),K4<>"",NOT(EXACT(K4,"not_applicable"))),AND(NOT(AND(D4="retain",E4="protocol_report")),L4<>"",NOT(EXACT(L4,"not_applicable")))),"CLEAR INACTIVE VALUES",IF(OR(NOT(OR(EXACT(D4,"retain"),EXACT(D4,"exclude"),EXACT(D4,"discuss"))),NOT(OR(EXACT(E4,"statistical_results"),EXACT(E4,"report_internal_inconsistency"),EXACT(E4,"plan_material"),EXACT(E4,"protocol_report"))),AND(AND(D4="retain",E4="statistical_results"),NOT(OR(EXACT(H4,"confirmed_issue"),EXACT(H4,"probable_issue"),EXACT(H4,"not_issue"),EXACT(H4,"indeterminate")))),AND(AND(D4="retain",E4="statistical_results"),NOT(OR(EXACT(I4,"substantive"),EXACT(I4,"minor_presentation"),EXACT(I4,"indeterminate")))),AND(AND(D4="retain",E4="statistical_results"),J4<>"",NOT(OR(EXACT(J4,"direct"),EXACT(J4,"possible"),EXACT(J4,"unlikely"),EXACT(J4,"unknown")))),AND(AND(D4="retain",OR(E4="report_internal_inconsistency",E4="plan_material")),NOT(OR(EXACT(K4,"substantive_inconsistency"),EXACT(K4,"minor_presentation"),EXACT(K4,"non_inconsistency"),EXACT(K4,"indeterminate")))),AND(AND(D4="retain",E4="protocol_report"),L4<>"",NOT(OR(EXACT(L4,"substantive_difference"),EXACT(L4,"minor_presentation"),EXACT(L4,"version_timing"),EXACT(L4,"non_inconsistency"),EXACT(L4,"indeterminate"))))),"CHECK FIELDS",IF(AND(F4<>"",NOT(OR(EXACT(F4,"no"),EXACT(F4,"primary_done")))),"CHECK COMPLETE",IF(EXACT(F4,"primary_done"),"PRIMARY READY","PRIMARY DRAFT")))))),"CHECK INPUT / KEY") | H4: =IF(AND(OR(D4="retain",D4=""),E4="statistical_results"),"","not_applicable") | I4: =IF(AND(OR(D4="retain",D4=""),E4="statistical_results"),"","not_applicable") | J4: =IF(AND(OR(D4="retain",D4=""),E4="statistical_results"),"","not_applicable") | K4: minor_presentation | L4: =IF(AND(OR(D4="retain",D4=""),E4="protocol_report"),"","not_applicable") | R4: Protocol p.11 defines cardiac arrests for preventability review as ratings 6 or 7 on the seven-point Children's Resuscitation Intensity Scale (Table 5: [6] CPR, [7] death). The Table 6 legend (p.27) says events 'that include a cardiac arrest (scale rating 4 or 5)'. Ratings 4-5 on Table 5 are circulatory/late transfer, not arrest. Likely a stale legend; intent clear from wording.
A5: 2018::jama.2018.0948::C004 | B5: Preventability threshold excludes and includes rating 4 | C5: Supplement 1 — PDF p. 11, Table 7 — PDF p. 28; Supplement 3 eTable 1 — PDF p. 6; main article — PDF p. 7. | D5: retain | E5: plan_material | F5: primary_done | G5: =IFERROR(IF(LEN(TRIM(CLEAN(SUBSTITUTE(Setup!$B$2,CHAR(160)," "))))=0,"CHECK REVIEWER ID",IF(OR(A5="",COUNTIF($A$2:$A$8,A5)<>1,LEFT(A5,LEN("2018::jama.2018.0948::"))<>"2018::jama.2018.0948::"),"CHECK KEY",IF(OR(AND(NOT(AND(D5="retain",E5="statistical_results")),H5<>"",NOT(EXACT(H5,"not_applicable"))),AND(NOT(AND(D5="retain",E5="statistical_results")),I5<>"",NOT(EXACT(I5,"not_applicable"))),AND(NOT(AND(D5="retain",E5="statistical_results")),J5<>"",NOT(EXACT(J5,"not_applicable"))),AND(NOT(AND(D5="retain",OR(E5="report_internal_inconsistency",E5="plan_material"))),K5<>"",NOT(EXACT(K5,"not_applicable"))),AND(NOT(AND(D5="retain",E5="protocol_report")),L5<>"",NOT(EXACT(L5,"not_applicable")))),"CLEAR INACTIVE VALUES",IF(OR(NOT(OR(EXACT(D5,"retain"),EXACT(D5,"exclude"),EXACT(D5,"discuss"))),NOT(OR(EXACT(E5,"statistical_results"),EXACT(E5,"report_internal_inconsistency"),EXACT(E5,"plan_material"),EXACT(E5,"protocol_report"))),AND(AND(D5="retain",E5="statistical_results"),NOT(OR(EXACT(H5,"confirmed_issue"),EXACT(H5,"probable_issue"),EXACT(H5,"not_issue"),EXACT(H5,"indeterminate")))),AND(AND(D5="retain",E5="statistical_results"),NOT(OR(EXACT(I5,"substantive"),EXACT(I5,"minor_presentation"),EXACT(I5,"indeterminate")))),AND(AND(D5="retain",E5="statistical_results"),J5<>"",NOT(OR(EXACT(J5,"direct"),EXACT(J5,"possible"),EXACT(J5,"unlikely"),EXACT(J5,"unknown")))),AND(AND(D5="retain",OR(E5="report_internal_inconsistency",E5="plan_material")),NOT(OR(EXACT(K5,"substantive_inconsistency"),EXACT(K5,"minor_presentation"),EXACT(K5,"non_inconsistency"),EXACT(K5,"indeterminate")))),AND(AND(D5="retain",E5="protocol_report"),L5<>"",NOT(OR(EXACT(L5,"substantive_difference"),EXACT(L5,"minor_presentation"),EXACT(L5,"version_timing"),EXACT(L5,"non_inconsistency"),EXACT(L5,"indeterminate"))))),"CHECK FIELDS",IF(AND(F5<>"",NOT(OR(EXACT(F5,"no"),EXACT(F5,"primary_done")))),"CHECK COMPLETE",IF(EXACT(F5,"primary_done"),"PRIMARY READY","PRIMARY DRAFT")))))),"CHECK INPUT / KEY") | H5: =IF(AND(OR(D5="retain",D5=""),E5="statistical_results"),"","not_applicable") | I5: =IF(AND(OR(D5="retain",D5=""),E5="statistical_results"),"","not_applicable") | J5: =IF(AND(OR(D5="retain",D5=""),E5="statistical_results"),"","not_applicable") | K5: minor_presentation | L5: =IF(AND(OR(D5="retain",D5=""),E5="protocol_report"),"","not_applicable") | R5: Protocol p.11: 'consensus rating of at >4 will be regarded as potentially preventable', then immediately lists ratings 4, 5 and 6 as preventable; Table 7 legend (p.28) says 'a rating of 4 or more'. Supplement 3 also uses 4-6. The '>4' is a typo within one paragraph whose next sentence states the intended inclusive rule. Minor.
A6: 2018::jama.2018.0948::C005 | B6: The same SCDE reference count is labelled annual and two-year | C6: Supplement 1 — PDF p. 14 and PDF p. 30. | D6: retain | E6: plan_material | F6: primary_done | G6: =IFERROR(IF(LEN(TRIM(CLEAN(SUBSTITUTE(Setup!$B$2,CHAR(160)," "))))=0,"CHECK REVIEWER ID",IF(OR(A6="",COUNTIF($A$2:$A$8,A6)<>1,LEFT(A6,LEN("2018::jama.2018.0948::"))<>"2018::jama.2018.0948::"),"CHECK KEY",IF(OR(AND(NOT(AND(D6="retain",E6="statistical_results")),H6<>"",NOT(EXACT(H6,"not_applicable"))),AND(NOT(AND(D6="retain",E6="statistical_results")),I6<>"",NOT(EXACT(I6,"not_applicable"))),AND(NOT(AND(D6="retain",E6="statistical_results")),J6<>"",NOT(EXACT(J6,"not_applicable"))),AND(NOT(AND(D6="retain",OR(E6="report_internal_inconsistency",E6="plan_material"))),K6<>"",NOT(EXACT(K6,"not_applicable"))),AND(NOT(AND(D6="retain",E6="protocol_report")),L6<>"",NOT(EXACT(L6,"not_applicable")))),"CLEAR INACTIVE VALUES",IF(OR(NOT(OR(EXACT(D6,"retain"),EXACT(D6,"exclude"),EXACT(D6,"discuss"))),NOT(OR(EXACT(E6,"statistical_results"),EXACT(E6,"report_internal_inconsistency"),EXACT(E6,"plan_material"),EXACT(E6,"protocol_report"))),AND(AND(D6="retain",E6="statistical_results"),NOT(OR(EXACT(H6,"confirmed_issue"),EXACT(H6,"probable_issue"),EXACT(H6,"not_issue"),EXACT(H6,"indeterminate")))),AND(AND(D6="retain",E6="statistical_results"),NOT(OR(EXACT(I6,"substantive"),EXACT(I6,"minor_presentation"),EXACT(I6,"indeterminate")))),AND(AND(D6="retain",E6="statistical_results"),J6<>"",NOT(OR(EXACT(J6,"direct"),EXACT(J6,"possible"),EXACT(J6,"unlikely"),EXACT(J6,"unknown")))),AND(AND(D6="retain",OR(E6="report_internal_inconsistency",E6="plan_material")),NOT(OR(EXACT(K6,"substantive_inconsistency"),EXACT(K6,"minor_presentation"),EXACT(K6,"non_inconsistency"),EXACT(K6,"indeterminate")))),AND(AND(D6="retain",E6="protocol_report"),L6<>"",NOT(OR(EXACT(L6,"substantive_difference"),EXACT(L6,"minor_presentation"),EXACT(L6,"version_timing"),EXACT(L6,"non_inconsistency"),EXACT(L6,"indeterminate"))))),"CHECK FIELDS",IF(AND(F6<>"",NOT(OR(EXACT(F6,"no"),EXACT(F6,"primary_done")))),"CHECK COMPLETE",IF(EXACT(F6,"primary_done"),"PRIMARY READY","PRIMARY DRAFT")))))),"CHECK INPUT / KEY") | H6: =IF(AND(OR(D6="retain",D6=""),E6="statistical_results"),"","not_applicable") | I6: =IF(AND(OR(D6="retain",D6=""),E6="statistical_results"),"","not_applicable") | J6: =IF(AND(OR(D6="retain",D6=""),E6="statistical_results"),"","not_applicable") | K6: minor_presentation | L6: =IF(AND(OR(D6="retain",D6=""),E6="protocol_report"),"","not_applicable") | R6: Protocol p.14: '1052 Urgent ICU admissions/ year' from 4 Ontario hospitals; appendix p.30: the same 1052 urgent PICU admissions occurred over two years after 31 Jan 2007. The SCDE assumption (2 per 1000 patient-days) reproduces only with the 2-year reading: 1052 x 0.40 / (55963 x 4) x 1000 = 1.88. So '/year' is a label error that did not propagate into the planning rate.
