Workbook

Sheet Start
A1: Step | B1: Instructions
A2: Release | B2: TEST ONLY - synthetic answers; never deliver as a review template
A3: Coordinator | B3: Assign two different people to the two role files. Distribute only the corresponding file to each person. The role label is not a person ID. This standalone workbook cannot verify the identity assigned to the other file.
A4: 1. Save a working copy | B4: Use Excel Save As before entering answers. Keep ordinary Excel backups. Setup B2: enter your own reviewer ID or name (required, no leading/trailing whitespace). B3: optional full name. B4/B5 identify this role and year.
A5: 2. Read candidate and evidence | B5: Start with Papers. Open a C_ paper sheet; click its key for Evidence, or the Candidates rationale if no Evidence rows exist. Filter Candidates, Evidence and Links by key; source links open original files. Structured evidence is embedded. Source PDFs require the repository folders to remain accessible.
A6: 3. Enter your assessment | B6: Choose D (retain / exclude / discuss), confirm or edit the AI-suggested E domain, answer applicable H-L and add optional English notes in R. Yellow = common/required; blue = optional; gray = inactive. M-Q are empty hidden spacers. Read Codebook for meanings.
A7: 4. Finish a row | B7: After manual review, set F=primary_done. G must show PRIMARY READY. Use F=no while drafting. Dropdowns help entry; G also checks pasted values. The complete flag alone never makes invalid fields ready.
A8: 5. Inspect progress | B8: Checks shows total, ready, unfinished and discuss/unresolved rows. Open Decisions and filter readiness for remaining work, then return to the matching C_ sheet. All calculations run in Excel; no refresh, terminal, scripts or export commands.
A9: 6. Save and deliver | B9: When Checks says PRIMARY READY, save the completed workbook and deliver this file. Built-in Decisions, Paper_counts and Protocol_plan_table update in Excel. Keep your backups; do not regenerate or overwrite completed review files.
A10: Changing completed answers | B10: Manually reset F to no BEFORE editing an already completed row. Review the revised row again, then set primary_done. Excel formulas cannot automatically erase an entered completion flag.
A11: Defaults / changing branches | B11: Untouched H-L formulas show blank for potentially applicable fields while D is blank or retain, and not_applicable otherwise. Choosing a value overwrites its formula. Changing D/E never clears a literal answer: clear inactive entries or use not_applicable, then answer newly required fields. A blank is blank.
A12: Required and optional | B12: Retained statistical_results: H and I required; J optional. Retained report_internal_inconsistency or plan_material: K required. Retained protocol_report: L optional, no extra required judgment. Exclude/discuss: all H-L inactive. Active optional fields may be blank, but may not contain not_applicable.
... A17: Source access | B17: Original href text is preserved in Candidates and Links; clickable targets are adjusted for this file location. Embedded source and evidence text remains available if original documents are not distributed.

Sheet Setup
A1: Field | B1: Value
A2: Reviewer ID or name (required) | B2: TEST_ONLY_REVIEWER
A3: Reviewer name (optional) | B3: Synthetic calculation fixture
A4: Reviewer role | B4: R_A
A5: Year | B5: 2019
A6: Schema | B6: xlsx-adjudication-independent-primary-2.3.1
A7: Identity guidance | B7: Enter your own ID or name in B2. Do not enter the role label as your identity. B3 is optional.

Sheet Checks
A1: Check | B1: Result
A2: Reviewer role | B2: =Setup!$B$2
A3: Total candidates | B3: 1
A4: Primary ready | B4: =COUNTIF(Decisions!$G$2:$G$2,"PRIMARY READY")
A5: Unfinished | B5: =B3-B4
A6: Discuss / unresolved | B6: =COUNTIF(Decisions!$K$2:$K$2,"discuss")
A7: Workflow status | B7: =IF(B4=B3,"PRIMARY READY","ACTION NEEDED")
A8: Ready discuss rows | B8: =COUNTIFS(Decisions!$K$2:$K$2,"discuss",Decisions!$G$2:$G$2,"PRIMARY READY")
A9: Papers with counts | B9: =COUNTIF(Paper_counts!$H$2:$H$2,"yes")
A10: Next action | B10: =IF(B7="PRIMARY READY",IF(B6>0,"Save and deliver this independent review. Discuss rows remain unresolved; affected paper counts are blank.","Save and deliver this independent review with its built-in results."),"Filter Decisions by readiness, return to the C_ sheet, correct entries and manually confirm F.")
A11: Scope | B11: Entry checks and independent completion only. Discuss is not a confirmed absence of error. Review the evidence; preserve ordinary Excel backups.

Sheet Papers
A1: Paper | B1: Review worksheet | C1: Candidates
A2: jama.2019.10517 | B2: C_jama.2019.10517 | C2: 1

Sheet C_jama.2019.10517
A1: Candidate key | B1: Candidate title | C1: Source location | D1: Disposition | E1: Review domain (AI suggestion; editable) | F1: Complete | G1: Validation hint | H1: Statistical/numerical issue | I1: Substantiveness | J1: Downstream impact | K1: Report-internal or planning-material inconsistency | L1: Protocol interpretation | R1: Notes (optional)
A2: 2019::jama.2019.10517::C001 | B2: Table 5 absolute difference does not reproduce from the displayed counts | C2: jama_flint_2019_oi_190079.pdf — PDF p. 9, Table 5, total-cholesterol and LDL rows. | D2: retain | E2: statistical_results | F2: primary_done | G2: =IFERROR(IF(OR(NOT(EXACT(Setup!$B$4,"R_A")),Setup!$B$5<>2019),"CHECK SETUP",IF(OR(LEN(TRIM(CLEAN(SUBSTITUTE(Setup!$B$2,CHAR(160)," "))))=0,Setup!$B$2<>TRIM(CLEAN(SUBSTITUTE(Setup!$B$2,CHAR(160)," ")))),"CHECK REVIEWER ID",IF(OR(A2="",COUNTIF($A$2:$A$2,A2)<>1,COUNTIFS(Candidates!$G$2:$G$2,A2,Candidates!$K$2:$K$2,"jama.2019.10517")<>1),"CHECK KEY",IF(NOT(OR(EXACT(F2,"no"),EXACT(F2,"primary_done"),EXACT(F2,""))),"CHECK COMPLETE FLAG",IF(OR(D2="",E2=""),"MISSING D / E",IF(OR(NOT(OR(EXACT(D2,"retain"),EXACT(D2,"exclude"),EXACT(D2,"discuss"))),NOT(OR(EXACT(E2,"statistical_results"),EXACT(E2,"report_internal_inconsistency"),EXACT(E2,"plan_material"),EXACT(E2,"protocol_report")))),"INVALID D / E",IF(OR(AND(NOT(AND(D2="retain",E2="statistical_results")),H2<>"",NOT(EXACT(H2,"not_applicable"))),AND(NOT(AND(D2="retain",E2="statistical_results")),I2<>"",NOT(EXACT(I2,"not_applicable"))),AND(NOT(AND(D2="retain",E2="statistical_results")),J2<>"",NOT(EXACT(J2,"not_applicable"))),AND(NOT(AND(D2="retain",OR(E2="report_internal_inconsistency",E2="plan_material"))),K2<>"",NOT(EXACT(K2,"not_applicable"))),AND(NOT(AND(D2="retain",E2="protocol_report")),L2<>"",NOT(EXACT(L2,"not_applicable")))),"CLEAR INACTIVE VALUES",IF(OR(AND(AND(D2="retain",E2="statistical_results"),OR(H2="",EXACT(H2,"not_applicable"))),AND(AND(D2="retain",E2="statistical_results"),OR(I2="",EXACT(I2,"not_applicable"))),AND(AND(D2="retain",OR(E2="report_internal_inconsistency",E2="plan_material")),OR(K2="",EXACT(K2,"not_applicable")))),"MISSING REQUIRED JUDGMENT",IF(OR(AND(AND(D2="retain",E2="statistical_results"),H2<>"",NOT(OR(EXACT(H2,"confirmed_issue"),EXACT(H2,"probable_issue"),EXACT(H2,"not_issue"),EXACT(H2,"indeterminate")))),AND(AND(D2="retain",E2="statistical_results"),I2<>"",NOT(OR(EXACT(I2,"substantive"),EXACT(I2,"minor_presentation"),EXACT(I2,"indeterminate")))),AND(AND(D2="retain",E2="statistical_results"),J2<>"",NOT(OR(EXACT(J2,"direct"),EXACT(J2,"possible"),EXACT(J2,"unlikely"),EXACT(J2,"unknown")))),AND(AND(D2="retain",OR(E2="report_internal_inconsistency",E2="plan_material")),K2<>"",NOT(OR(EXACT(K2,"substantive_inconsistency"),EXACT(K2,"minor_presentation"),EXACT(K2,"non_inconsistency"),EXACT(K2,"indeterminate")))),AND(AND(D2="retain",E2="protocol_report"),L2<>"",NOT(OR(EXACT(L2,"substantive_difference"),EXACT(L2,"minor_presentation"),EXACT(L2,"version_timing"),EXACT(L2,"non_inconsistency"),EXACT(L2,"indeterminate"))))),"INVALID ACTIVE JUDGMENT",IF(F2<>"primary_done","PRIMARY DRAFT","PRIMARY READY")))))))))),"CHECK INPUT ERROR") | H2: confirmed_issue | I2: substantive | J2: =IF(AND(OR(D2="retain",D2=""),E2="statistical_results"),"","not_applicable") | K2: =IF(AND(OR(D2="retain",D2=""),OR(E2="report_internal_inconsistency",E2="plan_material")),"","not_applicable") | L2: =IF(AND(OR(D2="retain",D2=""),E2="protocol_report"),"","not_applicable") | R2: TEST note for 2019::jama.2019.10517::C001

Sheet Decisions
A1: year | B1: paper | C1: key | D1: relationship | E1: reviewerRole | F1: reviewerId | G1: readiness | H1: outcome | I1: aiDisposition | J1: aiDomain | K1: disposition | L1: domain | M1: statisticalIssueStatus | N1: substantiveStatus | O1: downstreamImpact | P1: internalStatus | Q1: protocolInterpretation | R1: notes | S1: reviewerName | T1: complete | U1: unresolved
A2: 2019 | B2: jama.2019.10517 | C2: 2019::jama.2019.10517::C001 | D2: S_W | E2: =Setup!$B$2 | F2: =IF(Setup!$B$2="","",Setup!$B$2) | G2: =IFERROR(IF(COUNTIF('C_jama.2019.10517'!$A$2:$A$2,C2)<>1,"CHECK KEY",INDEX('C_jama.2019.10517'!$G$2:$G$2,MATCH(C2,'C_jama.2019.10517'!$A$2:$A$2,0))),"CHECK KEY") | H2: =IF(OR(G2<>"PRIMARY READY",K2="discuss"),"",IF(K2<>"retain","not_eligible",IF(D2="P_R","protocol_descriptive",IF(D2="P_P","plan_descriptive",IF(AND(OR(D2="S_C",D2="S_W"),L2="statistical_results",OR(M2="confirmed_issue",M2="probable_issue"),N2="substantive"),"primary_temporal",IF(AND(OR(D2="S_C",D2="S_W"),L2="report_internal_inconsistency",P2="substantive_inconsistency"),"secondary_temporal","not_eligible")))))) | I2: retain | J2: statistical_results | K2: =IFERROR(IF(INDEX('C_jama.2019.10517'!$D$2:$D$2,MATCH(C2,'C_jama.2019.10517'!$A$2:$A$2,0))="","",INDEX('C_jama.2019.10517'!$D$2:$D$2,MATCH(C2,'C_jama.2019.10517'!$A$2:$A$2,0))),"") | L2: =IFERROR(IF(INDEX('C_jama.2019.10517'!$E$2:$E$2,MATCH(C2,'C_jama.2019.10517'!$A$2:$A$2,0))="","",INDEX('C_jama.2019.10517'!$E$2:$E$2,MATCH(C2,'C_jama.2019.10517'!$A$2:$A$2,0))),"") | M2: =IFERROR(IF(AND(K2="retain",L2="statistical_results"),IF(INDEX('C_jama.2019.10517'!$H$2:$H$2,MATCH(C2,'C_jama.2019.10517'!$A$2:$A$2,0))="","",INDEX('C_jama.2019.10517'!$H$2:$H$2,MATCH(C2,'C_jama.2019.10517'!$A$2:$A$2,0))),"not_applicable"),"") | N2: =IFERROR(IF(AND(K2="retain",L2="statistical_results"),IF(INDEX('C_jama.2019.10517'!$I$2:$I$2,MATCH(C2,'C_jama.2019.10517'!$A$2:$A$2,0))="","",INDEX('C_jama.2019.10517'!$I$2:$I$2,MATCH(C2,'C_jama.2019.10517'!$A$2:$A$2,0))),"not_applicable"),"") | O2: =IFERROR(IF(AND(K2="retain",L2="statistical_results"),IF(INDEX('C_jama.2019.10517'!$J$2:$J$2,MATCH(C2,'C_jama.2019.10517'!$A$2:$A$2,0))="","",INDEX('C_jama.2019.10517'!$J$2:$J$2,MATCH(C2,'C_jama.2019.10517'!$A$2:$A$2,0))),"not_applicable"),"") | P2: =IFERROR(IF(AND(K2="retain",OR(L2="report_internal_inconsistency",L2="plan_material")),IF(INDEX('C_jama.2019.10517'!$K$2:$K$2,MATCH(C2,'C_jama.2019.10517'!$A$2:$A$2,0))="","",INDEX('C_jama.2019.10517'!$K$2:$K$2,MATCH(C2,'C_jama.2019.10517'!$A$2:$A$2,0))),"not_applicable"),"") | Q2: =IFERROR(IF(AND(K2="retain",L2="protocol_report"),IF(INDEX('C_jama.2019.10517'!$L$2:$L$2,MATCH(C2,'C_jama.2019.10517'!$A$2:$A$2,0))="","",INDEX('C_jama.2019.10517'!$L$2:$L$2,MATCH(C2,'C_jama.2019.10517'!$A$2:$A$2,0))),"not_applicable"),"") | R2: =IFERROR(IF(INDEX('C_jama.2019.10517'!$R$2:$R$2,MATCH(C2,'C_jama.2019.10517'!$A$2:$A$2,0))="","",INDEX('C_jama.2019.10517'!$R$2:$R$2,MATCH(C2,'C_jama.2019.10517'!$A$2:$A$2,0))),"") | S2: =IF(Setup!$B$3="","",Setup!$B$3) | T2: =IFERROR(IF(INDEX('C_jama.2019.10517'!$F$2:$F$2,MATCH(C2,'C_jama.2019.10517'!$A$2:$A$2,0))="","",INDEX('C_jama.2019.10517'!$F$2:$F$2,MATCH(C2,'C_jama.2019.10517'!$A$2:$A$2,0))),"") | U2: =IF(K2="discuss","yes","no")

Sheet Paper_counts
A1: year | B1: paper | C1: candidates | D1: primary_ready | E1: unfinished | F1: discuss_unresolved | G1: review_complete | H1: counts_available | I1: primary_temporal | J1: secondary_temporal | K1: protocol_descriptive | L1: plan_descriptive | M1: not_eligible
A2: 2019 | B2: jama.2019.10517 | C2: 1 | D2: =COUNTIFS(Decisions!$B$2:$B$2,B2,Decisions!$G$2:$G$2,"PRIMARY READY") | E2: =C2-D2 | F2: =COUNTIFS(Decisions!$B$2:$B$2,B2,Decisions!$K$2:$K$2,"discuss") | G2: =IF(D2=C2,"yes","no") | H2: =IF(AND(G2="yes",F2=0),"yes","no") | I2: =IF(H2<>"yes","",COUNTIFS(Decisions!$B$2:$B$2,B2,Decisions!$H$2:$H$2,"primary_temporal")) | J2: =IF(H2<>"yes","",COUNTIFS(Decisions!$B$2:$B$2,B2,Decisions!$H$2:$H$2,"secondary_temporal")) | K2: =IF(H2<>"yes","",COUNTIFS(Decisions!$B$2:$B$2,B2,Decisions!$H$2:$H$2,"protocol_descriptive")) | L2: =IF(H2<>"yes","",COUNTIFS(Decisions!$B$2:$B$2,B2,Decisions!$H$2:$H$2,"plan_descriptive")) | M2: =IF(H2<>"yes","",COUNTIFS(Decisions!$B$2:$B$2,B2,Decisions!$H$2:$H$2,"not_eligible"))

Sheet Protocol_plan_table
A1: year | B1: paper | C1: key | D1: relationship | E1: title | F1: statement | G1: readiness | H1: disposition | I1: domain | J1: interpretation | K1: internalStatus | L1: notes | M1: outcome | N1: reviewerRole | O1: reviewerId

Sheet Candidates
A1: additionalSensitivityExclude | B1: ambiguity | C1: broadPlanInvolved | D1: category | E1: currentReportCrossDocument | F1: id | G1: key | H1: legacyRelationship | I1: locations | J1: originalCrossDocument | K1: package | L1: planMechanism | M1: primary | N1: rationale | O1: reportHref | P1: reportPath | Q1: sourceId | R1: sourceStatus | S1: statement | T1: submissionInvolved | U1: subtype | V1: suggestedDomain | W1: title | X1: year | Y1: ai_source | Z1: ai_relationship | AA1: ai_domain | AB1: ai_disposition
A2: FALSE | B2: Truncation, unprinted denominators, or a distinct estimator could explain the small difference. | C2: FALSE | D2: Numeric or arithmetic inconsistency | E2: FALSE | F2: C001 | G2: 2019::jama.2019.10517::C001 | I2: jama_flint_2019_oi_190079.pdf — PDF p. 9, Table 5, total-cholesterol and LDL rows. | J2: FALSE | K2: jama.2019.10517 | M2: S_W | N2: Within main Table 5, 9/64 versus 6/62 yields 4.4 percentage points by ordinary one-decimal rounding, while two rows show 4.3. No plan comparator is involved. | O2: ../../2019/jama.2019.10517/.ai_paper_validation/final_report_1_5_1.html | P2: 2019/jama.2019.10517/.ai_paper_validation/final_report_1_5_1.md | Q2: C001 | R2: Pending Human Adjudication | S2: Table 5 prints an absolute unadjusted difference of 4.3% for two rows whose displayed counts and percentages yield approximately 4.4 percentage points under the ordinary raw-proportion calculation and nearest one-decimal rounding. Pending Human Adjudication. | T2: TRUE | U2: effect_arithmetic | V2: statistical_results | W2: Table 5 absolute difference does not reproduce from the displayed counts | X2: 2019 | Y2: meta_report/consistency_reclassification_2026-09-04/reclassified_candidates.json | Z2: S_W | AA2: statistical_results | AB2: retain

Sheet Evidence
A1: key | B1: order | C1: section | D1: text
A2: 2019::jama.2019.10517::C001 | B2: 0 | C2: Source evidence | D2: Each cited row prints 9/64 (14.1%) for sertraline plus olanzapine and 6/62 (9.7%) for sertraline plus placebo. Each prints 4.3 (-8 to 17.2) in the “Absolute Unadjusted Difference Between Groups, % (95% CI)” column.
A3: 2019::jama.2019.10517::C001 | B3: 1 | C3: Reported-versus-comparator | D3: Reported point value: 4.3%. Comparator: the first displayed raw proportion minus the second, (9/64 − 6/62) × 100, and independently 14.1 − 9.7 percentage points.
A4: 2019::jama.2019.10517::C001 | B4: 2 | C4: Calculation | D4: 9/64 = 14.0625% and 6/62 = 9.677419%; (9/64 − 6/62) × 100 = 4.38508065 percentage points, which is 4.4 to one decimal under nearest rounding. The displayed rounded percentages also give 14.1 − 9.7 = 4.4. The gap from the printed 4.3 is about 0.085 percentage point, exceeding a half-unit one-decimal rounding interval of 0.05.
A5: 2019::jama.2019.10517::C001 | B5: 3 | C5: Alternative source-grounded interpretations | D5: The source may have used truncation, undocumented row-specific denominators, a different estimator, or unprinted analysis-population inputs. The cited table does not identify any such basis. The repeated value could also be an intentional reuse of one result, but that does not establish how 4.3 was obtained.

Sheet Links
A1: key | B1: kind | C1: order | D1: label | E1: href
A2: 2019::jama.2019.10517::C001 | B2: sourceLinks | C2: 0 | D2: jama_flint_2019_oi_190079.pdf — PDF p. 9 | E2: ../../2019/jama.2019.10517/jama_flint_2019_oi_190079.pdf#page=9
A3: 2019::jama.2019.10517::C001 | B3: evidencePaths | C3: 0 | D3: 2019/jama.2019.10517/.ai_paper_validation/review_1_5_1/source_inventory.md | E3: ../../2019/jama.2019.10517/.ai_paper_validation/review_1_5_1/source_inventory.md

Sheet Relations
A1: key | B1: kind | C1: order | D1: relationship
A2: 2019::jama.2019.10517::C001 | B2: relations | C2: 0 | D2: S_W

Sheet Codebook
A1: Field name | B1: Option / value | C1: Requirement / scope | D1: Explanation and example | E1: Internal key
A2: Working method | B2: GUIDE | C2: Independent primary review | D2: No inherited blanks or control words. Keep the existing answers; edit directly. Blank = no answer; indeterminate/unknown = uncertain; not_applicable = inactive. Clear obsolete answers after changing a branch.
A3: Required judgments | B3: GUIDE | C3: Retain only | D3: statistical_results: issue + substantiveness; report_internal_inconsistency or plan_material: internalStatus. protocol_report: no extra required judgment; interpretation is optional.
A4: How to read this Codebook
A5: 1 | Common decisions and optional notes
A6: Disposition | B6: FIELD | C6: Required; all domains | D6: Keep, exclude, or defer for discussion. Blank means untouched, not discuss. No AI disposition is preselected. Enter your own independent assessment. | E6: disposition
B7: retain | C7: Option | D7: Retain candidate. After human review, keep this finding in the applicable review results; retaining a protocol discrepancy does not automatically confirm an issue.
B8: exclude | C8: Option | D8: Do not retain. The candidate has been assessed and should not remain as a finding, for example because the apparent mismatch has a satisfactory explanation.
B9: discuss | C9: Option | D9: Needs discussion. The reviewer has considered the candidate but cannot settle the disposition without further discussion. This is a decision to defer, not an untouched blank.
A10: Review domain | B10: FIELD | C10: Required; all domains | D10: Choose the assessment branch first. It controls automatic not_applicable defaults and which judgments are required. All four choices are available; the frozen document relationship code does not change. | E10: domain
B11: statistical_results | C11: Option | D11: Statistical results (S_C / S_W). Assess reported numbers, estimates, intervals, denominators or statistical claims in the current report materials.
B12: report_internal_inconsistency | C12: Option | D12: Report internal inconsistency (S_C / S_W). Assess inconsistencies within the main paper, within the updated supplement, or between the main paper and updated supplement. The name describes the report materials being compared; it is not restricted to nonstatistical content. Use statistical_results when specifically judging a statistical or numerical reporting issue.
B13: protocol_report | C13: Option | D13: Protocol-report (P_R). Assess whether planned and reported conduct or analyses meaningfully differ, using the compared materials. No search for acknowledgment or reasons for changes is required.
B14: plan_material | C14: Option | D14: Plan material (P_P). Assess an inconsistency involving planning materials themselves rather than a planned-versus-reported result. The original relationship code remains unchanged.
A15: Complete | B15: FIELD | C15: Independent primary review | D15: Use no while drafting, then primary_done after manual review. Before changing a completed row, reset F to no, review again, then mark primary_done. Formulas cannot erase a completion flag. | E15: reviewComplete
B16: no | C16: Option | D16: Draft. Independent primary review is not yet confirmed complete; AI suggestions and partially filled fields do not count as completed human review.
A17: Validation hint | B17: FIELD | C17: Calculated | D17: Calculated entry checks for this reviewer only. PRIMARY READY requires valid identity, key, fields and primary_done. Discuss can be ready and remains unresolved. Checks do not establish scientific accuracy. | E17: readiness
A18: Notes (optional) | B18: FIELD | C18: Optional | D18: Optional English context. Clearing removes the text; no inheritance and no control words. | E18: notes
A19: 2 | Statistical results: two required judgments
A20: Statistcal_or_numerical issue | B20: FIELD | C20: Required; retained statistical_results | D20: Does a statistical or numerical reporting issue exist? Example: a reported percentage conflicts with its stated numerator and denominator after checking definitions. Certainty is separate from importance. | E20: statisticalIssueStatus
B21: confirmed_issue | C21: Option | D21: Confirmed statistical or numerical reporting issue. The available evidence establishes a reporting issue or contradiction, even if the correct replacement value is not known.
B22: probable_issue | C22: Option | D22: Probable statistical or numerical reporting issue. The evidence favors a reporting issue, but an unresolved limitation or plausible alternative prevents confirmation.
B23: not_issue | C23: Option | D23: Not a statistical or numerical issue. The apparent discrepancy is consistent with a valid calculation, definition, analysis method or reporting context.
B24: indeterminate | C24: Option | D24: Indeterminate. The available evidence does not support deciding whether a statistical or numerical reporting issue exists; neither confirmation nor dismissal is justified.
B25: not_applicable | C25: Option | D25: Automatic default outside this field's review domain or for a non-retained candidate. It is not an issue verdict, missing evidence, or an unanswered applicable question. Do not choose it for an applicable field.
A26: Substantiveness | B26: FIELD | C26: Required; retained statistical_results | D26: Could the issue meaningfully affect interpretation or data use? A harmless spacing typo is minor_presentation; an ambiguous extractable effect estimate may be substantive. An issue can be confirmed yet minor. | E26: substantiveStatus
B27: substantive | C27: Option | D27: Substantive. The issue could meaningfully change interpretation, data extraction or downstream analysis, rather than only the presentation of the result.
B28: minor_presentation | C28: Option | D28: Minor or presentation only. The intended result remains clear and the issue is a small formatting, labeling or typographic problem without a meaningful change in interpretation.
B29: indeterminate | C29: Option | D29: Indeterminate. There is not enough information to decide whether the issue is substantive or limited to presentation.
B30: not_applicable | C30: Option | D30: Automatic default outside this field's review domain or for a non-retained candidate. It is not an issue verdict, missing evidence, or an unanswered applicable question. Do not choose it for an applicable field.
A31: Downstream impact | B31: FIELD | C31: Optional; retained statistical_results | D31: Add only useful information about later extraction or analysis. direct means the affected value itself may be extracted, not that harm has occurred. Blank is allowed and means not assessed; it is not unlikely or not_applicable. This field does not determine temporal eligibility. | E31: downstreamImpact
B32: direct | C32: Option | D32: Direct extraction or analysis impact. The affected value or definition is itself an input to data extraction or subsequent analysis; this describes potential impact, not proven downstream harm.
B33: possible | C33: Option | D33: Possible downstream impact. A plausible route to affecting later interpretation, extraction or analysis exists, but the connection is indirect or uncertain.
B34: unlikely | C34: Option | D34: Unlikely downstream impact. The issue is unlikely to change extracted information or later analysis because the relevant result remains clear and usable.
B35: unknown | C35: Option | D35: Unable to assess. The materials do not establish enough about the affected information or its likely use to judge downstream impact.
B36: not_applicable | C36: Option | D36: Automatic default outside this field's review domain or for a non-retained candidate. It is not an issue verdict, missing evidence, or an unanswered applicable question. Do not choose it for an applicable field.
A37: 3 | Report internal or planning-material inconsistency
A38: Report-internal or planning-material inconsistency | B38: FIELD | C38: Required; retained report_internal_inconsistency or plan_material | D38: Judge whether the compared materials are inconsistent and how much that matters. For report_internal_inconsistency, compare content within the main paper, within the updated supplement, or between those two report materials. For plan_material, compare planning materials such as protocol versus protocol or SAP. Plan versus final report belongs to protocol_report. Use statistical_results when specifically judging a statistical or numerical reporting issue. | E38: internalStatus
B39: substantive_inconsistency | C39: Option | D39: Substantive inconsistency. Conflicting statements, values, labels, or descriptions in the compared report or planning materials could materially change how the study, population, procedures or results are understood.
B40: minor_presentation | C40: Option | D40: Minor presentation inconsistency. A real discrepancy exists, but it mainly affects presentation, including minor wording or labeling problems, and the intended meaning remains clear. Example: an imprecise label whose intended meaning is clear from context.
...

Sheet Rule_defaults
A1: Retained domain | B1: Required | C1: Optional | D1: Inactive | E1: Inactive effective value
A2: statistical_results | B2: H, I | C2: J | D2: K, L | E2: not_applicable
A3: report_internal_inconsistency | B3: K | C3: None | D3: H, I, J, L | E3: not_applicable
A4: plan_material | B4: K | C4: None | D4: H, I, J, L | E4: not_applicable
A5: protocol_report | B5: None | C5: L | D5: H, I, J, K | E5: not_applicable
A6: exclude / discuss | B6: D and valid E | C6: R notes | D6: H, I, J, K, L | E6: not_applicable
A7: Reference only | B7: Protected ranges: none | C7: All inputs remain editable | D7: WORKFLOW.md sections 5-6 | E7: not_applicable

Sheet Manifest
A1: field | B1: value
A2: version | B2: v.2.3.1
A3: schema | B3: xlsx-adjudication-independent-primary-2.3.1
A4: year | B4: 2019
A5: reviewer_role | B5: R_A
A6: cohort | B6: User-authorized subset of the annual v.2.1.5.3 baseline: 9 papers / 62 candidates.
A7: source_baseline | B7: Frozen v.2.1.5.3 annual workbook and catalog, recovered from archived_not_touch.zip. All seven source hashes match supplied inventory.
A8: source_sheets | B8: Included Candidates, Evidence, Links and Relations rows preserved exactly, in baseline order. Clickable source targets added separately.
A9: protected_ranges | B9: None. All cell styles, cells and unused cells explicitly unlocked; no sheet or workbook protection, passwords or hidden formulas.
A10: C_columns | B10: A=key; B=title; C=source location; D=disposition; E=editable AI-suggested domain; F=manual completion; G=readiness; H=issue; I=substantiveness; J=optional impact; K=inconsistency; L=optional protocol interpretation; M-Q=empty hidden spacers; R=optional English notes.
A11: Setup_cells | B11: B2=required reviewer ID or name; B3=optional reviewer name; B4=this role; B5=2019; B6=schema.
A12: Decisions_columns | B12: A-D=year/paper/key/relationship; E-F=role/ID; G=readiness; H=outcome; I-J=baseline AI suggestions; K-R=effective disposition/domain/H-L/notes; S=name; T=completion; U=unresolved flag.
A13: Paper_counts_columns | B13: A-C=year/paper/total; D=ready; E=unfinished; F=discuss; G=entry complete; H=counts available; I-M=primary/secondary temporal, protocol/plan descriptive, not eligible.
A14: Protocol_plan_table_columns | B14: A-F=source year/paper/key/relationship/title/statement; G=readiness; H=disposition; I=domain; J=interpretation; K=internalStatus; L=notes; M=outcome; N-O=role/ID.
A15: counts_gate_adaptation | B15: v.2.3.1: all paper rows primary-ready AND no discuss before outcome counts appear. Independent completion may include discuss.
A16: default_behavior | B16: Original H-L formulas preserved. Selecting an answer replaces the formula. Inactive effective values normalize to not_applicable; stale inactive inputs block readiness first.
... A28: sha256 maintenance/codebook.json | B28: ac8b19fb1bbf9b55a1ad86644f07d1b33ad2f9ca30c073c25493b733b837a7d5
